Workbook

Sheet Cover
A1: AL NAKHEEL GATE – MIXED-USE DEVELOPMENT, RIYADH (SAR)
A2: Development and hold model · monthly, 96 months · synthetic demo data prepared for Adel Real Estate
A4: Purpose | B4: Investment committee model for a mixed-use scheme: residential for sale, retail and office for lease, a 220-key hotel.
A5: Currency and units | B5: SAR. Monthly cash flows on the Cash Flow sheet; annual summary on Annual; headline results on Dashboard.
A6: How to use | B6: Change only the yellow cells on Inputs (blue figures). Pick the case on Inputs!C5. Every other figure is a formula.
A7: Sheets | B7: Inputs · Cash Flow · Annual · Financing · Waterfall · Sensitivity · Checks · Dashboard
A8: Checks | B8: All checks on the Checks sheet must read OK; the overall flag is on the Dashboard.
A9: Status | B9: Synthetic demo model: no client data.

Sheet Dashboard
A1: DASHBOARD – AL NAKHEEL GATE
A2: Headline results for the case running on Inputs!C5
A4: Case | B4: =Inputs!D5 -> Base | D4: Checks | E4: =Checks!C14 -> OK
A6: Levered IRR | B6: =Returns!B6 -> 0.57448578 | D6: Total development cost (SAR) | E6: =Returns!B10 -> 2.1062646e+09
A7: Unlevered IRR | B7: =Returns!B5 -> 0.47109571 | D7: Peak debt (SAR) | E7: =Returns!B13 -> 9.8399335e+08
A8: Net profit to equity (SAR) | B8: =Returns!B9 -> 8.3381152e+09 | D8: Peak equity (SAR) | E8: =Returns!B14 -> 1.095802e+09
A9: Profit on cost | B9: =Returns!B11 -> 4.1235626 | D9: Minimum DSCR | E9: =Returns!B15 -> 5.7464552
A10: Equity multiple | B10: =Returns!B12 -> 8.4639044 | D10: Maximum LTV in operation | E10: =Returns!B16 -> 0.11221875
A11: NPV at the discount rate (SAR) | B11: =Returns!B7 -> 4.5376353e+09 | D11: Exit value (SAR) | E11: =Returns!B17 -> 8.5642364e+09
A13: Joint venture
A14: LP multiple | B14: =Returns!B18 -> 6.5979283
A15: GP multiple | B15: =Returns!B19 -> 25.257689
A16: Promote paid to the GP (SAR) | B16: =Returns!B20 -> 2.0845288e+09

Sheet Inputs
A1: INPUTS
A2: Yellow cells are inputs; the live case is chosen in C5
A4: Case
A5: Case running (1 = Base, 2 = Upside, 3 = Downside) | C5: 1 | D5: =CHOOSE(C5,"Base","Upside","Downside") -> Base
A7: Assumption | B7: Live | C7: Base | D7: Upside | E7: Downside | G7: Note
A9: Timing
A10: Model start (month 0) | B10: =CHOOSE($C$5,C10,D10,E10) -> 46387 | C10: 46387 | D10: 46387 | E10: 46387
A11: Construction period (months) | B11: =CHOOSE($C$5,C11,D11,E11) -> 30 | C11: 30 | D11: 28 | E11: 32
A12: Hold after completion before the exit (months) | B12: =CHOOSE($C$5,C12,D12,E12) -> 42 | C12: 42 | D12: 42 | E12: 42 | G12: Exit at month construction + hold
A14: Land and construction
A15: Land price (SAR) | B15: =CHOOSE($C$5,C15,D15,E15) -> 650000000 | C15: 650000000 | D15: 650000000 | E15: 650000000
A16: Real estate transaction tax on land | B16: =CHOOSE($C$5,C16,D16,E16) -> 0.05 | C16: 0.05 | D16: 0.05 | E16: 0.05
A17: Gross floor area (sqm) | B17: =CHOOSE($C$5,C17,D17,E17) -> 186000 | C17: 186000 | D17: 186000 | E17: 186000
A18: Construction cost (SAR per sqm GFA) | B18: =CHOOSE($C$5,C18,D18,E18) -> 6200 | C18: 6200 | D18: 6000 | E18: 6350
A19: Professional fees and soft costs (share of construction) | B19: =CHOOSE($C$5,C19,D19,E19) -> 0.11 | C19: 0.11 | D19: 0.1 | E19: 0.12
A20: Contingency (share of construction) | B20: =CHOOSE($C$5,C20,D20,E20) -> 0.06 | C20: 0.06 | D20: 0.05 | E20: 0.08
A22: Residential for sale (off-plan)
A23: Apartments | B23: =CHOOSE($C$5,C23,D23,E23) -> 540 | C23: 540 | D23: 540 | E23: 540
A24: Average price per apartment (SAR) | B24: =CHOOSE($C$5,C24,D24,E24) -> 1750000 | C24: 1750000 | D24: 1850000 | E24: 1710000
A25: Sales launch (month) | B25: =CHOOSE($C$5,C25,D25,E25) -> 3 | C25: 3 | D25: 3 | E25: 6
A26: Months to sell out | B26: =CHOOSE($C$5,C26,D26,E26) -> 30 | C26: 30 | D26: 24 | E26: 36
A27: Deposit at signing | B27: =CHOOSE($C$5,C27,D27,E27) -> 0.1 | C27: 0.1 | D27: 0.1 | E27: 0.1
A28: Escrow released to the developer, share of construction progress | B28: =CHOOSE($C$5,C28,D28,E28) -> 1 | C28: 1 | D28: 1 | E28: 0.95 | G28: Wafi: collections released as the build progresses
A29: Sales commission and marketing | B29: =CHOOSE($C$5,C29,D29,E29) -> 0.025 | C29: 0.025 | D29: 0.025 | E29: 0.03
A31: Retail and offices (leased and held)
A32: Retail leasable area (sqm) | B32: =CHOOSE($C$5,C32,D32,E32) -> 32000 | C32: 32000 | D32: 32000 | E32: 32000
A33: Retail rent (SAR per sqm a year) | B33: =CHOOSE($C$5,C33,D33,E33) -> 1850 | C33: 1850 | D33: 1950 | E33: 1790
A34: Office leasable area (sqm) | B34: =CHOOSE($C$5,C34,D34,E34) -> 410000 | C34: 410000 | D34: 41000 | E34: 41000
A35: Office rent (SAR per sqm a year) | B35: =CHOOSE($C$5,C35,D35,E35) -> 1350 | C35: 1350 | D35: 1450 | E35: 1310
A36: Lease-up after completion (months to stabilise) | B36: =CHOOSE($C$5,C36,D36,E36) -> 18 | C36: 18 | D36: 12 | E36: 24
A37: Stabilised occupancy | B37: =CHOOSE($C$5,C37,D37,E37) -> 0.92 | C37: 0.92 | D37: 0.95 | E37: 0.9
A38: Rent-free on first leases (months) | B38: =CHOOSE($C$5,C38,D38,E38) -> 4 | C38: 4 | D38: 3 | E38: 6
A39: Rent growth a year | B39: =CHOOSE($C$5,C39,D39,E39) -> 0.03 | C39: 0.03 | D39: 0.035 | E39: 0.015
A40: Non-recoverable costs (share of rent) | B40: =CHOOSE($C$5,C40,D40,E40) -> 0.12 | C40: 0.12 | D40: 0.11 | E40: 0.14
A42: Hotel (220 keys)
A43: Keys | B43: =CHOOSE($C$5,C43,D43,E43) -> 220 | C43: 220 | D43: 220 | E43: 220
A44: Average daily rate, opening year (SAR) | B44: =CHOOSE($C$5,C44,D44,E44) -> 780 | C44: 780 | D44: 820 | E44: 755
A45: Stabilised occupancy | B45: =CHOOSE($C$5,C45,D45,E45) -> 0.72 | C45: 0.72 | D45: 0.76 | E45: 0.69
A46: Ramp-up (months to stabilise) | B46: =CHOOSE($C$5,C46,D46,E46) -> 24 | C46: 24 | D46: 18 | E46: 30
A47: GOP margin (after operator fees) | B47: =CHOOSE($C$5,C47,D47,E47) -> 0.34 | C47: 0.34 | D47: 0.36 | E47: 0.3
...

Sheet Cash Flow
A1: CASH FLOW – MONTHLY (SAR)
A2: Months 0–96 across; every row is a formula; totals in column B
A5: Month | B5: Total | C5: 0 | D5: 1 | E5: 2 | F5: 3 | G5: 4 | H5: 5 | I5: 6 | J5: 7 | K5: 8 | L5: 9 | M5: 10 | N5: 11 | O5: 12 | P5: 13 | Q5: 14 | R5: 15 | S5: 16 | T5: 17 | U5: 18 | V5: 19 | W5: 20 | X5: 21 | Y5: 22 | Z5: 23 | AA5: 24 | AB5: 25 | AC5: 26 | AD5: 27 | AE5: 28 | AF5: 29 | AG5: 30 | AH5: 31 | AI5: 32 | AJ5: 33 | AK5: 34 | AL5: 35 | AM5: 36 | AN5: 37 | AO5: 38 | AP5: 39 | AQ5: 40 | AR5: 41 | AS5: 42 | AT5: 43 | AU5: 44 | AV5: 45 | AW5: 46 | AX5: 47 | AY5: 48 | AZ5: 49 | BA5: 50 | BB5: 51 | BC5: 52 | BD5: 53 | BE5: 54 | BF5: 55 | BG5: 56 | BH5: 57 | BI5: 58 | BJ5: 59 | BK5: 60 | BL5: 61 | BM5: 62 | BN5: 63 | BO5: 64 | BP5: 65 | BQ5: 66 | BR5: 67 | BS5: 68 | BT5: 69 | BU5: 70 | BV5: 71 | BW5: 72 | BX5: 73 | BY5: 74 | BZ5: 75 | CA5: 76 | CB5: 77 | CC5: 78 | CD5: 79 | CE5: 80 | CF5: 81 | CG5: 82 | CH5: 83 | CI5: 84 | CJ5: 85 | CK5: 86 | CL5: 87 | CM5: 88 | CN5: 89 | CO5: 90 | CP5: 91 | CQ5: 92 | CR5: 93 | CS5: 94 | CT5: 95 | CU5: 96
A8: Timeline
A9: Month | C9: =C$5 -> 0 | D9: =D$5 -> 1 | E9: =E$5 -> 2 | F9: =F$5 -> 3 | G9: =G$5 -> 4 | H9: =H$5 -> 5 | I9: =I$5 -> 6 | J9: =J$5 -> 7 | ... CU9: =CU$5 -> 96
A10: Month end | C10: =EOMONTH(StartDate,C$5) -> 46387 | D10: =EOMONTH(StartDate,D$5) -> 46418 | E10: =EOMONTH(StartDate,E$5) -> 46446 | F10: =EOMONTH(StartDate,F$5) -> 46477 | G10: =EOMONTH(StartDate,G$5) -> 46507 | H10: =EOMONTH(StartDate,H$5) -> 46538 | I10: =EOMONTH(StartDate,I$5) -> 46568 | J10: =EOMONTH(StartDate,J$5) -> 46599 | ... CU10: =EOMONTH(StartDate,CU$5) -> 49309
A11: Year | C11: =YEAR(C10) -> 2026 | D11: =YEAR(D10) -> 2027 | E11: =YEAR(E10) -> 2027 | F11: =YEAR(F10) -> 2027 | G11: =YEAR(G10) -> 2027 | H11: =YEAR(H10) -> 2027 | I11: =YEAR(I10) -> 2027 | J11: =YEAR(J10) -> 2027 | ... CU11: =YEAR(CU10) -> 2034
A12: Construction flag | C12: =IF(AND(C$5>=1,C$5<=BuildMonths),1,0) -> 0 | D12: =IF(AND(D$5>=1,D$5<=BuildMonths),1,0) -> 1 | E12: =IF(AND(E$5>=1,E$5<=BuildMonths),1,0) -> 1 | F12: =IF(AND(F$5>=1,F$5<=BuildMonths),1,0) -> 1 | G12: =IF(AND(G$5>=1,G$5<=BuildMonths),1,0) -> 1 | H12: =IF(AND(H$5>=1,H$5<=BuildMonths),1,0) -> 1 | I12: =IF(AND(I$5>=1,I$5<=BuildMonths),1,0) -> 1 | J12: =IF(AND(J$5>=1,J$5<=BuildMonths),1,0) -> 1 | ... CU12: =IF(AND(CU$5>=1,CU$5<=BuildMonths),1,0) -> 0
A13: Operating flag | C13: =IF(AND(C$5>BuildMonths,C$5<=BuildMonths+HoldMonths),1,0) -> 0 | D13: =IF(AND(D$5>BuildMonths,D$5<=BuildMonths+HoldMonths),1,0) -> 0 | E13: =IF(AND(E$5>BuildMonths,E$5<=BuildMonths+HoldMonths),1,0) -> 0 | F13: =IF(AND(F$5>BuildMonths,F$5<=BuildMonths+HoldMonths),1,0) -> 0 | G13: =IF(AND(G$5>BuildMonths,G$5<=BuildMonths+HoldMonths),1,0) -> 0 | H13: =IF(AND(H$5>BuildMonths,H$5<=BuildMonths+HoldMonths),1,0) -> 0 | I13: =IF(AND(I$5>BuildMonths,I$5<=BuildMonths+HoldMonths),1,0) -> 0 | J13: =IF(AND(J$5>BuildMonths,J$5<=BuildMonths+HoldMonths),1,0) -> 0 | ... CU13: =IF(AND(CU$5>BuildMonths,CU$5<=BuildMonths+HoldMonths),1,0) -> 0
A14: Exit flag | C14: =IF(C$5=BuildMonths+HoldMonths,1,0) -> 0 | D14: =IF(D$5=BuildMonths+HoldMonths,1,0) -> 0 | E14: =IF(E$5=BuildMonths+HoldMonths,1,0) -> 0 | F14: =IF(F$5=BuildMonths+HoldMonths,1,0) -> 0 | G14: =IF(G$5=BuildMonths+HoldMonths,1,0) -> 0 | H14: =IF(H$5=BuildMonths+HoldMonths,1,0) -> 0 | I14: =IF(I$5=BuildMonths+HoldMonths,1,0) -> 0 | J14: =IF(J$5=BuildMonths+HoldMonths,1,0) -> 0 | ... CU14: =IF(CU$5=BuildMonths+HoldMonths,1,0) -> 0
A15: Construction S-curve (share this month) | B15: =SUM(C15:CU15) -> 1 | C15: =IF(C12=1,(1-COS(PI()*C$5/BuildMonths))/2-(1-COS(PI()*(C$5-1)/BuildMonths))/2,0) -> 0 | D15: =IF(D12=1,(1-COS(PI()*D$5/BuildMonths))/2-(1-COS(PI()*(D$5-1)/BuildMonths))/2,0) -> 0.0027390523 | E15: =IF(E12=1,(1-COS(PI()*E$5/BuildMonths))/2-(1-COS(PI()*(E$5-1)/BuildMonths))/2,0) -> 0.0081871473 | F15: =IF(F12=1,(1-COS(PI()*F$5/BuildMonths))/2-(1-COS(PI()*(F$5-1)/BuildMonths))/2,0) -> 0.013545542 | G15: =IF(G12=1,(1-COS(PI()*G$5/BuildMonths))/2-(1-COS(PI()*(G$5-1)/BuildMonths))/2,0) -> 0.018755529 | H15: =IF(H12=1,(1-COS(PI()*H$5/BuildMonths))/2-(1-COS(PI()*(H$5-1)/BuildMonths))/2,0) -> 0.023760027 | I15: =IF(I12=1,(1-COS(PI()*I$5/BuildMonths))/2-(1-COS(PI()*(I$5-1)/BuildMonths))/2,0) -> 0.028504205 | J15: =IF(J12=1,(1-COS(PI()*J$5/BuildMonths))/2-(1-COS(PI()*(J$5-1)/BuildMonths))/2,0) -> 0.032936084 | ... CU15: =IF(CU12=1,(1-COS(PI()*CU$5/BuildMonths))/2-(1-COS(PI()*(CU$5-1)/BuildMonths))/2,0) -> 0
A16: Construction progress (cumulative) | C16: =SUM($C15:C15) -> 0 | D16: =SUM($C15:D15) -> 0.0027390523 | E16: =SUM($C15:E15) -> 0.0109262 | F16: =SUM($C15:F15) -> 0.024471742 | G16: =SUM($C15:G15) -> 0.043227271 | H16: =SUM($C15:H15) -> 0.066987298 | I16: =SUM($C15:I15) -> 0.095491503 | J16: =SUM($C15:J15) -> 0.12842759 | ... CU16: =SUM($C15:CU15) -> 1
A18: Development cost
A19: Land | B19: =SUM(C19:CU19) -> 650000000 | C19: =IF(C$5=0,Land,0) -> 650000000 | D19: =IF(D$5=0,Land,0) -> 0 | E19: =IF(E$5=0,Land,0) -> 0 | F19: =IF(F$5=0,Land,0) -> 0 | G19: =IF(G$5=0,Land,0) -> 0 | H19: =IF(H$5=0,Land,0) -> 0 | I19: =IF(I$5=0,Land,0) -> 0 | J19: =IF(J$5=0,Land,0) -> 0 | ... CU19: =IF(CU$5=0,Land,0) -> 0
A20: RETT on land | B20: =SUM(C20:CU20) -> 32500000 | C20: =C19*RETT -> 32500000 | D20: =D19*RETT -> 0 | E20: =E19*RETT -> 0 | F20: =F19*RETT -> 0 | G20: =G19*RETT -> 0 | H20: =H19*RETT -> 0 | I20: =I19*RETT -> 0 | J20: =J19*RETT -> 0 | ... CU20: =CU19*RETT -> 0
A21: Construction | B21: =SUM(C21:CU21) -> 1153200000 | C21: =GFA*BuildRate*C15 -> 0 | D21: =GFA*BuildRate*D15 -> 3158675.1 | E21: =GFA*BuildRate*E15 -> 9441418.3 | F21: =GFA*BuildRate*F15 -> 15620719 | G21: =GFA*BuildRate*G15 -> 21628876 | H21: =GFA*BuildRate*H15 -> 27400063 | I21: =GFA*BuildRate*I15 -> 32871049 | J21: =GFA*BuildRate*J15 -> 37981893 | ... CU21: =GFA*BuildRate*CU15 -> 0
A22: Soft costs | B22: =SUM(C22:CU22) -> 126852000 | C22: =C21*SoftCosts -> 0 | D22: =D21*SoftCosts -> 347454.26 | E22: =E21*SoftCosts -> 1038556 | F22: =F21*SoftCosts -> 1718279.1 | G22: =G21*SoftCosts -> 2379176.4 | H22: =H21*SoftCosts -> 3014006.9 | I22: =I21*SoftCosts -> 3615815.4 | J22: =J21*SoftCosts -> 4178008.2 | ... CU22: =CU21*SoftCosts -> 0
A23: Contingency | B23: =SUM(C23:CU23) -> 69192000 | C23: =C21*Contingency -> 0 | D23: =D21*Contingency -> 189520.51 | E23: =E21*Contingency -> 566485.1 | F23: =F21*Contingency -> 937243.16 | G23: =G21*Contingency -> 1297732.6 | H23: =H21*Contingency -> 1644003.8 | I23: =I21*Contingency -> 1972262.9 | J23: =J21*Contingency -> 2278913.6 | ... CU23: =CU21*Contingency -> 0
A24: Development cost before finance | B24: =SUM(C24:AF24) -> 2.0280484e+09 | C24: =SUM(C19:C23) -> 682500000 | D24: =SUM(D19:D23) -> 3695649.9 | E24: =SUM(E19:E23) -> 11046459 | F24: =SUM(F19:F23) -> 18276242 | G24: =SUM(G19:G23) -> 25305785 | H24: =SUM(H19:H23) -> 32058074 | I24: =SUM(I19:I23) -> 38459127 | J24: =SUM(J19:J23) -> 44438814 | ... CU24: =SUM(CU19:CU23) -> 0
A26: Residential sales (off-plan)
A27: Apartments sold | B27: =SUM(C27:CU27) -> 540 | C27: =IF(AND(C$5>=ResSalesStart,C$5<ResSalesStart+ResSalesMonths),ResUnits/ResSalesMonths,0) -> 0 | D27: =IF(AND(D$5>=ResSalesStart,D$5<ResSalesStart+ResSalesMonths),ResUnits/ResSalesMonths,0) -> 0 | E27: =IF(AND(E$5>=ResSalesStart,E$5<ResSalesStart+ResSalesMonths),ResUnits/ResSalesMonths,0) -> 0 | F27: =IF(AND(F$5>=ResSalesStart,F$5<ResSalesStart+ResSalesMonths),ResUnits/ResSalesMonths,0) -> 18 | G27: =IF(AND(G$5>=ResSalesStart,G$5<ResSalesStart+ResSalesMonths),ResUnits/ResSalesMonths,0) -> 18 | H27: =IF(AND(H$5>=ResSalesStart,H$5<ResSalesStart+ResSalesMonths),ResUnits/ResSalesMonths,0) -> 18 | I27: =IF(AND(I$5>=ResSalesStart,I$5<ResSalesStart+ResSalesMonths),ResUnits/ResSalesMonths,0) -> 18 | J27: =IF(AND(J$5>=ResSalesStart,J$5<ResSalesStart+ResSalesMonths),ResUnits/ResSalesMonths,0) -> 18 | ... CU27: =IF(AND(CU$5>=ResSalesStart,CU$5<ResSalesStart+ResSalesMonths),ResUnits/ResSalesMonths,0) -> 0
A28: Contract value signed | B28: =SUM(C28:CU28) -> 945000000 | C28: =C27*ResPrice -> 0 | D28: =D27*ResPrice -> 0 | E28: =E27*ResPrice -> 0 | F28: =F27*ResPrice -> 31500000 | G28: =G27*ResPrice -> 31500000 | H28: =H27*ResPrice -> 31500000 | I28: =I27*ResPrice -> 31500000 | J28: =J27*ResPrice -> 31500000 | ... CU28: =CU27*ResPrice -> 0
A29: Balance owed by buyers before this month's payments | C29: =C28*(1-ResDeposit) -> 0 | D29: =C31+D28*(1-ResDeposit) -> 0 | E29: =D31+E28*(1-ResDeposit) -> 0 | F29: =E31+F28*(1-ResDeposit) -> 28350000 | G29: =F31+G28*(1-ResDeposit) -> 56311742 | H29: =G31+H28*(1-ResDeposit) -> 83579091 | I29: =H31+I28*(1-ResDeposit) -> 1.0985353e+08 | J29: =I31+J28*(1-ResDeposit) -> 1.3484742e+08 | K29: =J31+K28*(1-ResDeposit) -> 1.5828719e+08 | ... CU29: =CT31+CU28*(1-ResDeposit) -> 0
A30: Instalments paid (with construction progress; in full after completion) | B30: =SUM(C30:CU30) -> 850500000 | C30: =IF(C$5<=BuildMonths,C29*C15/MAX(0.000001,1-C16+C15),C29) -> 0 | D30: =IF(D$5<=BuildMonths,D29*D15/MAX(0.000001,1-D16+D15),D29) -> 0 | E30: =IF(E$5<=BuildMonths,E29*E15/MAX(0.000001,1-E16+E15),E29) -> 0 | F30: =IF(F$5<=BuildMonths,F29*F15/MAX(0.000001,1-F16+F15),F29) -> 388258.31 | G30: =IF(G$5<=BuildMonths,G29*G15/MAX(0.000001,1-G16+G15),G29) -> 1082650.9 | H30: =IF(H$5<=BuildMonths,H29*H15/MAX(0.000001,1-H16+H15),H29) -> 2075562.3 | I30: =IF(I$5<=BuildMonths,I29*I15/MAX(0.000001,1-I16+I15),I29) -> 3356103.8 | J30: =IF(J$5<=BuildMonths,J29*J15/MAX(0.000001,1-J16+J15),J29) -> 4910231.6 | ... CU30: =IF(CU$5<=BuildMonths,CU29*CU15/MAX(0.000001,1-CU16+CU15),CU29) -> 0
A31: Balance owed by buyers | C31: =C29-C30 -> 0 | D31: =D29-D30 -> 0 | E31: =E29-E30 -> 0 | F31: =F29-F30 -> 27961742 | G31: =G29-G30 -> 55229091 | H31: =H29-H30 -> 81503528 | I31: =I29-I30 -> 1.0649742e+08 | J31: =J29-J30 -> 1.2993719e+08 | ... CU31: =CU29-CU30 -> 0
A32: Buyer payments into escrow | B32: =SUM(C32:CU32) -> 945000000 | C32: =C28*ResDeposit+C30 -> 0 | D32: =D28*ResDeposit+D30 -> 0 | E32: =E28*ResDeposit+E30 -> 0 | F32: =F28*ResDeposit+F30 -> 3538258.3 | G32: =G28*ResDeposit+G30 -> 4232650.9 | H32: =H28*ResDeposit+H30 -> 5225562.3 | I32: =I28*ResDeposit+I30 -> 6506103.8 | J32: =J28*ResDeposit+J30 -> 8060231.6 | ... CU32: =CU28*ResDeposit+CU30 -> 0
A33: Escrow the developer may draw (cumulative) | C33: =IF(C$5<BuildMonths,SUM($C32:C32)*C16*ResEscrowRel,SUM($C32:C32)) -> 0 | D33: =IF(D$5<BuildMonths,SUM($C32:D32)*D16*ResEscrowRel,SUM($C32:D32)) -> 0 | E33: =IF(E$5<BuildMonths,SUM($C32:E32)*E16*ResEscrowRel,SUM($C32:E32)) -> 0 | F33: =IF(F$5<BuildMonths,SUM($C32:F32)*F16*ResEscrowRel,SUM($C32:F32)) -> 86587.344 | G33: =IF(G$5<BuildMonths,SUM($C32:G32)*G16*ResEscrowRel,SUM($C32:G32)) -> 335915.2 | H33: =IF(H$5<BuildMonths,SUM($C32:H32)*H16*ResEscrowRel,SUM($C32:H32)) -> 870598.51 | I33: =IF(I$5<BuildMonths,SUM($C32:I32)*I16*ResEscrowRel,SUM($C32:I32)) -> 1862330.2 | J33: =IF(J$5<BuildMonths,SUM($C32:J32)*J16*ResEscrowRel,SUM($C32:J32)) -> 3539824.8 | ... CU33: =IF(CU$5<BuildMonths,SUM($C32:CU32)*CU16*ResEscrowRel,SUM($C32:CU32)) -> 945000000
A34: Escrow released to the developer | B34: =SUM(C34:CU34) -> 945000000 | C34: =C33 -> 0 | D34: =MAX(0,D33-SUM($C34:C34)) -> 0 | E34: =MAX(0,E33-SUM($C34:D34)) -> 0 | F34: =MAX(0,F33-SUM($C34:E34)) -> 86587.344 | G34: =MAX(0,G33-SUM($C34:F34)) -> 249327.85 | H34: =MAX(0,H33-SUM($C34:G34)) -> 534683.31 | I34: =MAX(0,I33-SUM($C34:H34)) -> 991731.71 | J34: =MAX(0,J33-SUM($C34:I34)) -> 1677494.6 | K34: =MAX(0,K33-SUM($C34:J34)) -> 2653009.3 | ... CU34: =MAX(0,CU33-SUM($C34:CT34)) -> 0
A35: Sales commission and marketing | B35: =SUM(C35:CU35) -> 23625000 | C35: =C28*SalesComm -> 0 | D35: =D28*SalesComm -> 0 | E35: =E28*SalesComm -> 0 | F35: =F28*SalesComm -> 787500 | G35: =G28*SalesComm -> 787500 | H35: =H28*SalesComm -> 787500 | I35: =I28*SalesComm -> 787500 | J35: =J28*SalesComm -> 787500 | ... CU35: =CU28*SalesComm -> 0
A36: VAT on sales | B36: =SUM(C36:CU36) -> 0 | C36: =C34*VAT -> 0 | D36: =D34*VAT -> 0 | E36: =E34*VAT -> 0 | F36: =F34*VAT -> 0 | G36: =G34*VAT -> 0 | H36: =H34*VAT -> 0 | I36: =I34*VAT -> 0 | J36: =J34*VAT -> 0 | ... CU36: =CU34*VAT -> 0
A38: Retail and offices
A39: Occupancy | C39: =IF(C13=1,StabOcc*MIN(1,(C$5-BuildMonths)/LeaseUp),0) -> 0 | D39: =IF(D13=1,StabOcc*MIN(1,(D$5-BuildMonths)/LeaseUp),0) -> 0 | E39: =IF(E13=1,StabOcc*MIN(1,(E$5-BuildMonths)/LeaseUp),0) -> 0 | F39: =IF(F13=1,StabOcc*MIN(1,(F$5-BuildMonths)/LeaseUp),0) -> 0 | G39: =IF(G13=1,StabOcc*MIN(1,(G$5-BuildMonths)/LeaseUp),0) -> 0 | H39: =IF(H13=1,StabOcc*MIN(1,(H$5-BuildMonths)/LeaseUp),0) -> 0 | I39: =IF(I13=1,StabOcc*MIN(1,(I$5-BuildMonths)/LeaseUp),0) -> 0 | J39: =IF(J13=1,StabOcc*MIN(1,(J$5-BuildMonths)/LeaseUp),0) -> 0 | ... CU39: =IF(CU13=1,StabOcc*MIN(1,(CU$5-BuildMonths)/LeaseUp),0) -> 0
A40: Rent index | C40: =(1+RentGrowth)^(MAX(0,C$5-1)/12) -> 1 | D40: =(1+RentGrowth)^(MAX(0,D$5-1)/12) -> 1 | E40: =(1+RentGrowth)^(MAX(0,E$5-1)/12) -> 1.0024663 | F40: =(1+RentGrowth)^(MAX(0,F$5-1)/12) -> 1.0049386 | G40: =(1+RentGrowth)^(MAX(0,G$5-1)/12) -> 1.0074171 | H40: =(1+RentGrowth)^(MAX(0,H$5-1)/12) -> 1.0099016 | I40: =(1+RentGrowth)^(MAX(0,I$5-1)/12) -> 1.0123923 | J40: =(1+RentGrowth)^(MAX(0,J$5-1)/12) -> 1.0148892 | ... CU40: =(1+RentGrowth)^(MAX(0,CU$5-1)/12) -> 1.2636536
A41: Rent-free factor | C41: =IF(AND(C13=1,C$5<=BuildMonths+RentFree),0,1) -> 1 | D41: =IF(AND(D13=1,D$5<=BuildMonths+RentFree),0,1) -> 1 | E41: =IF(AND(E13=1,E$5<=BuildMonths+RentFree),0,1) -> 1 | F41: =IF(AND(F13=1,F$5<=BuildMonths+RentFree),0,1) -> 1 | G41: =IF(AND(G13=1,G$5<=BuildMonths+RentFree),0,1) -> 1 | H41: =IF(AND(H13=1,H$5<=BuildMonths+RentFree),0,1) -> 1 | I41: =IF(AND(I13=1,I$5<=BuildMonths+RentFree),0,1) -> 1 | J41: =IF(AND(J13=1,J$5<=BuildMonths+RentFree),0,1) -> 1 | ... CU41: =IF(AND(CU13=1,CU$5<=BuildMonths+RentFree),0,1) -> 1
A42: Retail rent | B42: =SUM(C42:CU42) -> 1.7115328e+08 | C42: =RetailGLA*RetailRent/12*C39*C40*C41 -> 0 | D42: =RetailGLA*RetailRent/12*D39*D40*D41 -> 0 | E42: =RetailGLA*RetailRent/12*E39*E40*E41 -> 0 | F42: =RetailGLA*RetailRent/12*F39*F40*F41 -> 0 | G42: =RetailGLA*RetailRent/12*G39*G40*G41 -> 0 | H42: =RetailGLA*RetailRent/12*H39*H40*H41 -> 0 | I42: =RetailGLA*RetailRent/12*I39*I40*I41 -> 0 | J42: =RetailGLA*RetailRent/12*J39*J40*J41 -> 0 | ... CU42: =RetailGLA*RetailRent/12*CU39*CU40*CU41 -> 0
A43: Office rent | B43: =SUM(C43:CU43) -> 1.5746858e+09 | C43: =OfficeGLA*OfficeRent/12*C39*C40*C41 -> 0 | D43: =OfficeGLA*OfficeRent/12*D39*D40*D41 -> 0 | E43: =OfficeGLA*OfficeRent/12*E39*E40*E41 -> 0 | F43: =OfficeGLA*OfficeRent/12*F39*F40*F41 -> 0 | G43: =OfficeGLA*OfficeRent/12*G39*G40*G41 -> 0 | H43: =OfficeGLA*OfficeRent/12*H39*H40*H41 -> 0 | I43: =OfficeGLA*OfficeRent/12*I39*I40*I41 -> 0 | J43: =OfficeGLA*OfficeRent/12*J39*J40*J41 -> 0 | ... AP43: =OfficeGLA*OfficeRent/12*AP39*AP40*AP41 -> 23299437 | AQ43: 412500 | AR43: =OfficeGLA*OfficeRent/12*AR39*AR40*AR41 -> 28617727 | AS43: =OfficeGLA*OfficeRent/12*AS39*AS40*AS41 -> 31296334 | AT43: =OfficeGLA*OfficeRent/12*AT39*AT40*AT41 -> 33987979 | AU43: =OfficeGLA*OfficeRent/12*AU39*AU40*AU41 -> 36692710 | AV43: =OfficeGLA*OfficeRent/12*AV39*AV40*AV41 -> 39410576 | AW43: =OfficeGLA*OfficeRent/12*AW39*AW40*AW41 -> 42141625 | AX43: =OfficeGLA*OfficeRent/12*AX39*AX40*AX41 -> 44885905 | AY43: =OfficeGLA*OfficeRent/12*AY39*AY40*AY41 -> 47643465 | ... CU43: =OfficeGLA*OfficeRent/12*CU39*CU40*CU41 -> 0
A44: Non-recoverable costs | B44: =SUM(C44:CU44) -> 2.0950068e+08 | C44: =(C42+C43)*Opex -> 0 | D44: =(D42+D43)*Opex -> 0 | E44: =(E42+E43)*Opex -> 0 | F44: =(F42+F43)*Opex -> 0 | G44: =(G42+G43)*Opex -> 0 | H44: =(H42+H43)*Opex -> 0 | I44: =(I42+I43)*Opex -> 0 | J44: =(J42+J43)*Opex -> 0 | ... CU44: =(CU42+CU43)*Opex -> 0
A45: Net operating income, retail and offices | B45: =SUM(C45:CU45) -> 1.5426983e+09 | C45: =C42+C43-C44 -> 0 | D45: =D42+D43-D44 -> 0 | E45: =E42+E43-E44 -> 0 | F45: =F42+F43-F44 -> 0 | G45: =G42+G43-G44 -> 0 | H45: =H42+H43-H44 -> 0 | I45: =I42+I43-I44 -> 0 | J45: =J42+J43-J44 -> 0 | ... AZ45: =AZ42+AZ43-AZ44 -> 46524963 | BA45: =BA42+BA43 -> 52999666 | BB45: =BB42+BB43-BB44 -> 46754732 | BC45: =BC42+BC43-BC44 -> 46870042 | BD45: =BD42+BD43-BD44 -> 46985636 | BE45: =BE42+BE43-BE44 -> 47101515 | BF45: =BF42+BF43-BF44 -> 47217680 | BG45: =BG42+BG43-BG44 -> 47334132 | BH45: =BH42+BH43-BH44 -> 47450870 | BI45: =BI42+BI43-BI44 -> 47567897 | ... CU45: =CU42+CU43-CU44 -> 0
A47: Hotel
A48: Hotel occupancy | C48: =IF(C13=1,HotelOcc*MIN(1,0.55+0.45*(C$5-BuildMonths)/HotelRamp),0) -> 0 | D48: =IF(D13=1,HotelOcc*MIN(1,0.55+0.45*(D$5-BuildMonths)/HotelRamp),0) -> 0 | E48: =IF(E13=1,HotelOcc*MIN(1,0.55+0.45*(E$5-BuildMonths)/HotelRamp),0) -> 0 | F48: =IF(F13=1,HotelOcc*MIN(1,0.55+0.45*(F$5-BuildMonths)/HotelRamp),0) -> 0 | G48: =IF(G13=1,HotelOcc*MIN(1,0.55+0.45*(G$5-BuildMonths)/HotelRamp),0) -> 0 | H48: =IF(H13=1,HotelOcc*MIN(1,0.55+0.45*(H$5-BuildMonths)/HotelRamp),0) -> 0 | I48: =IF(I13=1,HotelOcc*MIN(1,0.55+0.45*(I$5-BuildMonths)/HotelRamp),0) -> 0 | J48: =IF(J13=1,HotelOcc*MIN(1,0.55+0.45*(J$5-BuildMonths)/HotelRamp),0) -> 0 | ... CU48: =IF(CU13=1,HotelOcc*MIN(1,0.55+0.45*(CU$5-BuildMonths)/HotelRamp),0) -> 0
...

Sheet Financing
A1: FINANCING – MURABAHA CONSTRUCTION FACILITY
A2: Draws fund cost after the equity first loss; profit capitalised in construction, paid in operation
A5: Month | B5: Total | C5: 0 | D5: 1 | E5: 2 | F5: 3 | G5: 4 | H5: 5 | I5: 6 | J5: 7 | K5: 8 | L5: 9 | M5: 10 | N5: 11 | O5: 12 | P5: 13 | Q5: 14 | R5: 15 | S5: 16 | T5: 17 | U5: 18 | V5: 19 | W5: 20 | X5: 21 | Y5: 22 | Z5: 23 | AA5: 24 | AB5: 25 | AC5: 26 | AD5: 27 | AE5: 28 | AF5: 29 | AG5: 30 | AH5: 31 | AI5: 32 | AJ5: 33 | AK5: 34 | AL5: 35 | AM5: 36 | AN5: 37 | AO5: 38 | AP5: 39 | AQ5: 40 | AR5: 41 | AS5: 42 | AT5: 43 | AU5: 44 | AV5: 45 | AW5: 46 | AX5: 47 | AY5: 48 | AZ5: 49 | BA5: 50 | BB5: 51 | BC5: 52 | BD5: 53 | BE5: 54 | BF5: 55 | BG5: 56 | BH5: 57 | BI5: 58 | BJ5: 59 | BK5: 60 | BL5: 61 | BM5: 62 | BN5: 63 | BO5: 64 | BP5: 65 | BQ5: 66 | BR5: 67 | BS5: 68 | BT5: 69 | BU5: 70 | BV5: 71 | BW5: 72 | BX5: 73 | BY5: 74 | BZ5: 75 | CA5: 76 | CB5: 77 | CC5: 78 | CD5: 79 | CE5: 80 | CF5: 81 | CG5: 82 | CH5: 83 | CI5: 84 | CJ5: 85 | CK5: 86 | CL5: 87 | CM5: 88 | CN5: 89 | CO5: 90 | CP5: 91 | CQ5: 92 | CR5: 93 | CS5: 94 | CT5: 95 | CU5: 96
A7: Facility size | B7: =LTC*'Cash Flow'!B24 -> 9.1262176e+08
A8: All-in profit rate | B8: =SAIBOR+Margin/10000 -> 0.082
A9: Equity first (development cost the equity pays before the facility draws) | B9: ='Cash Flow'!B24-B7 -> 1.1154266e+09
A11: Cost to fund this month | C11: ='Cash Flow'!C24 -> 682500000 | D11: ='Cash Flow'!D24 -> 3695649.9 | E11: ='Cash Flow'!E24 -> 11046459 | F11: ='Cash Flow'!F24 -> 18276242 | G11: ='Cash Flow'!G24 -> 25305785 | H11: ='Cash Flow'!H24 -> 32058074 | I11: ='Cash Flow'!I24 -> 38459127 | J11: ='Cash Flow'!J24 -> 44438814 | ... CU11: ='Cash Flow'!CU24 -> 0
A12: Cost funded so far | C12: =SUM($C11:C11) -> 682500000 | D12: =SUM($C11:D11) -> 6.8619565e+08 | E12: =SUM($C11:E11) -> 6.9724211e+08 | F12: =SUM($C11:F11) -> 7.1551835e+08 | G12: =SUM($C11:G11) -> 7.4082414e+08 | H12: =SUM($C11:H11) -> 7.7288221e+08 | I12: =SUM($C11:I11) -> 8.1134134e+08 | J12: =SUM($C11:J11) -> 8.5578015e+08 | ... CU12: =SUM($C11:CU11) -> 2031744000
A13: Facility drawn | B13: =SUM(C13:CU13) -> 9.1262176e+08 | C13: =0 -> 0 | D13: =MAX(0,MIN($B$7-SUM($C13:C13),D12-$B$9-SUM($C13:C13))) -> 0 | E13: =MAX(0,MIN($B$7-SUM($C13:D13),E12-$B$9-SUM($C13:D13))) -> 0 | F13: =MAX(0,MIN($B$7-SUM($C13:E13),F12-$B$9-SUM($C13:E13))) -> 0 | G13: =MAX(0,MIN($B$7-SUM($C13:F13),G12-$B$9-SUM($C13:F13))) -> 0 | H13: =MAX(0,MIN($B$7-SUM($C13:G13),H12-$B$9-SUM($C13:G13))) -> 0 | I13: =MAX(0,MIN($B$7-SUM($C13:H13),I12-$B$9-SUM($C13:H13))) -> 0 | J13: =MAX(0,MIN($B$7-SUM($C13:I13),J12-$B$9-SUM($C13:I13))) -> 0 | K13: =MAX(0,MIN($B$7-SUM($C13:J13),K12-$B$9-SUM($C13:J13))) -> 0 | ... CU13: =MAX(0,MIN($B$7-SUM($C13:CT13),CU12-$B$9-SUM($C13:CT13))) -> 0
A14: Opening balance | C14: =0 -> 0 | D14: =C19 -> 0 | E14: =D19 -> 0 | F14: =E19 -> 0 | G14: =F19 -> 0 | H14: =G19 -> 0 | I14: =H19 -> 0 | J14: =I19 -> 0 | K14: =J19 -> 0 | ... CU14: =CT19 -> 0
A15: Profit (capitalised in construction) | B15: =SUM(C15:CU15) -> 71371593 | C15: =IF('Cash Flow'!C12=1,C14*$B$8/12,0) -> 0 | D15: =IF('Cash Flow'!D12=1,D14*$B$8/12,0) -> 0 | E15: =IF('Cash Flow'!E12=1,E14*$B$8/12,0) -> 0 | F15: =IF('Cash Flow'!F12=1,F14*$B$8/12,0) -> 0 | G15: =IF('Cash Flow'!G12=1,G14*$B$8/12,0) -> 0 | H15: =IF('Cash Flow'!H12=1,H14*$B$8/12,0) -> 0 | I15: =IF('Cash Flow'!I12=1,I14*$B$8/12,0) -> 0 | J15: =IF('Cash Flow'!J12=1,J14*$B$8/12,0) -> 0 | ... CU15: =IF('Cash Flow'!CU12=1,CU14*$B$8/12,0) -> 0
A16: Upfront fee | B16: =SUM(C16:CU16) -> 6844663.2 | C16: =0 -> 0 | D16: =IF(D13>0,IF(SUM($C13:C13)=0,$B$7*UpfrontFee,0),0) -> 0 | E16: =IF(E13>0,IF(SUM($C13:D13)=0,$B$7*UpfrontFee,0),0) -> 0 | F16: =IF(F13>0,IF(SUM($C13:E13)=0,$B$7*UpfrontFee,0),0) -> 0 | G16: =IF(G13>0,IF(SUM($C13:F13)=0,$B$7*UpfrontFee,0),0) -> 0 | H16: =IF(H13>0,IF(SUM($C13:G13)=0,$B$7*UpfrontFee,0),0) -> 0 | I16: =IF(I13>0,IF(SUM($C13:H13)=0,$B$7*UpfrontFee,0),0) -> 0 | J16: =IF(J13>0,IF(SUM($C13:I13)=0,$B$7*UpfrontFee,0),0) -> 0 | K16: =IF(K13>0,IF(SUM($C13:J13)=0,$B$7*UpfrontFee,0),0) -> 0 | ... CU16: =IF(CU13>0,IF(SUM($C13:CT13)=0,$B$7*UpfrontFee,0),0) -> 0
A17: Profit and fees paid in cash | B17: =SUM(C17:CU17) -> 2.7582723e+08 | C17: =IF('Cash Flow'!C12=1,C16,C14*$B$8/12+C16) -> 0 | D17: =IF('Cash Flow'!D12=1,D16,D14*$B$8/12+D16) -> 0 | E17: =IF('Cash Flow'!E12=1,E16,E14*$B$8/12+E16) -> 0 | F17: =IF('Cash Flow'!F12=1,F16,F14*$B$8/12+F16) -> 0 | G17: =IF('Cash Flow'!G12=1,G16,G14*$B$8/12+G16) -> 0 | H17: =IF('Cash Flow'!H12=1,H16,H14*$B$8/12+H16) -> 0 | I17: =IF('Cash Flow'!I12=1,I16,I14*$B$8/12+I16) -> 0 | J17: =IF('Cash Flow'!J12=1,J16,J14*$B$8/12+J16) -> 0 | ... CU17: =IF('Cash Flow'!CU12=1,CU16,CU14*$B$8/12+CU16) -> 0
A18: Repayment | B18: =SUM(C18:CU18) -> 9.8399335e+08 | C18: =IF('Cash Flow'!C14=1,C14,IF('Cash Flow'!C13=1,MIN(C14,$B$7*Amort/12),0)) -> 0 | D18: =IF('Cash Flow'!D14=1,D14,IF('Cash Flow'!D13=1,MIN(D14,$B$7*Amort/12),0)) -> 0 | E18: =IF('Cash Flow'!E14=1,E14,IF('Cash Flow'!E13=1,MIN(E14,$B$7*Amort/12),0)) -> 0 | F18: =IF('Cash Flow'!F14=1,F14,IF('Cash Flow'!F13=1,MIN(F14,$B$7*Amort/12),0)) -> 0 | G18: =IF('Cash Flow'!G14=1,G14,IF('Cash Flow'!G13=1,MIN(G14,$B$7*Amort/12),0)) -> 0 | H18: =IF('Cash Flow'!H14=1,H14,IF('Cash Flow'!H13=1,MIN(H14,$B$7*Amort/12),0)) -> 0 | I18: =IF('Cash Flow'!I14=1,I14,IF('Cash Flow'!I13=1,MIN(I14,$B$7*Amort/12),0)) -> 0 | J18: =IF('Cash Flow'!J14=1,J14,IF('Cash Flow'!J13=1,MIN(J14,$B$7*Amort/12),0)) -> 0 | ... CU18: =IF('Cash Flow'!CU14=1,CU14,IF('Cash Flow'!CU13=1,MIN(CU14,$B$7*Amort/12),0)) -> 0
A19: Closing balance | C19: =C14+C13+C15-C18 -> 0 | D19: =D14+D13+D15-D18 -> 0 | E19: =E14+E13+E15-E18 -> 0 | F19: =F14+F13+F15-F18 -> 0 | G19: =G14+G13+G15-G18 -> 0 | H19: =H14+H13+H15-H18 -> 0 | I19: =I14+I13+I15-I18 -> 0 | J19: =J14+J13+J15-J18 -> 0 | ... CU19: =CU14+CU13+CU15-CU18 -> 0
A20: DSCR (trailing 12 months, tested from 12 months after stabilisation) | C20: =IF(AND('Cash Flow'!C13=1,'Cash Flow'!C9>=BuildMonths+LeaseUp+12,'Cash Flow'!C14=0),C22/MAX(1,SUM(C17:C17)+SUM(C18:C18)),0) -> 0 | D20: =IF(AND('Cash Flow'!D13=1,'Cash Flow'!D9>=BuildMonths+LeaseUp+12,'Cash Flow'!D14=0),D22/MAX(1,SUM(C17:D17)+SUM(C18:D18)),0) -> 0 | E20: =IF(AND('Cash Flow'!E13=1,'Cash Flow'!E9>=BuildMonths+LeaseUp+12,'Cash Flow'!E14=0),E22/MAX(1,SUM(C17:E17)+SUM(C18:E18)),0) -> 0 | F20: =IF(AND('Cash Flow'!F13=1,'Cash Flow'!F9>=BuildMonths+LeaseUp+12,'Cash Flow'!F14=0),F22/MAX(1,SUM(C17:F17)+SUM(C18:F18)),0) -> 0 | G20: =IF(AND('Cash Flow'!G13=1,'Cash Flow'!G9>=BuildMonths+LeaseUp+12,'Cash Flow'!G14=0),G22/MAX(1,SUM(C17:G17)+SUM(C18:G18)),0) -> 0 | H20: =IF(AND('Cash Flow'!H13=1,'Cash Flow'!H9>=BuildMonths+LeaseUp+12,'Cash Flow'!H14=0),H22/MAX(1,SUM(C17:H17)+SUM(C18:H18)),0) -> 0 | I20: =IF(AND('Cash Flow'!I13=1,'Cash Flow'!I9>=BuildMonths+LeaseUp+12,'Cash Flow'!I14=0),I22/MAX(1,SUM(C17:I17)+SUM(C18:I18)),0) -> 0 | J20: =IF(AND('Cash Flow'!J13=1,'Cash Flow'!J9>=BuildMonths+LeaseUp+12,'Cash Flow'!J14=0),J22/MAX(1,SUM(C17:J17)+SUM(C18:J18)),0) -> 0 | K20: =IF(AND('Cash Flow'!K13=1,'Cash Flow'!K9>=BuildMonths+LeaseUp+12,'Cash Flow'!K14=0),K22/MAX(1,SUM(C17:K17)+SUM(C18:K18)),0) -> 0 | L20: =IF(AND('Cash Flow'!L13=1,'Cash Flow'!L9>=BuildMonths+LeaseUp+12,'Cash Flow'!L14=0),L22/MAX(1,SUM(C17:L17)+SUM(C18:L18)),0) -> 0 | M20: =IF(AND('Cash Flow'!M13=1,'Cash Flow'!M9>=BuildMonths+LeaseUp+12,'Cash Flow'!M14=0),M22/MAX(1,SUM(C17:M17)+SUM(C18:M18)),0) -> 0 | N20: =IF(AND('Cash Flow'!N13=1,'Cash Flow'!N9>=BuildMonths+LeaseUp+12,'Cash Flow'!N14=0),N22/MAX(1,SUM(C17:N17)+SUM(C18:N18)),0) -> 0 | O20: =IF(AND('Cash Flow'!O13=1,'Cash Flow'!O9>=BuildMonths+LeaseUp+12,'Cash Flow'!O14=0),O22/MAX(1,SUM(D17:O17)+SUM(D18:O18)),0) -> 0 | P20: =IF(AND('Cash Flow'!P13=1,'Cash Flow'!P9>=BuildMonths+LeaseUp+12,'Cash Flow'!P14=0),P22/MAX(1,SUM(E17:P17)+SUM(E18:P18)),0) -> 0 | Q20: =IF(AND('Cash Flow'!Q13=1,'Cash Flow'!Q9>=BuildMonths+LeaseUp+12,'Cash Flow'!Q14=0),Q22/MAX(1,SUM(F17:Q17)+SUM(F18:Q18)),0) -> 0 | R20: =IF(AND('Cash Flow'!R13=1,'Cash Flow'!R9>=BuildMonths+LeaseUp+12,'Cash Flow'!R14=0),R22/MAX(1,SUM(G17:R17)+SUM(G18:R18)),0) -> 0 | S20: =IF(AND('Cash Flow'!S13=1,'Cash Flow'!S9>=BuildMonths+LeaseUp+12,'Cash Flow'!S14=0),S22/MAX(1,SUM(H17:S17)+SUM(H18:S18)),0) -> 0 | T20: =IF(AND('Cash Flow'!T13=1,'Cash Flow'!T9>=BuildMonths+LeaseUp+12,'Cash Flow'!T14=0),T22/MAX(1,SUM(I17:T17)+SUM(I18:T18)),0) -> 0 | U20: =IF(AND('Cash Flow'!U13=1,'Cash Flow'!U9>=BuildMonths+LeaseUp+12,'Cash Flow'!U14=0),U22/MAX(1,SUM(J17:U17)+SUM(J18:U18)),0) -> 0 | ... CU20: =IF(AND('Cash Flow'!CU13=1,'Cash Flow'!CU9>=BuildMonths+LeaseUp+12,'Cash Flow'!CU14=0),CU22/MAX(1,SUM(CJ17:CU17)+SUM(CJ18:CU18)),0) -> 0
A21: LTV (balance on value, tested from 12 months after stabilisation) | C21: =IF(AND(C23>0,'Cash Flow'!C9>=BuildMonths+LeaseUp+12),C19/C23,0) -> 0 | D21: =IF(AND(D23>0,'Cash Flow'!D9>=BuildMonths+LeaseUp+12),D19/D23,0) -> 0 | E21: =IF(AND(E23>0,'Cash Flow'!E9>=BuildMonths+LeaseUp+12),E19/E23,0) -> 0 | F21: =IF(AND(F23>0,'Cash Flow'!F9>=BuildMonths+LeaseUp+12),F19/F23,0) -> 0 | G21: =IF(AND(G23>0,'Cash Flow'!G9>=BuildMonths+LeaseUp+12),G19/G23,0) -> 0 | H21: =IF(AND(H23>0,'Cash Flow'!H9>=BuildMonths+LeaseUp+12),H19/H23,0) -> 0 | I21: =IF(AND(I23>0,'Cash Flow'!I9>=BuildMonths+LeaseUp+12),I19/I23,0) -> 0 | J21: =IF(AND(J23>0,'Cash Flow'!J9>=BuildMonths+LeaseUp+12),J19/J23,0) -> 0 | ... CU21: =IF(AND(CU23>0,'Cash Flow'!CU9>=BuildMonths+LeaseUp+12),CU19/CU23,0) -> 0
A22: Cash available for debt service (12 months) | C22: =SUM('Cash Flow'!C45:C45)+SUM('Cash Flow'!C52:C52) -> 0 | D22: =SUM('Cash Flow'!C45:D45)+SUM('Cash Flow'!C52:D52) -> 0 | E22: =SUM('Cash Flow'!C45:E45)+SUM('Cash Flow'!C52:E52) -> 0 | F22: =SUM('Cash Flow'!C45:F45)+SUM('Cash Flow'!C52:F52) -> 0 | G22: =SUM('Cash Flow'!C45:G45)+SUM('Cash Flow'!C52:G52) -> 0 | H22: =SUM('Cash Flow'!C45:H45)+SUM('Cash Flow'!C52:H52) -> 0 | I22: =SUM('Cash Flow'!C45:I45)+SUM('Cash Flow'!C52:I52) -> 0 | J22: =SUM('Cash Flow'!C45:J45)+SUM('Cash Flow'!C52:J52) -> 0 | K22: =SUM('Cash Flow'!C45:K45)+SUM('Cash Flow'!C52:K52) -> 0 | L22: =SUM('Cash Flow'!C45:L45)+SUM('Cash Flow'!C52:L52) -> 0 | M22: =SUM('Cash Flow'!C45:M45)+SUM('Cash Flow'!C52:M52) -> 0 | N22: =SUM('Cash Flow'!C45:N45)+SUM('Cash Flow'!C52:N52) -> 0 | O22: =SUM('Cash Flow'!D45:O45)+SUM('Cash Flow'!D52:O52) -> 0 | P22: =SUM('Cash Flow'!E45:P45)+SUM('Cash Flow'!E52:P52) -> 0 | Q22: =SUM('Cash Flow'!F45:Q45)+SUM('Cash Flow'!F52:Q52) -> 0 | R22: =SUM('Cash Flow'!G45:R45)+SUM('Cash Flow'!G52:R52) -> 0 | S22: =SUM('Cash Flow'!H45:S45)+SUM('Cash Flow'!H52:S52) -> 0 | T22: =SUM('Cash Flow'!I45:T45)+SUM('Cash Flow'!I52:T52) -> 0 | U22: =SUM('Cash Flow'!J45:U45)+SUM('Cash Flow'!J52:U52) -> 0 | ... CU22: =SUM('Cash Flow'!CJ45:CU45)+SUM('Cash Flow'!CJ52:CU52) -> 0
A23: Value of the income-producing assets | C23: =IF('Cash Flow'!C13=1,SUM('Cash Flow'!C45:C45)/ExitYield+SUM('Cash Flow'!C52:C52)*HotelMult,0) -> 0 | D23: =IF('Cash Flow'!D13=1,SUM('Cash Flow'!C45:D45)/ExitYield+SUM('Cash Flow'!C52:D52)*HotelMult,0) -> 0 | E23: =IF('Cash Flow'!E13=1,SUM('Cash Flow'!C45:E45)/ExitYield+SUM('Cash Flow'!C52:E52)*HotelMult,0) -> 0 | F23: =IF('Cash Flow'!F13=1,SUM('Cash Flow'!C45:F45)/ExitYield+SUM('Cash Flow'!C52:F52)*HotelMult,0) -> 0 | G23: =IF('Cash Flow'!G13=1,SUM('Cash Flow'!C45:G45)/ExitYield+SUM('Cash Flow'!C52:G52)*HotelMult,0) -> 0 | H23: =IF('Cash Flow'!H13=1,SUM('Cash Flow'!C45:H45)/ExitYield+SUM('Cash Flow'!C52:H52)*HotelMult,0) -> 0 | I23: =IF('Cash Flow'!I13=1,SUM('Cash Flow'!C45:I45)/ExitYield+SUM('Cash Flow'!C52:I52)*HotelMult,0) -> 0 | J23: =IF('Cash Flow'!J13=1,SUM('Cash Flow'!C45:J45)/ExitYield+SUM('Cash Flow'!C52:J52)*HotelMult,0) -> 0 | K23: =IF('Cash Flow'!K13=1,SUM('Cash Flow'!C45:K45)/ExitYield+SUM('Cash Flow'!C52:K52)*HotelMult,0) -> 0 | L23: =IF('Cash Flow'!L13=1,SUM('Cash Flow'!C45:L45)/ExitYield+SUM('Cash Flow'!C52:L52)*HotelMult,0) -> 0 | M23: =IF('Cash Flow'!M13=1,SUM('Cash Flow'!C45:M45)/ExitYield+SUM('Cash Flow'!C52:M52)*HotelMult,0) -> 0 | N23: =IF('Cash Flow'!N13=1,SUM('Cash Flow'!C45:N45)/ExitYield+SUM('Cash Flow'!C52:N52)*HotelMult,0) -> 0 | O23: =IF('Cash Flow'!O13=1,SUM('Cash Flow'!D45:O45)/ExitYield+SUM('Cash Flow'!D52:O52)*HotelMult,0) -> 0 | P23: =IF('Cash Flow'!P13=1,SUM('Cash Flow'!E45:P45)/ExitYield+SUM('Cash Flow'!E52:P52)*HotelMult,0) -> 0 | Q23: =IF('Cash Flow'!Q13=1,SUM('Cash Flow'!F45:Q45)/ExitYield+SUM('Cash Flow'!F52:Q52)*HotelMult,0) -> 0 | R23: =IF('Cash Flow'!R13=1,SUM('Cash Flow'!G45:R45)/ExitYield+SUM('Cash Flow'!G52:R52)*HotelMult,0) -> 0 | S23: =IF('Cash Flow'!S13=1,SUM('Cash Flow'!H45:S45)/ExitYield+SUM('Cash Flow'!H52:S52)*HotelMult,0) -> 0 | T23: =IF('Cash Flow'!T13=1,SUM('Cash Flow'!I45:T45)/ExitYield+SUM('Cash Flow'!I52:T52)*HotelMult,0) -> 0 | U23: =IF('Cash Flow'!U13=1,SUM('Cash Flow'!J45:U45)/ExitYield+SUM('Cash Flow'!J52:U52)*HotelMult,0) -> 0 | ... CU23: =IF('Cash Flow'!CU13=1,SUM('Cash Flow'!CJ45:CU45)/ExitYield+SUM('Cash Flow'!CJ52:CU52)*HotelMult,0) -> 0

Sheet Annual
A1: ANNUAL SUMMARY (SAR)
A2: SUMIFS of the monthly rows by calendar year
A5: Year | B5: 2026 | C5: 2027 | D5: 2028 | E5: 2029 | F5: 2030 | G5: 2031 | H5: 2032
A6: Residential collections released | B6: =SUMIFS('Cash Flow'!$C$34:$CU$34,'Cash Flow'!$C$11:$CU$11,B$5) -> 0 | C6: =SUMIFS('Cash Flow'!$C$34:$CU$34,'Cash Flow'!$C$11:$CU$11,C$5) -> 34344224 | D6: =SUMIFS('Cash Flow'!$C$34:$CU$34,'Cash Flow'!$C$11:$CU$11,D$5) -> 4.6436487e+08 | E6: =SUMIFS('Cash Flow'!$C$34:$CU$34,'Cash Flow'!$C$11:$CU$11,E$5) -> 4.462909e+08 | F6: =SUMIFS('Cash Flow'!$C$34:$CU$34,'Cash Flow'!$C$11:$CU$11,F$5) -> 0 | G6: =SUMIFS('Cash Flow'!$C$34:$CU$34,'Cash Flow'!$C$11:$CU$11,G$5) -> 0 | H6: =SUMIFS('Cash Flow'!$C$34:$CU$34,'Cash Flow'!$C$11:$CU$11,H$5) -> 0
A7: Retail and office NOI | B7: =SUMIFS('Cash Flow'!$C$45:$CU$45,'Cash Flow'!$C$11:$CU$11,B$5) -> 0 | C7: =SUMIFS('Cash Flow'!$C$45:$CU$45,'Cash Flow'!$C$11:$CU$11,C$5) -> 0 | D7: =SUMIFS('Cash Flow'!$C$45:$CU$45,'Cash Flow'!$C$11:$CU$11,D$5) -> 0 | E7: =SUMIFS('Cash Flow'!$C$45:$CU$45,'Cash Flow'!$C$11:$CU$11,E$5) -> 27505104 | F7: =SUMIFS('Cash Flow'!$C$45:$CU$45,'Cash Flow'!$C$11:$CU$11,F$5) -> 3.599848e+08 | G7: =SUMIFS('Cash Flow'!$C$45:$CU$45,'Cash Flow'!$C$11:$CU$11,G$5) -> 5.7229516e+08 | H7: =SUMIFS('Cash Flow'!$C$45:$CU$45,'Cash Flow'!$C$11:$CU$11,H$5) -> 5.8291326e+08
A8: Hotel EBITDA | B8: =SUMIFS('Cash Flow'!$C$52:$CU$52,'Cash Flow'!$C$11:$CU$11,B$5) -> 0 | C8: =SUMIFS('Cash Flow'!$C$52:$CU$52,'Cash Flow'!$C$11:$CU$11,C$5) -> 0 | D8: =SUMIFS('Cash Flow'!$C$52:$CU$52,'Cash Flow'!$C$11:$CU$11,D$5) -> 0 | E8: =SUMIFS('Cash Flow'!$C$52:$CU$52,'Cash Flow'!$C$11:$CU$11,E$5) -> 7336732.5 | F8: =SUMIFS('Cash Flow'!$C$52:$CU$52,'Cash Flow'!$C$11:$CU$11,F$5) -> 18984915 | G8: =SUMIFS('Cash Flow'!$C$52:$CU$52,'Cash Flow'!$C$11:$CU$11,G$5) -> 24326207 | H8: =SUMIFS('Cash Flow'!$C$52:$CU$52,'Cash Flow'!$C$11:$CU$11,H$5) -> 25713464
A9: Exit proceeds (net) | B9: =SUMIFS('Cash Flow'!$C$55:$CU$55,'Cash Flow'!$C$11:$CU$11,B$5)+SUMIFS('Cash Flow'!$C$56:$CU$56,'Cash Flow'!$C$11:$CU$11,B$5)-SUMIFS('Cash Flow'!$C$57:$CU$57,'Cash Flow'!$C$11:$CU$11,B$5) -> 0 | C9: =SUMIFS('Cash Flow'!$C$55:$CU$55,'Cash Flow'!$C$11:$CU$11,C$5)+SUMIFS('Cash Flow'!$C$56:$CU$56,'Cash Flow'!$C$11:$CU$11,C$5)-SUMIFS('Cash Flow'!$C$57:$CU$57,'Cash Flow'!$C$11:$CU$11,C$5) -> 0 | D9: =SUMIFS('Cash Flow'!$C$55:$CU$55,'Cash Flow'!$C$11:$CU$11,D$5)+SUMIFS('Cash Flow'!$C$56:$CU$56,'Cash Flow'!$C$11:$CU$11,D$5)-SUMIFS('Cash Flow'!$C$57:$CU$57,'Cash Flow'!$C$11:$CU$11,D$5) -> 0 | E9: =SUMIFS('Cash Flow'!$C$55:$CU$55,'Cash Flow'!$C$11:$CU$11,E$5)+SUMIFS('Cash Flow'!$C$56:$CU$56,'Cash Flow'!$C$11:$CU$11,E$5)-SUMIFS('Cash Flow'!$C$57:$CU$57,'Cash Flow'!$C$11:$CU$11,E$5) -> 0 | F9: =SUMIFS('Cash Flow'!$C$55:$CU$55,'Cash Flow'!$C$11:$CU$11,F$5)+SUMIFS('Cash Flow'!$C$56:$CU$56,'Cash Flow'!$C$11:$CU$11,F$5)-SUMIFS('Cash Flow'!$C$57:$CU$57,'Cash Flow'!$C$11:$CU$11,F$5) -> 0 | G9: =SUMIFS('Cash Flow'!$C$55:$CU$55,'Cash Flow'!$C$11:$CU$11,G$5)+SUMIFS('Cash Flow'!$C$56:$CU$56,'Cash Flow'!$C$11:$CU$11,G$5)-SUMIFS('Cash Flow'!$C$57:$CU$57,'Cash Flow'!$C$11:$CU$11,G$5) -> 0 | H9: =SUMIFS('Cash Flow'!$C$55:$CU$55,'Cash Flow'!$C$11:$CU$11,H$5)+SUMIFS('Cash Flow'!$C$56:$CU$56,'Cash Flow'!$C$11:$CU$11,H$5)-SUMIFS('Cash Flow'!$C$57:$CU$57,'Cash Flow'!$C$11:$CU$11,H$5) -> 8.4357729e+09
A10: Development cost | B10: =SUMIFS('Cash Flow'!$C$24:$CU$24,'Cash Flow'!$C$11:$CU$11,B$5) -> 682500000 | C10: =SUMIFS('Cash Flow'!$C$24:$CU$24,'Cash Flow'!$C$11:$CU$11,C$5) -> 4.6615234e+08 | D10: =SUMIFS('Cash Flow'!$C$24:$CU$24,'Cash Flow'!$C$11:$CU$11,D$5) -> 7.5425033e+08 | E10: =SUMIFS('Cash Flow'!$C$24:$CU$24,'Cash Flow'!$C$11:$CU$11,E$5) -> 1.2884134e+08 | F10: =SUMIFS('Cash Flow'!$C$24:$CU$24,'Cash Flow'!$C$11:$CU$11,F$5) -> 0 | G10: =SUMIFS('Cash Flow'!$C$24:$CU$24,'Cash Flow'!$C$11:$CU$11,G$5) -> 0 | H10: =SUMIFS('Cash Flow'!$C$24:$CU$24,'Cash Flow'!$C$11:$CU$11,H$5) -> 0
A11: Zakat | B11: =SUMIFS('Cash Flow'!$C$62:$CU$62,'Cash Flow'!$C$11:$CU$11,B$5) -> 0 | C11: =SUMIFS('Cash Flow'!$C$62:$CU$62,'Cash Flow'!$C$11:$CU$11,C$5) -> 0 | D11: =SUMIFS('Cash Flow'!$C$62:$CU$62,'Cash Flow'!$C$11:$CU$11,D$5) -> 0 | E11: =SUMIFS('Cash Flow'!$C$62:$CU$62,'Cash Flow'!$C$11:$CU$11,E$5) -> 8649785.1 | F11: =SUMIFS('Cash Flow'!$C$62:$CU$62,'Cash Flow'!$C$11:$CU$11,F$5) -> 9474242.8 | G11: =SUMIFS('Cash Flow'!$C$62:$CU$62,'Cash Flow'!$C$11:$CU$11,G$5) -> 14915534 | H11: =SUMIFS('Cash Flow'!$C$62:$CU$62,'Cash Flow'!$C$11:$CU$11,H$5) -> 2.2610999e+08
A12: Unlevered cash flow | B12: =SUMIFS('Cash Flow'!$C$63:$CU$63,'Cash Flow'!$C$11:$CU$11,B$5) -> -682500000 | C12: =SUMIFS('Cash Flow'!$C$63:$CU$63,'Cash Flow'!$C$11:$CU$11,C$5) -> -4.3968311e+08 | D12: =SUMIFS('Cash Flow'!$C$63:$CU$63,'Cash Flow'!$C$11:$CU$11,D$5) -> -2.9933545e+08 | E12: =SUMIFS('Cash Flow'!$C$63:$CU$63,'Cash Flow'!$C$11:$CU$11,E$5) -> 3.3734162e+08 | F12: =SUMIFS('Cash Flow'!$C$63:$CU$63,'Cash Flow'!$C$11:$CU$11,F$5) -> 3.6949547e+08 | G12: =SUMIFS('Cash Flow'!$C$63:$CU$63,'Cash Flow'!$C$11:$CU$11,G$5) -> 5.8170583e+08 | H12: =SUMIFS('Cash Flow'!$C$63:$CU$63,'Cash Flow'!$C$11:$CU$11,H$5) -> 8.8182896e+09
A13: Levered cash flow to equity | B13: =SUMIFS('Cash Flow'!$C$69:$CU$69,'Cash Flow'!$C$11:$CU$11,B$5) -> -682500000 | C13: =SUMIFS('Cash Flow'!$C$69:$CU$69,'Cash Flow'!$C$11:$CU$11,C$5) -> -4.1330203e+08 | D13: =SUMIFS('Cash Flow'!$C$69:$CU$69,'Cash Flow'!$C$11:$CU$11,D$5) -> 4.5491487e+08 | E13: =SUMIFS('Cash Flow'!$C$69:$CU$69,'Cash Flow'!$C$11:$CU$11,E$5) -> 4.0868811e+08 | F13: =SUMIFS('Cash Flow'!$C$69:$CU$69,'Cash Flow'!$C$11:$CU$11,F$5) -> 2.6358087e+08 | G13: =SUMIFS('Cash Flow'!$C$69:$CU$69,'Cash Flow'!$C$11:$CU$11,G$5) -> 4.7803628e+08 | H13: =SUMIFS('Cash Flow'!$C$69:$CU$69,'Cash Flow'!$C$11:$CU$11,H$5) -> 7.8286971e+09

Sheet Waterfall
A1: JOINT VENTURE WATERFALL
A2: Pref to all equity → GP catch-up → promote split; on the whole-life levered cash flow
A5: Equity invested | B5: =-SUMIF('Cash Flow'!$C$69:$CU$69,"<0") -> 1.1171251e+09
A6: Distributions to equity | B6: =SUMIF('Cash Flow'!$C$69:$CU$69,">0") -> 9.4552403e+09
A7: Profit to equity | B7: =B6-B5 -> 8.3381152e+09
A8: Equity life (years, weighted) | B8: =(BuildMonths+HoldMonths)/12/2 -> 3
A9: Preferred return | B9: =MIN(B7,B5*((1+Pref)^B8-1)) -> 3.6976842e+08
A10: GP catch-up | B10: =MIN(B7-B9,Promote*B9/(1-Promote)) -> 1.2325614e+08
A11: Remaining profit | B11: =B7-B9-B10 -> 7.8450906e+09
A12: GP promote on the remaining profit | B12: =B11*Promote -> 1.9612726e+09
A13: GP total (pro rata + catch-up + promote) | B13: =(B5+B9)*GPShare+B10+B12+(B11-B12)*GPShare -> 2.8215999e+09
A14: LP total | B14: =B6-B13 -> 6.6336403e+09
A15: GP multiple | B15: =B13/(B5*GPShare) -> 25.257689
A16: LP multiple | B16: =B14/(B5*(1-GPShare)) -> 6.5979283
A17: Promote paid to the GP | B17: =B10+B12 -> 2.0845288e+09

Sheet Returns
A1: RETURNS
A2: Annualised from the monthly cash flows
A5: Unlevered IRR | B5: =XIRR('Cash Flow'!$C$63:$CU$63,'Cash Flow'!$C$10:$CU$10) -> 0.47109571
A6: Levered IRR | B6: =XIRR('Cash Flow'!$C$69:$CU$69,'Cash Flow'!$C$10:$CU$10) -> 0.57448578
A7: NPV at the discount rate (unlevered) | B7: =XNPV(DiscRate,'Cash Flow'!$C$63:$CU$63,'Cash Flow'!$C$10:$CU$10) -> 4.5376353e+09
A8: Net profit (unlevered) | B8: ='Cash Flow'!B63 -> 8.685314e+09
A9: Net profit to equity | B9: ='Cash Flow'!B69 -> 8.3381152e+09
A10: Total development cost | B10: ='Cash Flow'!B24+Financing!B15+Financing!B16 -> 2.1062646e+09
A11: Profit on cost | B11: =B8/B10 -> 4.1235626
A12: Equity multiple | B12: =Waterfall!B6/Waterfall!B5 -> 8.4639044
A13: Peak debt | B13: =MAX(Financing!C19:CU19) -> 9.8399335e+08
A14: Peak equity | B14: =-MIN('Cash Flow'!C70:CU70) -> 1.095802e+09
A15: Minimum DSCR | B15: =_xlfn.MINIFS(Financing!C20:CU20,Financing!C20:CU20,">0") -> 5.7464552
A16: Maximum LTV in operation | B16: =MAX(Financing!C21:CU21) -> 0.11221875
A17: Exit value | B17: ='Cash Flow'!B55+'Cash Flow'!B56 -> 8.5642364e+09
A18: LP multiple | B18: =Waterfall!B16 -> 6.5979283
A19: GP multiple | B19: =Waterfall!B15 -> 25.257689
A20: Promote paid to the GP | B20: =Waterfall!B17 -> 2.0845288e+09

Sheet Sensitivity
A1: SENSITIVITY
A2: Net profit (SAR m) for construction cost and residential price, each cell its own formula on the live case
A5: Construction cost change ↓ / residential price change → | B5: -0.1 | C5: -0.05 | D5: 0 | E5: 0.05 | F5: 0.1
A6: -0.1 | B6: =(Returns!$B$8+'Cash Flow'!$B$34*B$5*(1-SalesComm)-'Cash Flow'!$B$21*(1+SoftCosts+Contingency)*$A6)/1000000 -> 8728.1009 | C6: =(Returns!$B$8+'Cash Flow'!$B$34*C$5*(1-SalesComm)-'Cash Flow'!$B$21*(1+SoftCosts+Contingency)*$A6)/1000000 -> 8774.1696 | D6: =(Returns!$B$8+'Cash Flow'!$B$34*D$5*(1-SalesComm)-'Cash Flow'!$B$21*(1+SoftCosts+Contingency)*$A6)/1000000 -> 8820.2384 | E6: =(Returns!$B$8+'Cash Flow'!$B$34*E$5*(1-SalesComm)-'Cash Flow'!$B$21*(1+SoftCosts+Contingency)*$A6)/1000000 -> 8866.3071 | F6: =(Returns!$B$8+'Cash Flow'!$B$34*F$5*(1-SalesComm)-'Cash Flow'!$B$21*(1+SoftCosts+Contingency)*$A6)/1000000 -> 8912.3759
A7: -0.05 | B7: =(Returns!$B$8+'Cash Flow'!$B$34*B$5*(1-SalesComm)-'Cash Flow'!$B$21*(1+SoftCosts+Contingency)*$A7)/1000000 -> 8660.6387 | C7: =(Returns!$B$8+'Cash Flow'!$B$34*C$5*(1-SalesComm)-'Cash Flow'!$B$21*(1+SoftCosts+Contingency)*$A7)/1000000 -> 8706.7074 | D7: =(Returns!$B$8+'Cash Flow'!$B$34*D$5*(1-SalesComm)-'Cash Flow'!$B$21*(1+SoftCosts+Contingency)*$A7)/1000000 -> 8752.7762 | E7: =(Returns!$B$8+'Cash Flow'!$B$34*E$5*(1-SalesComm)-'Cash Flow'!$B$21*(1+SoftCosts+Contingency)*$A7)/1000000 -> 8798.8449 | F7: =(Returns!$B$8+'Cash Flow'!$B$34*F$5*(1-SalesComm)-'Cash Flow'!$B$21*(1+SoftCosts+Contingency)*$A7)/1000000 -> 8844.9137
A8: 0 | B8: =(Returns!$B$8+'Cash Flow'!$B$34*B$5*(1-SalesComm)-'Cash Flow'!$B$21*(1+SoftCosts+Contingency)*$A8)/1000000 -> 8593.1765 | C8: =(Returns!$B$8+'Cash Flow'!$B$34*C$5*(1-SalesComm)-'Cash Flow'!$B$21*(1+SoftCosts+Contingency)*$A8)/1000000 -> 8639.2452 | D8: =(Returns!$B$8+'Cash Flow'!$B$34*D$5*(1-SalesComm)-'Cash Flow'!$B$21*(1+SoftCosts+Contingency)*$A8)/1000000 -> 8685.314 | E8: =(Returns!$B$8+'Cash Flow'!$B$34*E$5*(1-SalesComm)-'Cash Flow'!$B$21*(1+SoftCosts+Contingency)*$A8)/1000000 -> 8731.3827 | F8: =(Returns!$B$8+'Cash Flow'!$B$34*F$5*(1-SalesComm)-'Cash Flow'!$B$21*(1+SoftCosts+Contingency)*$A8)/1000000 -> 8777.4515
A9: 0.05 | B9: =(Returns!$B$8+'Cash Flow'!$B$34*B$5*(1-SalesComm)-'Cash Flow'!$B$21*(1+SoftCosts+Contingency)*$A9)/1000000 -> 8525.7143 | C9: =(Returns!$B$8+'Cash Flow'!$B$34*C$5*(1-SalesComm)-'Cash Flow'!$B$21*(1+SoftCosts+Contingency)*$A9)/1000000 -> 8571.783 | D9: =(Returns!$B$8+'Cash Flow'!$B$34*D$5*(1-SalesComm)-'Cash Flow'!$B$21*(1+SoftCosts+Contingency)*$A9)/1000000 -> 8617.8518 | E9: =(Returns!$B$8+'Cash Flow'!$B$34*E$5*(1-SalesComm)-'Cash Flow'!$B$21*(1+SoftCosts+Contingency)*$A9)/1000000 -> 8663.9205 | F9: =(Returns!$B$8+'Cash Flow'!$B$34*F$5*(1-SalesComm)-'Cash Flow'!$B$21*(1+SoftCosts+Contingency)*$A9)/1000000 -> 8709.9893
A10: 0.1 | B10: =(Returns!$B$8+'Cash Flow'!$B$34*B$5*(1-SalesComm)-'Cash Flow'!$B$21*(1+SoftCosts+Contingency)*$A10)/1000000 -> 8458.2521 | C10: =(Returns!$B$8+'Cash Flow'!$B$34*C$5*(1-SalesComm)-'Cash Flow'!$B$21*(1+SoftCosts+Contingency)*$A10)/1000000 -> 8504.3208 | D10: =(Returns!$B$8+'Cash Flow'!$B$34*D$5*(1-SalesComm)-'Cash Flow'!$B$21*(1+SoftCosts+Contingency)*$A10)/1000000 -> 8550.3896 | E10: =(Returns!$B$8+'Cash Flow'!$B$34*E$5*(1-SalesComm)-'Cash Flow'!$B$21*(1+SoftCosts+Contingency)*$A10)/1000000 -> 8596.4583 | F10: =(Returns!$B$8+'Cash Flow'!$B$34*F$5*(1-SalesComm)-'Cash Flow'!$B$21*(1+SoftCosts+Contingency)*$A10)/1000000 -> 8642.5271
A12: Shading: red below zero.

Sheet Checks
A1: CHECKS
A2: Each must read OK
A5: Construction S-curve sums to 100% | B5: ='Cash Flow'!B15 -> 1 | C5: =IF(ABS(B5-1)<0.000001,"OK","CHECK") -> OK
A6: All buyer payments released from escrow by the exit | B6: ='Cash Flow'!B32-'Cash Flow'!B34 -> 0 | C6: =IF(ABS(B6)<1,"OK","CHECK") -> OK
A7: Facility repaid in full at the exit | B7: =Financing!CU19 -> 0 | C7: =IF(ABS(B7)<1,"OK","CHECK") -> OK
A8: Draws do not exceed the facility | B8: =Financing!B13-Financing!B7 -> 0 | C8: =IF(B8<=1,"OK","CHECK") -> OK
A9: Minimum DSCR at or above the covenant | B9: =Returns!B15-MinDSCR -> 4.4964552 | C9: =IF(B9>=0,"OK","BREACH") -> OK
A10: Maximum LTV at or below the covenant | B10: =MaxLTV-Returns!B16 -> 0.48778125 | C10: =IF(B10>=0,"OK","BREACH") -> OK
A11: Waterfall pays out exactly what equity receives | B11: =Waterfall!B13+Waterfall!B14-Waterfall!B6 -> 0 | C11: =IF(ABS(B11)<1,"OK","CHECK") -> OK
A12: Annual summary equals the monthly total (levered) | B12: =SUM(Annual!B13:H13)-'Cash Flow'!B69 -> 0 | C12: =IF(ABS(B12)<1,"OK","CHECK") -> OK
A14: All checks | C14: =IF(COUNTIF(C5:C12,"OK")=8,"OK","CHECK") -> OK
