Workbook

Sheet Inputs
A1: Negative fraction | B1: -1.25
A2: Fraction | B2: 2.9
A3: Months fraction | B3: 1.9
A4: Start date | B4: 45322
A5: Rate | B5: 0.05
A6: Periods | B6: 10
A7: Amount | B7: -1000
A8: Small | B8: 0.004
A9: Half | B9: 2.5
A10: Neg half | B10: -2.5
A11: Count | B11: 3
A12: Zero | B12: 0
... A17: Lag | B17: 2.2

Sheet Calc
A1: INT neg | B1: =INT(Inputs!$B$1) -> -2
A2: INT neg half | B2: =INT(Inputs!$B$10) -> -3
A3: INT frac | B3: =INT(Inputs!$B$2) -> 2
A4: INT expr | B4: =INT((Inputs!$B$11-Inputs!$B$6-1)/2) -> -4
A5: TRUNC | B5: =TRUNC(Inputs!$B$1) -> -1
A6: CHOOSE frac | B6: =CHOOSE(Inputs!$B$2,10,20,30) -> 20
A7: ROUND half | B7: =ROUND(Inputs!$B$9,0) -> 3
A8: ROUND neg half | B8: =ROUND(Inputs!$B$10,0) -> -3
A9: ROUND -2 | B9: =ROUND(Inputs!$B$13,-2) -> 1200
A10: ROUNDUP neg | B10: =ROUNDUP(Inputs!$B$1,0) -> -2
A11: ROUNDDOWN neg | B11: =ROUNDDOWN(Inputs!$B$1,0) -> -1
A12: CEILING | B12: =CEILING(Inputs!$B$2,1) -> 3
A13: FLOOR | B13: =FLOOR(Inputs!$B$2,1) -> 2
A14: MROUND | B14: =MROUND(Inputs!$B$13,5) -> 1235
A15: MOD neg | B15: =MOD(Inputs!$B$1,2) -> 0.75
A16: MOD neg div | B16: =MOD(Inputs!$B$2,-2) -> -1.1
A17: QUOTIENT | B17: =QUOTIENT(Inputs!$B$1*10,4) -> -3
A18: EDATE frac | B18: =EDATE(Inputs!$B$4,Inputs!$B$3) -> 45351
A19: EDATE neg frac | B19: =EDATE(Inputs!$B$4,-Inputs!$B$3) -> 45291
A20: EOMONTH frac | B20: =EOMONTH(Inputs!$B$4,Inputs!$B$3) -> 45351
A21: EOMONTH neg | B21: =EOMONTH(Inputs!$B$4,-Inputs!$B$3) -> 45291
A22: DATE frac month | B22: =DATE(2024,Inputs!$B$3,1) -> 45292
A23: DATE month 13 | B23: =DATE(2024,12+Inputs!$B$11,1) -> 45717
A24: DATE day 0 | B24: =DATE(2024,3,Inputs!$B$12) -> 45351
A25: YEAR | B25: =YEAR(Inputs!$B$4) -> 2024
A26: MONTH | B26: =MONTH(Inputs!$B$4+Inputs!$B$2) -> 2
A27: DAY | B27: =DAY(Inputs!$B$14) -> 27
A28: YEARFRAC0 | B28: =YEARFRAC(Inputs!$B$4,Inputs!$B$14) -> 0.49166667
A29: YEARFRAC1 | B29: =YEARFRAC(Inputs!$B$4,Inputs!$B$14,1) -> 0.4863388
A30: YEARFRAC3 | B30: =YEARFRAC(Inputs!$B$4,Inputs!$B$14,3) -> 0.48767123
A31: DAYS360 | B31: =DAYS360(Inputs!$B$4,Inputs!$B$14) -> 177
A32: DATEDIF m | B32: =DATEDIF(Inputs!$B$4,Inputs!$B$14,"m") -> 5
A33: DATEDIF y | B33: =DATEDIF(Inputs!$B$4,Inputs!$B$14,"y") -> 0
A34: DATEDIF d | B34: =DATEDIF(Inputs!$B$4,Inputs!$B$14,"d") -> 178
A35: EOMONTH 0 | B35: =EOMONTH(Inputs!$B$14,0) -> 45504
A36: WEEKDAY | B36: =WEEKDAY(Inputs!$B$14) -> 7
A37: NETWORKDAYS | B37: =NETWORKDAYS(Inputs!$B$4,Inputs!$B$14) -> 128
A38: WORKDAY | B38: =WORKDAY(Inputs!$B$4,Inputs!$B$11*Inputs!$B$2) -> 45334
A39: PMT | B39: =PMT(Inputs!$B$5/12,Inputs!$B$6*12,Inputs!$B$7) -> 10.606552
A40: PMT type1 | B40: =PMT(Inputs!$B$5,Inputs!$B$6,Inputs!$B$7,0,1) -> 123.33769
...

Sheet Table
A1: 1 | B1: 10 | C1: 45030 | D1: k1 | E1: -0.5
A2: 2 | B2: 20 | C2: 45060 | D2: k2 | E2: 0.5
A3: 3 | B3: 30 | C3: 45090 | D3: k3 | E3: 1.5
A4: 4 | B4: 40 | C4: 45120 | D4: k4 | E4: -1.5
A5: 5 | B5: 50 | C5: 45150 | D5: k5 | E5: -0.5
A6: 6 | B6: 60 | C6: 45180 | D6: k6 | E6: 0.5
A7: 7 | B7: 70 | C7: 45210 | D7: k7 | E7: 1.5
A8: 8 | B8: 80 | C8: 45240 | D8: k8 | E8: -1.5
A9: 9 | B9: 90 | C9: 45270 | D9: k9 | E9: -0.5
A10: 10 | B10: 100 | C10: 45300 | D10: k10 | E10: 0.5
A11: 11 | B11: 110 | C11: 45330 | D11: k11 | E11: 1.5
A12: 12 | B12: 120 | C12: 45360 | D12: k12 | E12: -1.5
