Workbook
Name Rate: Data!$G$2
Name CFs: Data!$B$2:$B$13

Sheet Data
A1: Period | B1: CF | C1: Date | D1: Cat | E1: Rent | G1: Rate | H1: Len | I1: Txt
A2: 1 | B2: -1000 | C2: 46053 | D2: Retail | E2: 100 | G2: 0.08 | H2: 6 | I2: 5 | J2: TRUE
A3: 2 | B3: 50 | C3: =EOMONTH(DATE(2026,1,31),1) -> 46081 | D3: Office | E3: 107 | I3: =""
A4: 3 | B4: 60 | C4: =EOMONTH(DATE(2026,1,31),2) -> 46112 | D4: Retail | E4: 114 | I4: abc
A5: 4 | B5: 70 | C5: =EOMONTH(DATE(2026,1,31),3) -> 46142 | D5: Hotel | E5: 121
A6: 5 | B6: 80 | C6: =EOMONTH(DATE(2026,1,31),4) -> 46173 | D6: Office | E6: 128
A7: 6 | B7: 90 | C7: =EOMONTH(DATE(2026,1,31),5) -> 46203 | D7: Retail | E7: 135
A8: 7 | B8: 100 | C8: =EOMONTH(DATE(2026,1,31),6) -> 46234 | D8: Hotel | E8: 142
A9: 8 | B9: 110 | C9: =EOMONTH(DATE(2026,1,31),7) -> 46265 | D9: Office | E9: 149
A10: 9 | B10: 120 | C10: =EOMONTH(DATE(2026,1,31),8) -> 46295 | D10: Retail | E10: 156
A11: 10 | B11: 130 | C11: =EOMONTH(DATE(2026,1,31),9) -> 46326 | D11: Hotel | E11: 163
A12: 11 | B12: 140 | C12: =EOMONTH(DATE(2026,1,31),10) -> 46356 | D12: Office | E12: 170
A13: 12 | B13: 1200 | C13: =EOMONTH(DATE(2026,1,31),11) -> 46387 | D13: Retail | E13: 177

Sheet S1
A1: 10

Sheet S2
A1: 20

Sheet S3
A1: 30

Sheet Units
A1: Unit | B1: Area | C1: Price
A2: A | B2: 100 | C2: 1.5
A3: B | B3: 120 | C3: 1.6
A4: C | B4: 90 | C4: 1.4

Sheet F
A1: Label | B1: Formula | C1: Excel expected
A2: NPV | B2: =NPV(0.08,Data!B3:B13)+Data!B2 -> 109.93182
A3: IRR | B3: =IRR(Data!B2:B13) -> 0.093951751
A4: IRR guess | B4: =IRR(Data!B2:B13,0.2) -> 0.093951751
A5: XNPV | B5: =XNPV(0.08,Data!B2:B13,Data!C2:C13) -> 1030.8
A6: XIRR | B6: =XIRR(Data!B2:B13,Data!C2:C13) -> 1.95217
A7: MIRR | B7: =MIRR(Data!B2:B13,0.06,0.1) -> 0.09558594
A8: PMT | B8: =PMT(0.07/12,240,-1000000) -> 7752.9894
A9: IPMT | B9: =IPMT(0.07/12,5,240,-1000000) -> 5788.1479
A10: PPMT | B10: =PPMT(0.07/12,5,240,-1000000) -> 1964.8415
A11: PV | B11: =PV(0.06,10,-50000,0) -> 368004.35
A12: FV | B12: =FV(0.05/12,120,-1000) -> 155282.28
A13: NPER | B13: =NPER(0.06/12,-2000,200000) -> 138.97572
A14: RATE | B14: =RATE(240,-7752.99,1000000) -> 0.0058333342
A15: CUMIPMT | B15: =CUMIPMT(0.07/12,240,1000000,1,12,0) -> -69246.371
A16: CUMPRINC | B16: =CUMPRINC(0.07/12,240,1000000,1,12,0) -> -23789.501
A17: EFFECT | B17: =EFFECT(0.06,12) -> 0.061677812
A18: NOMINAL | B18: =NOMINAL(0.0617,12) -> 0.060021003
A19: SLN | B19: =SLN(100000,10000,10) -> 9000
A20: DB | B20: =DB(100000,10000,10,1) -> 20600
A21: DDB | B21: =DDB(100000,10000,10,1) -> 20000
A22: Named range NPV | B22: =NPV(Rate,CFs) -> 101.78872
A23: DATE | B23: =DATE(2026,2,30) -> 46083 | C23: 46083
A24: EDATE end-month | B24: =EDATE(DATE(2026,1,31),1) -> 46081 | C24: 46081
A25: EOMONTH negative | B25: =EOMONTH(DATE(2026,3,15),-1) -> 46081 | C25: 46081
A26: YEARFRAC basis 0 | B26: =YEARFRAC(DATE(2026,1,31),DATE(2026,3,31),0) -> 0.16666667
A27: YEARFRAC basis 1 | B27: =YEARFRAC(DATE(2026,1,1),DATE(2027,7,1),1) -> 1.4958904
A28: YEARFRAC basis 3 | B28: =YEARFRAC(DATE(2026,1,1),DATE(2027,7,1),3) -> 1.4958904
A29: DAYS360 | B29: =DAYS360(DATE(2026,1,31),DATE(2026,3,31)) -> 60 | C29: 60
A30: DAYS | B30: =_xlfn.DAYS(DATE(2026,12,31),DATE(2026,1,1)) -> 364 | C30: 364
A31: DATEDIF m | B31: =DATEDIF(DATE(2026,1,31),DATE(2026,7,30),"m") -> 5 | C31: 5
A32: DATEDIF y | B32: =DATEDIF(DATE(2020,2,29),DATE(2026,2,28),"y") -> 5 | C32: 5
A33: NETWORKDAYS | B33: =NETWORKDAYS(DATE(2026,1,1),DATE(2026,1,31)) -> 22 | C33: 22
A34: WORKDAY | B34: =WORKDAY(DATE(2026,1,1),10) -> 46037 | C34: 46037
A35: WEEKDAY 2 | B35: =WEEKDAY(DATE(2026,1,1),2) -> 4 | C35: 4
A36: YEAR of text date | B36: =YEAR("2026-03-15") -> 2026 | C36: 2026
A37: 1900 leap serial | B37: =DATE(1900,3,1) -> 61 | C37: 61
A38: Month count from dates | B38: =(YEAR(Data!C13)-YEAR(Data!C2))*12+MONTH(Data!C13)-MONTH(Data!C2) -> 11 | C38: 11
A39: INDEX/MATCH exact | B39: =INDEX(Data!E2:E13,MATCH("Hotel",Data!D2:D13,0)) -> 121 | C39: 121
A40: MATCH approx | B40: =MATCH(105,Data!E2:E13,1) -> 1 | C40: 1
...
