Workbook

Sheet Inputs
A1: 70 FENCHURCH AVENUE – MULTI-LET OFFICE DCF (GBP)
A3: Valuation date | B3: 46023
A4: Purchase price (£) | B4: 245000000
A5: Purchase costs | B5: 0.068
A6: ERV growth a year | B6: 0.025
A7: Void on a new letting (months) | B7: 12
A8: Rent free, new letting (months) | B8: 18
A9: Rent free, renewal (months) | B9: 6
A10: Fit-out contribution, new (£/sq ft) | B10: 60
A11: Fit-out contribution, renewal (£/sq ft) | B11: 20
A12: Letting fees (% of first-year rent) | B12: 0.15
A13: Non-recoverable costs (% of rent) | B13: 0.04
A14: Discount rate | B14: 0.075
... A16: Sale costs | B16: 0.018

Sheet Tenancy
A1: Floor | B1: Tenant | C1: Area (sq ft) | D1: Passing rent (£/sq ft) | E1: Lease expiry | F1: ERV (£/sq ft) | G1: Renewal probability
A2: Ground | B2: Fenchurch Retail | C2: 12000 | D2: 72 | E2: 48023 | F2: 70 | G2: 0.6
A3: 1 | B3: Halden Insurance | C3: 21000 | D3: 61.5 | E3: 46470 | F3: 68 | G3: 0.55
A4: 2 | B4: Halden Insurance | C4: 21000 | D4: 61.5 | E4: 46470 | F4: 68 | G4: 0.55
A5: 3 | B5: Marlow Legal | C5: 21000 | D5: 64 | E5: 47389 | F5: 68 | G5: 0.7
A6: 4 | B6: Vacant | C6: 21000 | D6: 0 | E6: 46023 | F6: 68 | G6: 0
A7: 5 | B7: Coral Re | C7: 20500 | D7: 66 | E7: 48572 | F7: 69 | G7: 0.65
A8: 6 | B8: Tessel Bank | C8: 20500 | D8: 63 | E8: 46927 | F8: 69 | G8: 0.5
A9: 7 | B9: Tessel Bank | C9: 20500 | D9: 63 | E9: 46927 | F9: 69 | G9: 0.5
A10: 8 | B10: Arkwright Partners | C10: 19000 | D10: 70 | E10: 49027 | F10: 72 | G10: 0.6
A11: 9 | B11: Arkwright Partners | C11: 19000 | D11: 70 | E11: 49027 | F11: 72 | G11: 0.6
A12: 10 | B12: Nimbus Capital | C12: 17000 | D12: 78 | E12: 47841 | F12: 76 | G12: 0.45
A13: 11 | B13: Nimbus Capital | C13: 17000 | D13: 78 | E13: 47841 | F13: 76 | G13: 0.45

Sheet Rent
A2: Year | B2: Year start | C2: 1 | D2: 2 | E2: 3 | F2: 4 | G2: 5 | H2: 6 | I2: 7 | J2: 8 | K2: 9 | L2: 10 | M2: 11
A3: Year start date | C3: =EDATE(Inputs!$B$3,12*0) -> 46023 | D3: =EDATE(Inputs!$B$3,12*1) -> 46388 | E3: =EDATE(Inputs!$B$3,12*2) -> 46753 | F3: =EDATE(Inputs!$B$3,12*3) -> 47119 | G3: =EDATE(Inputs!$B$3,12*4) -> 47484 | H3: =EDATE(Inputs!$B$3,12*5) -> 47849 | I3: =EDATE(Inputs!$B$3,12*6) -> 48214 | J3: =EDATE(Inputs!$B$3,12*7) -> 48580 | K3: =EDATE(Inputs!$B$3,12*8) -> 48945 | L3: =EDATE(Inputs!$B$3,12*9) -> 49310 | M3: =EDATE(Inputs!$B$3,12*10) -> 49675
A4: Tenant rows: rent received (probability-weighted)
A5: =Tenancy!B2&" · "&Tenancy!A2 -> Fenchurch Retail · Ground | C5: =Tenancy!$C$2*(Tenancy!$D$2*MAX(0,MIN(1,YEARFRAC(C$3,MIN(Tenancy!$E$2,EDATE(C$3,12)),1)*(Tenancy!$E$2>C$3)))+Tenancy!$F$2*(1+Inputs!$B$6)^(C$2-1)*IF(Tenancy!$E$2<EDATE(C$3,12),Tenancy!$G$2*MAX(0,MAX(0,MIN(12,DATEDIF(MAX(Tenancy!$E$2,C$3),EDATE(C$3,12),"m")))-MAX(0,Inputs!$B$9-IF(Tenancy!$E$2<C$3,DATEDIF(Tenancy!$E$2,C$3,"m"),0)))/12+(1-Tenancy!$G$2)*MAX(0,MAX(0,MIN(12,DATEDIF(MAX(Tenancy!$E$2,C$3),EDATE(C$3,12),"m")))-MAX(0,Inputs!$B$7+Inputs!$B$8-IF(Tenancy!$E$2<C$3,DATEDIF(Tenancy!$E$2,C$3,"m"),0)))/12,0)) -> 864000 | D5: =Tenancy!$C$2*(Tenancy!$D$2*MAX(0,MIN(1,YEARFRAC(D$3,MIN(Tenancy!$E$2,EDATE(D$3,12)),1)*(Tenancy!$E$2>D$3)))+Tenancy!$F$2*(1+Inputs!$B$6)^(D$2-1)*IF(Tenancy!$E$2<EDATE(D$3,12),Tenancy!$G$2*MAX(0,MAX(0,MIN(12,DATEDIF(MAX(Tenancy!$E$2,D$3),EDATE(D$3,12),"m")))-MAX(0,Inputs!$B$9-IF(Tenancy!$E$2<D$3,DATEDIF(Tenancy!$E$2,D$3,"m"),0)))/12+(1-Tenancy!$G$2)*MAX(0,MAX(0,MIN(12,DATEDIF(MAX(Tenancy!$E$2,D$3),EDATE(D$3,12),"m")))-MAX(0,Inputs!$B$7+Inputs!$B$8-IF(Tenancy!$E$2<D$3,DATEDIF(Tenancy!$E$2,D$3,"m"),0)))/12,0)) -> 864000 | E5: =Tenancy!$C$2*(Tenancy!$D$2*MAX(0,MIN(1,YEARFRAC(E$3,MIN(Tenancy!$E$2,EDATE(E$3,12)),1)*(Tenancy!$E$2>E$3)))+Tenancy!$F$2*(1+Inputs!$B$6)^(E$2-1)*IF(Tenancy!$E$2<EDATE(E$3,12),Tenancy!$G$2*MAX(0,MAX(0,MIN(12,DATEDIF(MAX(Tenancy!$E$2,E$3),EDATE(E$3,12),"m")))-MAX(0,Inputs!$B$9-IF(Tenancy!$E$2<E$3,DATEDIF(Tenancy!$E$2,E$3,"m"),0)))/12+(1-Tenancy!$G$2)*MAX(0,MAX(0,MIN(12,DATEDIF(MAX(Tenancy!$E$2,E$3),EDATE(E$3,12),"m")))-MAX(0,Inputs!$B$7+Inputs!$B$8-IF(Tenancy!$E$2<E$3,DATEDIF(Tenancy!$E$2,E$3,"m"),0)))/12,0)) -> 864000 | F5: =Tenancy!$C$2*(Tenancy!$D$2*MAX(0,MIN(1,YEARFRAC(F$3,MIN(Tenancy!$E$2,EDATE(F$3,12)),1)*(Tenancy!$E$2>F$3)))+Tenancy!$F$2*(1+Inputs!$B$6)^(F$2-1)*IF(Tenancy!$E$2<EDATE(F$3,12),Tenancy!$G$2*MAX(0,MAX(0,MIN(12,DATEDIF(MAX(Tenancy!$E$2,F$3),EDATE(F$3,12),"m")))-MAX(0,Inputs!$B$9-IF(Tenancy!$E$2<F$3,DATEDIF(Tenancy!$E$2,F$3,"m"),0)))/12+(1-Tenancy!$G$2)*MAX(0,MAX(0,MIN(12,DATEDIF(MAX(Tenancy!$E$2,F$3),EDATE(F$3,12),"m")))-MAX(0,Inputs!$B$7+Inputs!$B$8-IF(Tenancy!$E$2<F$3,DATEDIF(Tenancy!$E$2,F$3,"m"),0)))/12,0)) -> 864000 | G5: =Tenancy!$C$2*(Tenancy!$D$2*MAX(0,MIN(1,YEARFRAC(G$3,MIN(Tenancy!$E$2,EDATE(G$3,12)),1)*(Tenancy!$E$2>G$3)))+Tenancy!$F$2*(1+Inputs!$B$6)^(G$2-1)*IF(Tenancy!$E$2<EDATE(G$3,12),Tenancy!$G$2*MAX(0,MAX(0,MIN(12,DATEDIF(MAX(Tenancy!$E$2,G$3),EDATE(G$3,12),"m")))-MAX(0,Inputs!$B$9-IF(Tenancy!$E$2<G$3,DATEDIF(Tenancy!$E$2,G$3,"m"),0)))/12+(1-Tenancy!$G$2)*MAX(0,MAX(0,MIN(12,DATEDIF(MAX(Tenancy!$E$2,G$3),EDATE(G$3,12),"m")))-MAX(0,Inputs!$B$7+Inputs!$B$8-IF(Tenancy!$E$2<G$3,DATEDIF(Tenancy!$E$2,G$3,"m"),0)))/12,0)) -> 864000 | H5: =Tenancy!$C$2*(Tenancy!$D$2*MAX(0,MIN(1,YEARFRAC(H$3,MIN(Tenancy!$E$2,EDATE(H$3,12)),1)*(Tenancy!$E$2>H$3)))+Tenancy!$F$2*(1+Inputs!$B$6)^(H$2-1)*IF(Tenancy!$E$2<EDATE(H$3,12),Tenancy!$G$2*MAX(0,MAX(0,MIN(12,DATEDIF(MAX(Tenancy!$E$2,H$3),EDATE(H$3,12),"m")))-MAX(0,Inputs!$B$9-IF(Tenancy!$E$2<H$3,DATEDIF(Tenancy!$E$2,H$3,"m"),0)))/12+(1-Tenancy!$G$2)*MAX(0,MAX(0,MIN(12,DATEDIF(MAX(Tenancy!$E$2,H$3),EDATE(H$3,12),"m")))-MAX(0,Inputs!$B$7+Inputs!$B$8-IF(Tenancy!$E$2<H$3,DATEDIF(Tenancy!$E$2,H$3,"m"),0)))/12,0)) -> 411879.45 | I5: =Tenancy!$C$2*(Tenancy!$D$2*MAX(0,MIN(1,YEARFRAC(I$3,MIN(Tenancy!$E$2,EDATE(I$3,12)),1)*(Tenancy!$E$2>I$3)))+Tenancy!$F$2*(1+Inputs!$B$6)^(I$2-1)*IF(Tenancy!$E$2<EDATE(I$3,12),Tenancy!$G$2*MAX(0,MAX(0,MIN(12,DATEDIF(MAX(Tenancy!$E$2,I$3),EDATE(I$3,12),"m")))-MAX(0,Inputs!$B$9-IF(Tenancy!$E$2<I$3,DATEDIF(Tenancy!$E$2,I$3,"m"),0)))/12+(1-Tenancy!$G$2)*MAX(0,MAX(0,MIN(12,DATEDIF(MAX(Tenancy!$E$2,I$3),EDATE(I$3,12),"m")))-MAX(0,Inputs!$B$7+Inputs!$B$8-IF(Tenancy!$E$2<I$3,DATEDIF(Tenancy!$E$2,I$3,"m"),0)))/12,0)) -> 584485.48 | J5: =Tenancy!$C$2*(Tenancy!$D$2*MAX(0,MIN(1,YEARFRAC(J$3,MIN(Tenancy!$E$2,EDATE(J$3,12)),1)*(Tenancy!$E$2>J$3)))+Tenancy!$F$2*(1+Inputs!$B$6)^(J$2-1)*IF(Tenancy!$E$2<EDATE(J$3,12),Tenancy!$G$2*MAX(0,MAX(0,MIN(12,DATEDIF(MAX(Tenancy!$E$2,J$3),EDATE(J$3,12),"m")))-MAX(0,Inputs!$B$9-IF(Tenancy!$E$2<J$3,DATEDIF(Tenancy!$E$2,J$3,"m"),0)))/12+(1-Tenancy!$G$2)*MAX(0,MAX(0,MIN(12,DATEDIF(MAX(Tenancy!$E$2,J$3),EDATE(J$3,12),"m")))-MAX(0,Inputs!$B$7+Inputs!$B$8-IF(Tenancy!$E$2<J$3,DATEDIF(Tenancy!$E$2,J$3,"m"),0)))/12,0)) -> 599097.62 | ... M5: =Tenancy!$C$2*(Tenancy!$D$2*MAX(0,MIN(1,YEARFRAC(M$3,MIN(Tenancy!$E$2,EDATE(M$3,12)),1)*(Tenancy!$E$2>M$3)))+Tenancy!$F$2*(1+Inputs!$B$6)^(M$2-1)*IF(Tenancy!$E$2<EDATE(M$3,12),Tenancy!$G$2*MAX(0,MAX(0,MIN(12,DATEDIF(MAX(Tenancy!$E$2,M$3),EDATE(M$3,12),"m")))-MAX(0,Inputs!$B$9-IF(Tenancy!$E$2<M$3,DATEDIF(Tenancy!$E$2,M$3,"m"),0)))/12+(1-Tenancy!$G$2)*MAX(0,MAX(0,MIN(12,DATEDIF(MAX(Tenancy!$E$2,M$3),EDATE(M$3,12),"m")))-MAX(0,Inputs!$B$7+Inputs!$B$8-IF(Tenancy!$E$2<M$3,DATEDIF(Tenancy!$E$2,M$3,"m"),0)))/12,0)) -> 1075271
A6: =Tenancy!B3&" · "&Tenancy!A3 -> Halden Insurance · 1 | C6: =Tenancy!$C$3*(Tenancy!$D$3*MAX(0,MIN(1,YEARFRAC(C$3,MIN(Tenancy!$E$3,EDATE(C$3,12)),1)*(Tenancy!$E$3>C$3)))+Tenancy!$F$3*(1+Inputs!$B$6)^(C$2-1)*IF(Tenancy!$E$3<EDATE(C$3,12),Tenancy!$G$3*MAX(0,MAX(0,MIN(12,DATEDIF(MAX(Tenancy!$E$3,C$3),EDATE(C$3,12),"m")))-MAX(0,Inputs!$B$9-IF(Tenancy!$E$3<C$3,DATEDIF(Tenancy!$E$3,C$3,"m"),0)))/12+(1-Tenancy!$G$3)*MAX(0,MAX(0,MIN(12,DATEDIF(MAX(Tenancy!$E$3,C$3),EDATE(C$3,12),"m")))-MAX(0,Inputs!$B$7+Inputs!$B$8-IF(Tenancy!$E$3<C$3,DATEDIF(Tenancy!$E$3,C$3,"m"),0)))/12,0)) -> 1291500 | D6: =Tenancy!$C$3*(Tenancy!$D$3*MAX(0,MIN(1,YEARFRAC(D$3,MIN(Tenancy!$E$3,EDATE(D$3,12)),1)*(Tenancy!$E$3>D$3)))+Tenancy!$F$3*(1+Inputs!$B$6)^(D$2-1)*IF(Tenancy!$E$3<EDATE(D$3,12),Tenancy!$G$3*MAX(0,MAX(0,MIN(12,DATEDIF(MAX(Tenancy!$E$3,D$3),EDATE(D$3,12),"m")))-MAX(0,Inputs!$B$9-IF(Tenancy!$E$3<D$3,DATEDIF(Tenancy!$E$3,D$3,"m"),0)))/12+(1-Tenancy!$G$3)*MAX(0,MAX(0,MIN(12,DATEDIF(MAX(Tenancy!$E$3,D$3),EDATE(D$3,12),"m")))-MAX(0,Inputs!$B$7+Inputs!$B$8-IF(Tenancy!$E$3<D$3,DATEDIF(Tenancy!$E$3,D$3,"m"),0)))/12,0)) -> 491403.96 | E6: =Tenancy!$C$3*(Tenancy!$D$3*MAX(0,MIN(1,YEARFRAC(E$3,MIN(Tenancy!$E$3,EDATE(E$3,12)),1)*(Tenancy!$E$3>E$3)))+Tenancy!$F$3*(1+Inputs!$B$6)^(E$2-1)*IF(Tenancy!$E$3<EDATE(E$3,12),Tenancy!$G$3*MAX(0,MAX(0,MIN(12,DATEDIF(MAX(Tenancy!$E$3,E$3),EDATE(E$3,12),"m")))-MAX(0,Inputs!$B$9-IF(Tenancy!$E$3<E$3,DATEDIF(Tenancy!$E$3,E$3,"m"),0)))/12+(1-Tenancy!$G$3)*MAX(0,MAX(0,MIN(12,DATEDIF(MAX(Tenancy!$E$3,E$3),EDATE(E$3,12),"m")))-MAX(0,Inputs!$B$7+Inputs!$B$8-IF(Tenancy!$E$3<E$3,DATEDIF(Tenancy!$E$3,E$3,"m"),0)))/12,0)) -> 825160.88 | F6: =Tenancy!$C$3*(Tenancy!$D$3*MAX(0,MIN(1,YEARFRAC(F$3,MIN(Tenancy!$E$3,EDATE(F$3,12)),1)*(Tenancy!$E$3>F$3)))+Tenancy!$F$3*(1+Inputs!$B$6)^(F$2-1)*IF(Tenancy!$E$3<EDATE(F$3,12),Tenancy!$G$3*MAX(0,MAX(0,MIN(12,DATEDIF(MAX(Tenancy!$E$3,F$3),EDATE(F$3,12),"m")))-MAX(0,Inputs!$B$9-IF(Tenancy!$E$3<F$3,DATEDIF(Tenancy!$E$3,F$3,"m"),0)))/12+(1-Tenancy!$G$3)*MAX(0,MAX(0,MIN(12,DATEDIF(MAX(Tenancy!$E$3,F$3),EDATE(F$3,12),"m")))-MAX(0,Inputs!$B$7+Inputs!$B$8-IF(Tenancy!$E$3<F$3,DATEDIF(Tenancy!$E$3,F$3,"m"),0)))/12,0)) -> 1018792.4 | G6: =Tenancy!$C$3*(Tenancy!$D$3*MAX(0,MIN(1,YEARFRAC(G$3,MIN(Tenancy!$E$3,EDATE(G$3,12)),1)*(Tenancy!$E$3>G$3)))+Tenancy!$F$3*(1+Inputs!$B$6)^(G$2-1)*IF(Tenancy!$E$3<EDATE(G$3,12),Tenancy!$G$3*MAX(0,MAX(0,MIN(12,DATEDIF(MAX(Tenancy!$E$3,G$3),EDATE(G$3,12),"m")))-MAX(0,Inputs!$B$9-IF(Tenancy!$E$3<G$3,DATEDIF(Tenancy!$E$3,G$3,"m"),0)))/12+(1-Tenancy!$G$3)*MAX(0,MAX(0,MIN(12,DATEDIF(MAX(Tenancy!$E$3,G$3),EDATE(G$3,12),"m")))-MAX(0,Inputs!$B$7+Inputs!$B$8-IF(Tenancy!$E$3<G$3,DATEDIF(Tenancy!$E$3,G$3,"m"),0)))/12,0)) -> 1576244.8 | H6: =Tenancy!$C$3*(Tenancy!$D$3*MAX(0,MIN(1,YEARFRAC(H$3,MIN(Tenancy!$E$3,EDATE(H$3,12)),1)*(Tenancy!$E$3>H$3)))+Tenancy!$F$3*(1+Inputs!$B$6)^(H$2-1)*IF(Tenancy!$E$3<EDATE(H$3,12),Tenancy!$G$3*MAX(0,MAX(0,MIN(12,DATEDIF(MAX(Tenancy!$E$3,H$3),EDATE(H$3,12),"m")))-MAX(0,Inputs!$B$9-IF(Tenancy!$E$3<H$3,DATEDIF(Tenancy!$E$3,H$3,"m"),0)))/12+(1-Tenancy!$G$3)*MAX(0,MAX(0,MIN(12,DATEDIF(MAX(Tenancy!$E$3,H$3),EDATE(H$3,12),"m")))-MAX(0,Inputs!$B$7+Inputs!$B$8-IF(Tenancy!$E$3<H$3,DATEDIF(Tenancy!$E$3,H$3,"m"),0)))/12,0)) -> 1615650.9 | I6: =Tenancy!$C$3*(Tenancy!$D$3*MAX(0,MIN(1,YEARFRAC(I$3,MIN(Tenancy!$E$3,EDATE(I$3,12)),1)*(Tenancy!$E$3>I$3)))+Tenancy!$F$3*(1+Inputs!$B$6)^(I$2-1)*IF(Tenancy!$E$3<EDATE(I$3,12),Tenancy!$G$3*MAX(0,MAX(0,MIN(12,DATEDIF(MAX(Tenancy!$E$3,I$3),EDATE(I$3,12),"m")))-MAX(0,Inputs!$B$9-IF(Tenancy!$E$3<I$3,DATEDIF(Tenancy!$E$3,I$3,"m"),0)))/12+(1-Tenancy!$G$3)*MAX(0,MAX(0,MIN(12,DATEDIF(MAX(Tenancy!$E$3,I$3),EDATE(I$3,12),"m")))-MAX(0,Inputs!$B$7+Inputs!$B$8-IF(Tenancy!$E$3<I$3,DATEDIF(Tenancy!$E$3,I$3,"m"),0)))/12,0)) -> 1656042.2 | J6: =Tenancy!$C$3*(Tenancy!$D$3*MAX(0,MIN(1,YEARFRAC(J$3,MIN(Tenancy!$E$3,EDATE(J$3,12)),1)*(Tenancy!$E$3>J$3)))+Tenancy!$F$3*(1+Inputs!$B$6)^(J$2-1)*IF(Tenancy!$E$3<EDATE(J$3,12),Tenancy!$G$3*MAX(0,MAX(0,MIN(12,DATEDIF(MAX(Tenancy!$E$3,J$3),EDATE(J$3,12),"m")))-MAX(0,Inputs!$B$9-IF(Tenancy!$E$3<J$3,DATEDIF(Tenancy!$E$3,J$3,"m"),0)))/12+(1-Tenancy!$G$3)*MAX(0,MAX(0,MIN(12,DATEDIF(MAX(Tenancy!$E$3,J$3),EDATE(J$3,12),"m")))-MAX(0,Inputs!$B$7+Inputs!$B$8-IF(Tenancy!$E$3<J$3,DATEDIF(Tenancy!$E$3,J$3,"m"),0)))/12,0)) -> 1697443.3 | ... M6: =Tenancy!$C$3*(Tenancy!$D$3*MAX(0,MIN(1,YEARFRAC(M$3,MIN(Tenancy!$E$3,EDATE(M$3,12)),1)*(Tenancy!$E$3>M$3)))+Tenancy!$F$3*(1+Inputs!$B$6)^(M$2-1)*IF(Tenancy!$E$3<EDATE(M$3,12),Tenancy!$G$3*MAX(0,MAX(0,MIN(12,DATEDIF(MAX(Tenancy!$E$3,M$3),EDATE(M$3,12),"m")))-MAX(0,Inputs!$B$9-IF(Tenancy!$E$3<M$3,DATEDIF(Tenancy!$E$3,M$3,"m"),0)))/12+(1-Tenancy!$G$3)*MAX(0,MAX(0,MIN(12,DATEDIF(MAX(Tenancy!$E$3,M$3),EDATE(M$3,12),"m")))-MAX(0,Inputs!$B$7+Inputs!$B$8-IF(Tenancy!$E$3<M$3,DATEDIF(Tenancy!$E$3,M$3,"m"),0)))/12,0)) -> 1827960.7
A7: =Tenancy!B4&" · "&Tenancy!A4 -> Halden Insurance · 2 | C7: =Tenancy!$C$4*(Tenancy!$D$4*MAX(0,MIN(1,YEARFRAC(C$3,MIN(Tenancy!$E$4,EDATE(C$3,12)),1)*(Tenancy!$E$4>C$3)))+Tenancy!$F$4*(1+Inputs!$B$6)^(C$2-1)*IF(Tenancy!$E$4<EDATE(C$3,12),Tenancy!$G$4*MAX(0,MAX(0,MIN(12,DATEDIF(MAX(Tenancy!$E$4,C$3),EDATE(C$3,12),"m")))-MAX(0,Inputs!$B$9-IF(Tenancy!$E$4<C$3,DATEDIF(Tenancy!$E$4,C$3,"m"),0)))/12+(1-Tenancy!$G$4)*MAX(0,MAX(0,MIN(12,DATEDIF(MAX(Tenancy!$E$4,C$3),EDATE(C$3,12),"m")))-MAX(0,Inputs!$B$7+Inputs!$B$8-IF(Tenancy!$E$4<C$3,DATEDIF(Tenancy!$E$4,C$3,"m"),0)))/12,0)) -> 1291500 | D7: =Tenancy!$C$4*(Tenancy!$D$4*MAX(0,MIN(1,YEARFRAC(D$3,MIN(Tenancy!$E$4,EDATE(D$3,12)),1)*(Tenancy!$E$4>D$3)))+Tenancy!$F$4*(1+Inputs!$B$6)^(D$2-1)*IF(Tenancy!$E$4<EDATE(D$3,12),Tenancy!$G$4*MAX(0,MAX(0,MIN(12,DATEDIF(MAX(Tenancy!$E$4,D$3),EDATE(D$3,12),"m")))-MAX(0,Inputs!$B$9-IF(Tenancy!$E$4<D$3,DATEDIF(Tenancy!$E$4,D$3,"m"),0)))/12+(1-Tenancy!$G$4)*MAX(0,MAX(0,MIN(12,DATEDIF(MAX(Tenancy!$E$4,D$3),EDATE(D$3,12),"m")))-MAX(0,Inputs!$B$7+Inputs!$B$8-IF(Tenancy!$E$4<D$3,DATEDIF(Tenancy!$E$4,D$3,"m"),0)))/12,0)) -> 491403.96 | E7: =Tenancy!$C$4*(Tenancy!$D$4*MAX(0,MIN(1,YEARFRAC(E$3,MIN(Tenancy!$E$4,EDATE(E$3,12)),1)*(Tenancy!$E$4>E$3)))+Tenancy!$F$4*(1+Inputs!$B$6)^(E$2-1)*IF(Tenancy!$E$4<EDATE(E$3,12),Tenancy!$G$4*MAX(0,MAX(0,MIN(12,DATEDIF(MAX(Tenancy!$E$4,E$3),EDATE(E$3,12),"m")))-MAX(0,Inputs!$B$9-IF(Tenancy!$E$4<E$3,DATEDIF(Tenancy!$E$4,E$3,"m"),0)))/12+(1-Tenancy!$G$4)*MAX(0,MAX(0,MIN(12,DATEDIF(MAX(Tenancy!$E$4,E$3),EDATE(E$3,12),"m")))-MAX(0,Inputs!$B$7+Inputs!$B$8-IF(Tenancy!$E$4<E$3,DATEDIF(Tenancy!$E$4,E$3,"m"),0)))/12,0)) -> 825160.88 | F7: =Tenancy!$C$4*(Tenancy!$D$4*MAX(0,MIN(1,YEARFRAC(F$3,MIN(Tenancy!$E$4,EDATE(F$3,12)),1)*(Tenancy!$E$4>F$3)))+Tenancy!$F$4*(1+Inputs!$B$6)^(F$2-1)*IF(Tenancy!$E$4<EDATE(F$3,12),Tenancy!$G$4*MAX(0,MAX(0,MIN(12,DATEDIF(MAX(Tenancy!$E$4,F$3),EDATE(F$3,12),"m")))-MAX(0,Inputs!$B$9-IF(Tenancy!$E$4<F$3,DATEDIF(Tenancy!$E$4,F$3,"m"),0)))/12+(1-Tenancy!$G$4)*MAX(0,MAX(0,MIN(12,DATEDIF(MAX(Tenancy!$E$4,F$3),EDATE(F$3,12),"m")))-MAX(0,Inputs!$B$7+Inputs!$B$8-IF(Tenancy!$E$4<F$3,DATEDIF(Tenancy!$E$4,F$3,"m"),0)))/12,0)) -> 1018792.4 | G7: =Tenancy!$C$4*(Tenancy!$D$4*MAX(0,MIN(1,YEARFRAC(G$3,MIN(Tenancy!$E$4,EDATE(G$3,12)),1)*(Tenancy!$E$4>G$3)))+Tenancy!$F$4*(1+Inputs!$B$6)^(G$2-1)*IF(Tenancy!$E$4<EDATE(G$3,12),Tenancy!$G$4*MAX(0,MAX(0,MIN(12,DATEDIF(MAX(Tenancy!$E$4,G$3),EDATE(G$3,12),"m")))-MAX(0,Inputs!$B$9-IF(Tenancy!$E$4<G$3,DATEDIF(Tenancy!$E$4,G$3,"m"),0)))/12+(1-Tenancy!$G$4)*MAX(0,MAX(0,MIN(12,DATEDIF(MAX(Tenancy!$E$4,G$3),EDATE(G$3,12),"m")))-MAX(0,Inputs!$B$7+Inputs!$B$8-IF(Tenancy!$E$4<G$3,DATEDIF(Tenancy!$E$4,G$3,"m"),0)))/12,0)) -> 1576244.8 | H7: =Tenancy!$C$4*(Tenancy!$D$4*MAX(0,MIN(1,YEARFRAC(H$3,MIN(Tenancy!$E$4,EDATE(H$3,12)),1)*(Tenancy!$E$4>H$3)))+Tenancy!$F$4*(1+Inputs!$B$6)^(H$2-1)*IF(Tenancy!$E$4<EDATE(H$3,12),Tenancy!$G$4*MAX(0,MAX(0,MIN(12,DATEDIF(MAX(Tenancy!$E$4,H$3),EDATE(H$3,12),"m")))-MAX(0,Inputs!$B$9-IF(Tenancy!$E$4<H$3,DATEDIF(Tenancy!$E$4,H$3,"m"),0)))/12+(1-Tenancy!$G$4)*MAX(0,MAX(0,MIN(12,DATEDIF(MAX(Tenancy!$E$4,H$3),EDATE(H$3,12),"m")))-MAX(0,Inputs!$B$7+Inputs!$B$8-IF(Tenancy!$E$4<H$3,DATEDIF(Tenancy!$E$4,H$3,"m"),0)))/12,0)) -> 1615650.9 | I7: =Tenancy!$C$4*(Tenancy!$D$4*MAX(0,MIN(1,YEARFRAC(I$3,MIN(Tenancy!$E$4,EDATE(I$3,12)),1)*(Tenancy!$E$4>I$3)))+Tenancy!$F$4*(1+Inputs!$B$6)^(I$2-1)*IF(Tenancy!$E$4<EDATE(I$3,12),Tenancy!$G$4*MAX(0,MAX(0,MIN(12,DATEDIF(MAX(Tenancy!$E$4,I$3),EDATE(I$3,12),"m")))-MAX(0,Inputs!$B$9-IF(Tenancy!$E$4<I$3,DATEDIF(Tenancy!$E$4,I$3,"m"),0)))/12+(1-Tenancy!$G$4)*MAX(0,MAX(0,MIN(12,DATEDIF(MAX(Tenancy!$E$4,I$3),EDATE(I$3,12),"m")))-MAX(0,Inputs!$B$7+Inputs!$B$8-IF(Tenancy!$E$4<I$3,DATEDIF(Tenancy!$E$4,I$3,"m"),0)))/12,0)) -> 1656042.2 | J7: =Tenancy!$C$4*(Tenancy!$D$4*MAX(0,MIN(1,YEARFRAC(J$3,MIN(Tenancy!$E$4,EDATE(J$3,12)),1)*(Tenancy!$E$4>J$3)))+Tenancy!$F$4*(1+Inputs!$B$6)^(J$2-1)*IF(Tenancy!$E$4<EDATE(J$3,12),Tenancy!$G$4*MAX(0,MAX(0,MIN(12,DATEDIF(MAX(Tenancy!$E$4,J$3),EDATE(J$3,12),"m")))-MAX(0,Inputs!$B$9-IF(Tenancy!$E$4<J$3,DATEDIF(Tenancy!$E$4,J$3,"m"),0)))/12+(1-Tenancy!$G$4)*MAX(0,MAX(0,MIN(12,DATEDIF(MAX(Tenancy!$E$4,J$3),EDATE(J$3,12),"m")))-MAX(0,Inputs!$B$7+Inputs!$B$8-IF(Tenancy!$E$4<J$3,DATEDIF(Tenancy!$E$4,J$3,"m"),0)))/12,0)) -> 1697443.3 | ... M7: =Tenancy!$C$4*(Tenancy!$D$4*MAX(0,MIN(1,YEARFRAC(M$3,MIN(Tenancy!$E$4,EDATE(M$3,12)),1)*(Tenancy!$E$4>M$3)))+Tenancy!$F$4*(1+Inputs!$B$6)^(M$2-1)*IF(Tenancy!$E$4<EDATE(M$3,12),Tenancy!$G$4*MAX(0,MAX(0,MIN(12,DATEDIF(MAX(Tenancy!$E$4,M$3),EDATE(M$3,12),"m")))-MAX(0,Inputs!$B$9-IF(Tenancy!$E$4<M$3,DATEDIF(Tenancy!$E$4,M$3,"m"),0)))/12+(1-Tenancy!$G$4)*MAX(0,MAX(0,MIN(12,DATEDIF(MAX(Tenancy!$E$4,M$3),EDATE(M$3,12),"m")))-MAX(0,Inputs!$B$7+Inputs!$B$8-IF(Tenancy!$E$4<M$3,DATEDIF(Tenancy!$E$4,M$3,"m"),0)))/12,0)) -> 1827960.7
A8: =Tenancy!B5&" · "&Tenancy!A5 -> Marlow Legal · 3 | C8: =Tenancy!$C$5*(Tenancy!$D$5*MAX(0,MIN(1,YEARFRAC(C$3,MIN(Tenancy!$E$5,EDATE(C$3,12)),1)*(Tenancy!$E$5>C$3)))+Tenancy!$F$5*(1+Inputs!$B$6)^(C$2-1)*IF(Tenancy!$E$5<EDATE(C$3,12),Tenancy!$G$5*MAX(0,MAX(0,MIN(12,DATEDIF(MAX(Tenancy!$E$5,C$3),EDATE(C$3,12),"m")))-MAX(0,Inputs!$B$9-IF(Tenancy!$E$5<C$3,DATEDIF(Tenancy!$E$5,C$3,"m"),0)))/12+(1-Tenancy!$G$5)*MAX(0,MAX(0,MIN(12,DATEDIF(MAX(Tenancy!$E$5,C$3),EDATE(C$3,12),"m")))-MAX(0,Inputs!$B$7+Inputs!$B$8-IF(Tenancy!$E$5<C$3,DATEDIF(Tenancy!$E$5,C$3,"m"),0)))/12,0)) -> 1344000 | D8: =Tenancy!$C$5*(Tenancy!$D$5*MAX(0,MIN(1,YEARFRAC(D$3,MIN(Tenancy!$E$5,EDATE(D$3,12)),1)*(Tenancy!$E$5>D$3)))+Tenancy!$F$5*(1+Inputs!$B$6)^(D$2-1)*IF(Tenancy!$E$5<EDATE(D$3,12),Tenancy!$G$5*MAX(0,MAX(0,MIN(12,DATEDIF(MAX(Tenancy!$E$5,D$3),EDATE(D$3,12),"m")))-MAX(0,Inputs!$B$9-IF(Tenancy!$E$5<D$3,DATEDIF(Tenancy!$E$5,D$3,"m"),0)))/12+(1-Tenancy!$G$5)*MAX(0,MAX(0,MIN(12,DATEDIF(MAX(Tenancy!$E$5,D$3),EDATE(D$3,12),"m")))-MAX(0,Inputs!$B$7+Inputs!$B$8-IF(Tenancy!$E$5<D$3,DATEDIF(Tenancy!$E$5,D$3,"m"),0)))/12,0)) -> 1344000 | E8: =Tenancy!$C$5*(Tenancy!$D$5*MAX(0,MIN(1,YEARFRAC(E$3,MIN(Tenancy!$E$5,EDATE(E$3,12)),1)*(Tenancy!$E$5>E$3)))+Tenancy!$F$5*(1+Inputs!$B$6)^(E$2-1)*IF(Tenancy!$E$5<EDATE(E$3,12),Tenancy!$G$5*MAX(0,MAX(0,MIN(12,DATEDIF(MAX(Tenancy!$E$5,E$3),EDATE(E$3,12),"m")))-MAX(0,Inputs!$B$9-IF(Tenancy!$E$5<E$3,DATEDIF(Tenancy!$E$5,E$3,"m"),0)))/12+(1-Tenancy!$G$5)*MAX(0,MAX(0,MIN(12,DATEDIF(MAX(Tenancy!$E$5,E$3),EDATE(E$3,12),"m")))-MAX(0,Inputs!$B$7+Inputs!$B$8-IF(Tenancy!$E$5<E$3,DATEDIF(Tenancy!$E$5,E$3,"m"),0)))/12,0)) -> 1344000 | F8: =Tenancy!$C$5*(Tenancy!$D$5*MAX(0,MIN(1,YEARFRAC(F$3,MIN(Tenancy!$E$5,EDATE(F$3,12)),1)*(Tenancy!$E$5>F$3)))+Tenancy!$F$5*(1+Inputs!$B$6)^(F$2-1)*IF(Tenancy!$E$5<EDATE(F$3,12),Tenancy!$G$5*MAX(0,MAX(0,MIN(12,DATEDIF(MAX(Tenancy!$E$5,F$3),EDATE(F$3,12),"m")))-MAX(0,Inputs!$B$9-IF(Tenancy!$E$5<F$3,DATEDIF(Tenancy!$E$5,F$3,"m"),0)))/12+(1-Tenancy!$G$5)*MAX(0,MAX(0,MIN(12,DATEDIF(MAX(Tenancy!$E$5,F$3),EDATE(F$3,12),"m")))-MAX(0,Inputs!$B$7+Inputs!$B$8-IF(Tenancy!$E$5<F$3,DATEDIF(Tenancy!$E$5,F$3,"m"),0)))/12,0)) -> 994191.78 | G8: =Tenancy!$C$5*(Tenancy!$D$5*MAX(0,MIN(1,YEARFRAC(G$3,MIN(Tenancy!$E$5,EDATE(G$3,12)),1)*(Tenancy!$E$5>G$3)))+Tenancy!$F$5*(1+Inputs!$B$6)^(G$2-1)*IF(Tenancy!$E$5<EDATE(G$3,12),Tenancy!$G$5*MAX(0,MAX(0,MIN(12,DATEDIF(MAX(Tenancy!$E$5,G$3),EDATE(G$3,12),"m")))-MAX(0,Inputs!$B$9-IF(Tenancy!$E$5<G$3,DATEDIF(Tenancy!$E$5,G$3,"m"),0)))/12+(1-Tenancy!$G$5)*MAX(0,MAX(0,MIN(12,DATEDIF(MAX(Tenancy!$E$5,G$3),EDATE(G$3,12),"m")))-MAX(0,Inputs!$B$7+Inputs!$B$8-IF(Tenancy!$E$5<G$3,DATEDIF(Tenancy!$E$5,G$3,"m"),0)))/12,0)) -> 827528.52 | H8: =Tenancy!$C$5*(Tenancy!$D$5*MAX(0,MIN(1,YEARFRAC(H$3,MIN(Tenancy!$E$5,EDATE(H$3,12)),1)*(Tenancy!$E$5>H$3)))+Tenancy!$F$5*(1+Inputs!$B$6)^(H$2-1)*IF(Tenancy!$E$5<EDATE(H$3,12),Tenancy!$G$5*MAX(0,MAX(0,MIN(12,DATEDIF(MAX(Tenancy!$E$5,H$3),EDATE(H$3,12),"m")))-MAX(0,Inputs!$B$9-IF(Tenancy!$E$5<H$3,DATEDIF(Tenancy!$E$5,H$3,"m"),0)))/12+(1-Tenancy!$G$5)*MAX(0,MAX(0,MIN(12,DATEDIF(MAX(Tenancy!$E$5,H$3),EDATE(H$3,12),"m")))-MAX(0,Inputs!$B$7+Inputs!$B$8-IF(Tenancy!$E$5<H$3,DATEDIF(Tenancy!$E$5,H$3,"m"),0)))/12,0)) -> 1130955.6 | I8: =Tenancy!$C$5*(Tenancy!$D$5*MAX(0,MIN(1,YEARFRAC(I$3,MIN(Tenancy!$E$5,EDATE(I$3,12)),1)*(Tenancy!$E$5>I$3)))+Tenancy!$F$5*(1+Inputs!$B$6)^(I$2-1)*IF(Tenancy!$E$5<EDATE(I$3,12),Tenancy!$G$5*MAX(0,MAX(0,MIN(12,DATEDIF(MAX(Tenancy!$E$5,I$3),EDATE(I$3,12),"m")))-MAX(0,Inputs!$B$9-IF(Tenancy!$E$5<I$3,DATEDIF(Tenancy!$E$5,I$3,"m"),0)))/12+(1-Tenancy!$G$5)*MAX(0,MAX(0,MIN(12,DATEDIF(MAX(Tenancy!$E$5,I$3),EDATE(I$3,12),"m")))-MAX(0,Inputs!$B$7+Inputs!$B$8-IF(Tenancy!$E$5<I$3,DATEDIF(Tenancy!$E$5,I$3,"m"),0)))/12,0)) -> 1531839 | J8: =Tenancy!$C$5*(Tenancy!$D$5*MAX(0,MIN(1,YEARFRAC(J$3,MIN(Tenancy!$E$5,EDATE(J$3,12)),1)*(Tenancy!$E$5>J$3)))+Tenancy!$F$5*(1+Inputs!$B$6)^(J$2-1)*IF(Tenancy!$E$5<EDATE(J$3,12),Tenancy!$G$5*MAX(0,MAX(0,MIN(12,DATEDIF(MAX(Tenancy!$E$5,J$3),EDATE(J$3,12),"m")))-MAX(0,Inputs!$B$9-IF(Tenancy!$E$5<J$3,DATEDIF(Tenancy!$E$5,J$3,"m"),0)))/12+(1-Tenancy!$G$5)*MAX(0,MAX(0,MIN(12,DATEDIF(MAX(Tenancy!$E$5,J$3),EDATE(J$3,12),"m")))-MAX(0,Inputs!$B$7+Inputs!$B$8-IF(Tenancy!$E$5<J$3,DATEDIF(Tenancy!$E$5,J$3,"m"),0)))/12,0)) -> 1697443.3 | ... M8: =Tenancy!$C$5*(Tenancy!$D$5*MAX(0,MIN(1,YEARFRAC(M$3,MIN(Tenancy!$E$5,EDATE(M$3,12)),1)*(Tenancy!$E$5>M$3)))+Tenancy!$F$5*(1+Inputs!$B$6)^(M$2-1)*IF(Tenancy!$E$5<EDATE(M$3,12),Tenancy!$G$5*MAX(0,MAX(0,MIN(12,DATEDIF(MAX(Tenancy!$E$5,M$3),EDATE(M$3,12),"m")))-MAX(0,Inputs!$B$9-IF(Tenancy!$E$5<M$3,DATEDIF(Tenancy!$E$5,M$3,"m"),0)))/12+(1-Tenancy!$G$5)*MAX(0,MAX(0,MIN(12,DATEDIF(MAX(Tenancy!$E$5,M$3),EDATE(M$3,12),"m")))-MAX(0,Inputs!$B$7+Inputs!$B$8-IF(Tenancy!$E$5<M$3,DATEDIF(Tenancy!$E$5,M$3,"m"),0)))/12,0)) -> 1827960.7
A9: =Tenancy!B6&" · "&Tenancy!A6 -> Vacant · 4 | C9: =Tenancy!$C$6*(Tenancy!$D$6*MAX(0,MIN(1,YEARFRAC(C$3,MIN(Tenancy!$E$6,EDATE(C$3,12)),1)*(Tenancy!$E$6>C$3)))+Tenancy!$F$6*(1+Inputs!$B$6)^(C$2-1)*IF(Tenancy!$E$6<EDATE(C$3,12),Tenancy!$G$6*MAX(0,MAX(0,MIN(12,DATEDIF(MAX(Tenancy!$E$6,C$3),EDATE(C$3,12),"m")))-MAX(0,Inputs!$B$9-IF(Tenancy!$E$6<C$3,DATEDIF(Tenancy!$E$6,C$3,"m"),0)))/12+(1-Tenancy!$G$6)*MAX(0,MAX(0,MIN(12,DATEDIF(MAX(Tenancy!$E$6,C$3),EDATE(C$3,12),"m")))-MAX(0,Inputs!$B$7+Inputs!$B$8-IF(Tenancy!$E$6<C$3,DATEDIF(Tenancy!$E$6,C$3,"m"),0)))/12,0)) -> 0 | D9: =Tenancy!$C$6*(Tenancy!$D$6*MAX(0,MIN(1,YEARFRAC(D$3,MIN(Tenancy!$E$6,EDATE(D$3,12)),1)*(Tenancy!$E$6>D$3)))+Tenancy!$F$6*(1+Inputs!$B$6)^(D$2-1)*IF(Tenancy!$E$6<EDATE(D$3,12),Tenancy!$G$6*MAX(0,MAX(0,MIN(12,DATEDIF(MAX(Tenancy!$E$6,D$3),EDATE(D$3,12),"m")))-MAX(0,Inputs!$B$9-IF(Tenancy!$E$6<D$3,DATEDIF(Tenancy!$E$6,D$3,"m"),0)))/12+(1-Tenancy!$G$6)*MAX(0,MAX(0,MIN(12,DATEDIF(MAX(Tenancy!$E$6,D$3),EDATE(D$3,12),"m")))-MAX(0,Inputs!$B$7+Inputs!$B$8-IF(Tenancy!$E$6<D$3,DATEDIF(Tenancy!$E$6,D$3,"m"),0)))/12,0)) -> 0 | E9: =Tenancy!$C$6*(Tenancy!$D$6*MAX(0,MIN(1,YEARFRAC(E$3,MIN(Tenancy!$E$6,EDATE(E$3,12)),1)*(Tenancy!$E$6>E$3)))+Tenancy!$F$6*(1+Inputs!$B$6)^(E$2-1)*IF(Tenancy!$E$6<EDATE(E$3,12),Tenancy!$G$6*MAX(0,MAX(0,MIN(12,DATEDIF(MAX(Tenancy!$E$6,E$3),EDATE(E$3,12),"m")))-MAX(0,Inputs!$B$9-IF(Tenancy!$E$6<E$3,DATEDIF(Tenancy!$E$6,E$3,"m"),0)))/12+(1-Tenancy!$G$6)*MAX(0,MAX(0,MIN(12,DATEDIF(MAX(Tenancy!$E$6,E$3),EDATE(E$3,12),"m")))-MAX(0,Inputs!$B$7+Inputs!$B$8-IF(Tenancy!$E$6<E$3,DATEDIF(Tenancy!$E$6,E$3,"m"),0)))/12,0)) -> 750146.25 | F9: =Tenancy!$C$6*(Tenancy!$D$6*MAX(0,MIN(1,YEARFRAC(F$3,MIN(Tenancy!$E$6,EDATE(F$3,12)),1)*(Tenancy!$E$6>F$3)))+Tenancy!$F$6*(1+Inputs!$B$6)^(F$2-1)*IF(Tenancy!$E$6<EDATE(F$3,12),Tenancy!$G$6*MAX(0,MAX(0,MIN(12,DATEDIF(MAX(Tenancy!$E$6,F$3),EDATE(F$3,12),"m")))-MAX(0,Inputs!$B$9-IF(Tenancy!$E$6<F$3,DATEDIF(Tenancy!$E$6,F$3,"m"),0)))/12+(1-Tenancy!$G$6)*MAX(0,MAX(0,MIN(12,DATEDIF(MAX(Tenancy!$E$6,F$3),EDATE(F$3,12),"m")))-MAX(0,Inputs!$B$7+Inputs!$B$8-IF(Tenancy!$E$6<F$3,DATEDIF(Tenancy!$E$6,F$3,"m"),0)))/12,0)) -> 1537799.8 | G9: =Tenancy!$C$6*(Tenancy!$D$6*MAX(0,MIN(1,YEARFRAC(G$3,MIN(Tenancy!$E$6,EDATE(G$3,12)),1)*(Tenancy!$E$6>G$3)))+Tenancy!$F$6*(1+Inputs!$B$6)^(G$2-1)*IF(Tenancy!$E$6<EDATE(G$3,12),Tenancy!$G$6*MAX(0,MAX(0,MIN(12,DATEDIF(MAX(Tenancy!$E$6,G$3),EDATE(G$3,12),"m")))-MAX(0,Inputs!$B$9-IF(Tenancy!$E$6<G$3,DATEDIF(Tenancy!$E$6,G$3,"m"),0)))/12+(1-Tenancy!$G$6)*MAX(0,MAX(0,MIN(12,DATEDIF(MAX(Tenancy!$E$6,G$3),EDATE(G$3,12),"m")))-MAX(0,Inputs!$B$7+Inputs!$B$8-IF(Tenancy!$E$6<G$3,DATEDIF(Tenancy!$E$6,G$3,"m"),0)))/12,0)) -> 1576244.8 | H9: =Tenancy!$C$6*(Tenancy!$D$6*MAX(0,MIN(1,YEARFRAC(H$3,MIN(Tenancy!$E$6,EDATE(H$3,12)),1)*(Tenancy!$E$6>H$3)))+Tenancy!$F$6*(1+Inputs!$B$6)^(H$2-1)*IF(Tenancy!$E$6<EDATE(H$3,12),Tenancy!$G$6*MAX(0,MAX(0,MIN(12,DATEDIF(MAX(Tenancy!$E$6,H$3),EDATE(H$3,12),"m")))-MAX(0,Inputs!$B$9-IF(Tenancy!$E$6<H$3,DATEDIF(Tenancy!$E$6,H$3,"m"),0)))/12+(1-Tenancy!$G$6)*MAX(0,MAX(0,MIN(12,DATEDIF(MAX(Tenancy!$E$6,H$3),EDATE(H$3,12),"m")))-MAX(0,Inputs!$B$7+Inputs!$B$8-IF(Tenancy!$E$6<H$3,DATEDIF(Tenancy!$E$6,H$3,"m"),0)))/12,0)) -> 1615650.9 | I9: =Tenancy!$C$6*(Tenancy!$D$6*MAX(0,MIN(1,YEARFRAC(I$3,MIN(Tenancy!$E$6,EDATE(I$3,12)),1)*(Tenancy!$E$6>I$3)))+Tenancy!$F$6*(1+Inputs!$B$6)^(I$2-1)*IF(Tenancy!$E$6<EDATE(I$3,12),Tenancy!$G$6*MAX(0,MAX(0,MIN(12,DATEDIF(MAX(Tenancy!$E$6,I$3),EDATE(I$3,12),"m")))-MAX(0,Inputs!$B$9-IF(Tenancy!$E$6<I$3,DATEDIF(Tenancy!$E$6,I$3,"m"),0)))/12+(1-Tenancy!$G$6)*MAX(0,MAX(0,MIN(12,DATEDIF(MAX(Tenancy!$E$6,I$3),EDATE(I$3,12),"m")))-MAX(0,Inputs!$B$7+Inputs!$B$8-IF(Tenancy!$E$6<I$3,DATEDIF(Tenancy!$E$6,I$3,"m"),0)))/12,0)) -> 1656042.2 | J9: =Tenancy!$C$6*(Tenancy!$D$6*MAX(0,MIN(1,YEARFRAC(J$3,MIN(Tenancy!$E$6,EDATE(J$3,12)),1)*(Tenancy!$E$6>J$3)))+Tenancy!$F$6*(1+Inputs!$B$6)^(J$2-1)*IF(Tenancy!$E$6<EDATE(J$3,12),Tenancy!$G$6*MAX(0,MAX(0,MIN(12,DATEDIF(MAX(Tenancy!$E$6,J$3),EDATE(J$3,12),"m")))-MAX(0,Inputs!$B$9-IF(Tenancy!$E$6<J$3,DATEDIF(Tenancy!$E$6,J$3,"m"),0)))/12+(1-Tenancy!$G$6)*MAX(0,MAX(0,MIN(12,DATEDIF(MAX(Tenancy!$E$6,J$3),EDATE(J$3,12),"m")))-MAX(0,Inputs!$B$7+Inputs!$B$8-IF(Tenancy!$E$6<J$3,DATEDIF(Tenancy!$E$6,J$3,"m"),0)))/12,0)) -> 1697443.3 | ... M9: =Tenancy!$C$6*(Tenancy!$D$6*MAX(0,MIN(1,YEARFRAC(M$3,MIN(Tenancy!$E$6,EDATE(M$3,12)),1)*(Tenancy!$E$6>M$3)))+Tenancy!$F$6*(1+Inputs!$B$6)^(M$2-1)*IF(Tenancy!$E$6<EDATE(M$3,12),Tenancy!$G$6*MAX(0,MAX(0,MIN(12,DATEDIF(MAX(Tenancy!$E$6,M$3),EDATE(M$3,12),"m")))-MAX(0,Inputs!$B$9-IF(Tenancy!$E$6<M$3,DATEDIF(Tenancy!$E$6,M$3,"m"),0)))/12+(1-Tenancy!$G$6)*MAX(0,MAX(0,MIN(12,DATEDIF(MAX(Tenancy!$E$6,M$3),EDATE(M$3,12),"m")))-MAX(0,Inputs!$B$7+Inputs!$B$8-IF(Tenancy!$E$6<M$3,DATEDIF(Tenancy!$E$6,M$3,"m"),0)))/12,0)) -> 1827960.7
A10: =Tenancy!B7&" · "&Tenancy!A7 -> Coral Re · 5 | C10: =Tenancy!$C$7*(Tenancy!$D$7*MAX(0,MIN(1,YEARFRAC(C$3,MIN(Tenancy!$E$7,EDATE(C$3,12)),1)*(Tenancy!$E$7>C$3)))+Tenancy!$F$7*(1+Inputs!$B$6)^(C$2-1)*IF(Tenancy!$E$7<EDATE(C$3,12),Tenancy!$G$7*MAX(0,MAX(0,MIN(12,DATEDIF(MAX(Tenancy!$E$7,C$3),EDATE(C$3,12),"m")))-MAX(0,Inputs!$B$9-IF(Tenancy!$E$7<C$3,DATEDIF(Tenancy!$E$7,C$3,"m"),0)))/12+(1-Tenancy!$G$7)*MAX(0,MAX(0,MIN(12,DATEDIF(MAX(Tenancy!$E$7,C$3),EDATE(C$3,12),"m")))-MAX(0,Inputs!$B$7+Inputs!$B$8-IF(Tenancy!$E$7<C$3,DATEDIF(Tenancy!$E$7,C$3,"m"),0)))/12,0)) -> 1353000 | D10: =Tenancy!$C$7*(Tenancy!$D$7*MAX(0,MIN(1,YEARFRAC(D$3,MIN(Tenancy!$E$7,EDATE(D$3,12)),1)*(Tenancy!$E$7>D$3)))+Tenancy!$F$7*(1+Inputs!$B$6)^(D$2-1)*IF(Tenancy!$E$7<EDATE(D$3,12),Tenancy!$G$7*MAX(0,MAX(0,MIN(12,DATEDIF(MAX(Tenancy!$E$7,D$3),EDATE(D$3,12),"m")))-MAX(0,Inputs!$B$9-IF(Tenancy!$E$7<D$3,DATEDIF(Tenancy!$E$7,D$3,"m"),0)))/12+(1-Tenancy!$G$7)*MAX(0,MAX(0,MIN(12,DATEDIF(MAX(Tenancy!$E$7,D$3),EDATE(D$3,12),"m")))-MAX(0,Inputs!$B$7+Inputs!$B$8-IF(Tenancy!$E$7<D$3,DATEDIF(Tenancy!$E$7,D$3,"m"),0)))/12,0)) -> 1353000 | E10: =Tenancy!$C$7*(Tenancy!$D$7*MAX(0,MIN(1,YEARFRAC(E$3,MIN(Tenancy!$E$7,EDATE(E$3,12)),1)*(Tenancy!$E$7>E$3)))+Tenancy!$F$7*(1+Inputs!$B$6)^(E$2-1)*IF(Tenancy!$E$7<EDATE(E$3,12),Tenancy!$G$7*MAX(0,MAX(0,MIN(12,DATEDIF(MAX(Tenancy!$E$7,E$3),EDATE(E$3,12),"m")))-MAX(0,Inputs!$B$9-IF(Tenancy!$E$7<E$3,DATEDIF(Tenancy!$E$7,E$3,"m"),0)))/12+(1-Tenancy!$G$7)*MAX(0,MAX(0,MIN(12,DATEDIF(MAX(Tenancy!$E$7,E$3),EDATE(E$3,12),"m")))-MAX(0,Inputs!$B$7+Inputs!$B$8-IF(Tenancy!$E$7<E$3,DATEDIF(Tenancy!$E$7,E$3,"m"),0)))/12,0)) -> 1353000 | F10: =Tenancy!$C$7*(Tenancy!$D$7*MAX(0,MIN(1,YEARFRAC(F$3,MIN(Tenancy!$E$7,EDATE(F$3,12)),1)*(Tenancy!$E$7>F$3)))+Tenancy!$F$7*(1+Inputs!$B$6)^(F$2-1)*IF(Tenancy!$E$7<EDATE(F$3,12),Tenancy!$G$7*MAX(0,MAX(0,MIN(12,DATEDIF(MAX(Tenancy!$E$7,F$3),EDATE(F$3,12),"m")))-MAX(0,Inputs!$B$9-IF(Tenancy!$E$7<F$3,DATEDIF(Tenancy!$E$7,F$3,"m"),0)))/12+(1-Tenancy!$G$7)*MAX(0,MAX(0,MIN(12,DATEDIF(MAX(Tenancy!$E$7,F$3),EDATE(F$3,12),"m")))-MAX(0,Inputs!$B$7+Inputs!$B$8-IF(Tenancy!$E$7<F$3,DATEDIF(Tenancy!$E$7,F$3,"m"),0)))/12,0)) -> 1353000 | G10: =Tenancy!$C$7*(Tenancy!$D$7*MAX(0,MIN(1,YEARFRAC(G$3,MIN(Tenancy!$E$7,EDATE(G$3,12)),1)*(Tenancy!$E$7>G$3)))+Tenancy!$F$7*(1+Inputs!$B$6)^(G$2-1)*IF(Tenancy!$E$7<EDATE(G$3,12),Tenancy!$G$7*MAX(0,MAX(0,MIN(12,DATEDIF(MAX(Tenancy!$E$7,G$3),EDATE(G$3,12),"m")))-MAX(0,Inputs!$B$9-IF(Tenancy!$E$7<G$3,DATEDIF(Tenancy!$E$7,G$3,"m"),0)))/12+(1-Tenancy!$G$7)*MAX(0,MAX(0,MIN(12,DATEDIF(MAX(Tenancy!$E$7,G$3),EDATE(G$3,12),"m")))-MAX(0,Inputs!$B$7+Inputs!$B$8-IF(Tenancy!$E$7<G$3,DATEDIF(Tenancy!$E$7,G$3,"m"),0)))/12,0)) -> 1353000 | H10: =Tenancy!$C$7*(Tenancy!$D$7*MAX(0,MIN(1,YEARFRAC(H$3,MIN(Tenancy!$E$7,EDATE(H$3,12)),1)*(Tenancy!$E$7>H$3)))+Tenancy!$F$7*(1+Inputs!$B$6)^(H$2-1)*IF(Tenancy!$E$7<EDATE(H$3,12),Tenancy!$G$7*MAX(0,MAX(0,MIN(12,DATEDIF(MAX(Tenancy!$E$7,H$3),EDATE(H$3,12),"m")))-MAX(0,Inputs!$B$9-IF(Tenancy!$E$7<H$3,DATEDIF(Tenancy!$E$7,H$3,"m"),0)))/12+(1-Tenancy!$G$7)*MAX(0,MAX(0,MIN(12,DATEDIF(MAX(Tenancy!$E$7,H$3),EDATE(H$3,12),"m")))-MAX(0,Inputs!$B$7+Inputs!$B$8-IF(Tenancy!$E$7<H$3,DATEDIF(Tenancy!$E$7,H$3,"m"),0)))/12,0)) -> 1353000 | I10: =Tenancy!$C$7*(Tenancy!$D$7*MAX(0,MIN(1,YEARFRAC(I$3,MIN(Tenancy!$E$7,EDATE(I$3,12)),1)*(Tenancy!$E$7>I$3)))+Tenancy!$F$7*(1+Inputs!$B$6)^(I$2-1)*IF(Tenancy!$E$7<EDATE(I$3,12),Tenancy!$G$7*MAX(0,MAX(0,MIN(12,DATEDIF(MAX(Tenancy!$E$7,I$3),EDATE(I$3,12),"m")))-MAX(0,Inputs!$B$9-IF(Tenancy!$E$7<I$3,DATEDIF(Tenancy!$E$7,I$3,"m"),0)))/12+(1-Tenancy!$G$7)*MAX(0,MAX(0,MIN(12,DATEDIF(MAX(Tenancy!$E$7,I$3),EDATE(I$3,12),"m")))-MAX(0,Inputs!$B$7+Inputs!$B$8-IF(Tenancy!$E$7<I$3,DATEDIF(Tenancy!$E$7,I$3,"m"),0)))/12,0)) -> 1323426.2 | J10: =Tenancy!$C$7*(Tenancy!$D$7*MAX(0,MIN(1,YEARFRAC(J$3,MIN(Tenancy!$E$7,EDATE(J$3,12)),1)*(Tenancy!$E$7>J$3)))+Tenancy!$F$7*(1+Inputs!$B$6)^(J$2-1)*IF(Tenancy!$E$7<EDATE(J$3,12),Tenancy!$G$7*MAX(0,MAX(0,MIN(12,DATEDIF(MAX(Tenancy!$E$7,J$3),EDATE(J$3,12),"m")))-MAX(0,Inputs!$B$9-IF(Tenancy!$E$7<J$3,DATEDIF(Tenancy!$E$7,J$3,"m"),0)))/12+(1-Tenancy!$G$7)*MAX(0,MAX(0,MIN(12,DATEDIF(MAX(Tenancy!$E$7,J$3),EDATE(J$3,12),"m")))-MAX(0,Inputs!$B$7+Inputs!$B$8-IF(Tenancy!$E$7<J$3,DATEDIF(Tenancy!$E$7,J$3,"m"),0)))/12,0)) -> 546453.7 | ... M10: =Tenancy!$C$7*(Tenancy!$D$7*MAX(0,MIN(1,YEARFRAC(M$3,MIN(Tenancy!$E$7,EDATE(M$3,12)),1)*(Tenancy!$E$7>M$3)))+Tenancy!$F$7*(1+Inputs!$B$6)^(M$2-1)*IF(Tenancy!$E$7<EDATE(M$3,12),Tenancy!$G$7*MAX(0,MAX(0,MIN(12,DATEDIF(MAX(Tenancy!$E$7,M$3),EDATE(M$3,12),"m")))-MAX(0,Inputs!$B$9-IF(Tenancy!$E$7<M$3,DATEDIF(Tenancy!$E$7,M$3,"m"),0)))/12+(1-Tenancy!$G$7)*MAX(0,MAX(0,MIN(12,DATEDIF(MAX(Tenancy!$E$7,M$3),EDATE(M$3,12),"m")))-MAX(0,Inputs!$B$7+Inputs!$B$8-IF(Tenancy!$E$7<M$3,DATEDIF(Tenancy!$E$7,M$3,"m"),0)))/12,0)) -> 1810679.6
A11: =Tenancy!B8&" · "&Tenancy!A8 -> Tessel Bank · 6 | C11: =Tenancy!$C$8*(Tenancy!$D$8*MAX(0,MIN(1,YEARFRAC(C$3,MIN(Tenancy!$E$8,EDATE(C$3,12)),1)*(Tenancy!$E$8>C$3)))+Tenancy!$F$8*(1+Inputs!$B$6)^(C$2-1)*IF(Tenancy!$E$8<EDATE(C$3,12),Tenancy!$G$8*MAX(0,MAX(0,MIN(12,DATEDIF(MAX(Tenancy!$E$8,C$3),EDATE(C$3,12),"m")))-MAX(0,Inputs!$B$9-IF(Tenancy!$E$8<C$3,DATEDIF(Tenancy!$E$8,C$3,"m"),0)))/12+(1-Tenancy!$G$8)*MAX(0,MAX(0,MIN(12,DATEDIF(MAX(Tenancy!$E$8,C$3),EDATE(C$3,12),"m")))-MAX(0,Inputs!$B$7+Inputs!$B$8-IF(Tenancy!$E$8<C$3,DATEDIF(Tenancy!$E$8,C$3,"m"),0)))/12,0)) -> 1291500 | D11: =Tenancy!$C$8*(Tenancy!$D$8*MAX(0,MIN(1,YEARFRAC(D$3,MIN(Tenancy!$E$8,EDATE(D$3,12)),1)*(Tenancy!$E$8>D$3)))+Tenancy!$F$8*(1+Inputs!$B$6)^(D$2-1)*IF(Tenancy!$E$8<EDATE(D$3,12),Tenancy!$G$8*MAX(0,MAX(0,MIN(12,DATEDIF(MAX(Tenancy!$E$8,D$3),EDATE(D$3,12),"m")))-MAX(0,Inputs!$B$9-IF(Tenancy!$E$8<D$3,DATEDIF(Tenancy!$E$8,D$3,"m"),0)))/12+(1-Tenancy!$G$8)*MAX(0,MAX(0,MIN(12,DATEDIF(MAX(Tenancy!$E$8,D$3),EDATE(D$3,12),"m")))-MAX(0,Inputs!$B$7+Inputs!$B$8-IF(Tenancy!$E$8<D$3,DATEDIF(Tenancy!$E$8,D$3,"m"),0)))/12,0)) -> 1291500 | E11: =Tenancy!$C$8*(Tenancy!$D$8*MAX(0,MIN(1,YEARFRAC(E$3,MIN(Tenancy!$E$8,EDATE(E$3,12)),1)*(Tenancy!$E$8>E$3)))+Tenancy!$F$8*(1+Inputs!$B$6)^(E$2-1)*IF(Tenancy!$E$8<EDATE(E$3,12),Tenancy!$G$8*MAX(0,MAX(0,MIN(12,DATEDIF(MAX(Tenancy!$E$8,E$3),EDATE(E$3,12),"m")))-MAX(0,Inputs!$B$9-IF(Tenancy!$E$8<E$3,DATEDIF(Tenancy!$E$8,E$3,"m"),0)))/12+(1-Tenancy!$G$8)*MAX(0,MAX(0,MIN(12,DATEDIF(MAX(Tenancy!$E$8,E$3),EDATE(E$3,12),"m")))-MAX(0,Inputs!$B$7+Inputs!$B$8-IF(Tenancy!$E$8<E$3,DATEDIF(Tenancy!$E$8,E$3,"m"),0)))/12,0)) -> 613991.8 | F11: =Tenancy!$C$8*(Tenancy!$D$8*MAX(0,MIN(1,YEARFRAC(F$3,MIN(Tenancy!$E$8,EDATE(F$3,12)),1)*(Tenancy!$E$8>F$3)))+Tenancy!$F$8*(1+Inputs!$B$6)^(F$2-1)*IF(Tenancy!$E$8<EDATE(F$3,12),Tenancy!$G$8*MAX(0,MAX(0,MIN(12,DATEDIF(MAX(Tenancy!$E$8,F$3),EDATE(F$3,12),"m")))-MAX(0,Inputs!$B$9-IF(Tenancy!$E$8<F$3,DATEDIF(Tenancy!$E$8,F$3,"m"),0)))/12+(1-Tenancy!$G$8)*MAX(0,MAX(0,MIN(12,DATEDIF(MAX(Tenancy!$E$8,F$3),EDATE(F$3,12),"m")))-MAX(0,Inputs!$B$7+Inputs!$B$8-IF(Tenancy!$E$8<F$3,DATEDIF(Tenancy!$E$8,F$3,"m"),0)))/12,0)) -> 761630.89 | G11: =Tenancy!$C$8*(Tenancy!$D$8*MAX(0,MIN(1,YEARFRAC(G$3,MIN(Tenancy!$E$8,EDATE(G$3,12)),1)*(Tenancy!$E$8>G$3)))+Tenancy!$F$8*(1+Inputs!$B$6)^(G$2-1)*IF(Tenancy!$E$8<EDATE(G$3,12),Tenancy!$G$8*MAX(0,MAX(0,MIN(12,DATEDIF(MAX(Tenancy!$E$8,G$3),EDATE(G$3,12),"m")))-MAX(0,Inputs!$B$9-IF(Tenancy!$E$8<G$3,DATEDIF(Tenancy!$E$8,G$3,"m"),0)))/12+(1-Tenancy!$G$8)*MAX(0,MAX(0,MIN(12,DATEDIF(MAX(Tenancy!$E$8,G$3),EDATE(G$3,12),"m")))-MAX(0,Inputs!$B$7+Inputs!$B$8-IF(Tenancy!$E$8<G$3,DATEDIF(Tenancy!$E$8,G$3,"m"),0)))/12,0)) -> 780671.67 | H11: =Tenancy!$C$8*(Tenancy!$D$8*MAX(0,MIN(1,YEARFRAC(H$3,MIN(Tenancy!$E$8,EDATE(H$3,12)),1)*(Tenancy!$E$8>H$3)))+Tenancy!$F$8*(1+Inputs!$B$6)^(H$2-1)*IF(Tenancy!$E$8<EDATE(H$3,12),Tenancy!$G$8*MAX(0,MAX(0,MIN(12,DATEDIF(MAX(Tenancy!$E$8,H$3),EDATE(H$3,12),"m")))-MAX(0,Inputs!$B$9-IF(Tenancy!$E$8<H$3,DATEDIF(Tenancy!$E$8,H$3,"m"),0)))/12+(1-Tenancy!$G$8)*MAX(0,MAX(0,MIN(12,DATEDIF(MAX(Tenancy!$E$8,H$3),EDATE(H$3,12),"m")))-MAX(0,Inputs!$B$7+Inputs!$B$8-IF(Tenancy!$E$8<H$3,DATEDIF(Tenancy!$E$8,H$3,"m"),0)))/12,0)) -> 1600376.9 | I11: =Tenancy!$C$8*(Tenancy!$D$8*MAX(0,MIN(1,YEARFRAC(I$3,MIN(Tenancy!$E$8,EDATE(I$3,12)),1)*(Tenancy!$E$8>I$3)))+Tenancy!$F$8*(1+Inputs!$B$6)^(I$2-1)*IF(Tenancy!$E$8<EDATE(I$3,12),Tenancy!$G$8*MAX(0,MAX(0,MIN(12,DATEDIF(MAX(Tenancy!$E$8,I$3),EDATE(I$3,12),"m")))-MAX(0,Inputs!$B$9-IF(Tenancy!$E$8<I$3,DATEDIF(Tenancy!$E$8,I$3,"m"),0)))/12+(1-Tenancy!$G$8)*MAX(0,MAX(0,MIN(12,DATEDIF(MAX(Tenancy!$E$8,I$3),EDATE(I$3,12),"m")))-MAX(0,Inputs!$B$7+Inputs!$B$8-IF(Tenancy!$E$8<I$3,DATEDIF(Tenancy!$E$8,I$3,"m"),0)))/12,0)) -> 1640386.3 | J11: =Tenancy!$C$8*(Tenancy!$D$8*MAX(0,MIN(1,YEARFRAC(J$3,MIN(Tenancy!$E$8,EDATE(J$3,12)),1)*(Tenancy!$E$8>J$3)))+Tenancy!$F$8*(1+Inputs!$B$6)^(J$2-1)*IF(Tenancy!$E$8<EDATE(J$3,12),Tenancy!$G$8*MAX(0,MAX(0,MIN(12,DATEDIF(MAX(Tenancy!$E$8,J$3),EDATE(J$3,12),"m")))-MAX(0,Inputs!$B$9-IF(Tenancy!$E$8<J$3,DATEDIF(Tenancy!$E$8,J$3,"m"),0)))/12+(1-Tenancy!$G$8)*MAX(0,MAX(0,MIN(12,DATEDIF(MAX(Tenancy!$E$8,J$3),EDATE(J$3,12),"m")))-MAX(0,Inputs!$B$7+Inputs!$B$8-IF(Tenancy!$E$8<J$3,DATEDIF(Tenancy!$E$8,J$3,"m"),0)))/12,0)) -> 1681396 | ... M11: =Tenancy!$C$8*(Tenancy!$D$8*MAX(0,MIN(1,YEARFRAC(M$3,MIN(Tenancy!$E$8,EDATE(M$3,12)),1)*(Tenancy!$E$8>M$3)))+Tenancy!$F$8*(1+Inputs!$B$6)^(M$2-1)*IF(Tenancy!$E$8<EDATE(M$3,12),Tenancy!$G$8*MAX(0,MAX(0,MIN(12,DATEDIF(MAX(Tenancy!$E$8,M$3),EDATE(M$3,12),"m")))-MAX(0,Inputs!$B$9-IF(Tenancy!$E$8<M$3,DATEDIF(Tenancy!$E$8,M$3,"m"),0)))/12+(1-Tenancy!$G$8)*MAX(0,MAX(0,MIN(12,DATEDIF(MAX(Tenancy!$E$8,M$3),EDATE(M$3,12),"m")))-MAX(0,Inputs!$B$7+Inputs!$B$8-IF(Tenancy!$E$8<M$3,DATEDIF(Tenancy!$E$8,M$3,"m"),0)))/12,0)) -> 1810679.6
A12: =Tenancy!B9&" · "&Tenancy!A9 -> Tessel Bank · 7 | C12: =Tenancy!$C$9*(Tenancy!$D$9*MAX(0,MIN(1,YEARFRAC(C$3,MIN(Tenancy!$E$9,EDATE(C$3,12)),1)*(Tenancy!$E$9>C$3)))+Tenancy!$F$9*(1+Inputs!$B$6)^(C$2-1)*IF(Tenancy!$E$9<EDATE(C$3,12),Tenancy!$G$9*MAX(0,MAX(0,MIN(12,DATEDIF(MAX(Tenancy!$E$9,C$3),EDATE(C$3,12),"m")))-MAX(0,Inputs!$B$9-IF(Tenancy!$E$9<C$3,DATEDIF(Tenancy!$E$9,C$3,"m"),0)))/12+(1-Tenancy!$G$9)*MAX(0,MAX(0,MIN(12,DATEDIF(MAX(Tenancy!$E$9,C$3),EDATE(C$3,12),"m")))-MAX(0,Inputs!$B$7+Inputs!$B$8-IF(Tenancy!$E$9<C$3,DATEDIF(Tenancy!$E$9,C$3,"m"),0)))/12,0)) -> 1291500 | D12: =Tenancy!$C$9*(Tenancy!$D$9*MAX(0,MIN(1,YEARFRAC(D$3,MIN(Tenancy!$E$9,EDATE(D$3,12)),1)*(Tenancy!$E$9>D$3)))+Tenancy!$F$9*(1+Inputs!$B$6)^(D$2-1)*IF(Tenancy!$E$9<EDATE(D$3,12),Tenancy!$G$9*MAX(0,MAX(0,MIN(12,DATEDIF(MAX(Tenancy!$E$9,D$3),EDATE(D$3,12),"m")))-MAX(0,Inputs!$B$9-IF(Tenancy!$E$9<D$3,DATEDIF(Tenancy!$E$9,D$3,"m"),0)))/12+(1-Tenancy!$G$9)*MAX(0,MAX(0,MIN(12,DATEDIF(MAX(Tenancy!$E$9,D$3),EDATE(D$3,12),"m")))-MAX(0,Inputs!$B$7+Inputs!$B$8-IF(Tenancy!$E$9<D$3,DATEDIF(Tenancy!$E$9,D$3,"m"),0)))/12,0)) -> 1291500 | E12: =Tenancy!$C$9*(Tenancy!$D$9*MAX(0,MIN(1,YEARFRAC(E$3,MIN(Tenancy!$E$9,EDATE(E$3,12)),1)*(Tenancy!$E$9>E$3)))+Tenancy!$F$9*(1+Inputs!$B$6)^(E$2-1)*IF(Tenancy!$E$9<EDATE(E$3,12),Tenancy!$G$9*MAX(0,MAX(0,MIN(12,DATEDIF(MAX(Tenancy!$E$9,E$3),EDATE(E$3,12),"m")))-MAX(0,Inputs!$B$9-IF(Tenancy!$E$9<E$3,DATEDIF(Tenancy!$E$9,E$3,"m"),0)))/12+(1-Tenancy!$G$9)*MAX(0,MAX(0,MIN(12,DATEDIF(MAX(Tenancy!$E$9,E$3),EDATE(E$3,12),"m")))-MAX(0,Inputs!$B$7+Inputs!$B$8-IF(Tenancy!$E$9<E$3,DATEDIF(Tenancy!$E$9,E$3,"m"),0)))/12,0)) -> 613991.8 | F12: =Tenancy!$C$9*(Tenancy!$D$9*MAX(0,MIN(1,YEARFRAC(F$3,MIN(Tenancy!$E$9,EDATE(F$3,12)),1)*(Tenancy!$E$9>F$3)))+Tenancy!$F$9*(1+Inputs!$B$6)^(F$2-1)*IF(Tenancy!$E$9<EDATE(F$3,12),Tenancy!$G$9*MAX(0,MAX(0,MIN(12,DATEDIF(MAX(Tenancy!$E$9,F$3),EDATE(F$3,12),"m")))-MAX(0,Inputs!$B$9-IF(Tenancy!$E$9<F$3,DATEDIF(Tenancy!$E$9,F$3,"m"),0)))/12+(1-Tenancy!$G$9)*MAX(0,MAX(0,MIN(12,DATEDIF(MAX(Tenancy!$E$9,F$3),EDATE(F$3,12),"m")))-MAX(0,Inputs!$B$7+Inputs!$B$8-IF(Tenancy!$E$9<F$3,DATEDIF(Tenancy!$E$9,F$3,"m"),0)))/12,0)) -> 761630.89 | G12: =Tenancy!$C$9*(Tenancy!$D$9*MAX(0,MIN(1,YEARFRAC(G$3,MIN(Tenancy!$E$9,EDATE(G$3,12)),1)*(Tenancy!$E$9>G$3)))+Tenancy!$F$9*(1+Inputs!$B$6)^(G$2-1)*IF(Tenancy!$E$9<EDATE(G$3,12),Tenancy!$G$9*MAX(0,MAX(0,MIN(12,DATEDIF(MAX(Tenancy!$E$9,G$3),EDATE(G$3,12),"m")))-MAX(0,Inputs!$B$9-IF(Tenancy!$E$9<G$3,DATEDIF(Tenancy!$E$9,G$3,"m"),0)))/12+(1-Tenancy!$G$9)*MAX(0,MAX(0,MIN(12,DATEDIF(MAX(Tenancy!$E$9,G$3),EDATE(G$3,12),"m")))-MAX(0,Inputs!$B$7+Inputs!$B$8-IF(Tenancy!$E$9<G$3,DATEDIF(Tenancy!$E$9,G$3,"m"),0)))/12,0)) -> 780671.67 | H12: =Tenancy!$C$9*(Tenancy!$D$9*MAX(0,MIN(1,YEARFRAC(H$3,MIN(Tenancy!$E$9,EDATE(H$3,12)),1)*(Tenancy!$E$9>H$3)))+Tenancy!$F$9*(1+Inputs!$B$6)^(H$2-1)*IF(Tenancy!$E$9<EDATE(H$3,12),Tenancy!$G$9*MAX(0,MAX(0,MIN(12,DATEDIF(MAX(Tenancy!$E$9,H$3),EDATE(H$3,12),"m")))-MAX(0,Inputs!$B$9-IF(Tenancy!$E$9<H$3,DATEDIF(Tenancy!$E$9,H$3,"m"),0)))/12+(1-Tenancy!$G$9)*MAX(0,MAX(0,MIN(12,DATEDIF(MAX(Tenancy!$E$9,H$3),EDATE(H$3,12),"m")))-MAX(0,Inputs!$B$7+Inputs!$B$8-IF(Tenancy!$E$9<H$3,DATEDIF(Tenancy!$E$9,H$3,"m"),0)))/12,0)) -> 1600376.9 | I12: =Tenancy!$C$9*(Tenancy!$D$9*MAX(0,MIN(1,YEARFRAC(I$3,MIN(Tenancy!$E$9,EDATE(I$3,12)),1)*(Tenancy!$E$9>I$3)))+Tenancy!$F$9*(1+Inputs!$B$6)^(I$2-1)*IF(Tenancy!$E$9<EDATE(I$3,12),Tenancy!$G$9*MAX(0,MAX(0,MIN(12,DATEDIF(MAX(Tenancy!$E$9,I$3),EDATE(I$3,12),"m")))-MAX(0,Inputs!$B$9-IF(Tenancy!$E$9<I$3,DATEDIF(Tenancy!$E$9,I$3,"m"),0)))/12+(1-Tenancy!$G$9)*MAX(0,MAX(0,MIN(12,DATEDIF(MAX(Tenancy!$E$9,I$3),EDATE(I$3,12),"m")))-MAX(0,Inputs!$B$7+Inputs!$B$8-IF(Tenancy!$E$9<I$3,DATEDIF(Tenancy!$E$9,I$3,"m"),0)))/12,0)) -> 1640386.3 | J12: =Tenancy!$C$9*(Tenancy!$D$9*MAX(0,MIN(1,YEARFRAC(J$3,MIN(Tenancy!$E$9,EDATE(J$3,12)),1)*(Tenancy!$E$9>J$3)))+Tenancy!$F$9*(1+Inputs!$B$6)^(J$2-1)*IF(Tenancy!$E$9<EDATE(J$3,12),Tenancy!$G$9*MAX(0,MAX(0,MIN(12,DATEDIF(MAX(Tenancy!$E$9,J$3),EDATE(J$3,12),"m")))-MAX(0,Inputs!$B$9-IF(Tenancy!$E$9<J$3,DATEDIF(Tenancy!$E$9,J$3,"m"),0)))/12+(1-Tenancy!$G$9)*MAX(0,MAX(0,MIN(12,DATEDIF(MAX(Tenancy!$E$9,J$3),EDATE(J$3,12),"m")))-MAX(0,Inputs!$B$7+Inputs!$B$8-IF(Tenancy!$E$9<J$3,DATEDIF(Tenancy!$E$9,J$3,"m"),0)))/12,0)) -> 1681396 | ... M12: =Tenancy!$C$9*(Tenancy!$D$9*MAX(0,MIN(1,YEARFRAC(M$3,MIN(Tenancy!$E$9,EDATE(M$3,12)),1)*(Tenancy!$E$9>M$3)))+Tenancy!$F$9*(1+Inputs!$B$6)^(M$2-1)*IF(Tenancy!$E$9<EDATE(M$3,12),Tenancy!$G$9*MAX(0,MAX(0,MIN(12,DATEDIF(MAX(Tenancy!$E$9,M$3),EDATE(M$3,12),"m")))-MAX(0,Inputs!$B$9-IF(Tenancy!$E$9<M$3,DATEDIF(Tenancy!$E$9,M$3,"m"),0)))/12+(1-Tenancy!$G$9)*MAX(0,MAX(0,MIN(12,DATEDIF(MAX(Tenancy!$E$9,M$3),EDATE(M$3,12),"m")))-MAX(0,Inputs!$B$7+Inputs!$B$8-IF(Tenancy!$E$9<M$3,DATEDIF(Tenancy!$E$9,M$3,"m"),0)))/12,0)) -> 1810679.6
A13: =Tenancy!B10&" · "&Tenancy!A10 -> Arkwright Partners · 8 | C13: =Tenancy!$C$10*(Tenancy!$D$10*MAX(0,MIN(1,YEARFRAC(C$3,MIN(Tenancy!$E$10,EDATE(C$3,12)),1)*(Tenancy!$E$10>C$3)))+Tenancy!$F$10*(1+Inputs!$B$6)^(C$2-1)*IF(Tenancy!$E$10<EDATE(C$3,12),Tenancy!$G$10*MAX(0,MAX(0,MIN(12,DATEDIF(MAX(Tenancy!$E$10,C$3),EDATE(C$3,12),"m")))-MAX(0,Inputs!$B$9-IF(Tenancy!$E$10<C$3,DATEDIF(Tenancy!$E$10,C$3,"m"),0)))/12+(1-Tenancy!$G$10)*MAX(0,MAX(0,MIN(12,DATEDIF(MAX(Tenancy!$E$10,C$3),EDATE(C$3,12),"m")))-MAX(0,Inputs!$B$7+Inputs!$B$8-IF(Tenancy!$E$10<C$3,DATEDIF(Tenancy!$E$10,C$3,"m"),0)))/12,0)) -> 1330000 | D13: =Tenancy!$C$10*(Tenancy!$D$10*MAX(0,MIN(1,YEARFRAC(D$3,MIN(Tenancy!$E$10,EDATE(D$3,12)),1)*(Tenancy!$E$10>D$3)))+Tenancy!$F$10*(1+Inputs!$B$6)^(D$2-1)*IF(Tenancy!$E$10<EDATE(D$3,12),Tenancy!$G$10*MAX(0,MAX(0,MIN(12,DATEDIF(MAX(Tenancy!$E$10,D$3),EDATE(D$3,12),"m")))-MAX(0,Inputs!$B$9-IF(Tenancy!$E$10<D$3,DATEDIF(Tenancy!$E$10,D$3,"m"),0)))/12+(1-Tenancy!$G$10)*MAX(0,MAX(0,MIN(12,DATEDIF(MAX(Tenancy!$E$10,D$3),EDATE(D$3,12),"m")))-MAX(0,Inputs!$B$7+Inputs!$B$8-IF(Tenancy!$E$10<D$3,DATEDIF(Tenancy!$E$10,D$3,"m"),0)))/12,0)) -> 1330000 | E13: =Tenancy!$C$10*(Tenancy!$D$10*MAX(0,MIN(1,YEARFRAC(E$3,MIN(Tenancy!$E$10,EDATE(E$3,12)),1)*(Tenancy!$E$10>E$3)))+Tenancy!$F$10*(1+Inputs!$B$6)^(E$2-1)*IF(Tenancy!$E$10<EDATE(E$3,12),Tenancy!$G$10*MAX(0,MAX(0,MIN(12,DATEDIF(MAX(Tenancy!$E$10,E$3),EDATE(E$3,12),"m")))-MAX(0,Inputs!$B$9-IF(Tenancy!$E$10<E$3,DATEDIF(Tenancy!$E$10,E$3,"m"),0)))/12+(1-Tenancy!$G$10)*MAX(0,MAX(0,MIN(12,DATEDIF(MAX(Tenancy!$E$10,E$3),EDATE(E$3,12),"m")))-MAX(0,Inputs!$B$7+Inputs!$B$8-IF(Tenancy!$E$10<E$3,DATEDIF(Tenancy!$E$10,E$3,"m"),0)))/12,0)) -> 1330000 | F13: =Tenancy!$C$10*(Tenancy!$D$10*MAX(0,MIN(1,YEARFRAC(F$3,MIN(Tenancy!$E$10,EDATE(F$3,12)),1)*(Tenancy!$E$10>F$3)))+Tenancy!$F$10*(1+Inputs!$B$6)^(F$2-1)*IF(Tenancy!$E$10<EDATE(F$3,12),Tenancy!$G$10*MAX(0,MAX(0,MIN(12,DATEDIF(MAX(Tenancy!$E$10,F$3),EDATE(F$3,12),"m")))-MAX(0,Inputs!$B$9-IF(Tenancy!$E$10<F$3,DATEDIF(Tenancy!$E$10,F$3,"m"),0)))/12+(1-Tenancy!$G$10)*MAX(0,MAX(0,MIN(12,DATEDIF(MAX(Tenancy!$E$10,F$3),EDATE(F$3,12),"m")))-MAX(0,Inputs!$B$7+Inputs!$B$8-IF(Tenancy!$E$10<F$3,DATEDIF(Tenancy!$E$10,F$3,"m"),0)))/12,0)) -> 1330000 | G13: =Tenancy!$C$10*(Tenancy!$D$10*MAX(0,MIN(1,YEARFRAC(G$3,MIN(Tenancy!$E$10,EDATE(G$3,12)),1)*(Tenancy!$E$10>G$3)))+Tenancy!$F$10*(1+Inputs!$B$6)^(G$2-1)*IF(Tenancy!$E$10<EDATE(G$3,12),Tenancy!$G$10*MAX(0,MAX(0,MIN(12,DATEDIF(MAX(Tenancy!$E$10,G$3),EDATE(G$3,12),"m")))-MAX(0,Inputs!$B$9-IF(Tenancy!$E$10<G$3,DATEDIF(Tenancy!$E$10,G$3,"m"),0)))/12+(1-Tenancy!$G$10)*MAX(0,MAX(0,MIN(12,DATEDIF(MAX(Tenancy!$E$10,G$3),EDATE(G$3,12),"m")))-MAX(0,Inputs!$B$7+Inputs!$B$8-IF(Tenancy!$E$10<G$3,DATEDIF(Tenancy!$E$10,G$3,"m"),0)))/12,0)) -> 1330000 | H13: =Tenancy!$C$10*(Tenancy!$D$10*MAX(0,MIN(1,YEARFRAC(H$3,MIN(Tenancy!$E$10,EDATE(H$3,12)),1)*(Tenancy!$E$10>H$3)))+Tenancy!$F$10*(1+Inputs!$B$6)^(H$2-1)*IF(Tenancy!$E$10<EDATE(H$3,12),Tenancy!$G$10*MAX(0,MAX(0,MIN(12,DATEDIF(MAX(Tenancy!$E$10,H$3),EDATE(H$3,12),"m")))-MAX(0,Inputs!$B$9-IF(Tenancy!$E$10<H$3,DATEDIF(Tenancy!$E$10,H$3,"m"),0)))/12+(1-Tenancy!$G$10)*MAX(0,MAX(0,MIN(12,DATEDIF(MAX(Tenancy!$E$10,H$3),EDATE(H$3,12),"m")))-MAX(0,Inputs!$B$7+Inputs!$B$8-IF(Tenancy!$E$10<H$3,DATEDIF(Tenancy!$E$10,H$3,"m"),0)))/12,0)) -> 1330000 | I13: =Tenancy!$C$10*(Tenancy!$D$10*MAX(0,MIN(1,YEARFRAC(I$3,MIN(Tenancy!$E$10,EDATE(I$3,12)),1)*(Tenancy!$E$10>I$3)))+Tenancy!$F$10*(1+Inputs!$B$6)^(I$2-1)*IF(Tenancy!$E$10<EDATE(I$3,12),Tenancy!$G$10*MAX(0,MAX(0,MIN(12,DATEDIF(MAX(Tenancy!$E$10,I$3),EDATE(I$3,12),"m")))-MAX(0,Inputs!$B$9-IF(Tenancy!$E$10<I$3,DATEDIF(Tenancy!$E$10,I$3,"m"),0)))/12+(1-Tenancy!$G$10)*MAX(0,MAX(0,MIN(12,DATEDIF(MAX(Tenancy!$E$10,I$3),EDATE(I$3,12),"m")))-MAX(0,Inputs!$B$7+Inputs!$B$8-IF(Tenancy!$E$10<I$3,DATEDIF(Tenancy!$E$10,I$3,"m"),0)))/12,0)) -> 1330000 | J13: =Tenancy!$C$10*(Tenancy!$D$10*MAX(0,MIN(1,YEARFRAC(J$3,MIN(Tenancy!$E$10,EDATE(J$3,12)),1)*(Tenancy!$E$10>J$3)))+Tenancy!$F$10*(1+Inputs!$B$6)^(J$2-1)*IF(Tenancy!$E$10<EDATE(J$3,12),Tenancy!$G$10*MAX(0,MAX(0,MIN(12,DATEDIF(MAX(Tenancy!$E$10,J$3),EDATE(J$3,12),"m")))-MAX(0,Inputs!$B$9-IF(Tenancy!$E$10<J$3,DATEDIF(Tenancy!$E$10,J$3,"m"),0)))/12+(1-Tenancy!$G$10)*MAX(0,MAX(0,MIN(12,DATEDIF(MAX(Tenancy!$E$10,J$3),EDATE(J$3,12),"m")))-MAX(0,Inputs!$B$7+Inputs!$B$8-IF(Tenancy!$E$10<J$3,DATEDIF(Tenancy!$E$10,J$3,"m"),0)))/12,0)) -> 1330000 | ... M13: =Tenancy!$C$10*(Tenancy!$D$10*MAX(0,MIN(1,YEARFRAC(M$3,MIN(Tenancy!$E$10,EDATE(M$3,12)),1)*(Tenancy!$E$10>M$3)))+Tenancy!$F$10*(1+Inputs!$B$6)^(M$2-1)*IF(Tenancy!$E$10<EDATE(M$3,12),Tenancy!$G$10*MAX(0,MAX(0,MIN(12,DATEDIF(MAX(Tenancy!$E$10,M$3),EDATE(M$3,12),"m")))-MAX(0,Inputs!$B$9-IF(Tenancy!$E$10<M$3,DATEDIF(Tenancy!$E$10,M$3,"m"),0)))/12+(1-Tenancy!$G$10)*MAX(0,MAX(0,MIN(12,DATEDIF(MAX(Tenancy!$E$10,M$3),EDATE(M$3,12),"m")))-MAX(0,Inputs!$B$7+Inputs!$B$8-IF(Tenancy!$E$10<M$3,DATEDIF(Tenancy!$E$10,M$3,"m"),0)))/12,0)) -> 1225809
A14: =Tenancy!B11&" · "&Tenancy!A11 -> Arkwright Partners · 9 | C14: =Tenancy!$C$11*(Tenancy!$D$11*MAX(0,MIN(1,YEARFRAC(C$3,MIN(Tenancy!$E$11,EDATE(C$3,12)),1)*(Tenancy!$E$11>C$3)))+Tenancy!$F$11*(1+Inputs!$B$6)^(C$2-1)*IF(Tenancy!$E$11<EDATE(C$3,12),Tenancy!$G$11*MAX(0,MAX(0,MIN(12,DATEDIF(MAX(Tenancy!$E$11,C$3),EDATE(C$3,12),"m")))-MAX(0,Inputs!$B$9-IF(Tenancy!$E$11<C$3,DATEDIF(Tenancy!$E$11,C$3,"m"),0)))/12+(1-Tenancy!$G$11)*MAX(0,MAX(0,MIN(12,DATEDIF(MAX(Tenancy!$E$11,C$3),EDATE(C$3,12),"m")))-MAX(0,Inputs!$B$7+Inputs!$B$8-IF(Tenancy!$E$11<C$3,DATEDIF(Tenancy!$E$11,C$3,"m"),0)))/12,0)) -> 1330000 | D14: =Tenancy!$C$11*(Tenancy!$D$11*MAX(0,MIN(1,YEARFRAC(D$3,MIN(Tenancy!$E$11,EDATE(D$3,12)),1)*(Tenancy!$E$11>D$3)))+Tenancy!$F$11*(1+Inputs!$B$6)^(D$2-1)*IF(Tenancy!$E$11<EDATE(D$3,12),Tenancy!$G$11*MAX(0,MAX(0,MIN(12,DATEDIF(MAX(Tenancy!$E$11,D$3),EDATE(D$3,12),"m")))-MAX(0,Inputs!$B$9-IF(Tenancy!$E$11<D$3,DATEDIF(Tenancy!$E$11,D$3,"m"),0)))/12+(1-Tenancy!$G$11)*MAX(0,MAX(0,MIN(12,DATEDIF(MAX(Tenancy!$E$11,D$3),EDATE(D$3,12),"m")))-MAX(0,Inputs!$B$7+Inputs!$B$8-IF(Tenancy!$E$11<D$3,DATEDIF(Tenancy!$E$11,D$3,"m"),0)))/12,0)) -> 1330000 | E14: =Tenancy!$C$11*(Tenancy!$D$11*MAX(0,MIN(1,YEARFRAC(E$3,MIN(Tenancy!$E$11,EDATE(E$3,12)),1)*(Tenancy!$E$11>E$3)))+Tenancy!$F$11*(1+Inputs!$B$6)^(E$2-1)*IF(Tenancy!$E$11<EDATE(E$3,12),Tenancy!$G$11*MAX(0,MAX(0,MIN(12,DATEDIF(MAX(Tenancy!$E$11,E$3),EDATE(E$3,12),"m")))-MAX(0,Inputs!$B$9-IF(Tenancy!$E$11<E$3,DATEDIF(Tenancy!$E$11,E$3,"m"),0)))/12+(1-Tenancy!$G$11)*MAX(0,MAX(0,MIN(12,DATEDIF(MAX(Tenancy!$E$11,E$3),EDATE(E$3,12),"m")))-MAX(0,Inputs!$B$7+Inputs!$B$8-IF(Tenancy!$E$11<E$3,DATEDIF(Tenancy!$E$11,E$3,"m"),0)))/12,0)) -> 1330000 | F14: =Tenancy!$C$11*(Tenancy!$D$11*MAX(0,MIN(1,YEARFRAC(F$3,MIN(Tenancy!$E$11,EDATE(F$3,12)),1)*(Tenancy!$E$11>F$3)))+Tenancy!$F$11*(1+Inputs!$B$6)^(F$2-1)*IF(Tenancy!$E$11<EDATE(F$3,12),Tenancy!$G$11*MAX(0,MAX(0,MIN(12,DATEDIF(MAX(Tenancy!$E$11,F$3),EDATE(F$3,12),"m")))-MAX(0,Inputs!$B$9-IF(Tenancy!$E$11<F$3,DATEDIF(Tenancy!$E$11,F$3,"m"),0)))/12+(1-Tenancy!$G$11)*MAX(0,MAX(0,MIN(12,DATEDIF(MAX(Tenancy!$E$11,F$3),EDATE(F$3,12),"m")))-MAX(0,Inputs!$B$7+Inputs!$B$8-IF(Tenancy!$E$11<F$3,DATEDIF(Tenancy!$E$11,F$3,"m"),0)))/12,0)) -> 1330000 | G14: =Tenancy!$C$11*(Tenancy!$D$11*MAX(0,MIN(1,YEARFRAC(G$3,MIN(Tenancy!$E$11,EDATE(G$3,12)),1)*(Tenancy!$E$11>G$3)))+Tenancy!$F$11*(1+Inputs!$B$6)^(G$2-1)*IF(Tenancy!$E$11<EDATE(G$3,12),Tenancy!$G$11*MAX(0,MAX(0,MIN(12,DATEDIF(MAX(Tenancy!$E$11,G$3),EDATE(G$3,12),"m")))-MAX(0,Inputs!$B$9-IF(Tenancy!$E$11<G$3,DATEDIF(Tenancy!$E$11,G$3,"m"),0)))/12+(1-Tenancy!$G$11)*MAX(0,MAX(0,MIN(12,DATEDIF(MAX(Tenancy!$E$11,G$3),EDATE(G$3,12),"m")))-MAX(0,Inputs!$B$7+Inputs!$B$8-IF(Tenancy!$E$11<G$3,DATEDIF(Tenancy!$E$11,G$3,"m"),0)))/12,0)) -> 1330000 | H14: =Tenancy!$C$11*(Tenancy!$D$11*MAX(0,MIN(1,YEARFRAC(H$3,MIN(Tenancy!$E$11,EDATE(H$3,12)),1)*(Tenancy!$E$11>H$3)))+Tenancy!$F$11*(1+Inputs!$B$6)^(H$2-1)*IF(Tenancy!$E$11<EDATE(H$3,12),Tenancy!$G$11*MAX(0,MAX(0,MIN(12,DATEDIF(MAX(Tenancy!$E$11,H$3),EDATE(H$3,12),"m")))-MAX(0,Inputs!$B$9-IF(Tenancy!$E$11<H$3,DATEDIF(Tenancy!$E$11,H$3,"m"),0)))/12+(1-Tenancy!$G$11)*MAX(0,MAX(0,MIN(12,DATEDIF(MAX(Tenancy!$E$11,H$3),EDATE(H$3,12),"m")))-MAX(0,Inputs!$B$7+Inputs!$B$8-IF(Tenancy!$E$11<H$3,DATEDIF(Tenancy!$E$11,H$3,"m"),0)))/12,0)) -> 1330000 | I14: =Tenancy!$C$11*(Tenancy!$D$11*MAX(0,MIN(1,YEARFRAC(I$3,MIN(Tenancy!$E$11,EDATE(I$3,12)),1)*(Tenancy!$E$11>I$3)))+Tenancy!$F$11*(1+Inputs!$B$6)^(I$2-1)*IF(Tenancy!$E$11<EDATE(I$3,12),Tenancy!$G$11*MAX(0,MAX(0,MIN(12,DATEDIF(MAX(Tenancy!$E$11,I$3),EDATE(I$3,12),"m")))-MAX(0,Inputs!$B$9-IF(Tenancy!$E$11<I$3,DATEDIF(Tenancy!$E$11,I$3,"m"),0)))/12+(1-Tenancy!$G$11)*MAX(0,MAX(0,MIN(12,DATEDIF(MAX(Tenancy!$E$11,I$3),EDATE(I$3,12),"m")))-MAX(0,Inputs!$B$7+Inputs!$B$8-IF(Tenancy!$E$11<I$3,DATEDIF(Tenancy!$E$11,I$3,"m"),0)))/12,0)) -> 1330000 | J14: =Tenancy!$C$11*(Tenancy!$D$11*MAX(0,MIN(1,YEARFRAC(J$3,MIN(Tenancy!$E$11,EDATE(J$3,12)),1)*(Tenancy!$E$11>J$3)))+Tenancy!$F$11*(1+Inputs!$B$6)^(J$2-1)*IF(Tenancy!$E$11<EDATE(J$3,12),Tenancy!$G$11*MAX(0,MAX(0,MIN(12,DATEDIF(MAX(Tenancy!$E$11,J$3),EDATE(J$3,12),"m")))-MAX(0,Inputs!$B$9-IF(Tenancy!$E$11<J$3,DATEDIF(Tenancy!$E$11,J$3,"m"),0)))/12+(1-Tenancy!$G$11)*MAX(0,MAX(0,MIN(12,DATEDIF(MAX(Tenancy!$E$11,J$3),EDATE(J$3,12),"m")))-MAX(0,Inputs!$B$7+Inputs!$B$8-IF(Tenancy!$E$11<J$3,DATEDIF(Tenancy!$E$11,J$3,"m"),0)))/12,0)) -> 1330000 | ... M14: =Tenancy!$C$11*(Tenancy!$D$11*MAX(0,MIN(1,YEARFRAC(M$3,MIN(Tenancy!$E$11,EDATE(M$3,12)),1)*(Tenancy!$E$11>M$3)))+Tenancy!$F$11*(1+Inputs!$B$6)^(M$2-1)*IF(Tenancy!$E$11<EDATE(M$3,12),Tenancy!$G$11*MAX(0,MAX(0,MIN(12,DATEDIF(MAX(Tenancy!$E$11,M$3),EDATE(M$3,12),"m")))-MAX(0,Inputs!$B$9-IF(Tenancy!$E$11<M$3,DATEDIF(Tenancy!$E$11,M$3,"m"),0)))/12+(1-Tenancy!$G$11)*MAX(0,MAX(0,MIN(12,DATEDIF(MAX(Tenancy!$E$11,M$3),EDATE(M$3,12),"m")))-MAX(0,Inputs!$B$7+Inputs!$B$8-IF(Tenancy!$E$11<M$3,DATEDIF(Tenancy!$E$11,M$3,"m"),0)))/12,0)) -> 1225809
A15: =Tenancy!B12&" · "&Tenancy!A12 -> Nimbus Capital · 10 | C15: =Tenancy!$C$12*(Tenancy!$D$12*MAX(0,MIN(1,YEARFRAC(C$3,MIN(Tenancy!$E$12,EDATE(C$3,12)),1)*(Tenancy!$E$12>C$3)))+Tenancy!$F$12*(1+Inputs!$B$6)^(C$2-1)*IF(Tenancy!$E$12<EDATE(C$3,12),Tenancy!$G$12*MAX(0,MAX(0,MIN(12,DATEDIF(MAX(Tenancy!$E$12,C$3),EDATE(C$3,12),"m")))-MAX(0,Inputs!$B$9-IF(Tenancy!$E$12<C$3,DATEDIF(Tenancy!$E$12,C$3,"m"),0)))/12+(1-Tenancy!$G$12)*MAX(0,MAX(0,MIN(12,DATEDIF(MAX(Tenancy!$E$12,C$3),EDATE(C$3,12),"m")))-MAX(0,Inputs!$B$7+Inputs!$B$8-IF(Tenancy!$E$12<C$3,DATEDIF(Tenancy!$E$12,C$3,"m"),0)))/12,0)) -> 1326000 | D15: =Tenancy!$C$12*(Tenancy!$D$12*MAX(0,MIN(1,YEARFRAC(D$3,MIN(Tenancy!$E$12,EDATE(D$3,12)),1)*(Tenancy!$E$12>D$3)))+Tenancy!$F$12*(1+Inputs!$B$6)^(D$2-1)*IF(Tenancy!$E$12<EDATE(D$3,12),Tenancy!$G$12*MAX(0,MAX(0,MIN(12,DATEDIF(MAX(Tenancy!$E$12,D$3),EDATE(D$3,12),"m")))-MAX(0,Inputs!$B$9-IF(Tenancy!$E$12<D$3,DATEDIF(Tenancy!$E$12,D$3,"m"),0)))/12+(1-Tenancy!$G$12)*MAX(0,MAX(0,MIN(12,DATEDIF(MAX(Tenancy!$E$12,D$3),EDATE(D$3,12),"m")))-MAX(0,Inputs!$B$7+Inputs!$B$8-IF(Tenancy!$E$12<D$3,DATEDIF(Tenancy!$E$12,D$3,"m"),0)))/12,0)) -> 1326000 | E15: =Tenancy!$C$12*(Tenancy!$D$12*MAX(0,MIN(1,YEARFRAC(E$3,MIN(Tenancy!$E$12,EDATE(E$3,12)),1)*(Tenancy!$E$12>E$3)))+Tenancy!$F$12*(1+Inputs!$B$6)^(E$2-1)*IF(Tenancy!$E$12<EDATE(E$3,12),Tenancy!$G$12*MAX(0,MAX(0,MIN(12,DATEDIF(MAX(Tenancy!$E$12,E$3),EDATE(E$3,12),"m")))-MAX(0,Inputs!$B$9-IF(Tenancy!$E$12<E$3,DATEDIF(Tenancy!$E$12,E$3,"m"),0)))/12+(1-Tenancy!$G$12)*MAX(0,MAX(0,MIN(12,DATEDIF(MAX(Tenancy!$E$12,E$3),EDATE(E$3,12),"m")))-MAX(0,Inputs!$B$7+Inputs!$B$8-IF(Tenancy!$E$12<E$3,DATEDIF(Tenancy!$E$12,E$3,"m"),0)))/12,0)) -> 1326000 | F15: =Tenancy!$C$12*(Tenancy!$D$12*MAX(0,MIN(1,YEARFRAC(F$3,MIN(Tenancy!$E$12,EDATE(F$3,12)),1)*(Tenancy!$E$12>F$3)))+Tenancy!$F$12*(1+Inputs!$B$6)^(F$2-1)*IF(Tenancy!$E$12<EDATE(F$3,12),Tenancy!$G$12*MAX(0,MAX(0,MIN(12,DATEDIF(MAX(Tenancy!$E$12,F$3),EDATE(F$3,12),"m")))-MAX(0,Inputs!$B$9-IF(Tenancy!$E$12<F$3,DATEDIF(Tenancy!$E$12,F$3,"m"),0)))/12+(1-Tenancy!$G$12)*MAX(0,MAX(0,MIN(12,DATEDIF(MAX(Tenancy!$E$12,F$3),EDATE(F$3,12),"m")))-MAX(0,Inputs!$B$7+Inputs!$B$8-IF(Tenancy!$E$12<F$3,DATEDIF(Tenancy!$E$12,F$3,"m"),0)))/12,0)) -> 1326000 | G15: =Tenancy!$C$12*(Tenancy!$D$12*MAX(0,MIN(1,YEARFRAC(G$3,MIN(Tenancy!$E$12,EDATE(G$3,12)),1)*(Tenancy!$E$12>G$3)))+Tenancy!$F$12*(1+Inputs!$B$6)^(G$2-1)*IF(Tenancy!$E$12<EDATE(G$3,12),Tenancy!$G$12*MAX(0,MAX(0,MIN(12,DATEDIF(MAX(Tenancy!$E$12,G$3),EDATE(G$3,12),"m")))-MAX(0,Inputs!$B$9-IF(Tenancy!$E$12<G$3,DATEDIF(Tenancy!$E$12,G$3,"m"),0)))/12+(1-Tenancy!$G$12)*MAX(0,MAX(0,MIN(12,DATEDIF(MAX(Tenancy!$E$12,G$3),EDATE(G$3,12),"m")))-MAX(0,Inputs!$B$7+Inputs!$B$8-IF(Tenancy!$E$12<G$3,DATEDIF(Tenancy!$E$12,G$3,"m"),0)))/12,0)) -> 1296937 | H15: =Tenancy!$C$12*(Tenancy!$D$12*MAX(0,MIN(1,YEARFRAC(H$3,MIN(Tenancy!$E$12,EDATE(H$3,12)),1)*(Tenancy!$E$12>H$3)))+Tenancy!$F$12*(1+Inputs!$B$6)^(H$2-1)*IF(Tenancy!$E$12<EDATE(H$3,12),Tenancy!$G$12*MAX(0,MAX(0,MIN(12,DATEDIF(MAX(Tenancy!$E$12,H$3),EDATE(H$3,12),"m")))-MAX(0,Inputs!$B$9-IF(Tenancy!$E$12<H$3,DATEDIF(Tenancy!$E$12,H$3,"m"),0)))/12+(1-Tenancy!$G$12)*MAX(0,MAX(0,MIN(12,DATEDIF(MAX(Tenancy!$E$12,H$3),EDATE(H$3,12),"m")))-MAX(0,Inputs!$B$7+Inputs!$B$8-IF(Tenancy!$E$12<H$3,DATEDIF(Tenancy!$E$12,H$3,"m"),0)))/12,0)) -> 328900.37 | I15: =Tenancy!$C$12*(Tenancy!$D$12*MAX(0,MIN(1,YEARFRAC(I$3,MIN(Tenancy!$E$12,EDATE(I$3,12)),1)*(Tenancy!$E$12>I$3)))+Tenancy!$F$12*(1+Inputs!$B$6)^(I$2-1)*IF(Tenancy!$E$12<EDATE(I$3,12),Tenancy!$G$12*MAX(0,MAX(0,MIN(12,DATEDIF(MAX(Tenancy!$E$12,I$3),EDATE(I$3,12),"m")))-MAX(0,Inputs!$B$9-IF(Tenancy!$E$12<I$3,DATEDIF(Tenancy!$E$12,I$3,"m"),0)))/12+(1-Tenancy!$G$12)*MAX(0,MAX(0,MIN(12,DATEDIF(MAX(Tenancy!$E$12,I$3),EDATE(I$3,12),"m")))-MAX(0,Inputs!$B$7+Inputs!$B$8-IF(Tenancy!$E$12<I$3,DATEDIF(Tenancy!$E$12,I$3,"m"),0)))/12,0)) -> 674245.75 | J15: =Tenancy!$C$12*(Tenancy!$D$12*MAX(0,MIN(1,YEARFRAC(J$3,MIN(Tenancy!$E$12,EDATE(J$3,12)),1)*(Tenancy!$E$12>J$3)))+Tenancy!$F$12*(1+Inputs!$B$6)^(J$2-1)*IF(Tenancy!$E$12<EDATE(J$3,12),Tenancy!$G$12*MAX(0,MAX(0,MIN(12,DATEDIF(MAX(Tenancy!$E$12,J$3),EDATE(J$3,12),"m")))-MAX(0,Inputs!$B$9-IF(Tenancy!$E$12<J$3,DATEDIF(Tenancy!$E$12,J$3,"m"),0)))/12+(1-Tenancy!$G$12)*MAX(0,MAX(0,MIN(12,DATEDIF(MAX(Tenancy!$E$12,J$3),EDATE(J$3,12),"m")))-MAX(0,Inputs!$B$7+Inputs!$B$8-IF(Tenancy!$E$12<J$3,DATEDIF(Tenancy!$E$12,J$3,"m"),0)))/12,0)) -> 1113441.9 | ... M15: =Tenancy!$C$12*(Tenancy!$D$12*MAX(0,MIN(1,YEARFRAC(M$3,MIN(Tenancy!$E$12,EDATE(M$3,12)),1)*(Tenancy!$E$12>M$3)))+Tenancy!$F$12*(1+Inputs!$B$6)^(M$2-1)*IF(Tenancy!$E$12<EDATE(M$3,12),Tenancy!$G$12*MAX(0,MAX(0,MIN(12,DATEDIF(MAX(Tenancy!$E$12,M$3),EDATE(M$3,12),"m")))-MAX(0,Inputs!$B$9-IF(Tenancy!$E$12<M$3,DATEDIF(Tenancy!$E$12,M$3,"m"),0)))/12+(1-Tenancy!$G$12)*MAX(0,MAX(0,MIN(12,DATEDIF(MAX(Tenancy!$E$12,M$3),EDATE(M$3,12),"m")))-MAX(0,Inputs!$B$7+Inputs!$B$8-IF(Tenancy!$E$12<M$3,DATEDIF(Tenancy!$E$12,M$3,"m"),0)))/12,0)) -> 1653869.2
