Workbook

Sheet Inputs
A1: WADI AL NOOR MASTERPLAN – SIX PHASES (SAR)
A3: Scenario (1 Base, 2 Downside, 3 Upside) | B3: 1
A4: Land (SAR) | B4: 900000000
A5: Infrastructure (SAR) | B5: 420000000
A6: Infrastructure build (quarters) | B6: 8
A7: VAT on commercial sales | B7: 0.15
A8: Zakat | B8: 0.025
A9: Murabaha (% of phase cost) | B9: 0.6
A10: Murabaha profit rate (capitalised during build) | B10: 0.07
A11: Escrow: share of collections released by progress | B11: 0.7
A12: Discount rate | B12: 0.11

Sheet Scenarios
A1: Assumption | B1: Base | C1: Downside | D1: Upside | E1: Live
A2: Plot price (SAR/sqm) | B2: 3200 | C2: 2700 | D2: 3500 | E2: =CHOOSE(Inputs!$B$3,B2,C2,D2) -> 3200
A3: Villa price (SAR/sqm) | B3: 8800 | C3: 7600 | D3: 9500 | E3: =CHOOSE(Inputs!$B$3,B3,C3,D3) -> 8800
A4: BTR rent (SAR/sqm/yr) | B4: 950 | C4: 820 | D4: 1020 | E4: =CHOOSE(Inputs!$B$3,B4,C4,D4) -> 950
A5: Hotel ADR (SAR) | B5: 900 | C5: 760 | D5: 980 | E5: =CHOOSE(Inputs!$B$3,B5,C5,D5) -> 900
A6: Retail rent (SAR/sqm/yr) | B6: 1700 | C6: 1450 | D6: 1850 | E6: =CHOOSE(Inputs!$B$3,B6,C6,D6) -> 1700
A7: Office rent (SAR/sqm/yr) | B7: 1150 | C7: 980 | D7: 1250 | E7: =CHOOSE(Inputs!$B$3,B7,C7,D7) -> 1150
A8: Build cost (SAR/sqm) | B8: 4300 | C8: 4800 | D8: 4150 | E8: =CHOOSE(Inputs!$B$3,B8,C8,D8) -> 4300
A9: Exit yield (income phases) | B9: 0.075 | C9: 0.0875 | D9: 0.07 | E9: =CHOOSE(Inputs!$B$3,B9,C9,D9) -> 0.075

Sheet Phases
A1: Phase | B1: Type | C1: GFA / land (sqm) | D1: Start quarter | E1: Build (quarters) | F1: Sales / lease-up (quarters) | G1: Commercial (VAT)
A2: Plots | B2: sale | C2: 220000 | D2: 1 | E2: 6 | F2: 8 | G2: 0
A3: Villas | B3: sale | C3: 130000 | D3: 3 | E3: 8 | F3: 8 | G3: 0
A4: BTR | B4: income | C4: 90000 | D4: 6 | E4: 9 | F4: 0 | G4: 0
A5: Hotel | B5: hotel | C5: 40000 | D5: 9 | E5: 10 | F5: 0 | G5: 1
A6: Retail | B6: income | C6: 35000 | D6: 8 | E6: 8 | F6: 0 | G6: 1
A7: Offices | B7: income | C7: 60000 | D7: 12 | E7: 10 | F7: 0 | G7: 1

Sheet Cash Flow
A3: Quarter | B3: 0 | C3: 1 | D3: 2 | E3: 3 | F3: 4 | G3: 5 | H3: 6 | I3: 7 | J3: 8 | K3: 9 | L3: 10 | M3: 11 | N3: 12 | O3: 13 | P3: 14 | Q3: 15 | R3: 16 | S3: 17 | T3: 18 | U3: 19 | V3: 20 | W3: 21 | X3: 22 | Y3: 23 | Z3: 24 | AA3: 25 | AB3: 26 | AC3: 27 | AD3: 28 | AE3: 29 | AF3: 30 | AG3: 31 | AH3: 32 | AI3: 33 | AJ3: 34 | AK3: 35 | AL3: 36 | AM3: 37 | AN3: 38 | AO3: 39 | AP3: 40 | AQ3: 41 | AR3: 42 | AS3: 43 | AT3: 44 | AU3: 45 | AV3: 46 | AW3: 47 | AX3: 48
A4: Plots · build cost | B4: =IF(AND(B$3>=Phases!$D$2,B$3<Phases!$D$2+Phases!$E$2),Phases!$C$2*Scenarios!$E$8*IF("sale"="hotel",1.6,IF("Plots"="Plots",0.25,1))/Phases!$E$2,0) -> 0 | C4: =IF(AND(C$3>=Phases!$D$2,C$3<Phases!$D$2+Phases!$E$2),Phases!$C$2*Scenarios!$E$8*IF("sale"="hotel",1.6,IF("Plots"="Plots",0.25,1))/Phases!$E$2,0) -> 39416667 | D4: =IF(AND(D$3>=Phases!$D$2,D$3<Phases!$D$2+Phases!$E$2),Phases!$C$2*Scenarios!$E$8*IF("sale"="hotel",1.6,IF("Plots"="Plots",0.25,1))/Phases!$E$2,0) -> 39416667 | E4: =IF(AND(E$3>=Phases!$D$2,E$3<Phases!$D$2+Phases!$E$2),Phases!$C$2*Scenarios!$E$8*IF("sale"="hotel",1.6,IF("Plots"="Plots",0.25,1))/Phases!$E$2,0) -> 39416667 | F4: =IF(AND(F$3>=Phases!$D$2,F$3<Phases!$D$2+Phases!$E$2),Phases!$C$2*Scenarios!$E$8*IF("sale"="hotel",1.6,IF("Plots"="Plots",0.25,1))/Phases!$E$2,0) -> 39416667 | G4: =IF(AND(G$3>=Phases!$D$2,G$3<Phases!$D$2+Phases!$E$2),Phases!$C$2*Scenarios!$E$8*IF("sale"="hotel",1.6,IF("Plots"="Plots",0.25,1))/Phases!$E$2,0) -> 39416667 | H4: =IF(AND(H$3>=Phases!$D$2,H$3<Phases!$D$2+Phases!$E$2),Phases!$C$2*Scenarios!$E$8*IF("sale"="hotel",1.6,IF("Plots"="Plots",0.25,1))/Phases!$E$2,0) -> 39416667 | I4: =IF(AND(I$3>=Phases!$D$2,I$3<Phases!$D$2+Phases!$E$2),Phases!$C$2*Scenarios!$E$8*IF("sale"="hotel",1.6,IF("Plots"="Plots",0.25,1))/Phases!$E$2,0) -> 0 | ... AX4: =IF(AND(AX$3>=Phases!$D$2,AX$3<Phases!$D$2+Phases!$E$2),Phases!$C$2*Scenarios!$E$8*IF("sale"="hotel",1.6,IF("Plots"="Plots",0.25,1))/Phases!$E$2,0) -> 0
A5: Plots · revenue | B5: =IF(AND(B$3>=Phases!$D$2,B$3<Phases!$D$2+Phases!$F$2),Phases!$C$2*Scenarios!$E$2/Phases!$F$2,0)*(1+Inputs!$B$7*Phases!$G$2) -> 0 | C5: =IF(AND(C$3>=Phases!$D$2,C$3<Phases!$D$2+Phases!$F$2),Phases!$C$2*Scenarios!$E$2/Phases!$F$2,0)*(1+Inputs!$B$7*Phases!$G$2) -> 88000000 | D5: =IF(AND(D$3>=Phases!$D$2,D$3<Phases!$D$2+Phases!$F$2),Phases!$C$2*Scenarios!$E$2/Phases!$F$2,0)*(1+Inputs!$B$7*Phases!$G$2) -> 88000000 | E5: =IF(AND(E$3>=Phases!$D$2,E$3<Phases!$D$2+Phases!$F$2),Phases!$C$2*Scenarios!$E$2/Phases!$F$2,0)*(1+Inputs!$B$7*Phases!$G$2) -> 88000000 | F5: =IF(AND(F$3>=Phases!$D$2,F$3<Phases!$D$2+Phases!$F$2),Phases!$C$2*Scenarios!$E$2/Phases!$F$2,0)*(1+Inputs!$B$7*Phases!$G$2) -> 88000000 | G5: =IF(AND(G$3>=Phases!$D$2,G$3<Phases!$D$2+Phases!$F$2),Phases!$C$2*Scenarios!$E$2/Phases!$F$2,0)*(1+Inputs!$B$7*Phases!$G$2) -> 88000000 | H5: =IF(AND(H$3>=Phases!$D$2,H$3<Phases!$D$2+Phases!$F$2),Phases!$C$2*Scenarios!$E$2/Phases!$F$2,0)*(1+Inputs!$B$7*Phases!$G$2) -> 88000000 | I5: =IF(AND(I$3>=Phases!$D$2,I$3<Phases!$D$2+Phases!$F$2),Phases!$C$2*Scenarios!$E$2/Phases!$F$2,0)*(1+Inputs!$B$7*Phases!$G$2) -> 88000000 | ... AX5: =IF(AND(AX$3>=Phases!$D$2,AX$3<Phases!$D$2+Phases!$F$2),Phases!$C$2*Scenarios!$E$2/Phases!$F$2,0)*(1+Inputs!$B$7*Phases!$G$2) -> 0
A6: Plots · collections released | B6: =B5*(1-Inputs!$B$11) -> 0 | C6: =IF(C$3<Phases!$D$2+Phases!$E$2-1,C5*(1-Inputs!$B$11)+Inputs!$B$11*SUM($B$5:C5)*MIN(1,MAX(0,(C$3-Phases!$D$2+1)/Phases!$E$2))-Inputs!$B$11*SUM($B$5:B5)*MIN(1,MAX(0,(C$3-Phases!$D$2)/Phases!$E$2)),SUM($B$5:C5)-SUM($B$6:B6)+IF(C$3>=Phases!$D$2+Phases!$E$2-1,0,0)) -> 36666667 | D6: =IF(D$3<Phases!$D$2+Phases!$E$2-1,D5*(1-Inputs!$B$11)+Inputs!$B$11*SUM($B$5:D5)*MIN(1,MAX(0,(D$3-Phases!$D$2+1)/Phases!$E$2))-Inputs!$B$11*SUM($B$5:C5)*MIN(1,MAX(0,(D$3-Phases!$D$2)/Phases!$E$2)),SUM($B$5:D5)-SUM($B$6:C6)+IF(D$3>=Phases!$D$2+Phases!$E$2-1,0,0)) -> 57200000 | E6: =IF(E$3<Phases!$D$2+Phases!$E$2-1,E5*(1-Inputs!$B$11)+Inputs!$B$11*SUM($B$5:E5)*MIN(1,MAX(0,(E$3-Phases!$D$2+1)/Phases!$E$2))-Inputs!$B$11*SUM($B$5:D5)*MIN(1,MAX(0,(E$3-Phases!$D$2)/Phases!$E$2)),SUM($B$5:E5)-SUM($B$6:D6)+IF(E$3>=Phases!$D$2+Phases!$E$2-1,0,0)) -> 77733333 | F6: =IF(F$3<Phases!$D$2+Phases!$E$2-1,F5*(1-Inputs!$B$11)+Inputs!$B$11*SUM($B$5:F5)*MIN(1,MAX(0,(F$3-Phases!$D$2+1)/Phases!$E$2))-Inputs!$B$11*SUM($B$5:E5)*MIN(1,MAX(0,(F$3-Phases!$D$2)/Phases!$E$2)),SUM($B$5:F5)-SUM($B$6:E6)+IF(F$3>=Phases!$D$2+Phases!$E$2-1,0,0)) -> 98266667 | G6: =IF(G$3<Phases!$D$2+Phases!$E$2-1,G5*(1-Inputs!$B$11)+Inputs!$B$11*SUM($B$5:G5)*MIN(1,MAX(0,(G$3-Phases!$D$2+1)/Phases!$E$2))-Inputs!$B$11*SUM($B$5:F5)*MIN(1,MAX(0,(G$3-Phases!$D$2)/Phases!$E$2)),SUM($B$5:G5)-SUM($B$6:F6)+IF(G$3>=Phases!$D$2+Phases!$E$2-1,0,0)) -> 118800000 | H6: =IF(H$3<Phases!$D$2+Phases!$E$2-1,H5*(1-Inputs!$B$11)+Inputs!$B$11*SUM($B$5:H5)*MIN(1,MAX(0,(H$3-Phases!$D$2+1)/Phases!$E$2))-Inputs!$B$11*SUM($B$5:G5)*MIN(1,MAX(0,(H$3-Phases!$D$2)/Phases!$E$2)),SUM($B$5:H5)-SUM($B$6:G6)+IF(H$3>=Phases!$D$2+Phases!$E$2-1,0,0)) -> 1.3933333e+08 | I6: =IF(I$3<Phases!$D$2+Phases!$E$2-1,I5*(1-Inputs!$B$11)+Inputs!$B$11*SUM($B$5:I5)*MIN(1,MAX(0,(I$3-Phases!$D$2+1)/Phases!$E$2))-Inputs!$B$11*SUM($B$5:H5)*MIN(1,MAX(0,(I$3-Phases!$D$2)/Phases!$E$2)),SUM($B$5:I5)-SUM($B$6:H6)+IF(I$3>=Phases!$D$2+Phases!$E$2-1,0,0)) -> 88000000 | J6: =IF(J$3<Phases!$D$2+Phases!$E$2-1,J5*(1-Inputs!$B$11)+Inputs!$B$11*SUM($B$5:J5)*MIN(1,MAX(0,(J$3-Phases!$D$2+1)/Phases!$E$2))-Inputs!$B$11*SUM($B$5:I5)*MIN(1,MAX(0,(J$3-Phases!$D$2)/Phases!$E$2)),SUM($B$5:J5)-SUM($B$6:I6)+IF(J$3>=Phases!$D$2+Phases!$E$2-1,0,0)) -> 88000000 | ... AX6: =IF(AX$3<Phases!$D$2+Phases!$E$2-1,AX5*(1-Inputs!$B$11)+Inputs!$B$11*SUM($B$5:AX5)*MIN(1,MAX(0,(AX$3-Phases!$D$2+1)/Phases!$E$2))-Inputs!$B$11*SUM($B$5:AW5)*MIN(1,MAX(0,(AX$3-Phases!$D$2)/Phases!$E$2)),SUM($B$5:AX5)-SUM($B$6:AW6)+IF(AX$3>=Phases!$D$2+Phases!$E$2-1,0,0)) -> 0
A7: Plots · NOI | B7: =0 -> 0 | C7: =0 -> 0 | D7: =0 -> 0 | E7: =0 -> 0 | F7: =0 -> 0 | G7: =0 -> 0 | H7: =0 -> 0 | I7: =0 -> 0 | ... AX7: =0 -> 0
A8: Villas · build cost | B8: =IF(AND(B$3>=Phases!$D$3,B$3<Phases!$D$3+Phases!$E$3),Phases!$C$3*Scenarios!$E$8*IF("sale"="hotel",1.6,IF("Villas"="Plots",0.25,1))/Phases!$E$3,0) -> 0 | C8: =IF(AND(C$3>=Phases!$D$3,C$3<Phases!$D$3+Phases!$E$3),Phases!$C$3*Scenarios!$E$8*IF("sale"="hotel",1.6,IF("Villas"="Plots",0.25,1))/Phases!$E$3,0) -> 0 | D8: =IF(AND(D$3>=Phases!$D$3,D$3<Phases!$D$3+Phases!$E$3),Phases!$C$3*Scenarios!$E$8*IF("sale"="hotel",1.6,IF("Villas"="Plots",0.25,1))/Phases!$E$3,0) -> 0 | E8: =IF(AND(E$3>=Phases!$D$3,E$3<Phases!$D$3+Phases!$E$3),Phases!$C$3*Scenarios!$E$8*IF("sale"="hotel",1.6,IF("Villas"="Plots",0.25,1))/Phases!$E$3,0) -> 69875000 | F8: =IF(AND(F$3>=Phases!$D$3,F$3<Phases!$D$3+Phases!$E$3),Phases!$C$3*Scenarios!$E$8*IF("sale"="hotel",1.6,IF("Villas"="Plots",0.25,1))/Phases!$E$3,0) -> 69875000 | G8: =IF(AND(G$3>=Phases!$D$3,G$3<Phases!$D$3+Phases!$E$3),Phases!$C$3*Scenarios!$E$8*IF("sale"="hotel",1.6,IF("Villas"="Plots",0.25,1))/Phases!$E$3,0) -> 69875000 | H8: =IF(AND(H$3>=Phases!$D$3,H$3<Phases!$D$3+Phases!$E$3),Phases!$C$3*Scenarios!$E$8*IF("sale"="hotel",1.6,IF("Villas"="Plots",0.25,1))/Phases!$E$3,0) -> 69875000 | I8: =IF(AND(I$3>=Phases!$D$3,I$3<Phases!$D$3+Phases!$E$3),Phases!$C$3*Scenarios!$E$8*IF("sale"="hotel",1.6,IF("Villas"="Plots",0.25,1))/Phases!$E$3,0) -> 69875000 | ... AX8: =IF(AND(AX$3>=Phases!$D$3,AX$3<Phases!$D$3+Phases!$E$3),Phases!$C$3*Scenarios!$E$8*IF("sale"="hotel",1.6,IF("Villas"="Plots",0.25,1))/Phases!$E$3,0) -> 0
A9: Villas · revenue | B9: =IF(AND(B$3>=Phases!$D$3,B$3<Phases!$D$3+Phases!$F$3),Phases!$C$3*Scenarios!$E$3/Phases!$F$3,0)*(1+Inputs!$B$7*Phases!$G$3) -> 0 | C9: =IF(AND(C$3>=Phases!$D$3,C$3<Phases!$D$3+Phases!$F$3),Phases!$C$3*Scenarios!$E$3/Phases!$F$3,0)*(1+Inputs!$B$7*Phases!$G$3) -> 0 | D9: =IF(AND(D$3>=Phases!$D$3,D$3<Phases!$D$3+Phases!$F$3),Phases!$C$3*Scenarios!$E$3/Phases!$F$3,0)*(1+Inputs!$B$7*Phases!$G$3) -> 0 | E9: =IF(AND(E$3>=Phases!$D$3,E$3<Phases!$D$3+Phases!$F$3),Phases!$C$3*Scenarios!$E$3/Phases!$F$3,0)*(1+Inputs!$B$7*Phases!$G$3) -> 143000000 | F9: =IF(AND(F$3>=Phases!$D$3,F$3<Phases!$D$3+Phases!$F$3),Phases!$C$3*Scenarios!$E$3/Phases!$F$3,0)*(1+Inputs!$B$7*Phases!$G$3) -> 143000000 | G9: =IF(AND(G$3>=Phases!$D$3,G$3<Phases!$D$3+Phases!$F$3),Phases!$C$3*Scenarios!$E$3/Phases!$F$3,0)*(1+Inputs!$B$7*Phases!$G$3) -> 143000000 | H9: =IF(AND(H$3>=Phases!$D$3,H$3<Phases!$D$3+Phases!$F$3),Phases!$C$3*Scenarios!$E$3/Phases!$F$3,0)*(1+Inputs!$B$7*Phases!$G$3) -> 143000000 | I9: =IF(AND(I$3>=Phases!$D$3,I$3<Phases!$D$3+Phases!$F$3),Phases!$C$3*Scenarios!$E$3/Phases!$F$3,0)*(1+Inputs!$B$7*Phases!$G$3) -> 143000000 | ... AX9: =IF(AND(AX$3>=Phases!$D$3,AX$3<Phases!$D$3+Phases!$F$3),Phases!$C$3*Scenarios!$E$3/Phases!$F$3,0)*(1+Inputs!$B$7*Phases!$G$3) -> 0
A10: Villas · collections released | B10: =B9*(1-Inputs!$B$11) -> 0 | C10: =IF(C$3<Phases!$D$3+Phases!$E$3-1,C9*(1-Inputs!$B$11)+Inputs!$B$11*SUM($B$9:C9)*MIN(1,MAX(0,(C$3-Phases!$D$3+1)/Phases!$E$3))-Inputs!$B$11*SUM($B$9:B9)*MIN(1,MAX(0,(C$3-Phases!$D$3)/Phases!$E$3)),SUM($B$9:C9)-SUM($B$10:B10)+IF(C$3>=Phases!$D$3+Phases!$E$3-1,0,0)) -> 0 | D10: =IF(D$3<Phases!$D$3+Phases!$E$3-1,D9*(1-Inputs!$B$11)+Inputs!$B$11*SUM($B$9:D9)*MIN(1,MAX(0,(D$3-Phases!$D$3+1)/Phases!$E$3))-Inputs!$B$11*SUM($B$9:C9)*MIN(1,MAX(0,(D$3-Phases!$D$3)/Phases!$E$3)),SUM($B$9:D9)-SUM($B$10:C10)+IF(D$3>=Phases!$D$3+Phases!$E$3-1,0,0)) -> 0 | E10: =IF(E$3<Phases!$D$3+Phases!$E$3-1,E9*(1-Inputs!$B$11)+Inputs!$B$11*SUM($B$9:E9)*MIN(1,MAX(0,(E$3-Phases!$D$3+1)/Phases!$E$3))-Inputs!$B$11*SUM($B$9:D9)*MIN(1,MAX(0,(E$3-Phases!$D$3)/Phases!$E$3)),SUM($B$9:E9)-SUM($B$10:D10)+IF(E$3>=Phases!$D$3+Phases!$E$3-1,0,0)) -> 55412500 | F10: =IF(F$3<Phases!$D$3+Phases!$E$3-1,F9*(1-Inputs!$B$11)+Inputs!$B$11*SUM($B$9:F9)*MIN(1,MAX(0,(F$3-Phases!$D$3+1)/Phases!$E$3))-Inputs!$B$11*SUM($B$9:E9)*MIN(1,MAX(0,(F$3-Phases!$D$3)/Phases!$E$3)),SUM($B$9:F9)-SUM($B$10:E10)+IF(F$3>=Phases!$D$3+Phases!$E$3-1,0,0)) -> 80437500 | G10: =IF(G$3<Phases!$D$3+Phases!$E$3-1,G9*(1-Inputs!$B$11)+Inputs!$B$11*SUM($B$9:G9)*MIN(1,MAX(0,(G$3-Phases!$D$3+1)/Phases!$E$3))-Inputs!$B$11*SUM($B$9:F9)*MIN(1,MAX(0,(G$3-Phases!$D$3)/Phases!$E$3)),SUM($B$9:G9)-SUM($B$10:F10)+IF(G$3>=Phases!$D$3+Phases!$E$3-1,0,0)) -> 105462500 | H10: =IF(H$3<Phases!$D$3+Phases!$E$3-1,H9*(1-Inputs!$B$11)+Inputs!$B$11*SUM($B$9:H9)*MIN(1,MAX(0,(H$3-Phases!$D$3+1)/Phases!$E$3))-Inputs!$B$11*SUM($B$9:G9)*MIN(1,MAX(0,(H$3-Phases!$D$3)/Phases!$E$3)),SUM($B$9:H9)-SUM($B$10:G10)+IF(H$3>=Phases!$D$3+Phases!$E$3-1,0,0)) -> 130487500 | I10: =IF(I$3<Phases!$D$3+Phases!$E$3-1,I9*(1-Inputs!$B$11)+Inputs!$B$11*SUM($B$9:I9)*MIN(1,MAX(0,(I$3-Phases!$D$3+1)/Phases!$E$3))-Inputs!$B$11*SUM($B$9:H9)*MIN(1,MAX(0,(I$3-Phases!$D$3)/Phases!$E$3)),SUM($B$9:I9)-SUM($B$10:H10)+IF(I$3>=Phases!$D$3+Phases!$E$3-1,0,0)) -> 155512500 | J10: =IF(J$3<Phases!$D$3+Phases!$E$3-1,J9*(1-Inputs!$B$11)+Inputs!$B$11*SUM($B$9:J9)*MIN(1,MAX(0,(J$3-Phases!$D$3+1)/Phases!$E$3))-Inputs!$B$11*SUM($B$9:I9)*MIN(1,MAX(0,(J$3-Phases!$D$3)/Phases!$E$3)),SUM($B$9:J9)-SUM($B$10:I10)+IF(J$3>=Phases!$D$3+Phases!$E$3-1,0,0)) -> 180537500 | ... AX10: =IF(AX$3<Phases!$D$3+Phases!$E$3-1,AX9*(1-Inputs!$B$11)+Inputs!$B$11*SUM($B$9:AX9)*MIN(1,MAX(0,(AX$3-Phases!$D$3+1)/Phases!$E$3))-Inputs!$B$11*SUM($B$9:AW9)*MIN(1,MAX(0,(AX$3-Phases!$D$3)/Phases!$E$3)),SUM($B$9:AX9)-SUM($B$10:AW10)+IF(AX$3>=Phases!$D$3+Phases!$E$3-1,0,0)) -> 0
A11: Villas · NOI | B11: =0 -> 0 | C11: =0 -> 0 | D11: =0 -> 0 | E11: =0 -> 0 | F11: =0 -> 0 | G11: =0 -> 0 | H11: =0 -> 0 | I11: =0 -> 0 | ... AX11: =0 -> 0
A12: BTR · build cost | B12: =IF(AND(B$3>=Phases!$D$4,B$3<Phases!$D$4+Phases!$E$4),Phases!$C$4*Scenarios!$E$8*IF("income"="hotel",1.6,IF("BTR"="Plots",0.25,1))/Phases!$E$4,0) -> 0 | C12: =IF(AND(C$3>=Phases!$D$4,C$3<Phases!$D$4+Phases!$E$4),Phases!$C$4*Scenarios!$E$8*IF("income"="hotel",1.6,IF("BTR"="Plots",0.25,1))/Phases!$E$4,0) -> 0 | D12: =IF(AND(D$3>=Phases!$D$4,D$3<Phases!$D$4+Phases!$E$4),Phases!$C$4*Scenarios!$E$8*IF("income"="hotel",1.6,IF("BTR"="Plots",0.25,1))/Phases!$E$4,0) -> 0 | E12: =IF(AND(E$3>=Phases!$D$4,E$3<Phases!$D$4+Phases!$E$4),Phases!$C$4*Scenarios!$E$8*IF("income"="hotel",1.6,IF("BTR"="Plots",0.25,1))/Phases!$E$4,0) -> 0 | F12: =IF(AND(F$3>=Phases!$D$4,F$3<Phases!$D$4+Phases!$E$4),Phases!$C$4*Scenarios!$E$8*IF("income"="hotel",1.6,IF("BTR"="Plots",0.25,1))/Phases!$E$4,0) -> 0 | G12: =IF(AND(G$3>=Phases!$D$4,G$3<Phases!$D$4+Phases!$E$4),Phases!$C$4*Scenarios!$E$8*IF("income"="hotel",1.6,IF("BTR"="Plots",0.25,1))/Phases!$E$4,0) -> 0 | H12: =IF(AND(H$3>=Phases!$D$4,H$3<Phases!$D$4+Phases!$E$4),Phases!$C$4*Scenarios!$E$8*IF("income"="hotel",1.6,IF("BTR"="Plots",0.25,1))/Phases!$E$4,0) -> 43000000 | I12: =IF(AND(I$3>=Phases!$D$4,I$3<Phases!$D$4+Phases!$E$4),Phases!$C$4*Scenarios!$E$8*IF("income"="hotel",1.6,IF("BTR"="Plots",0.25,1))/Phases!$E$4,0) -> 43000000 | ... AX12: =IF(AND(AX$3>=Phases!$D$4,AX$3<Phases!$D$4+Phases!$E$4),Phases!$C$4*Scenarios!$E$8*IF("income"="hotel",1.6,IF("BTR"="Plots",0.25,1))/Phases!$E$4,0) -> 0
A13: BTR · revenue | B13: =0 -> 0 | C13: =0 -> 0 | D13: =0 -> 0 | E13: =0 -> 0 | F13: =0 -> 0 | G13: =0 -> 0 | H13: =0 -> 0 | I13: =0 -> 0 | ... AX13: =0 -> 0
A14: BTR · collections released | B14: =0 -> 0 | C14: =0 -> 0 | D14: =0 -> 0 | E14: =0 -> 0 | F14: =0 -> 0 | G14: =0 -> 0 | H14: =0 -> 0 | I14: =0 -> 0 | ... AX14: =0 -> 0
A15: BTR · NOI | B15: =IF((B$3>=Phases!$D$4+Phases!$E$4),Phases!$C$4*Scenarios!$E$4*0.9/4*MIN(1,(B$3-Phases!$D$4-Phases!$E$4+1)/6)*1.025^INT((B$3-Phases!$D$4-Phases!$E$4)/4),0) -> 0 | C15: =IF((C$3>=Phases!$D$4+Phases!$E$4),Phases!$C$4*Scenarios!$E$4*0.9/4*MIN(1,(C$3-Phases!$D$4-Phases!$E$4+1)/6)*1.025^INT((C$3-Phases!$D$4-Phases!$E$4)/4),0) -> 0 | D15: =IF((D$3>=Phases!$D$4+Phases!$E$4),Phases!$C$4*Scenarios!$E$4*0.9/4*MIN(1,(D$3-Phases!$D$4-Phases!$E$4+1)/6)*1.025^INT((D$3-Phases!$D$4-Phases!$E$4)/4),0) -> 0 | E15: =IF((E$3>=Phases!$D$4+Phases!$E$4),Phases!$C$4*Scenarios!$E$4*0.9/4*MIN(1,(E$3-Phases!$D$4-Phases!$E$4+1)/6)*1.025^INT((E$3-Phases!$D$4-Phases!$E$4)/4),0) -> 0 | F15: =IF((F$3>=Phases!$D$4+Phases!$E$4),Phases!$C$4*Scenarios!$E$4*0.9/4*MIN(1,(F$3-Phases!$D$4-Phases!$E$4+1)/6)*1.025^INT((F$3-Phases!$D$4-Phases!$E$4)/4),0) -> 0 | G15: =IF((G$3>=Phases!$D$4+Phases!$E$4),Phases!$C$4*Scenarios!$E$4*0.9/4*MIN(1,(G$3-Phases!$D$4-Phases!$E$4+1)/6)*1.025^INT((G$3-Phases!$D$4-Phases!$E$4)/4),0) -> 0 | H15: =IF((H$3>=Phases!$D$4+Phases!$E$4),Phases!$C$4*Scenarios!$E$4*0.9/4*MIN(1,(H$3-Phases!$D$4-Phases!$E$4+1)/6)*1.025^INT((H$3-Phases!$D$4-Phases!$E$4)/4),0) -> 0 | I15: =IF((I$3>=Phases!$D$4+Phases!$E$4),Phases!$C$4*Scenarios!$E$4*0.9/4*MIN(1,(I$3-Phases!$D$4-Phases!$E$4+1)/6)*1.025^INT((I$3-Phases!$D$4-Phases!$E$4)/4),0) -> 0 | ... AX15: =IF((AX$3>=Phases!$D$4+Phases!$E$4),Phases!$C$4*Scenarios!$E$4*0.9/4*MIN(1,(AX$3-Phases!$D$4-Phases!$E$4+1)/6)*1.025^INT((AX$3-Phases!$D$4-Phases!$E$4)/4),0) -> 23439026
A16: Hotel · build cost | B16: =IF(AND(B$3>=Phases!$D$5,B$3<Phases!$D$5+Phases!$E$5),Phases!$C$5*Scenarios!$E$8*IF("hotel"="hotel",1.6,IF("Hotel"="Plots",0.25,1))/Phases!$E$5,0) -> 0 | C16: =IF(AND(C$3>=Phases!$D$5,C$3<Phases!$D$5+Phases!$E$5),Phases!$C$5*Scenarios!$E$8*IF("hotel"="hotel",1.6,IF("Hotel"="Plots",0.25,1))/Phases!$E$5,0) -> 0 | D16: =IF(AND(D$3>=Phases!$D$5,D$3<Phases!$D$5+Phases!$E$5),Phases!$C$5*Scenarios!$E$8*IF("hotel"="hotel",1.6,IF("Hotel"="Plots",0.25,1))/Phases!$E$5,0) -> 0 | E16: =IF(AND(E$3>=Phases!$D$5,E$3<Phases!$D$5+Phases!$E$5),Phases!$C$5*Scenarios!$E$8*IF("hotel"="hotel",1.6,IF("Hotel"="Plots",0.25,1))/Phases!$E$5,0) -> 0 | F16: =IF(AND(F$3>=Phases!$D$5,F$3<Phases!$D$5+Phases!$E$5),Phases!$C$5*Scenarios!$E$8*IF("hotel"="hotel",1.6,IF("Hotel"="Plots",0.25,1))/Phases!$E$5,0) -> 0 | G16: =IF(AND(G$3>=Phases!$D$5,G$3<Phases!$D$5+Phases!$E$5),Phases!$C$5*Scenarios!$E$8*IF("hotel"="hotel",1.6,IF("Hotel"="Plots",0.25,1))/Phases!$E$5,0) -> 0 | H16: =IF(AND(H$3>=Phases!$D$5,H$3<Phases!$D$5+Phases!$E$5),Phases!$C$5*Scenarios!$E$8*IF("hotel"="hotel",1.6,IF("Hotel"="Plots",0.25,1))/Phases!$E$5,0) -> 0 | I16: =IF(AND(I$3>=Phases!$D$5,I$3<Phases!$D$5+Phases!$E$5),Phases!$C$5*Scenarios!$E$8*IF("hotel"="hotel",1.6,IF("Hotel"="Plots",0.25,1))/Phases!$E$5,0) -> 0 | ... AX16: =IF(AND(AX$3>=Phases!$D$5,AX$3<Phases!$D$5+Phases!$E$5),Phases!$C$5*Scenarios!$E$8*IF("hotel"="hotel",1.6,IF("Hotel"="Plots",0.25,1))/Phases!$E$5,0) -> 0
A17: Hotel · revenue | B17: =0 -> 0 | C17: =0 -> 0 | D17: =0 -> 0 | E17: =0 -> 0 | F17: =0 -> 0 | G17: =0 -> 0 | H17: =0 -> 0 | I17: =0 -> 0 | ... AX17: =0 -> 0
A18: Hotel · collections released | B18: =0 -> 0 | C18: =0 -> 0 | D18: =0 -> 0 | E18: =0 -> 0 | F18: =0 -> 0 | G18: =0 -> 0 | H18: =0 -> 0 | I18: =0 -> 0 | ... AX18: =0 -> 0
A19: Hotel · NOI | B19: =IF((B$3>=Phases!$D$5+Phases!$E$5),Phases!$C$5/45*Scenarios!$E$5*365*0.68*0.38/4*MIN(1,(B$3-Phases!$D$5-Phases!$E$5+1)/6)*1.025^INT((B$3-Phases!$D$5-Phases!$E$5)/4),0) -> 0 | C19: =IF((C$3>=Phases!$D$5+Phases!$E$5),Phases!$C$5/45*Scenarios!$E$5*365*0.68*0.38/4*MIN(1,(C$3-Phases!$D$5-Phases!$E$5+1)/6)*1.025^INT((C$3-Phases!$D$5-Phases!$E$5)/4),0) -> 0 | D19: =IF((D$3>=Phases!$D$5+Phases!$E$5),Phases!$C$5/45*Scenarios!$E$5*365*0.68*0.38/4*MIN(1,(D$3-Phases!$D$5-Phases!$E$5+1)/6)*1.025^INT((D$3-Phases!$D$5-Phases!$E$5)/4),0) -> 0 | E19: =IF((E$3>=Phases!$D$5+Phases!$E$5),Phases!$C$5/45*Scenarios!$E$5*365*0.68*0.38/4*MIN(1,(E$3-Phases!$D$5-Phases!$E$5+1)/6)*1.025^INT((E$3-Phases!$D$5-Phases!$E$5)/4),0) -> 0 | F19: =IF((F$3>=Phases!$D$5+Phases!$E$5),Phases!$C$5/45*Scenarios!$E$5*365*0.68*0.38/4*MIN(1,(F$3-Phases!$D$5-Phases!$E$5+1)/6)*1.025^INT((F$3-Phases!$D$5-Phases!$E$5)/4),0) -> 0 | G19: =IF((G$3>=Phases!$D$5+Phases!$E$5),Phases!$C$5/45*Scenarios!$E$5*365*0.68*0.38/4*MIN(1,(G$3-Phases!$D$5-Phases!$E$5+1)/6)*1.025^INT((G$3-Phases!$D$5-Phases!$E$5)/4),0) -> 0 | H19: =IF((H$3>=Phases!$D$5+Phases!$E$5),Phases!$C$5/45*Scenarios!$E$5*365*0.68*0.38/4*MIN(1,(H$3-Phases!$D$5-Phases!$E$5+1)/6)*1.025^INT((H$3-Phases!$D$5-Phases!$E$5)/4),0) -> 0 | I19: =IF((I$3>=Phases!$D$5+Phases!$E$5),Phases!$C$5/45*Scenarios!$E$5*365*0.68*0.38/4*MIN(1,(I$3-Phases!$D$5-Phases!$E$5+1)/6)*1.025^INT((I$3-Phases!$D$5-Phases!$E$5)/4),0) -> 0 | ... AX19: =IF((AX$3>=Phases!$D$5+Phases!$E$5),Phases!$C$5/45*Scenarios!$E$5*365*0.68*0.38/4*MIN(1,(AX$3-Phases!$D$5-Phases!$E$5+1)/6)*1.025^INT((AX$3-Phases!$D$5-Phases!$E$5)/4),0) -> 22422417
A20: Retail · build cost | B20: =IF(AND(B$3>=Phases!$D$6,B$3<Phases!$D$6+Phases!$E$6),Phases!$C$6*Scenarios!$E$8*IF("income"="hotel",1.6,IF("Retail"="Plots",0.25,1))/Phases!$E$6,0) -> 0 | C20: =IF(AND(C$3>=Phases!$D$6,C$3<Phases!$D$6+Phases!$E$6),Phases!$C$6*Scenarios!$E$8*IF("income"="hotel",1.6,IF("Retail"="Plots",0.25,1))/Phases!$E$6,0) -> 0 | D20: =IF(AND(D$3>=Phases!$D$6,D$3<Phases!$D$6+Phases!$E$6),Phases!$C$6*Scenarios!$E$8*IF("income"="hotel",1.6,IF("Retail"="Plots",0.25,1))/Phases!$E$6,0) -> 0 | E20: =IF(AND(E$3>=Phases!$D$6,E$3<Phases!$D$6+Phases!$E$6),Phases!$C$6*Scenarios!$E$8*IF("income"="hotel",1.6,IF("Retail"="Plots",0.25,1))/Phases!$E$6,0) -> 0 | F20: =IF(AND(F$3>=Phases!$D$6,F$3<Phases!$D$6+Phases!$E$6),Phases!$C$6*Scenarios!$E$8*IF("income"="hotel",1.6,IF("Retail"="Plots",0.25,1))/Phases!$E$6,0) -> 0 | G20: =IF(AND(G$3>=Phases!$D$6,G$3<Phases!$D$6+Phases!$E$6),Phases!$C$6*Scenarios!$E$8*IF("income"="hotel",1.6,IF("Retail"="Plots",0.25,1))/Phases!$E$6,0) -> 0 | H20: =IF(AND(H$3>=Phases!$D$6,H$3<Phases!$D$6+Phases!$E$6),Phases!$C$6*Scenarios!$E$8*IF("income"="hotel",1.6,IF("Retail"="Plots",0.25,1))/Phases!$E$6,0) -> 0 | I20: =IF(AND(I$3>=Phases!$D$6,I$3<Phases!$D$6+Phases!$E$6),Phases!$C$6*Scenarios!$E$8*IF("income"="hotel",1.6,IF("Retail"="Plots",0.25,1))/Phases!$E$6,0) -> 0 | ... AX20: =IF(AND(AX$3>=Phases!$D$6,AX$3<Phases!$D$6+Phases!$E$6),Phases!$C$6*Scenarios!$E$8*IF("income"="hotel",1.6,IF("Retail"="Plots",0.25,1))/Phases!$E$6,0) -> 0
A21: Retail · revenue | B21: =0 -> 0 | C21: =0 -> 0 | D21: =0 -> 0 | E21: =0 -> 0 | F21: =0 -> 0 | G21: =0 -> 0 | H21: =0 -> 0 | I21: =0 -> 0 | ... AX21: =0 -> 0
A22: Retail · collections released | B22: =0 -> 0 | C22: =0 -> 0 | D22: =0 -> 0 | E22: =0 -> 0 | F22: =0 -> 0 | G22: =0 -> 0 | H22: =0 -> 0 | I22: =0 -> 0 | ... AX22: =0 -> 0
A23: Retail · NOI | B23: =IF((B$3>=Phases!$D$6+Phases!$E$6),Phases!$C$6*Scenarios!$E$6*0.9/4*MIN(1,(B$3-Phases!$D$6-Phases!$E$6+1)/6)*1.025^INT((B$3-Phases!$D$6-Phases!$E$6)/4),0) -> 0 | C23: =IF((C$3>=Phases!$D$6+Phases!$E$6),Phases!$C$6*Scenarios!$E$6*0.9/4*MIN(1,(C$3-Phases!$D$6-Phases!$E$6+1)/6)*1.025^INT((C$3-Phases!$D$6-Phases!$E$6)/4),0) -> 0 | D23: =IF((D$3>=Phases!$D$6+Phases!$E$6),Phases!$C$6*Scenarios!$E$6*0.9/4*MIN(1,(D$3-Phases!$D$6-Phases!$E$6+1)/6)*1.025^INT((D$3-Phases!$D$6-Phases!$E$6)/4),0) -> 0 | E23: =IF((E$3>=Phases!$D$6+Phases!$E$6),Phases!$C$6*Scenarios!$E$6*0.9/4*MIN(1,(E$3-Phases!$D$6-Phases!$E$6+1)/6)*1.025^INT((E$3-Phases!$D$6-Phases!$E$6)/4),0) -> 0 | F23: =IF((F$3>=Phases!$D$6+Phases!$E$6),Phases!$C$6*Scenarios!$E$6*0.9/4*MIN(1,(F$3-Phases!$D$6-Phases!$E$6+1)/6)*1.025^INT((F$3-Phases!$D$6-Phases!$E$6)/4),0) -> 0 | G23: =IF((G$3>=Phases!$D$6+Phases!$E$6),Phases!$C$6*Scenarios!$E$6*0.9/4*MIN(1,(G$3-Phases!$D$6-Phases!$E$6+1)/6)*1.025^INT((G$3-Phases!$D$6-Phases!$E$6)/4),0) -> 0 | H23: =IF((H$3>=Phases!$D$6+Phases!$E$6),Phases!$C$6*Scenarios!$E$6*0.9/4*MIN(1,(H$3-Phases!$D$6-Phases!$E$6+1)/6)*1.025^INT((H$3-Phases!$D$6-Phases!$E$6)/4),0) -> 0 | I23: =IF((I$3>=Phases!$D$6+Phases!$E$6),Phases!$C$6*Scenarios!$E$6*0.9/4*MIN(1,(I$3-Phases!$D$6-Phases!$E$6+1)/6)*1.025^INT((I$3-Phases!$D$6-Phases!$E$6)/4),0) -> 0 | ... AX23: =IF((AX$3>=Phases!$D$6+Phases!$E$6),Phases!$C$6*Scenarios!$E$6*0.9/4*MIN(1,(AX$3-Phases!$D$6-Phases!$E$6+1)/6)*1.025^INT((AX$3-Phases!$D$6-Phases!$E$6)/4),0) -> 16311369
A24: Offices · build cost | B24: =IF(AND(B$3>=Phases!$D$7,B$3<Phases!$D$7+Phases!$E$7),Phases!$C$7*Scenarios!$E$8*IF("income"="hotel",1.6,IF("Offices"="Plots",0.25,1))/Phases!$E$7,0) -> 0 | C24: =IF(AND(C$3>=Phases!$D$7,C$3<Phases!$D$7+Phases!$E$7),Phases!$C$7*Scenarios!$E$8*IF("income"="hotel",1.6,IF("Offices"="Plots",0.25,1))/Phases!$E$7,0) -> 0 | D24: =IF(AND(D$3>=Phases!$D$7,D$3<Phases!$D$7+Phases!$E$7),Phases!$C$7*Scenarios!$E$8*IF("income"="hotel",1.6,IF("Offices"="Plots",0.25,1))/Phases!$E$7,0) -> 0 | E24: =IF(AND(E$3>=Phases!$D$7,E$3<Phases!$D$7+Phases!$E$7),Phases!$C$7*Scenarios!$E$8*IF("income"="hotel",1.6,IF("Offices"="Plots",0.25,1))/Phases!$E$7,0) -> 0 | F24: =IF(AND(F$3>=Phases!$D$7,F$3<Phases!$D$7+Phases!$E$7),Phases!$C$7*Scenarios!$E$8*IF("income"="hotel",1.6,IF("Offices"="Plots",0.25,1))/Phases!$E$7,0) -> 0 | G24: =IF(AND(G$3>=Phases!$D$7,G$3<Phases!$D$7+Phases!$E$7),Phases!$C$7*Scenarios!$E$8*IF("income"="hotel",1.6,IF("Offices"="Plots",0.25,1))/Phases!$E$7,0) -> 0 | H24: =IF(AND(H$3>=Phases!$D$7,H$3<Phases!$D$7+Phases!$E$7),Phases!$C$7*Scenarios!$E$8*IF("income"="hotel",1.6,IF("Offices"="Plots",0.25,1))/Phases!$E$7,0) -> 0 | I24: =IF(AND(I$3>=Phases!$D$7,I$3<Phases!$D$7+Phases!$E$7),Phases!$C$7*Scenarios!$E$8*IF("income"="hotel",1.6,IF("Offices"="Plots",0.25,1))/Phases!$E$7,0) -> 0 | ... AX24: =IF(AND(AX$3>=Phases!$D$7,AX$3<Phases!$D$7+Phases!$E$7),Phases!$C$7*Scenarios!$E$8*IF("income"="hotel",1.6,IF("Offices"="Plots",0.25,1))/Phases!$E$7,0) -> 0
A25: Offices · revenue | B25: =0 -> 0 | C25: =0 -> 0 | D25: =0 -> 0 | E25: =0 -> 0 | F25: =0 -> 0 | G25: =0 -> 0 | H25: =0 -> 0 | I25: =0 -> 0 | ... AX25: =0 -> 0
A26: Offices · collections released | B26: =0 -> 0 | C26: =0 -> 0 | D26: =0 -> 0 | E26: =0 -> 0 | F26: =0 -> 0 | G26: =0 -> 0 | H26: =0 -> 0 | I26: =0 -> 0 | ... AX26: =0 -> 0
A27: Offices · NOI | B27: =IF((B$3>=Phases!$D$7+Phases!$E$7),Phases!$C$7*Scenarios!$E$7*0.9/4*MIN(1,(B$3-Phases!$D$7-Phases!$E$7+1)/6)*1.025^INT((B$3-Phases!$D$7-Phases!$E$7)/4),0) -> 0 | C27: =IF((C$3>=Phases!$D$7+Phases!$E$7),Phases!$C$7*Scenarios!$E$7*0.9/4*MIN(1,(C$3-Phases!$D$7-Phases!$E$7+1)/6)*1.025^INT((C$3-Phases!$D$7-Phases!$E$7)/4),0) -> 0 | D27: =IF((D$3>=Phases!$D$7+Phases!$E$7),Phases!$C$7*Scenarios!$E$7*0.9/4*MIN(1,(D$3-Phases!$D$7-Phases!$E$7+1)/6)*1.025^INT((D$3-Phases!$D$7-Phases!$E$7)/4),0) -> 0 | E27: =IF((E$3>=Phases!$D$7+Phases!$E$7),Phases!$C$7*Scenarios!$E$7*0.9/4*MIN(1,(E$3-Phases!$D$7-Phases!$E$7+1)/6)*1.025^INT((E$3-Phases!$D$7-Phases!$E$7)/4),0) -> 0 | F27: =IF((F$3>=Phases!$D$7+Phases!$E$7),Phases!$C$7*Scenarios!$E$7*0.9/4*MIN(1,(F$3-Phases!$D$7-Phases!$E$7+1)/6)*1.025^INT((F$3-Phases!$D$7-Phases!$E$7)/4),0) -> 0 | G27: =IF((G$3>=Phases!$D$7+Phases!$E$7),Phases!$C$7*Scenarios!$E$7*0.9/4*MIN(1,(G$3-Phases!$D$7-Phases!$E$7+1)/6)*1.025^INT((G$3-Phases!$D$7-Phases!$E$7)/4),0) -> 0 | H27: =IF((H$3>=Phases!$D$7+Phases!$E$7),Phases!$C$7*Scenarios!$E$7*0.9/4*MIN(1,(H$3-Phases!$D$7-Phases!$E$7+1)/6)*1.025^INT((H$3-Phases!$D$7-Phases!$E$7)/4),0) -> 0 | I27: =IF((I$3>=Phases!$D$7+Phases!$E$7),Phases!$C$7*Scenarios!$E$7*0.9/4*MIN(1,(I$3-Phases!$D$7-Phases!$E$7+1)/6)*1.025^INT((I$3-Phases!$D$7-Phases!$E$7)/4),0) -> 0 | ... AX27: =IF((AX$3>=Phases!$D$7+Phases!$E$7),Phases!$C$7*Scenarios!$E$7*0.9/4*MIN(1,(AX$3-Phases!$D$7-Phases!$E$7+1)/6)*1.025^INT((AX$3-Phases!$D$7-Phases!$E$7)/4),0) -> 18004240
A28: Land | B28: =IF(B$3=0,Inputs!$B$4,0) -> 900000000 | C28: =IF(C$3=0,Inputs!$B$4,0) -> 0 | D28: =IF(D$3=0,Inputs!$B$4,0) -> 0 | E28: =IF(E$3=0,Inputs!$B$4,0) -> 0 | F28: =IF(F$3=0,Inputs!$B$4,0) -> 0 | G28: =IF(G$3=0,Inputs!$B$4,0) -> 0 | H28: =IF(H$3=0,Inputs!$B$4,0) -> 0 | I28: =IF(I$3=0,Inputs!$B$4,0) -> 0 | ... AX28: =IF(AX$3=0,Inputs!$B$4,0) -> 0
A29: Infrastructure | B29: =IF(AND(B$3>=1,B$3<=Inputs!$B$6),Inputs!$B$5/Inputs!$B$6,0) -> 0 | C29: =IF(AND(C$3>=1,C$3<=Inputs!$B$6),Inputs!$B$5/Inputs!$B$6,0) -> 52500000 | D29: =IF(AND(D$3>=1,D$3<=Inputs!$B$6),Inputs!$B$5/Inputs!$B$6,0) -> 52500000 | E29: =IF(AND(E$3>=1,E$3<=Inputs!$B$6),Inputs!$B$5/Inputs!$B$6,0) -> 52500000 | F29: =IF(AND(F$3>=1,F$3<=Inputs!$B$6),Inputs!$B$5/Inputs!$B$6,0) -> 52500000 | G29: =IF(AND(G$3>=1,G$3<=Inputs!$B$6),Inputs!$B$5/Inputs!$B$6,0) -> 52500000 | H29: =IF(AND(H$3>=1,H$3<=Inputs!$B$6),Inputs!$B$5/Inputs!$B$6,0) -> 52500000 | I29: =IF(AND(I$3>=1,I$3<=Inputs!$B$6),Inputs!$B$5/Inputs!$B$6,0) -> 52500000 | ... AX29: =IF(AND(AX$3>=1,AX$3<=Inputs!$B$6),Inputs!$B$5/Inputs!$B$6,0) -> 0
A30: Build cost | B30: =B4+B8+B12+B16+B20+B24 -> 0 | C30: =C4+C8+C12+C16+C20+C24 -> 39416667 | D30: =D4+D8+D12+D16+D20+D24 -> 39416667 | E30: =E4+E8+E12+E16+E20+E24 -> 1.0929167e+08 | F30: =F4+F8+F12+F16+F20+F24 -> 1.0929167e+08 | G30: =G4+G8+G12+G16+G20+G24 -> 1.0929167e+08 | H30: =H4+H8+H12+H16+H20+H24 -> 1.5229167e+08 | I30: =I4+I8+I12+I16+I20+I24 -> 112875000 | ... AX30: =AX4+AX8+AX12+AX16+AX20+AX24 -> 0
A31: Collections | B31: =B6+B10+B14+B18+B22+B26 -> 0 | C31: =C6+C10+C14+C18+C22+C26 -> 36666667 | D31: =D6+D10+D14+D18+D22+D26 -> 57200000 | E31: =E6+E10+E14+E18+E22+E26 -> 1.3314583e+08 | F31: =F6+F10+F14+F18+F22+F26 -> 1.7870417e+08 | G31: =G6+G10+G14+G18+G22+G26 -> 224262500 | H31: =H6+H10+H14+H18+H22+H26 -> 2.6982083e+08 | I31: =I6+I10+I14+I18+I22+I26 -> 243512500 | ... AX31: =AX6+AX10+AX14+AX18+AX22+AX26 -> 0
A32: NOI | B32: =B7+B11+B15+B19+B23+B27 -> 0 | C32: =C7+C11+C15+C19+C23+C27 -> 0 | D32: =D7+D11+D15+D19+D23+D27 -> 0 | E32: =E7+E11+E15+E19+E23+E27 -> 0 | F32: =F7+F11+F15+F19+F23+F27 -> 0 | G32: =G7+G11+G15+G19+G23+G27 -> 0 | H32: =H7+H11+H15+H19+H23+H27 -> 0 | I32: =I7+I11+I15+I19+I23+I27 -> 0 | ... AX32: =AX7+AX11+AX15+AX19+AX23+AX27 -> 80177052
A33: Exit value | B33: =IF(B$3=48,B32*4*1.025/Scenarios!$E$9,0) -> 0 | C33: =IF(C$3=48,C32*4*1.025/Scenarios!$E$9,0) -> 0 | D33: =IF(D$3=48,D32*4*1.025/Scenarios!$E$9,0) -> 0 | E33: =IF(E$3=48,E32*4*1.025/Scenarios!$E$9,0) -> 0 | F33: =IF(F$3=48,F32*4*1.025/Scenarios!$E$9,0) -> 0 | G33: =IF(G$3=48,G32*4*1.025/Scenarios!$E$9,0) -> 0 | H33: =IF(H$3=48,H32*4*1.025/Scenarios!$E$9,0) -> 0 | I33: =IF(I$3=48,I32*4*1.025/Scenarios!$E$9,0) -> 0 | ... AX33: =IF(AX$3=48,AX32*4*1.025/Scenarios!$E$9,0) -> 4.3830122e+09
A34: Total cost | B34: =B28+B29+B30 -> 900000000 | C34: =C28+C29+C30 -> 91916667 | D34: =D28+D29+D30 -> 91916667 | E34: =E28+E29+E30 -> 1.6179167e+08 | F34: =F28+F29+F30 -> 1.6179167e+08 | G34: =G28+G29+G30 -> 1.6179167e+08 | H34: =H28+H29+H30 -> 2.0479167e+08 | I34: =I28+I29+I30 -> 165375000 | ... AX34: =AX28+AX29+AX30 -> 0
A35: Murabaha drawn | B35: =B30*Inputs!$B$9 -> 0 | C35: =C30*Inputs!$B$9 -> 23650000 | D35: =D30*Inputs!$B$9 -> 23650000 | E35: =E30*Inputs!$B$9 -> 65575000 | F35: =F30*Inputs!$B$9 -> 65575000 | G35: =G30*Inputs!$B$9 -> 65575000 | H35: =H30*Inputs!$B$9 -> 91375000 | I35: =I30*Inputs!$B$9 -> 67725000 | ... AX35: =AX30*Inputs!$B$9 -> 0
A36: Murabaha profit | B36: =0*Inputs!$B$10/4 -> 0 | C36: =B38*Inputs!$B$10/4 -> 0 | D36: =C38*Inputs!$B$10/4 -> 0 | E36: =D38*Inputs!$B$10/4 -> 0 | F36: =E38*Inputs!$B$10/4 -> 0 | G36: =F38*Inputs!$B$10/4 -> 0 | H36: =G38*Inputs!$B$10/4 -> 0 | I36: =H38*Inputs!$B$10/4 -> 0 | J36: =I38*Inputs!$B$10/4 -> 0 | ... AX36: =AW38*Inputs!$B$10/4 -> 0
A37: Murabaha repaid | B37: =MIN(B31+B32+B33,0+B35+B36) -> 0 | C37: =MIN(C31+C32+C33,B38+C35+C36) -> 23650000 | D37: =MIN(D31+D32+D33,C38+D35+D36) -> 23650000 | E37: =MIN(E31+E32+E33,D38+E35+E36) -> 65575000 | F37: =MIN(F31+F32+F33,E38+F35+F36) -> 65575000 | G37: =MIN(G31+G32+G33,F38+G35+G36) -> 65575000 | H37: =MIN(H31+H32+H33,G38+H35+H36) -> 91375000 | I37: =MIN(I31+I32+I33,H38+I35+I36) -> 67725000 | J37: =MIN(J31+J32+J33,I38+J35+J36) -> 79012500 | ... AX37: =MIN(AX31+AX32+AX33,AW38+AX35+AX36) -> 0
A38: Murabaha balance | B38: =0+B35+B36-B37 -> 0 | C38: =B38+C35+C36-C37 -> 0 | D38: =C38+D35+D36-D37 -> 0 | E38: =D38+E35+E36-E37 -> 0 | F38: =E38+F35+F36-F37 -> 0 | G38: =F38+G35+G36-G37 -> 0 | H38: =G38+H35+H36-H37 -> 0 | I38: =H38+I35+I36-I37 -> 0 | J38: =I38+J35+J36-J37 -> 0 | ... AX38: =AW38+AX35+AX36-AX37 -> 0
A39: Pre-zakat cash flow | B39: =B31+B32+B33-B34 -> -900000000 | C39: =C31+C32+C33-C34 -> -55250000 | D39: =D31+D32+D33-D34 -> -34716667 | E39: =E31+E32+E33-E34 -> -28645833 | F39: =F31+F32+F33-F34 -> 16912500 | G39: =G31+G32+G33-G34 -> 62470833 | H39: =H31+H32+H33-H34 -> 65029167 | I39: =I31+I32+I33-I34 -> 78137500 | ... AX39: =AX31+AX32+AX33-AX34 -> 4.4631892e+09
A40: Cumulative | B40: =B39 -> -900000000 | C40: =B40+C39 -> -955250000 | D40: =C40+D39 -> -9.8996667e+08 | E40: =D40+E39 -> -1018612500 | F40: =E40+F39 -> -1001700000 | G40: =F40+G39 -> -9.3922917e+08 | H40: =G40+H39 -> -874200000 | I40: =H40+I39 -> -796062500 | J40: =I40+J39 -> -711712500 | ... AX40: =AW40+AX39 -> 5.1452632e+09
A41: Zakat | B41: =MAX(0,B40)*Inputs!$B$8 -> 0 | C41: =MAX(0,C40)*Inputs!$B$8-MAX(0,B40)*Inputs!$B$8 -> 0 | D41: =MAX(0,D40)*Inputs!$B$8-MAX(0,C40)*Inputs!$B$8 -> 0 | E41: =MAX(0,E40)*Inputs!$B$8-MAX(0,D40)*Inputs!$B$8 -> 0 | F41: =MAX(0,F40)*Inputs!$B$8-MAX(0,E40)*Inputs!$B$8 -> 0 | G41: =MAX(0,G40)*Inputs!$B$8-MAX(0,F40)*Inputs!$B$8 -> 0 | H41: =MAX(0,H40)*Inputs!$B$8-MAX(0,G40)*Inputs!$B$8 -> 0 | I41: =MAX(0,I40)*Inputs!$B$8-MAX(0,H40)*Inputs!$B$8 -> 0 | J41: =MAX(0,J40)*Inputs!$B$8-MAX(0,I40)*Inputs!$B$8 -> 0 | ... AX41: =MAX(0,AX40)*Inputs!$B$8-MAX(0,AW40)*Inputs!$B$8 -> 1.1157973e+08
A42: Unlevered cash flow | B42: =B39-B41 -> -900000000 | C42: =C39-C41 -> -55250000 | D42: =D39-D41 -> -34716667 | E42: =E39-E41 -> -28645833 | F42: =F39-F41 -> 16912500 | G42: =G39-G41 -> 62470833 | H42: =H39-H41 -> 65029167 | I42: =I39-I41 -> 78137500 | ... AX42: =AX39-AX41 -> 4.3516095e+09
...

Sheet Returns
A3: Project IRR | B3: =(1+IRR('Cash Flow'!B42:AX42,0.02))^4-1 -> 0.18159516
A4: Equity IRR | B4: =(1+IRR('Cash Flow'!B43:AX43,0.02))^4-1 -> 0.18721952
A5: NPV (SAR) | B5: =NPV((1+Inputs!$B$12)^0.25-1,'Cash Flow'!C42:AX42)+'Cash Flow'!B42 -> 9.1849596e+08
A6: Net profit (SAR) | B6: =SUM('Cash Flow'!B42:AX42) -> 5.0166317e+09
A7: Total development cost (SAR) | B7: =SUM('Cash Flow'!B34:AX34)+SUM('Cash Flow'!B36:AX36) -> 3.2571735e+09
A8: Gross revenue (SAR) | B8: =SUM('Cash Flow'!B31:AX31)+SUM('Cash Flow'!B32:AX32)+SUM('Cash Flow'!B33:AX33) -> 8.3314632e+09
A9: Peak murabaha (SAR) | B9: =MAX('Cash Flow'!B38:AX38) -> 3.8364495e+08
A10: Profit capitalised (SAR) | B10: =SUM('Cash Flow'!B36:AX36) -> 70973524
A11: Zakat paid (SAR) | B11: =SUM('Cash Flow'!B41:AX41) -> 1.2863158e+08
A12: Escrow held at horizon (SAR) | B12: =SUM('Cash Flow'!B5:AX5,'Cash Flow'!B9:AX9,'Cash Flow'!B13:AX13,'Cash Flow'!B17:AX17,'Cash Flow'!B21:AX21,'Cash Flow'!B25:AX25)-SUM('Cash Flow'!B6:AX6,'Cash Flow'!B10:AX10,'Cash Flow'!B14:AX14,'Cash Flow'!B18:AX18,'Cash Flow'!B22:AX22,'Cash Flow'!B26:AX26) -> 0
