Workbook

Sheet Inputs
A1: NORTHGATE EUROPEAN LOGISTICS – EIGHT ASSETS, FOUR COUNTRIES (EUR)
A3: Valuation date | B3: 46023
A4: Portfolio price (EUR) | B4: 610000000
A5: Purchase costs | B5: 0.04
A6: Loan to value | B6: 0.5
A7: All-in rate | B7: 0.045
A8: LTV covenant | B8: 0.6
A9: Cash trap LTV | B9: 0.55
A10: Exit yield (blended) | B10: 0.055
A11: Hold (years) | B11: 7
A12: Void on expiry (months) | B12: 9
A13: Renewal probability | B13: 0.6
A14: Non-recoverable (% of rent) | B14: 0.03

Sheet Countries
A1: Country | B1: Currency | C1: FX to EUR | D1: CPI | E1: Indexation floor | F1: Indexation cap
A2: Germany | B2: EUR | C2: 1 | D2: 0.022 | E2: 0 | F2: 0.05
A3: Poland | B3: PLN | C3: 0.2315 | D3: 0.045 | E3: 0.01 | F3: 0.04
A4: Sweden | B4: SEK | C4: 0.0875 | D4: 0.02 | E4: 0 | F4: 0.03
A5: UK | B5: GBP | C5: 1.17 | D5: 0.03 | E5: 0.01 | F5: 0.05

Sheet Assets
A1: Asset | B1: Country | C1: Area (sqm) | D1: Rent (local/sqm/yr) | E1: Lease expiry | F1: ERV (local/sqm/yr) | G1: Disposal date | H1: Disposal yield
A2: Hamburg Nord | B2: Germany | C2: 48000 | D2: 62 | E2: 47938 | F2: 66
A3: Leipzig Park | B3: Germany | C3: 61000 | D3: 55 | E3: 47026 | F3: 60 | G3: 47483 | H3: 0.052
A4: Warsaw West | B4: Poland | C4: 72000 | D4: 260 | E4: 47664 | F4: 280
A5: Lodz Hub | B5: Poland | C5: 55000 | D5: 240 | E5: 46752 | F5: 265
A6: Malmo Gate | B6: Sweden | C6: 38000 | D6: 780 | E6: 48579 | F6: 800
A7: Gothenburg Port | B7: Sweden | C7: 44000 | D7: 760 | E7: 47299 | F7: 810 | G7: 47664 | H7: 0.05
A8: Midlands Cross | B8: UK | C8: 66000 | D8: 88 | E8: 48669 | F8: 96
A9: Thames Gateway | B9: UK | C9: 52000 | D9: 98 | E9: 46843 | F9: 104

Sheet Cash Flow
A3: Year | B3: 0 | C3: 1 | D3: 2 | E3: 3 | F3: 4 | G3: 5 | H3: 6 | I3: 7 | J3: 8 | K3: 9 | L3: 10
A4: Year start | B4: =EDATE(Inputs!$B$3,12*B3) -> 46023 | C4: =EDATE(Inputs!$B$3,12*C3) -> 46388 | D4: =EDATE(Inputs!$B$3,12*D3) -> 46753 | E4: =EDATE(Inputs!$B$3,12*E3) -> 47119 | F4: =EDATE(Inputs!$B$3,12*F3) -> 47484 | G4: =EDATE(Inputs!$B$3,12*G3) -> 47849 | H4: =EDATE(Inputs!$B$3,12*H3) -> 48214 | I4: =EDATE(Inputs!$B$3,12*I3) -> 48580 | ... L4: =EDATE(Inputs!$B$3,12*L3) -> 49675
A5: Hamburg Nord · rent (EUR) | B5: =IF(AND(B$3>=1,B$3<=Inputs!$B$11,OR(Assets!$G$2="",B$4<Assets!$G$2)),Assets!$C$2*(Assets!$D$2*(1+MIN(INDEX(Countries!$F$2:$F$5,MATCH(Assets!$B$2,Countries!$A$2:$A$5,0)),MAX(INDEX(Countries!$E$2:$E$5,MATCH(Assets!$B$2,Countries!$A$2:$A$5,0)),INDEX(Countries!$D$2:$D$5,MATCH(Assets!$B$2,Countries!$A$2:$A$5,0)))))^(B$3-1)*MAX(0,MIN(1,YEARFRAC(B$4,MIN(Assets!$E$2,EDATE(B$4,12)),1)*(Assets!$E$2>B$4)))+Assets!$F$2*(1+MIN(INDEX(Countries!$F$2:$F$5,MATCH(Assets!$B$2,Countries!$A$2:$A$5,0)),MAX(INDEX(Countries!$E$2:$E$5,MATCH(Assets!$B$2,Countries!$A$2:$A$5,0)),INDEX(Countries!$D$2:$D$5,MATCH(Assets!$B$2,Countries!$A$2:$A$5,0)))))^(B$3-1)*IF(Assets!$E$2<EDATE(B$4,12),(Inputs!$B$13*MAX(0,MIN(12,DATEDIF(MAX(Assets!$E$2,B$4),EDATE(B$4,12),"m")))+(1-Inputs!$B$13)*MAX(0,MAX(0,MIN(12,DATEDIF(MAX(Assets!$E$2,B$4),EDATE(B$4,12),"m")))-MAX(0,Inputs!$B$12-IF(Assets!$E$2<B$4,DATEDIF(Assets!$E$2,B$4,"m"),0))))/12,0))*INDEX(Countries!$C$2:$C$5,MATCH(Assets!$B$2,Countries!$A$2:$A$5,0)),0) -> 0 | C5: =IF(AND(C$3>=1,C$3<=Inputs!$B$11,OR(Assets!$G$2="",C$4<Assets!$G$2)),Assets!$C$2*(Assets!$D$2*(1+MIN(INDEX(Countries!$F$2:$F$5,MATCH(Assets!$B$2,Countries!$A$2:$A$5,0)),MAX(INDEX(Countries!$E$2:$E$5,MATCH(Assets!$B$2,Countries!$A$2:$A$5,0)),INDEX(Countries!$D$2:$D$5,MATCH(Assets!$B$2,Countries!$A$2:$A$5,0)))))^(C$3-1)*MAX(0,MIN(1,YEARFRAC(C$4,MIN(Assets!$E$2,EDATE(C$4,12)),1)*(Assets!$E$2>C$4)))+Assets!$F$2*(1+MIN(INDEX(Countries!$F$2:$F$5,MATCH(Assets!$B$2,Countries!$A$2:$A$5,0)),MAX(INDEX(Countries!$E$2:$E$5,MATCH(Assets!$B$2,Countries!$A$2:$A$5,0)),INDEX(Countries!$D$2:$D$5,MATCH(Assets!$B$2,Countries!$A$2:$A$5,0)))))^(C$3-1)*IF(Assets!$E$2<EDATE(C$4,12),(Inputs!$B$13*MAX(0,MIN(12,DATEDIF(MAX(Assets!$E$2,C$4),EDATE(C$4,12),"m")))+(1-Inputs!$B$13)*MAX(0,MAX(0,MIN(12,DATEDIF(MAX(Assets!$E$2,C$4),EDATE(C$4,12),"m")))-MAX(0,Inputs!$B$12-IF(Assets!$E$2<C$4,DATEDIF(Assets!$E$2,C$4,"m"),0))))/12,0))*INDEX(Countries!$C$2:$C$5,MATCH(Assets!$B$2,Countries!$A$2:$A$5,0)),0) -> 2976000 | D5: =IF(AND(D$3>=1,D$3<=Inputs!$B$11,OR(Assets!$G$2="",D$4<Assets!$G$2)),Assets!$C$2*(Assets!$D$2*(1+MIN(INDEX(Countries!$F$2:$F$5,MATCH(Assets!$B$2,Countries!$A$2:$A$5,0)),MAX(INDEX(Countries!$E$2:$E$5,MATCH(Assets!$B$2,Countries!$A$2:$A$5,0)),INDEX(Countries!$D$2:$D$5,MATCH(Assets!$B$2,Countries!$A$2:$A$5,0)))))^(D$3-1)*MAX(0,MIN(1,YEARFRAC(D$4,MIN(Assets!$E$2,EDATE(D$4,12)),1)*(Assets!$E$2>D$4)))+Assets!$F$2*(1+MIN(INDEX(Countries!$F$2:$F$5,MATCH(Assets!$B$2,Countries!$A$2:$A$5,0)),MAX(INDEX(Countries!$E$2:$E$5,MATCH(Assets!$B$2,Countries!$A$2:$A$5,0)),INDEX(Countries!$D$2:$D$5,MATCH(Assets!$B$2,Countries!$A$2:$A$5,0)))))^(D$3-1)*IF(Assets!$E$2<EDATE(D$4,12),(Inputs!$B$13*MAX(0,MIN(12,DATEDIF(MAX(Assets!$E$2,D$4),EDATE(D$4,12),"m")))+(1-Inputs!$B$13)*MAX(0,MAX(0,MIN(12,DATEDIF(MAX(Assets!$E$2,D$4),EDATE(D$4,12),"m")))-MAX(0,Inputs!$B$12-IF(Assets!$E$2<D$4,DATEDIF(Assets!$E$2,D$4,"m"),0))))/12,0))*INDEX(Countries!$C$2:$C$5,MATCH(Assets!$B$2,Countries!$A$2:$A$5,0)),0) -> 3041472 | E5: =IF(AND(E$3>=1,E$3<=Inputs!$B$11,OR(Assets!$G$2="",E$4<Assets!$G$2)),Assets!$C$2*(Assets!$D$2*(1+MIN(INDEX(Countries!$F$2:$F$5,MATCH(Assets!$B$2,Countries!$A$2:$A$5,0)),MAX(INDEX(Countries!$E$2:$E$5,MATCH(Assets!$B$2,Countries!$A$2:$A$5,0)),INDEX(Countries!$D$2:$D$5,MATCH(Assets!$B$2,Countries!$A$2:$A$5,0)))))^(E$3-1)*MAX(0,MIN(1,YEARFRAC(E$4,MIN(Assets!$E$2,EDATE(E$4,12)),1)*(Assets!$E$2>E$4)))+Assets!$F$2*(1+MIN(INDEX(Countries!$F$2:$F$5,MATCH(Assets!$B$2,Countries!$A$2:$A$5,0)),MAX(INDEX(Countries!$E$2:$E$5,MATCH(Assets!$B$2,Countries!$A$2:$A$5,0)),INDEX(Countries!$D$2:$D$5,MATCH(Assets!$B$2,Countries!$A$2:$A$5,0)))))^(E$3-1)*IF(Assets!$E$2<EDATE(E$4,12),(Inputs!$B$13*MAX(0,MIN(12,DATEDIF(MAX(Assets!$E$2,E$4),EDATE(E$4,12),"m")))+(1-Inputs!$B$13)*MAX(0,MAX(0,MIN(12,DATEDIF(MAX(Assets!$E$2,E$4),EDATE(E$4,12),"m")))-MAX(0,Inputs!$B$12-IF(Assets!$E$2<E$4,DATEDIF(Assets!$E$2,E$4,"m"),0))))/12,0))*INDEX(Countries!$C$2:$C$5,MATCH(Assets!$B$2,Countries!$A$2:$A$5,0)),0) -> 3108384.4 | F5: =IF(AND(F$3>=1,F$3<=Inputs!$B$11,OR(Assets!$G$2="",F$4<Assets!$G$2)),Assets!$C$2*(Assets!$D$2*(1+MIN(INDEX(Countries!$F$2:$F$5,MATCH(Assets!$B$2,Countries!$A$2:$A$5,0)),MAX(INDEX(Countries!$E$2:$E$5,MATCH(Assets!$B$2,Countries!$A$2:$A$5,0)),INDEX(Countries!$D$2:$D$5,MATCH(Assets!$B$2,Countries!$A$2:$A$5,0)))))^(F$3-1)*MAX(0,MIN(1,YEARFRAC(F$4,MIN(Assets!$E$2,EDATE(F$4,12)),1)*(Assets!$E$2>F$4)))+Assets!$F$2*(1+MIN(INDEX(Countries!$F$2:$F$5,MATCH(Assets!$B$2,Countries!$A$2:$A$5,0)),MAX(INDEX(Countries!$E$2:$E$5,MATCH(Assets!$B$2,Countries!$A$2:$A$5,0)),INDEX(Countries!$D$2:$D$5,MATCH(Assets!$B$2,Countries!$A$2:$A$5,0)))))^(F$3-1)*IF(Assets!$E$2<EDATE(F$4,12),(Inputs!$B$13*MAX(0,MIN(12,DATEDIF(MAX(Assets!$E$2,F$4),EDATE(F$4,12),"m")))+(1-Inputs!$B$13)*MAX(0,MAX(0,MIN(12,DATEDIF(MAX(Assets!$E$2,F$4),EDATE(F$4,12),"m")))-MAX(0,Inputs!$B$12-IF(Assets!$E$2<F$4,DATEDIF(Assets!$E$2,F$4,"m"),0))))/12,0))*INDEX(Countries!$C$2:$C$5,MATCH(Assets!$B$2,Countries!$A$2:$A$5,0)),0) -> 3176768.8 | G5: =IF(AND(G$3>=1,G$3<=Inputs!$B$11,OR(Assets!$G$2="",G$4<Assets!$G$2)),Assets!$C$2*(Assets!$D$2*(1+MIN(INDEX(Countries!$F$2:$F$5,MATCH(Assets!$B$2,Countries!$A$2:$A$5,0)),MAX(INDEX(Countries!$E$2:$E$5,MATCH(Assets!$B$2,Countries!$A$2:$A$5,0)),INDEX(Countries!$D$2:$D$5,MATCH(Assets!$B$2,Countries!$A$2:$A$5,0)))))^(G$3-1)*MAX(0,MIN(1,YEARFRAC(G$4,MIN(Assets!$E$2,EDATE(G$4,12)),1)*(Assets!$E$2>G$4)))+Assets!$F$2*(1+MIN(INDEX(Countries!$F$2:$F$5,MATCH(Assets!$B$2,Countries!$A$2:$A$5,0)),MAX(INDEX(Countries!$E$2:$E$5,MATCH(Assets!$B$2,Countries!$A$2:$A$5,0)),INDEX(Countries!$D$2:$D$5,MATCH(Assets!$B$2,Countries!$A$2:$A$5,0)))))^(G$3-1)*IF(Assets!$E$2<EDATE(G$4,12),(Inputs!$B$13*MAX(0,MIN(12,DATEDIF(MAX(Assets!$E$2,G$4),EDATE(G$4,12),"m")))+(1-Inputs!$B$13)*MAX(0,MAX(0,MIN(12,DATEDIF(MAX(Assets!$E$2,G$4),EDATE(G$4,12),"m")))-MAX(0,Inputs!$B$12-IF(Assets!$E$2<G$4,DATEDIF(Assets!$E$2,G$4,"m"),0))))/12,0))*INDEX(Countries!$C$2:$C$5,MATCH(Assets!$B$2,Countries!$A$2:$A$5,0)),0) -> 2346904.6 | H5: =IF(AND(H$3>=1,H$3<=Inputs!$B$11,OR(Assets!$G$2="",H$4<Assets!$G$2)),Assets!$C$2*(Assets!$D$2*(1+MIN(INDEX(Countries!$F$2:$F$5,MATCH(Assets!$B$2,Countries!$A$2:$A$5,0)),MAX(INDEX(Countries!$E$2:$E$5,MATCH(Assets!$B$2,Countries!$A$2:$A$5,0)),INDEX(Countries!$D$2:$D$5,MATCH(Assets!$B$2,Countries!$A$2:$A$5,0)))))^(H$3-1)*MAX(0,MIN(1,YEARFRAC(H$4,MIN(Assets!$E$2,EDATE(H$4,12)),1)*(Assets!$E$2>H$4)))+Assets!$F$2*(1+MIN(INDEX(Countries!$F$2:$F$5,MATCH(Assets!$B$2,Countries!$A$2:$A$5,0)),MAX(INDEX(Countries!$E$2:$E$5,MATCH(Assets!$B$2,Countries!$A$2:$A$5,0)),INDEX(Countries!$D$2:$D$5,MATCH(Assets!$B$2,Countries!$A$2:$A$5,0)))))^(H$3-1)*IF(Assets!$E$2<EDATE(H$4,12),(Inputs!$B$13*MAX(0,MIN(12,DATEDIF(MAX(Assets!$E$2,H$4),EDATE(H$4,12),"m")))+(1-Inputs!$B$13)*MAX(0,MAX(0,MIN(12,DATEDIF(MAX(Assets!$E$2,H$4),EDATE(H$4,12),"m")))-MAX(0,Inputs!$B$12-IF(Assets!$E$2<H$4,DATEDIF(Assets!$E$2,H$4,"m"),0))))/12,0))*INDEX(Countries!$C$2:$C$5,MATCH(Assets!$B$2,Countries!$A$2:$A$5,0)),0) -> 3532154.2 | I5: =IF(AND(I$3>=1,I$3<=Inputs!$B$11,OR(Assets!$G$2="",I$4<Assets!$G$2)),Assets!$C$2*(Assets!$D$2*(1+MIN(INDEX(Countries!$F$2:$F$5,MATCH(Assets!$B$2,Countries!$A$2:$A$5,0)),MAX(INDEX(Countries!$E$2:$E$5,MATCH(Assets!$B$2,Countries!$A$2:$A$5,0)),INDEX(Countries!$D$2:$D$5,MATCH(Assets!$B$2,Countries!$A$2:$A$5,0)))))^(I$3-1)*MAX(0,MIN(1,YEARFRAC(I$4,MIN(Assets!$E$2,EDATE(I$4,12)),1)*(Assets!$E$2>I$4)))+Assets!$F$2*(1+MIN(INDEX(Countries!$F$2:$F$5,MATCH(Assets!$B$2,Countries!$A$2:$A$5,0)),MAX(INDEX(Countries!$E$2:$E$5,MATCH(Assets!$B$2,Countries!$A$2:$A$5,0)),INDEX(Countries!$D$2:$D$5,MATCH(Assets!$B$2,Countries!$A$2:$A$5,0)))))^(I$3-1)*IF(Assets!$E$2<EDATE(I$4,12),(Inputs!$B$13*MAX(0,MIN(12,DATEDIF(MAX(Assets!$E$2,I$4),EDATE(I$4,12),"m")))+(1-Inputs!$B$13)*MAX(0,MAX(0,MIN(12,DATEDIF(MAX(Assets!$E$2,I$4),EDATE(I$4,12),"m")))-MAX(0,Inputs!$B$12-IF(Assets!$E$2<I$4,DATEDIF(Assets!$E$2,I$4,"m"),0))))/12,0))*INDEX(Countries!$C$2:$C$5,MATCH(Assets!$B$2,Countries!$A$2:$A$5,0)),0) -> 3609861.6 | ... L5: =IF(AND(L$3>=1,L$3<=Inputs!$B$11,OR(Assets!$G$2="",L$4<Assets!$G$2)),Assets!$C$2*(Assets!$D$2*(1+MIN(INDEX(Countries!$F$2:$F$5,MATCH(Assets!$B$2,Countries!$A$2:$A$5,0)),MAX(INDEX(Countries!$E$2:$E$5,MATCH(Assets!$B$2,Countries!$A$2:$A$5,0)),INDEX(Countries!$D$2:$D$5,MATCH(Assets!$B$2,Countries!$A$2:$A$5,0)))))^(L$3-1)*MAX(0,MIN(1,YEARFRAC(L$4,MIN(Assets!$E$2,EDATE(L$4,12)),1)*(Assets!$E$2>L$4)))+Assets!$F$2*(1+MIN(INDEX(Countries!$F$2:$F$5,MATCH(Assets!$B$2,Countries!$A$2:$A$5,0)),MAX(INDEX(Countries!$E$2:$E$5,MATCH(Assets!$B$2,Countries!$A$2:$A$5,0)),INDEX(Countries!$D$2:$D$5,MATCH(Assets!$B$2,Countries!$A$2:$A$5,0)))))^(L$3-1)*IF(Assets!$E$2<EDATE(L$4,12),(Inputs!$B$13*MAX(0,MIN(12,DATEDIF(MAX(Assets!$E$2,L$4),EDATE(L$4,12),"m")))+(1-Inputs!$B$13)*MAX(0,MAX(0,MIN(12,DATEDIF(MAX(Assets!$E$2,L$4),EDATE(L$4,12),"m")))-MAX(0,Inputs!$B$12-IF(Assets!$E$2<L$4,DATEDIF(Assets!$E$2,L$4,"m"),0))))/12,0))*INDEX(Countries!$C$2:$C$5,MATCH(Assets!$B$2,Countries!$A$2:$A$5,0)),0) -> 0
A6: Hamburg Nord · disposal (EUR) | B6: =IF(AND(Assets!$G$2<>"",Assets!$G$2>=B$4,Assets!$G$2<EDATE(B$4,12)),Assets!$C$2*Assets!$F$2*(1+MIN(INDEX(Countries!$F$2:$F$5,MATCH(Assets!$B$2,Countries!$A$2:$A$5,0)),MAX(INDEX(Countries!$E$2:$E$5,MATCH(Assets!$B$2,Countries!$A$2:$A$5,0)),INDEX(Countries!$D$2:$D$5,MATCH(Assets!$B$2,Countries!$A$2:$A$5,0)))))^(B$3-1)*INDEX(Countries!$C$2:$C$5,MATCH(Assets!$B$2,Countries!$A$2:$A$5,0))/Assets!$H$2,0) -> 0 | C6: =IF(AND(Assets!$G$2<>"",Assets!$G$2>=C$4,Assets!$G$2<EDATE(C$4,12)),Assets!$C$2*Assets!$F$2*(1+MIN(INDEX(Countries!$F$2:$F$5,MATCH(Assets!$B$2,Countries!$A$2:$A$5,0)),MAX(INDEX(Countries!$E$2:$E$5,MATCH(Assets!$B$2,Countries!$A$2:$A$5,0)),INDEX(Countries!$D$2:$D$5,MATCH(Assets!$B$2,Countries!$A$2:$A$5,0)))))^(C$3-1)*INDEX(Countries!$C$2:$C$5,MATCH(Assets!$B$2,Countries!$A$2:$A$5,0))/Assets!$H$2,0) -> 0 | D6: =IF(AND(Assets!$G$2<>"",Assets!$G$2>=D$4,Assets!$G$2<EDATE(D$4,12)),Assets!$C$2*Assets!$F$2*(1+MIN(INDEX(Countries!$F$2:$F$5,MATCH(Assets!$B$2,Countries!$A$2:$A$5,0)),MAX(INDEX(Countries!$E$2:$E$5,MATCH(Assets!$B$2,Countries!$A$2:$A$5,0)),INDEX(Countries!$D$2:$D$5,MATCH(Assets!$B$2,Countries!$A$2:$A$5,0)))))^(D$3-1)*INDEX(Countries!$C$2:$C$5,MATCH(Assets!$B$2,Countries!$A$2:$A$5,0))/Assets!$H$2,0) -> 0 | E6: =IF(AND(Assets!$G$2<>"",Assets!$G$2>=E$4,Assets!$G$2<EDATE(E$4,12)),Assets!$C$2*Assets!$F$2*(1+MIN(INDEX(Countries!$F$2:$F$5,MATCH(Assets!$B$2,Countries!$A$2:$A$5,0)),MAX(INDEX(Countries!$E$2:$E$5,MATCH(Assets!$B$2,Countries!$A$2:$A$5,0)),INDEX(Countries!$D$2:$D$5,MATCH(Assets!$B$2,Countries!$A$2:$A$5,0)))))^(E$3-1)*INDEX(Countries!$C$2:$C$5,MATCH(Assets!$B$2,Countries!$A$2:$A$5,0))/Assets!$H$2,0) -> 0 | F6: =IF(AND(Assets!$G$2<>"",Assets!$G$2>=F$4,Assets!$G$2<EDATE(F$4,12)),Assets!$C$2*Assets!$F$2*(1+MIN(INDEX(Countries!$F$2:$F$5,MATCH(Assets!$B$2,Countries!$A$2:$A$5,0)),MAX(INDEX(Countries!$E$2:$E$5,MATCH(Assets!$B$2,Countries!$A$2:$A$5,0)),INDEX(Countries!$D$2:$D$5,MATCH(Assets!$B$2,Countries!$A$2:$A$5,0)))))^(F$3-1)*INDEX(Countries!$C$2:$C$5,MATCH(Assets!$B$2,Countries!$A$2:$A$5,0))/Assets!$H$2,0) -> 0 | G6: =IF(AND(Assets!$G$2<>"",Assets!$G$2>=G$4,Assets!$G$2<EDATE(G$4,12)),Assets!$C$2*Assets!$F$2*(1+MIN(INDEX(Countries!$F$2:$F$5,MATCH(Assets!$B$2,Countries!$A$2:$A$5,0)),MAX(INDEX(Countries!$E$2:$E$5,MATCH(Assets!$B$2,Countries!$A$2:$A$5,0)),INDEX(Countries!$D$2:$D$5,MATCH(Assets!$B$2,Countries!$A$2:$A$5,0)))))^(G$3-1)*INDEX(Countries!$C$2:$C$5,MATCH(Assets!$B$2,Countries!$A$2:$A$5,0))/Assets!$H$2,0) -> 0 | H6: =IF(AND(Assets!$G$2<>"",Assets!$G$2>=H$4,Assets!$G$2<EDATE(H$4,12)),Assets!$C$2*Assets!$F$2*(1+MIN(INDEX(Countries!$F$2:$F$5,MATCH(Assets!$B$2,Countries!$A$2:$A$5,0)),MAX(INDEX(Countries!$E$2:$E$5,MATCH(Assets!$B$2,Countries!$A$2:$A$5,0)),INDEX(Countries!$D$2:$D$5,MATCH(Assets!$B$2,Countries!$A$2:$A$5,0)))))^(H$3-1)*INDEX(Countries!$C$2:$C$5,MATCH(Assets!$B$2,Countries!$A$2:$A$5,0))/Assets!$H$2,0) -> 0 | I6: =IF(AND(Assets!$G$2<>"",Assets!$G$2>=I$4,Assets!$G$2<EDATE(I$4,12)),Assets!$C$2*Assets!$F$2*(1+MIN(INDEX(Countries!$F$2:$F$5,MATCH(Assets!$B$2,Countries!$A$2:$A$5,0)),MAX(INDEX(Countries!$E$2:$E$5,MATCH(Assets!$B$2,Countries!$A$2:$A$5,0)),INDEX(Countries!$D$2:$D$5,MATCH(Assets!$B$2,Countries!$A$2:$A$5,0)))))^(I$3-1)*INDEX(Countries!$C$2:$C$5,MATCH(Assets!$B$2,Countries!$A$2:$A$5,0))/Assets!$H$2,0) -> 0 | ... L6: =IF(AND(Assets!$G$2<>"",Assets!$G$2>=L$4,Assets!$G$2<EDATE(L$4,12)),Assets!$C$2*Assets!$F$2*(1+MIN(INDEX(Countries!$F$2:$F$5,MATCH(Assets!$B$2,Countries!$A$2:$A$5,0)),MAX(INDEX(Countries!$E$2:$E$5,MATCH(Assets!$B$2,Countries!$A$2:$A$5,0)),INDEX(Countries!$D$2:$D$5,MATCH(Assets!$B$2,Countries!$A$2:$A$5,0)))))^(L$3-1)*INDEX(Countries!$C$2:$C$5,MATCH(Assets!$B$2,Countries!$A$2:$A$5,0))/Assets!$H$2,0) -> 0
A7: Leipzig Park · rent (EUR) | B7: =IF(AND(B$3>=1,B$3<=Inputs!$B$11,OR(Assets!$G$3="",B$4<Assets!$G$3)),Assets!$C$3*(Assets!$D$3*(1+MIN(INDEX(Countries!$F$2:$F$5,MATCH(Assets!$B$3,Countries!$A$2:$A$5,0)),MAX(INDEX(Countries!$E$2:$E$5,MATCH(Assets!$B$3,Countries!$A$2:$A$5,0)),INDEX(Countries!$D$2:$D$5,MATCH(Assets!$B$3,Countries!$A$2:$A$5,0)))))^(B$3-1)*MAX(0,MIN(1,YEARFRAC(B$4,MIN(Assets!$E$3,EDATE(B$4,12)),1)*(Assets!$E$3>B$4)))+Assets!$F$3*(1+MIN(INDEX(Countries!$F$2:$F$5,MATCH(Assets!$B$3,Countries!$A$2:$A$5,0)),MAX(INDEX(Countries!$E$2:$E$5,MATCH(Assets!$B$3,Countries!$A$2:$A$5,0)),INDEX(Countries!$D$2:$D$5,MATCH(Assets!$B$3,Countries!$A$2:$A$5,0)))))^(B$3-1)*IF(Assets!$E$3<EDATE(B$4,12),(Inputs!$B$13*MAX(0,MIN(12,DATEDIF(MAX(Assets!$E$3,B$4),EDATE(B$4,12),"m")))+(1-Inputs!$B$13)*MAX(0,MAX(0,MIN(12,DATEDIF(MAX(Assets!$E$3,B$4),EDATE(B$4,12),"m")))-MAX(0,Inputs!$B$12-IF(Assets!$E$3<B$4,DATEDIF(Assets!$E$3,B$4,"m"),0))))/12,0))*INDEX(Countries!$C$2:$C$5,MATCH(Assets!$B$3,Countries!$A$2:$A$5,0)),0) -> 0 | C7: =IF(AND(C$3>=1,C$3<=Inputs!$B$11,OR(Assets!$G$3="",C$4<Assets!$G$3)),Assets!$C$3*(Assets!$D$3*(1+MIN(INDEX(Countries!$F$2:$F$5,MATCH(Assets!$B$3,Countries!$A$2:$A$5,0)),MAX(INDEX(Countries!$E$2:$E$5,MATCH(Assets!$B$3,Countries!$A$2:$A$5,0)),INDEX(Countries!$D$2:$D$5,MATCH(Assets!$B$3,Countries!$A$2:$A$5,0)))))^(C$3-1)*MAX(0,MIN(1,YEARFRAC(C$4,MIN(Assets!$E$3,EDATE(C$4,12)),1)*(Assets!$E$3>C$4)))+Assets!$F$3*(1+MIN(INDEX(Countries!$F$2:$F$5,MATCH(Assets!$B$3,Countries!$A$2:$A$5,0)),MAX(INDEX(Countries!$E$2:$E$5,MATCH(Assets!$B$3,Countries!$A$2:$A$5,0)),INDEX(Countries!$D$2:$D$5,MATCH(Assets!$B$3,Countries!$A$2:$A$5,0)))))^(C$3-1)*IF(Assets!$E$3<EDATE(C$4,12),(Inputs!$B$13*MAX(0,MIN(12,DATEDIF(MAX(Assets!$E$3,C$4),EDATE(C$4,12),"m")))+(1-Inputs!$B$13)*MAX(0,MAX(0,MIN(12,DATEDIF(MAX(Assets!$E$3,C$4),EDATE(C$4,12),"m")))-MAX(0,Inputs!$B$12-IF(Assets!$E$3<C$4,DATEDIF(Assets!$E$3,C$4,"m"),0))))/12,0))*INDEX(Countries!$C$2:$C$5,MATCH(Assets!$B$3,Countries!$A$2:$A$5,0)),0) -> 3355000 | D7: =IF(AND(D$3>=1,D$3<=Inputs!$B$11,OR(Assets!$G$3="",D$4<Assets!$G$3)),Assets!$C$3*(Assets!$D$3*(1+MIN(INDEX(Countries!$F$2:$F$5,MATCH(Assets!$B$3,Countries!$A$2:$A$5,0)),MAX(INDEX(Countries!$E$2:$E$5,MATCH(Assets!$B$3,Countries!$A$2:$A$5,0)),INDEX(Countries!$D$2:$D$5,MATCH(Assets!$B$3,Countries!$A$2:$A$5,0)))))^(D$3-1)*MAX(0,MIN(1,YEARFRAC(D$4,MIN(Assets!$E$3,EDATE(D$4,12)),1)*(Assets!$E$3>D$4)))+Assets!$F$3*(1+MIN(INDEX(Countries!$F$2:$F$5,MATCH(Assets!$B$3,Countries!$A$2:$A$5,0)),MAX(INDEX(Countries!$E$2:$E$5,MATCH(Assets!$B$3,Countries!$A$2:$A$5,0)),INDEX(Countries!$D$2:$D$5,MATCH(Assets!$B$3,Countries!$A$2:$A$5,0)))))^(D$3-1)*IF(Assets!$E$3<EDATE(D$4,12),(Inputs!$B$13*MAX(0,MIN(12,DATEDIF(MAX(Assets!$E$3,D$4),EDATE(D$4,12),"m")))+(1-Inputs!$B$13)*MAX(0,MAX(0,MIN(12,DATEDIF(MAX(Assets!$E$3,D$4),EDATE(D$4,12),"m")))-MAX(0,Inputs!$B$12-IF(Assets!$E$3<D$4,DATEDIF(Assets!$E$3,D$4,"m"),0))))/12,0))*INDEX(Countries!$C$2:$C$5,MATCH(Assets!$B$3,Countries!$A$2:$A$5,0)),0) -> 3118633 | E7: =IF(AND(E$3>=1,E$3<=Inputs!$B$11,OR(Assets!$G$3="",E$4<Assets!$G$3)),Assets!$C$3*(Assets!$D$3*(1+MIN(INDEX(Countries!$F$2:$F$5,MATCH(Assets!$B$3,Countries!$A$2:$A$5,0)),MAX(INDEX(Countries!$E$2:$E$5,MATCH(Assets!$B$3,Countries!$A$2:$A$5,0)),INDEX(Countries!$D$2:$D$5,MATCH(Assets!$B$3,Countries!$A$2:$A$5,0)))))^(E$3-1)*MAX(0,MIN(1,YEARFRAC(E$4,MIN(Assets!$E$3,EDATE(E$4,12)),1)*(Assets!$E$3>E$4)))+Assets!$F$3*(1+MIN(INDEX(Countries!$F$2:$F$5,MATCH(Assets!$B$3,Countries!$A$2:$A$5,0)),MAX(INDEX(Countries!$E$2:$E$5,MATCH(Assets!$B$3,Countries!$A$2:$A$5,0)),INDEX(Countries!$D$2:$D$5,MATCH(Assets!$B$3,Countries!$A$2:$A$5,0)))))^(E$3-1)*IF(Assets!$E$3<EDATE(E$4,12),(Inputs!$B$13*MAX(0,MIN(12,DATEDIF(MAX(Assets!$E$3,E$4),EDATE(E$4,12),"m")))+(1-Inputs!$B$13)*MAX(0,MAX(0,MIN(12,DATEDIF(MAX(Assets!$E$3,E$4),EDATE(E$4,12),"m")))-MAX(0,Inputs!$B$12-IF(Assets!$E$3<E$4,DATEDIF(Assets!$E$3,E$4,"m"),0))))/12,0))*INDEX(Countries!$C$2:$C$5,MATCH(Assets!$B$3,Countries!$A$2:$A$5,0)),0) -> 3058249.2 | F7: =IF(AND(F$3>=1,F$3<=Inputs!$B$11,OR(Assets!$G$3="",F$4<Assets!$G$3)),Assets!$C$3*(Assets!$D$3*(1+MIN(INDEX(Countries!$F$2:$F$5,MATCH(Assets!$B$3,Countries!$A$2:$A$5,0)),MAX(INDEX(Countries!$E$2:$E$5,MATCH(Assets!$B$3,Countries!$A$2:$A$5,0)),INDEX(Countries!$D$2:$D$5,MATCH(Assets!$B$3,Countries!$A$2:$A$5,0)))))^(F$3-1)*MAX(0,MIN(1,YEARFRAC(F$4,MIN(Assets!$E$3,EDATE(F$4,12)),1)*(Assets!$E$3>F$4)))+Assets!$F$3*(1+MIN(INDEX(Countries!$F$2:$F$5,MATCH(Assets!$B$3,Countries!$A$2:$A$5,0)),MAX(INDEX(Countries!$E$2:$E$5,MATCH(Assets!$B$3,Countries!$A$2:$A$5,0)),INDEX(Countries!$D$2:$D$5,MATCH(Assets!$B$3,Countries!$A$2:$A$5,0)))))^(F$3-1)*IF(Assets!$E$3<EDATE(F$4,12),(Inputs!$B$13*MAX(0,MIN(12,DATEDIF(MAX(Assets!$E$3,F$4),EDATE(F$4,12),"m")))+(1-Inputs!$B$13)*MAX(0,MAX(0,MIN(12,DATEDIF(MAX(Assets!$E$3,F$4),EDATE(F$4,12),"m")))-MAX(0,Inputs!$B$12-IF(Assets!$E$3<F$4,DATEDIF(Assets!$E$3,F$4,"m"),0))))/12,0))*INDEX(Countries!$C$2:$C$5,MATCH(Assets!$B$3,Countries!$A$2:$A$5,0)),0) -> 0 | G7: =IF(AND(G$3>=1,G$3<=Inputs!$B$11,OR(Assets!$G$3="",G$4<Assets!$G$3)),Assets!$C$3*(Assets!$D$3*(1+MIN(INDEX(Countries!$F$2:$F$5,MATCH(Assets!$B$3,Countries!$A$2:$A$5,0)),MAX(INDEX(Countries!$E$2:$E$5,MATCH(Assets!$B$3,Countries!$A$2:$A$5,0)),INDEX(Countries!$D$2:$D$5,MATCH(Assets!$B$3,Countries!$A$2:$A$5,0)))))^(G$3-1)*MAX(0,MIN(1,YEARFRAC(G$4,MIN(Assets!$E$3,EDATE(G$4,12)),1)*(Assets!$E$3>G$4)))+Assets!$F$3*(1+MIN(INDEX(Countries!$F$2:$F$5,MATCH(Assets!$B$3,Countries!$A$2:$A$5,0)),MAX(INDEX(Countries!$E$2:$E$5,MATCH(Assets!$B$3,Countries!$A$2:$A$5,0)),INDEX(Countries!$D$2:$D$5,MATCH(Assets!$B$3,Countries!$A$2:$A$5,0)))))^(G$3-1)*IF(Assets!$E$3<EDATE(G$4,12),(Inputs!$B$13*MAX(0,MIN(12,DATEDIF(MAX(Assets!$E$3,G$4),EDATE(G$4,12),"m")))+(1-Inputs!$B$13)*MAX(0,MAX(0,MIN(12,DATEDIF(MAX(Assets!$E$3,G$4),EDATE(G$4,12),"m")))-MAX(0,Inputs!$B$12-IF(Assets!$E$3<G$4,DATEDIF(Assets!$E$3,G$4,"m"),0))))/12,0))*INDEX(Countries!$C$2:$C$5,MATCH(Assets!$B$3,Countries!$A$2:$A$5,0)),0) -> 0 | H7: =IF(AND(H$3>=1,H$3<=Inputs!$B$11,OR(Assets!$G$3="",H$4<Assets!$G$3)),Assets!$C$3*(Assets!$D$3*(1+MIN(INDEX(Countries!$F$2:$F$5,MATCH(Assets!$B$3,Countries!$A$2:$A$5,0)),MAX(INDEX(Countries!$E$2:$E$5,MATCH(Assets!$B$3,Countries!$A$2:$A$5,0)),INDEX(Countries!$D$2:$D$5,MATCH(Assets!$B$3,Countries!$A$2:$A$5,0)))))^(H$3-1)*MAX(0,MIN(1,YEARFRAC(H$4,MIN(Assets!$E$3,EDATE(H$4,12)),1)*(Assets!$E$3>H$4)))+Assets!$F$3*(1+MIN(INDEX(Countries!$F$2:$F$5,MATCH(Assets!$B$3,Countries!$A$2:$A$5,0)),MAX(INDEX(Countries!$E$2:$E$5,MATCH(Assets!$B$3,Countries!$A$2:$A$5,0)),INDEX(Countries!$D$2:$D$5,MATCH(Assets!$B$3,Countries!$A$2:$A$5,0)))))^(H$3-1)*IF(Assets!$E$3<EDATE(H$4,12),(Inputs!$B$13*MAX(0,MIN(12,DATEDIF(MAX(Assets!$E$3,H$4),EDATE(H$4,12),"m")))+(1-Inputs!$B$13)*MAX(0,MAX(0,MIN(12,DATEDIF(MAX(Assets!$E$3,H$4),EDATE(H$4,12),"m")))-MAX(0,Inputs!$B$12-IF(Assets!$E$3<H$4,DATEDIF(Assets!$E$3,H$4,"m"),0))))/12,0))*INDEX(Countries!$C$2:$C$5,MATCH(Assets!$B$3,Countries!$A$2:$A$5,0)),0) -> 0 | I7: =IF(AND(I$3>=1,I$3<=Inputs!$B$11,OR(Assets!$G$3="",I$4<Assets!$G$3)),Assets!$C$3*(Assets!$D$3*(1+MIN(INDEX(Countries!$F$2:$F$5,MATCH(Assets!$B$3,Countries!$A$2:$A$5,0)),MAX(INDEX(Countries!$E$2:$E$5,MATCH(Assets!$B$3,Countries!$A$2:$A$5,0)),INDEX(Countries!$D$2:$D$5,MATCH(Assets!$B$3,Countries!$A$2:$A$5,0)))))^(I$3-1)*MAX(0,MIN(1,YEARFRAC(I$4,MIN(Assets!$E$3,EDATE(I$4,12)),1)*(Assets!$E$3>I$4)))+Assets!$F$3*(1+MIN(INDEX(Countries!$F$2:$F$5,MATCH(Assets!$B$3,Countries!$A$2:$A$5,0)),MAX(INDEX(Countries!$E$2:$E$5,MATCH(Assets!$B$3,Countries!$A$2:$A$5,0)),INDEX(Countries!$D$2:$D$5,MATCH(Assets!$B$3,Countries!$A$2:$A$5,0)))))^(I$3-1)*IF(Assets!$E$3<EDATE(I$4,12),(Inputs!$B$13*MAX(0,MIN(12,DATEDIF(MAX(Assets!$E$3,I$4),EDATE(I$4,12),"m")))+(1-Inputs!$B$13)*MAX(0,MAX(0,MIN(12,DATEDIF(MAX(Assets!$E$3,I$4),EDATE(I$4,12),"m")))-MAX(0,Inputs!$B$12-IF(Assets!$E$3<I$4,DATEDIF(Assets!$E$3,I$4,"m"),0))))/12,0))*INDEX(Countries!$C$2:$C$5,MATCH(Assets!$B$3,Countries!$A$2:$A$5,0)),0) -> 0 | ... L7: =IF(AND(L$3>=1,L$3<=Inputs!$B$11,OR(Assets!$G$3="",L$4<Assets!$G$3)),Assets!$C$3*(Assets!$D$3*(1+MIN(INDEX(Countries!$F$2:$F$5,MATCH(Assets!$B$3,Countries!$A$2:$A$5,0)),MAX(INDEX(Countries!$E$2:$E$5,MATCH(Assets!$B$3,Countries!$A$2:$A$5,0)),INDEX(Countries!$D$2:$D$5,MATCH(Assets!$B$3,Countries!$A$2:$A$5,0)))))^(L$3-1)*MAX(0,MIN(1,YEARFRAC(L$4,MIN(Assets!$E$3,EDATE(L$4,12)),1)*(Assets!$E$3>L$4)))+Assets!$F$3*(1+MIN(INDEX(Countries!$F$2:$F$5,MATCH(Assets!$B$3,Countries!$A$2:$A$5,0)),MAX(INDEX(Countries!$E$2:$E$5,MATCH(Assets!$B$3,Countries!$A$2:$A$5,0)),INDEX(Countries!$D$2:$D$5,MATCH(Assets!$B$3,Countries!$A$2:$A$5,0)))))^(L$3-1)*IF(Assets!$E$3<EDATE(L$4,12),(Inputs!$B$13*MAX(0,MIN(12,DATEDIF(MAX(Assets!$E$3,L$4),EDATE(L$4,12),"m")))+(1-Inputs!$B$13)*MAX(0,MAX(0,MIN(12,DATEDIF(MAX(Assets!$E$3,L$4),EDATE(L$4,12),"m")))-MAX(0,Inputs!$B$12-IF(Assets!$E$3<L$4,DATEDIF(Assets!$E$3,L$4,"m"),0))))/12,0))*INDEX(Countries!$C$2:$C$5,MATCH(Assets!$B$3,Countries!$A$2:$A$5,0)),0) -> 0
A8: Leipzig Park · disposal (EUR) | B8: =IF(AND(Assets!$G$3<>"",Assets!$G$3>=B$4,Assets!$G$3<EDATE(B$4,12)),Assets!$C$3*Assets!$F$3*(1+MIN(INDEX(Countries!$F$2:$F$5,MATCH(Assets!$B$3,Countries!$A$2:$A$5,0)),MAX(INDEX(Countries!$E$2:$E$5,MATCH(Assets!$B$3,Countries!$A$2:$A$5,0)),INDEX(Countries!$D$2:$D$5,MATCH(Assets!$B$3,Countries!$A$2:$A$5,0)))))^(B$3-1)*INDEX(Countries!$C$2:$C$5,MATCH(Assets!$B$3,Countries!$A$2:$A$5,0))/Assets!$H$3,0) -> 0 | C8: =IF(AND(Assets!$G$3<>"",Assets!$G$3>=C$4,Assets!$G$3<EDATE(C$4,12)),Assets!$C$3*Assets!$F$3*(1+MIN(INDEX(Countries!$F$2:$F$5,MATCH(Assets!$B$3,Countries!$A$2:$A$5,0)),MAX(INDEX(Countries!$E$2:$E$5,MATCH(Assets!$B$3,Countries!$A$2:$A$5,0)),INDEX(Countries!$D$2:$D$5,MATCH(Assets!$B$3,Countries!$A$2:$A$5,0)))))^(C$3-1)*INDEX(Countries!$C$2:$C$5,MATCH(Assets!$B$3,Countries!$A$2:$A$5,0))/Assets!$H$3,0) -> 0 | D8: =IF(AND(Assets!$G$3<>"",Assets!$G$3>=D$4,Assets!$G$3<EDATE(D$4,12)),Assets!$C$3*Assets!$F$3*(1+MIN(INDEX(Countries!$F$2:$F$5,MATCH(Assets!$B$3,Countries!$A$2:$A$5,0)),MAX(INDEX(Countries!$E$2:$E$5,MATCH(Assets!$B$3,Countries!$A$2:$A$5,0)),INDEX(Countries!$D$2:$D$5,MATCH(Assets!$B$3,Countries!$A$2:$A$5,0)))))^(D$3-1)*INDEX(Countries!$C$2:$C$5,MATCH(Assets!$B$3,Countries!$A$2:$A$5,0))/Assets!$H$3,0) -> 0 | E8: =IF(AND(Assets!$G$3<>"",Assets!$G$3>=E$4,Assets!$G$3<EDATE(E$4,12)),Assets!$C$3*Assets!$F$3*(1+MIN(INDEX(Countries!$F$2:$F$5,MATCH(Assets!$B$3,Countries!$A$2:$A$5,0)),MAX(INDEX(Countries!$E$2:$E$5,MATCH(Assets!$B$3,Countries!$A$2:$A$5,0)),INDEX(Countries!$D$2:$D$5,MATCH(Assets!$B$3,Countries!$A$2:$A$5,0)))))^(E$3-1)*INDEX(Countries!$C$2:$C$5,MATCH(Assets!$B$3,Countries!$A$2:$A$5,0))/Assets!$H$3,0) -> 73515605 | F8: =IF(AND(Assets!$G$3<>"",Assets!$G$3>=F$4,Assets!$G$3<EDATE(F$4,12)),Assets!$C$3*Assets!$F$3*(1+MIN(INDEX(Countries!$F$2:$F$5,MATCH(Assets!$B$3,Countries!$A$2:$A$5,0)),MAX(INDEX(Countries!$E$2:$E$5,MATCH(Assets!$B$3,Countries!$A$2:$A$5,0)),INDEX(Countries!$D$2:$D$5,MATCH(Assets!$B$3,Countries!$A$2:$A$5,0)))))^(F$3-1)*INDEX(Countries!$C$2:$C$5,MATCH(Assets!$B$3,Countries!$A$2:$A$5,0))/Assets!$H$3,0) -> 0 | G8: =IF(AND(Assets!$G$3<>"",Assets!$G$3>=G$4,Assets!$G$3<EDATE(G$4,12)),Assets!$C$3*Assets!$F$3*(1+MIN(INDEX(Countries!$F$2:$F$5,MATCH(Assets!$B$3,Countries!$A$2:$A$5,0)),MAX(INDEX(Countries!$E$2:$E$5,MATCH(Assets!$B$3,Countries!$A$2:$A$5,0)),INDEX(Countries!$D$2:$D$5,MATCH(Assets!$B$3,Countries!$A$2:$A$5,0)))))^(G$3-1)*INDEX(Countries!$C$2:$C$5,MATCH(Assets!$B$3,Countries!$A$2:$A$5,0))/Assets!$H$3,0) -> 0 | H8: =IF(AND(Assets!$G$3<>"",Assets!$G$3>=H$4,Assets!$G$3<EDATE(H$4,12)),Assets!$C$3*Assets!$F$3*(1+MIN(INDEX(Countries!$F$2:$F$5,MATCH(Assets!$B$3,Countries!$A$2:$A$5,0)),MAX(INDEX(Countries!$E$2:$E$5,MATCH(Assets!$B$3,Countries!$A$2:$A$5,0)),INDEX(Countries!$D$2:$D$5,MATCH(Assets!$B$3,Countries!$A$2:$A$5,0)))))^(H$3-1)*INDEX(Countries!$C$2:$C$5,MATCH(Assets!$B$3,Countries!$A$2:$A$5,0))/Assets!$H$3,0) -> 0 | I8: =IF(AND(Assets!$G$3<>"",Assets!$G$3>=I$4,Assets!$G$3<EDATE(I$4,12)),Assets!$C$3*Assets!$F$3*(1+MIN(INDEX(Countries!$F$2:$F$5,MATCH(Assets!$B$3,Countries!$A$2:$A$5,0)),MAX(INDEX(Countries!$E$2:$E$5,MATCH(Assets!$B$3,Countries!$A$2:$A$5,0)),INDEX(Countries!$D$2:$D$5,MATCH(Assets!$B$3,Countries!$A$2:$A$5,0)))))^(I$3-1)*INDEX(Countries!$C$2:$C$5,MATCH(Assets!$B$3,Countries!$A$2:$A$5,0))/Assets!$H$3,0) -> 0 | ... L8: =IF(AND(Assets!$G$3<>"",Assets!$G$3>=L$4,Assets!$G$3<EDATE(L$4,12)),Assets!$C$3*Assets!$F$3*(1+MIN(INDEX(Countries!$F$2:$F$5,MATCH(Assets!$B$3,Countries!$A$2:$A$5,0)),MAX(INDEX(Countries!$E$2:$E$5,MATCH(Assets!$B$3,Countries!$A$2:$A$5,0)),INDEX(Countries!$D$2:$D$5,MATCH(Assets!$B$3,Countries!$A$2:$A$5,0)))))^(L$3-1)*INDEX(Countries!$C$2:$C$5,MATCH(Assets!$B$3,Countries!$A$2:$A$5,0))/Assets!$H$3,0) -> 0
A9: Warsaw West · rent (EUR) | B9: =IF(AND(B$3>=1,B$3<=Inputs!$B$11,OR(Assets!$G$4="",B$4<Assets!$G$4)),Assets!$C$4*(Assets!$D$4*(1+MIN(INDEX(Countries!$F$2:$F$5,MATCH(Assets!$B$4,Countries!$A$2:$A$5,0)),MAX(INDEX(Countries!$E$2:$E$5,MATCH(Assets!$B$4,Countries!$A$2:$A$5,0)),INDEX(Countries!$D$2:$D$5,MATCH(Assets!$B$4,Countries!$A$2:$A$5,0)))))^(B$3-1)*MAX(0,MIN(1,YEARFRAC(B$4,MIN(Assets!$E$4,EDATE(B$4,12)),1)*(Assets!$E$4>B$4)))+Assets!$F$4*(1+MIN(INDEX(Countries!$F$2:$F$5,MATCH(Assets!$B$4,Countries!$A$2:$A$5,0)),MAX(INDEX(Countries!$E$2:$E$5,MATCH(Assets!$B$4,Countries!$A$2:$A$5,0)),INDEX(Countries!$D$2:$D$5,MATCH(Assets!$B$4,Countries!$A$2:$A$5,0)))))^(B$3-1)*IF(Assets!$E$4<EDATE(B$4,12),(Inputs!$B$13*MAX(0,MIN(12,DATEDIF(MAX(Assets!$E$4,B$4),EDATE(B$4,12),"m")))+(1-Inputs!$B$13)*MAX(0,MAX(0,MIN(12,DATEDIF(MAX(Assets!$E$4,B$4),EDATE(B$4,12),"m")))-MAX(0,Inputs!$B$12-IF(Assets!$E$4<B$4,DATEDIF(Assets!$E$4,B$4,"m"),0))))/12,0))*INDEX(Countries!$C$2:$C$5,MATCH(Assets!$B$4,Countries!$A$2:$A$5,0)),0) -> 0 | C9: =IF(AND(C$3>=1,C$3<=Inputs!$B$11,OR(Assets!$G$4="",C$4<Assets!$G$4)),Assets!$C$4*(Assets!$D$4*(1+MIN(INDEX(Countries!$F$2:$F$5,MATCH(Assets!$B$4,Countries!$A$2:$A$5,0)),MAX(INDEX(Countries!$E$2:$E$5,MATCH(Assets!$B$4,Countries!$A$2:$A$5,0)),INDEX(Countries!$D$2:$D$5,MATCH(Assets!$B$4,Countries!$A$2:$A$5,0)))))^(C$3-1)*MAX(0,MIN(1,YEARFRAC(C$4,MIN(Assets!$E$4,EDATE(C$4,12)),1)*(Assets!$E$4>C$4)))+Assets!$F$4*(1+MIN(INDEX(Countries!$F$2:$F$5,MATCH(Assets!$B$4,Countries!$A$2:$A$5,0)),MAX(INDEX(Countries!$E$2:$E$5,MATCH(Assets!$B$4,Countries!$A$2:$A$5,0)),INDEX(Countries!$D$2:$D$5,MATCH(Assets!$B$4,Countries!$A$2:$A$5,0)))))^(C$3-1)*IF(Assets!$E$4<EDATE(C$4,12),(Inputs!$B$13*MAX(0,MIN(12,DATEDIF(MAX(Assets!$E$4,C$4),EDATE(C$4,12),"m")))+(1-Inputs!$B$13)*MAX(0,MAX(0,MIN(12,DATEDIF(MAX(Assets!$E$4,C$4),EDATE(C$4,12),"m")))-MAX(0,Inputs!$B$12-IF(Assets!$E$4<C$4,DATEDIF(Assets!$E$4,C$4,"m"),0))))/12,0))*INDEX(Countries!$C$2:$C$5,MATCH(Assets!$B$4,Countries!$A$2:$A$5,0)),0) -> 4333680 | D9: =IF(AND(D$3>=1,D$3<=Inputs!$B$11,OR(Assets!$G$4="",D$4<Assets!$G$4)),Assets!$C$4*(Assets!$D$4*(1+MIN(INDEX(Countries!$F$2:$F$5,MATCH(Assets!$B$4,Countries!$A$2:$A$5,0)),MAX(INDEX(Countries!$E$2:$E$5,MATCH(Assets!$B$4,Countries!$A$2:$A$5,0)),INDEX(Countries!$D$2:$D$5,MATCH(Assets!$B$4,Countries!$A$2:$A$5,0)))))^(D$3-1)*MAX(0,MIN(1,YEARFRAC(D$4,MIN(Assets!$E$4,EDATE(D$4,12)),1)*(Assets!$E$4>D$4)))+Assets!$F$4*(1+MIN(INDEX(Countries!$F$2:$F$5,MATCH(Assets!$B$4,Countries!$A$2:$A$5,0)),MAX(INDEX(Countries!$E$2:$E$5,MATCH(Assets!$B$4,Countries!$A$2:$A$5,0)),INDEX(Countries!$D$2:$D$5,MATCH(Assets!$B$4,Countries!$A$2:$A$5,0)))))^(D$3-1)*IF(Assets!$E$4<EDATE(D$4,12),(Inputs!$B$13*MAX(0,MIN(12,DATEDIF(MAX(Assets!$E$4,D$4),EDATE(D$4,12),"m")))+(1-Inputs!$B$13)*MAX(0,MAX(0,MIN(12,DATEDIF(MAX(Assets!$E$4,D$4),EDATE(D$4,12),"m")))-MAX(0,Inputs!$B$12-IF(Assets!$E$4<D$4,DATEDIF(Assets!$E$4,D$4,"m"),0))))/12,0))*INDEX(Countries!$C$2:$C$5,MATCH(Assets!$B$4,Countries!$A$2:$A$5,0)),0) -> 4507027.2 | E9: =IF(AND(E$3>=1,E$3<=Inputs!$B$11,OR(Assets!$G$4="",E$4<Assets!$G$4)),Assets!$C$4*(Assets!$D$4*(1+MIN(INDEX(Countries!$F$2:$F$5,MATCH(Assets!$B$4,Countries!$A$2:$A$5,0)),MAX(INDEX(Countries!$E$2:$E$5,MATCH(Assets!$B$4,Countries!$A$2:$A$5,0)),INDEX(Countries!$D$2:$D$5,MATCH(Assets!$B$4,Countries!$A$2:$A$5,0)))))^(E$3-1)*MAX(0,MIN(1,YEARFRAC(E$4,MIN(Assets!$E$4,EDATE(E$4,12)),1)*(Assets!$E$4>E$4)))+Assets!$F$4*(1+MIN(INDEX(Countries!$F$2:$F$5,MATCH(Assets!$B$4,Countries!$A$2:$A$5,0)),MAX(INDEX(Countries!$E$2:$E$5,MATCH(Assets!$B$4,Countries!$A$2:$A$5,0)),INDEX(Countries!$D$2:$D$5,MATCH(Assets!$B$4,Countries!$A$2:$A$5,0)))))^(E$3-1)*IF(Assets!$E$4<EDATE(E$4,12),(Inputs!$B$13*MAX(0,MIN(12,DATEDIF(MAX(Assets!$E$4,E$4),EDATE(E$4,12),"m")))+(1-Inputs!$B$13)*MAX(0,MAX(0,MIN(12,DATEDIF(MAX(Assets!$E$4,E$4),EDATE(E$4,12),"m")))-MAX(0,Inputs!$B$12-IF(Assets!$E$4<E$4,DATEDIF(Assets!$E$4,E$4,"m"),0))))/12,0))*INDEX(Countries!$C$2:$C$5,MATCH(Assets!$B$4,Countries!$A$2:$A$5,0)),0) -> 4687308.3 | F9: =IF(AND(F$3>=1,F$3<=Inputs!$B$11,OR(Assets!$G$4="",F$4<Assets!$G$4)),Assets!$C$4*(Assets!$D$4*(1+MIN(INDEX(Countries!$F$2:$F$5,MATCH(Assets!$B$4,Countries!$A$2:$A$5,0)),MAX(INDEX(Countries!$E$2:$E$5,MATCH(Assets!$B$4,Countries!$A$2:$A$5,0)),INDEX(Countries!$D$2:$D$5,MATCH(Assets!$B$4,Countries!$A$2:$A$5,0)))))^(F$3-1)*MAX(0,MIN(1,YEARFRAC(F$4,MIN(Assets!$E$4,EDATE(F$4,12)),1)*(Assets!$E$4>F$4)))+Assets!$F$4*(1+MIN(INDEX(Countries!$F$2:$F$5,MATCH(Assets!$B$4,Countries!$A$2:$A$5,0)),MAX(INDEX(Countries!$E$2:$E$5,MATCH(Assets!$B$4,Countries!$A$2:$A$5,0)),INDEX(Countries!$D$2:$D$5,MATCH(Assets!$B$4,Countries!$A$2:$A$5,0)))))^(F$3-1)*IF(Assets!$E$4<EDATE(F$4,12),(Inputs!$B$13*MAX(0,MIN(12,DATEDIF(MAX(Assets!$E$4,F$4),EDATE(F$4,12),"m")))+(1-Inputs!$B$13)*MAX(0,MAX(0,MIN(12,DATEDIF(MAX(Assets!$E$4,F$4),EDATE(F$4,12),"m")))-MAX(0,Inputs!$B$12-IF(Assets!$E$4<F$4,DATEDIF(Assets!$E$4,F$4,"m"),0))))/12,0))*INDEX(Countries!$C$2:$C$5,MATCH(Assets!$B$4,Countries!$A$2:$A$5,0)),0) -> 3978946.8 | G9: =IF(AND(G$3>=1,G$3<=Inputs!$B$11,OR(Assets!$G$4="",G$4<Assets!$G$4)),Assets!$C$4*(Assets!$D$4*(1+MIN(INDEX(Countries!$F$2:$F$5,MATCH(Assets!$B$4,Countries!$A$2:$A$5,0)),MAX(INDEX(Countries!$E$2:$E$5,MATCH(Assets!$B$4,Countries!$A$2:$A$5,0)),INDEX(Countries!$D$2:$D$5,MATCH(Assets!$B$4,Countries!$A$2:$A$5,0)))))^(G$3-1)*MAX(0,MIN(1,YEARFRAC(G$4,MIN(Assets!$E$4,EDATE(G$4,12)),1)*(Assets!$E$4>G$4)))+Assets!$F$4*(1+MIN(INDEX(Countries!$F$2:$F$5,MATCH(Assets!$B$4,Countries!$A$2:$A$5,0)),MAX(INDEX(Countries!$E$2:$E$5,MATCH(Assets!$B$4,Countries!$A$2:$A$5,0)),INDEX(Countries!$D$2:$D$5,MATCH(Assets!$B$4,Countries!$A$2:$A$5,0)))))^(G$3-1)*IF(Assets!$E$4<EDATE(G$4,12),(Inputs!$B$13*MAX(0,MIN(12,DATEDIF(MAX(Assets!$E$4,G$4),EDATE(G$4,12),"m")))+(1-Inputs!$B$13)*MAX(0,MAX(0,MIN(12,DATEDIF(MAX(Assets!$E$4,G$4),EDATE(G$4,12),"m")))-MAX(0,Inputs!$B$12-IF(Assets!$E$4<G$4,DATEDIF(Assets!$E$4,G$4,"m"),0))))/12,0))*INDEX(Countries!$C$2:$C$5,MATCH(Assets!$B$4,Countries!$A$2:$A$5,0)),0) -> 4913799 | H9: =IF(AND(H$3>=1,H$3<=Inputs!$B$11,OR(Assets!$G$4="",H$4<Assets!$G$4)),Assets!$C$4*(Assets!$D$4*(1+MIN(INDEX(Countries!$F$2:$F$5,MATCH(Assets!$B$4,Countries!$A$2:$A$5,0)),MAX(INDEX(Countries!$E$2:$E$5,MATCH(Assets!$B$4,Countries!$A$2:$A$5,0)),INDEX(Countries!$D$2:$D$5,MATCH(Assets!$B$4,Countries!$A$2:$A$5,0)))))^(H$3-1)*MAX(0,MIN(1,YEARFRAC(H$4,MIN(Assets!$E$4,EDATE(H$4,12)),1)*(Assets!$E$4>H$4)))+Assets!$F$4*(1+MIN(INDEX(Countries!$F$2:$F$5,MATCH(Assets!$B$4,Countries!$A$2:$A$5,0)),MAX(INDEX(Countries!$E$2:$E$5,MATCH(Assets!$B$4,Countries!$A$2:$A$5,0)),INDEX(Countries!$D$2:$D$5,MATCH(Assets!$B$4,Countries!$A$2:$A$5,0)))))^(H$3-1)*IF(Assets!$E$4<EDATE(H$4,12),(Inputs!$B$13*MAX(0,MIN(12,DATEDIF(MAX(Assets!$E$4,H$4),EDATE(H$4,12),"m")))+(1-Inputs!$B$13)*MAX(0,MAX(0,MIN(12,DATEDIF(MAX(Assets!$E$4,H$4),EDATE(H$4,12),"m")))-MAX(0,Inputs!$B$12-IF(Assets!$E$4<H$4,DATEDIF(Assets!$E$4,H$4,"m"),0))))/12,0))*INDEX(Countries!$C$2:$C$5,MATCH(Assets!$B$4,Countries!$A$2:$A$5,0)),0) -> 5678167.8 | I9: =IF(AND(I$3>=1,I$3<=Inputs!$B$11,OR(Assets!$G$4="",I$4<Assets!$G$4)),Assets!$C$4*(Assets!$D$4*(1+MIN(INDEX(Countries!$F$2:$F$5,MATCH(Assets!$B$4,Countries!$A$2:$A$5,0)),MAX(INDEX(Countries!$E$2:$E$5,MATCH(Assets!$B$4,Countries!$A$2:$A$5,0)),INDEX(Countries!$D$2:$D$5,MATCH(Assets!$B$4,Countries!$A$2:$A$5,0)))))^(I$3-1)*MAX(0,MIN(1,YEARFRAC(I$4,MIN(Assets!$E$4,EDATE(I$4,12)),1)*(Assets!$E$4>I$4)))+Assets!$F$4*(1+MIN(INDEX(Countries!$F$2:$F$5,MATCH(Assets!$B$4,Countries!$A$2:$A$5,0)),MAX(INDEX(Countries!$E$2:$E$5,MATCH(Assets!$B$4,Countries!$A$2:$A$5,0)),INDEX(Countries!$D$2:$D$5,MATCH(Assets!$B$4,Countries!$A$2:$A$5,0)))))^(I$3-1)*IF(Assets!$E$4<EDATE(I$4,12),(Inputs!$B$13*MAX(0,MIN(12,DATEDIF(MAX(Assets!$E$4,I$4),EDATE(I$4,12),"m")))+(1-Inputs!$B$13)*MAX(0,MAX(0,MIN(12,DATEDIF(MAX(Assets!$E$4,I$4),EDATE(I$4,12),"m")))-MAX(0,Inputs!$B$12-IF(Assets!$E$4<I$4,DATEDIF(Assets!$E$4,I$4,"m"),0))))/12,0))*INDEX(Countries!$C$2:$C$5,MATCH(Assets!$B$4,Countries!$A$2:$A$5,0)),0) -> 5905294.5 | ... L9: =IF(AND(L$3>=1,L$3<=Inputs!$B$11,OR(Assets!$G$4="",L$4<Assets!$G$4)),Assets!$C$4*(Assets!$D$4*(1+MIN(INDEX(Countries!$F$2:$F$5,MATCH(Assets!$B$4,Countries!$A$2:$A$5,0)),MAX(INDEX(Countries!$E$2:$E$5,MATCH(Assets!$B$4,Countries!$A$2:$A$5,0)),INDEX(Countries!$D$2:$D$5,MATCH(Assets!$B$4,Countries!$A$2:$A$5,0)))))^(L$3-1)*MAX(0,MIN(1,YEARFRAC(L$4,MIN(Assets!$E$4,EDATE(L$4,12)),1)*(Assets!$E$4>L$4)))+Assets!$F$4*(1+MIN(INDEX(Countries!$F$2:$F$5,MATCH(Assets!$B$4,Countries!$A$2:$A$5,0)),MAX(INDEX(Countries!$E$2:$E$5,MATCH(Assets!$B$4,Countries!$A$2:$A$5,0)),INDEX(Countries!$D$2:$D$5,MATCH(Assets!$B$4,Countries!$A$2:$A$5,0)))))^(L$3-1)*IF(Assets!$E$4<EDATE(L$4,12),(Inputs!$B$13*MAX(0,MIN(12,DATEDIF(MAX(Assets!$E$4,L$4),EDATE(L$4,12),"m")))+(1-Inputs!$B$13)*MAX(0,MAX(0,MIN(12,DATEDIF(MAX(Assets!$E$4,L$4),EDATE(L$4,12),"m")))-MAX(0,Inputs!$B$12-IF(Assets!$E$4<L$4,DATEDIF(Assets!$E$4,L$4,"m"),0))))/12,0))*INDEX(Countries!$C$2:$C$5,MATCH(Assets!$B$4,Countries!$A$2:$A$5,0)),0) -> 0
A10: Warsaw West · disposal (EUR) | B10: =IF(AND(Assets!$G$4<>"",Assets!$G$4>=B$4,Assets!$G$4<EDATE(B$4,12)),Assets!$C$4*Assets!$F$4*(1+MIN(INDEX(Countries!$F$2:$F$5,MATCH(Assets!$B$4,Countries!$A$2:$A$5,0)),MAX(INDEX(Countries!$E$2:$E$5,MATCH(Assets!$B$4,Countries!$A$2:$A$5,0)),INDEX(Countries!$D$2:$D$5,MATCH(Assets!$B$4,Countries!$A$2:$A$5,0)))))^(B$3-1)*INDEX(Countries!$C$2:$C$5,MATCH(Assets!$B$4,Countries!$A$2:$A$5,0))/Assets!$H$4,0) -> 0 | C10: =IF(AND(Assets!$G$4<>"",Assets!$G$4>=C$4,Assets!$G$4<EDATE(C$4,12)),Assets!$C$4*Assets!$F$4*(1+MIN(INDEX(Countries!$F$2:$F$5,MATCH(Assets!$B$4,Countries!$A$2:$A$5,0)),MAX(INDEX(Countries!$E$2:$E$5,MATCH(Assets!$B$4,Countries!$A$2:$A$5,0)),INDEX(Countries!$D$2:$D$5,MATCH(Assets!$B$4,Countries!$A$2:$A$5,0)))))^(C$3-1)*INDEX(Countries!$C$2:$C$5,MATCH(Assets!$B$4,Countries!$A$2:$A$5,0))/Assets!$H$4,0) -> 0 | D10: =IF(AND(Assets!$G$4<>"",Assets!$G$4>=D$4,Assets!$G$4<EDATE(D$4,12)),Assets!$C$4*Assets!$F$4*(1+MIN(INDEX(Countries!$F$2:$F$5,MATCH(Assets!$B$4,Countries!$A$2:$A$5,0)),MAX(INDEX(Countries!$E$2:$E$5,MATCH(Assets!$B$4,Countries!$A$2:$A$5,0)),INDEX(Countries!$D$2:$D$5,MATCH(Assets!$B$4,Countries!$A$2:$A$5,0)))))^(D$3-1)*INDEX(Countries!$C$2:$C$5,MATCH(Assets!$B$4,Countries!$A$2:$A$5,0))/Assets!$H$4,0) -> 0 | E10: =IF(AND(Assets!$G$4<>"",Assets!$G$4>=E$4,Assets!$G$4<EDATE(E$4,12)),Assets!$C$4*Assets!$F$4*(1+MIN(INDEX(Countries!$F$2:$F$5,MATCH(Assets!$B$4,Countries!$A$2:$A$5,0)),MAX(INDEX(Countries!$E$2:$E$5,MATCH(Assets!$B$4,Countries!$A$2:$A$5,0)),INDEX(Countries!$D$2:$D$5,MATCH(Assets!$B$4,Countries!$A$2:$A$5,0)))))^(E$3-1)*INDEX(Countries!$C$2:$C$5,MATCH(Assets!$B$4,Countries!$A$2:$A$5,0))/Assets!$H$4,0) -> 0 | F10: =IF(AND(Assets!$G$4<>"",Assets!$G$4>=F$4,Assets!$G$4<EDATE(F$4,12)),Assets!$C$4*Assets!$F$4*(1+MIN(INDEX(Countries!$F$2:$F$5,MATCH(Assets!$B$4,Countries!$A$2:$A$5,0)),MAX(INDEX(Countries!$E$2:$E$5,MATCH(Assets!$B$4,Countries!$A$2:$A$5,0)),INDEX(Countries!$D$2:$D$5,MATCH(Assets!$B$4,Countries!$A$2:$A$5,0)))))^(F$3-1)*INDEX(Countries!$C$2:$C$5,MATCH(Assets!$B$4,Countries!$A$2:$A$5,0))/Assets!$H$4,0) -> 0 | G10: =IF(AND(Assets!$G$4<>"",Assets!$G$4>=G$4,Assets!$G$4<EDATE(G$4,12)),Assets!$C$4*Assets!$F$4*(1+MIN(INDEX(Countries!$F$2:$F$5,MATCH(Assets!$B$4,Countries!$A$2:$A$5,0)),MAX(INDEX(Countries!$E$2:$E$5,MATCH(Assets!$B$4,Countries!$A$2:$A$5,0)),INDEX(Countries!$D$2:$D$5,MATCH(Assets!$B$4,Countries!$A$2:$A$5,0)))))^(G$3-1)*INDEX(Countries!$C$2:$C$5,MATCH(Assets!$B$4,Countries!$A$2:$A$5,0))/Assets!$H$4,0) -> 0 | H10: =IF(AND(Assets!$G$4<>"",Assets!$G$4>=H$4,Assets!$G$4<EDATE(H$4,12)),Assets!$C$4*Assets!$F$4*(1+MIN(INDEX(Countries!$F$2:$F$5,MATCH(Assets!$B$4,Countries!$A$2:$A$5,0)),MAX(INDEX(Countries!$E$2:$E$5,MATCH(Assets!$B$4,Countries!$A$2:$A$5,0)),INDEX(Countries!$D$2:$D$5,MATCH(Assets!$B$4,Countries!$A$2:$A$5,0)))))^(H$3-1)*INDEX(Countries!$C$2:$C$5,MATCH(Assets!$B$4,Countries!$A$2:$A$5,0))/Assets!$H$4,0) -> 0 | I10: =IF(AND(Assets!$G$4<>"",Assets!$G$4>=I$4,Assets!$G$4<EDATE(I$4,12)),Assets!$C$4*Assets!$F$4*(1+MIN(INDEX(Countries!$F$2:$F$5,MATCH(Assets!$B$4,Countries!$A$2:$A$5,0)),MAX(INDEX(Countries!$E$2:$E$5,MATCH(Assets!$B$4,Countries!$A$2:$A$5,0)),INDEX(Countries!$D$2:$D$5,MATCH(Assets!$B$4,Countries!$A$2:$A$5,0)))))^(I$3-1)*INDEX(Countries!$C$2:$C$5,MATCH(Assets!$B$4,Countries!$A$2:$A$5,0))/Assets!$H$4,0) -> 0 | ... L10: =IF(AND(Assets!$G$4<>"",Assets!$G$4>=L$4,Assets!$G$4<EDATE(L$4,12)),Assets!$C$4*Assets!$F$4*(1+MIN(INDEX(Countries!$F$2:$F$5,MATCH(Assets!$B$4,Countries!$A$2:$A$5,0)),MAX(INDEX(Countries!$E$2:$E$5,MATCH(Assets!$B$4,Countries!$A$2:$A$5,0)),INDEX(Countries!$D$2:$D$5,MATCH(Assets!$B$4,Countries!$A$2:$A$5,0)))))^(L$3-1)*INDEX(Countries!$C$2:$C$5,MATCH(Assets!$B$4,Countries!$A$2:$A$5,0))/Assets!$H$4,0) -> 0
A11: Lodz Hub · rent (EUR) | B11: =IF(AND(B$3>=1,B$3<=Inputs!$B$11,OR(Assets!$G$5="",B$4<Assets!$G$5)),Assets!$C$5*(Assets!$D$5*(1+MIN(INDEX(Countries!$F$2:$F$5,MATCH(Assets!$B$5,Countries!$A$2:$A$5,0)),MAX(INDEX(Countries!$E$2:$E$5,MATCH(Assets!$B$5,Countries!$A$2:$A$5,0)),INDEX(Countries!$D$2:$D$5,MATCH(Assets!$B$5,Countries!$A$2:$A$5,0)))))^(B$3-1)*MAX(0,MIN(1,YEARFRAC(B$4,MIN(Assets!$E$5,EDATE(B$4,12)),1)*(Assets!$E$5>B$4)))+Assets!$F$5*(1+MIN(INDEX(Countries!$F$2:$F$5,MATCH(Assets!$B$5,Countries!$A$2:$A$5,0)),MAX(INDEX(Countries!$E$2:$E$5,MATCH(Assets!$B$5,Countries!$A$2:$A$5,0)),INDEX(Countries!$D$2:$D$5,MATCH(Assets!$B$5,Countries!$A$2:$A$5,0)))))^(B$3-1)*IF(Assets!$E$5<EDATE(B$4,12),(Inputs!$B$13*MAX(0,MIN(12,DATEDIF(MAX(Assets!$E$5,B$4),EDATE(B$4,12),"m")))+(1-Inputs!$B$13)*MAX(0,MAX(0,MIN(12,DATEDIF(MAX(Assets!$E$5,B$4),EDATE(B$4,12),"m")))-MAX(0,Inputs!$B$12-IF(Assets!$E$5<B$4,DATEDIF(Assets!$E$5,B$4,"m"),0))))/12,0))*INDEX(Countries!$C$2:$C$5,MATCH(Assets!$B$5,Countries!$A$2:$A$5,0)),0) -> 0 | C11: =IF(AND(C$3>=1,C$3<=Inputs!$B$11,OR(Assets!$G$5="",C$4<Assets!$G$5)),Assets!$C$5*(Assets!$D$5*(1+MIN(INDEX(Countries!$F$2:$F$5,MATCH(Assets!$B$5,Countries!$A$2:$A$5,0)),MAX(INDEX(Countries!$E$2:$E$5,MATCH(Assets!$B$5,Countries!$A$2:$A$5,0)),INDEX(Countries!$D$2:$D$5,MATCH(Assets!$B$5,Countries!$A$2:$A$5,0)))))^(C$3-1)*MAX(0,MIN(1,YEARFRAC(C$4,MIN(Assets!$E$5,EDATE(C$4,12)),1)*(Assets!$E$5>C$4)))+Assets!$F$5*(1+MIN(INDEX(Countries!$F$2:$F$5,MATCH(Assets!$B$5,Countries!$A$2:$A$5,0)),MAX(INDEX(Countries!$E$2:$E$5,MATCH(Assets!$B$5,Countries!$A$2:$A$5,0)),INDEX(Countries!$D$2:$D$5,MATCH(Assets!$B$5,Countries!$A$2:$A$5,0)))))^(C$3-1)*IF(Assets!$E$5<EDATE(C$4,12),(Inputs!$B$13*MAX(0,MIN(12,DATEDIF(MAX(Assets!$E$5,C$4),EDATE(C$4,12),"m")))+(1-Inputs!$B$13)*MAX(0,MAX(0,MIN(12,DATEDIF(MAX(Assets!$E$5,C$4),EDATE(C$4,12),"m")))-MAX(0,Inputs!$B$12-IF(Assets!$E$5<C$4,DATEDIF(Assets!$E$5,C$4,"m"),0))))/12,0))*INDEX(Countries!$C$2:$C$5,MATCH(Assets!$B$5,Countries!$A$2:$A$5,0)),0) -> 3047427.9 | D11: =IF(AND(D$3>=1,D$3<=Inputs!$B$11,OR(Assets!$G$5="",D$4<Assets!$G$5)),Assets!$C$5*(Assets!$D$5*(1+MIN(INDEX(Countries!$F$2:$F$5,MATCH(Assets!$B$5,Countries!$A$2:$A$5,0)),MAX(INDEX(Countries!$E$2:$E$5,MATCH(Assets!$B$5,Countries!$A$2:$A$5,0)),INDEX(Countries!$D$2:$D$5,MATCH(Assets!$B$5,Countries!$A$2:$A$5,0)))))^(D$3-1)*MAX(0,MIN(1,YEARFRAC(D$4,MIN(Assets!$E$5,EDATE(D$4,12)),1)*(Assets!$E$5>D$4)))+Assets!$F$5*(1+MIN(INDEX(Countries!$F$2:$F$5,MATCH(Assets!$B$5,Countries!$A$2:$A$5,0)),MAX(INDEX(Countries!$E$2:$E$5,MATCH(Assets!$B$5,Countries!$A$2:$A$5,0)),INDEX(Countries!$D$2:$D$5,MATCH(Assets!$B$5,Countries!$A$2:$A$5,0)))))^(D$3-1)*IF(Assets!$E$5<EDATE(D$4,12),(Inputs!$B$13*MAX(0,MIN(12,DATEDIF(MAX(Assets!$E$5,D$4),EDATE(D$4,12),"m")))+(1-Inputs!$B$13)*MAX(0,MAX(0,MIN(12,DATEDIF(MAX(Assets!$E$5,D$4),EDATE(D$4,12),"m")))-MAX(0,Inputs!$B$12-IF(Assets!$E$5<D$4,DATEDIF(Assets!$E$5,D$4,"m"),0))))/12,0))*INDEX(Countries!$C$2:$C$5,MATCH(Assets!$B$5,Countries!$A$2:$A$5,0)),0) -> 2456353.9 | E11: =IF(AND(E$3>=1,E$3<=Inputs!$B$11,OR(Assets!$G$5="",E$4<Assets!$G$5)),Assets!$C$5*(Assets!$D$5*(1+MIN(INDEX(Countries!$F$2:$F$5,MATCH(Assets!$B$5,Countries!$A$2:$A$5,0)),MAX(INDEX(Countries!$E$2:$E$5,MATCH(Assets!$B$5,Countries!$A$2:$A$5,0)),INDEX(Countries!$D$2:$D$5,MATCH(Assets!$B$5,Countries!$A$2:$A$5,0)))))^(E$3-1)*MAX(0,MIN(1,YEARFRAC(E$4,MIN(Assets!$E$5,EDATE(E$4,12)),1)*(Assets!$E$5>E$4)))+Assets!$F$5*(1+MIN(INDEX(Countries!$F$2:$F$5,MATCH(Assets!$B$5,Countries!$A$2:$A$5,0)),MAX(INDEX(Countries!$E$2:$E$5,MATCH(Assets!$B$5,Countries!$A$2:$A$5,0)),INDEX(Countries!$D$2:$D$5,MATCH(Assets!$B$5,Countries!$A$2:$A$5,0)))))^(E$3-1)*IF(Assets!$E$5<EDATE(E$4,12),(Inputs!$B$13*MAX(0,MIN(12,DATEDIF(MAX(Assets!$E$5,E$4),EDATE(E$4,12),"m")))+(1-Inputs!$B$13)*MAX(0,MAX(0,MIN(12,DATEDIF(MAX(Assets!$E$5,E$4),EDATE(E$4,12),"m")))-MAX(0,Inputs!$B$12-IF(Assets!$E$5<E$4,DATEDIF(Assets!$E$5,E$4,"m"),0))))/12,0))*INDEX(Countries!$C$2:$C$5,MATCH(Assets!$B$5,Countries!$A$2:$A$5,0)),0) -> 3649440.1 | F11: =IF(AND(F$3>=1,F$3<=Inputs!$B$11,OR(Assets!$G$5="",F$4<Assets!$G$5)),Assets!$C$5*(Assets!$D$5*(1+MIN(INDEX(Countries!$F$2:$F$5,MATCH(Assets!$B$5,Countries!$A$2:$A$5,0)),MAX(INDEX(Countries!$E$2:$E$5,MATCH(Assets!$B$5,Countries!$A$2:$A$5,0)),INDEX(Countries!$D$2:$D$5,MATCH(Assets!$B$5,Countries!$A$2:$A$5,0)))))^(F$3-1)*MAX(0,MIN(1,YEARFRAC(F$4,MIN(Assets!$E$5,EDATE(F$4,12)),1)*(Assets!$E$5>F$4)))+Assets!$F$5*(1+MIN(INDEX(Countries!$F$2:$F$5,MATCH(Assets!$B$5,Countries!$A$2:$A$5,0)),MAX(INDEX(Countries!$E$2:$E$5,MATCH(Assets!$B$5,Countries!$A$2:$A$5,0)),INDEX(Countries!$D$2:$D$5,MATCH(Assets!$B$5,Countries!$A$2:$A$5,0)))))^(F$3-1)*IF(Assets!$E$5<EDATE(F$4,12),(Inputs!$B$13*MAX(0,MIN(12,DATEDIF(MAX(Assets!$E$5,F$4),EDATE(F$4,12),"m")))+(1-Inputs!$B$13)*MAX(0,MAX(0,MIN(12,DATEDIF(MAX(Assets!$E$5,F$4),EDATE(F$4,12),"m")))-MAX(0,Inputs!$B$12-IF(Assets!$E$5<F$4,DATEDIF(Assets!$E$5,F$4,"m"),0))))/12,0))*INDEX(Countries!$C$2:$C$5,MATCH(Assets!$B$5,Countries!$A$2:$A$5,0)),0) -> 3795417.7 | G11: =IF(AND(G$3>=1,G$3<=Inputs!$B$11,OR(Assets!$G$5="",G$4<Assets!$G$5)),Assets!$C$5*(Assets!$D$5*(1+MIN(INDEX(Countries!$F$2:$F$5,MATCH(Assets!$B$5,Countries!$A$2:$A$5,0)),MAX(INDEX(Countries!$E$2:$E$5,MATCH(Assets!$B$5,Countries!$A$2:$A$5,0)),INDEX(Countries!$D$2:$D$5,MATCH(Assets!$B$5,Countries!$A$2:$A$5,0)))))^(G$3-1)*MAX(0,MIN(1,YEARFRAC(G$4,MIN(Assets!$E$5,EDATE(G$4,12)),1)*(Assets!$E$5>G$4)))+Assets!$F$5*(1+MIN(INDEX(Countries!$F$2:$F$5,MATCH(Assets!$B$5,Countries!$A$2:$A$5,0)),MAX(INDEX(Countries!$E$2:$E$5,MATCH(Assets!$B$5,Countries!$A$2:$A$5,0)),INDEX(Countries!$D$2:$D$5,MATCH(Assets!$B$5,Countries!$A$2:$A$5,0)))))^(G$3-1)*IF(Assets!$E$5<EDATE(G$4,12),(Inputs!$B$13*MAX(0,MIN(12,DATEDIF(MAX(Assets!$E$5,G$4),EDATE(G$4,12),"m")))+(1-Inputs!$B$13)*MAX(0,MAX(0,MIN(12,DATEDIF(MAX(Assets!$E$5,G$4),EDATE(G$4,12),"m")))-MAX(0,Inputs!$B$12-IF(Assets!$E$5<G$4,DATEDIF(Assets!$E$5,G$4,"m"),0))))/12,0))*INDEX(Countries!$C$2:$C$5,MATCH(Assets!$B$5,Countries!$A$2:$A$5,0)),0) -> 3947234.4 | H11: =IF(AND(H$3>=1,H$3<=Inputs!$B$11,OR(Assets!$G$5="",H$4<Assets!$G$5)),Assets!$C$5*(Assets!$D$5*(1+MIN(INDEX(Countries!$F$2:$F$5,MATCH(Assets!$B$5,Countries!$A$2:$A$5,0)),MAX(INDEX(Countries!$E$2:$E$5,MATCH(Assets!$B$5,Countries!$A$2:$A$5,0)),INDEX(Countries!$D$2:$D$5,MATCH(Assets!$B$5,Countries!$A$2:$A$5,0)))))^(H$3-1)*MAX(0,MIN(1,YEARFRAC(H$4,MIN(Assets!$E$5,EDATE(H$4,12)),1)*(Assets!$E$5>H$4)))+Assets!$F$5*(1+MIN(INDEX(Countries!$F$2:$F$5,MATCH(Assets!$B$5,Countries!$A$2:$A$5,0)),MAX(INDEX(Countries!$E$2:$E$5,MATCH(Assets!$B$5,Countries!$A$2:$A$5,0)),INDEX(Countries!$D$2:$D$5,MATCH(Assets!$B$5,Countries!$A$2:$A$5,0)))))^(H$3-1)*IF(Assets!$E$5<EDATE(H$4,12),(Inputs!$B$13*MAX(0,MIN(12,DATEDIF(MAX(Assets!$E$5,H$4),EDATE(H$4,12),"m")))+(1-Inputs!$B$13)*MAX(0,MAX(0,MIN(12,DATEDIF(MAX(Assets!$E$5,H$4),EDATE(H$4,12),"m")))-MAX(0,Inputs!$B$12-IF(Assets!$E$5<H$4,DATEDIF(Assets!$E$5,H$4,"m"),0))))/12,0))*INDEX(Countries!$C$2:$C$5,MATCH(Assets!$B$5,Countries!$A$2:$A$5,0)),0) -> 4105123.8 | I11: =IF(AND(I$3>=1,I$3<=Inputs!$B$11,OR(Assets!$G$5="",I$4<Assets!$G$5)),Assets!$C$5*(Assets!$D$5*(1+MIN(INDEX(Countries!$F$2:$F$5,MATCH(Assets!$B$5,Countries!$A$2:$A$5,0)),MAX(INDEX(Countries!$E$2:$E$5,MATCH(Assets!$B$5,Countries!$A$2:$A$5,0)),INDEX(Countries!$D$2:$D$5,MATCH(Assets!$B$5,Countries!$A$2:$A$5,0)))))^(I$3-1)*MAX(0,MIN(1,YEARFRAC(I$4,MIN(Assets!$E$5,EDATE(I$4,12)),1)*(Assets!$E$5>I$4)))+Assets!$F$5*(1+MIN(INDEX(Countries!$F$2:$F$5,MATCH(Assets!$B$5,Countries!$A$2:$A$5,0)),MAX(INDEX(Countries!$E$2:$E$5,MATCH(Assets!$B$5,Countries!$A$2:$A$5,0)),INDEX(Countries!$D$2:$D$5,MATCH(Assets!$B$5,Countries!$A$2:$A$5,0)))))^(I$3-1)*IF(Assets!$E$5<EDATE(I$4,12),(Inputs!$B$13*MAX(0,MIN(12,DATEDIF(MAX(Assets!$E$5,I$4),EDATE(I$4,12),"m")))+(1-Inputs!$B$13)*MAX(0,MAX(0,MIN(12,DATEDIF(MAX(Assets!$E$5,I$4),EDATE(I$4,12),"m")))-MAX(0,Inputs!$B$12-IF(Assets!$E$5<I$4,DATEDIF(Assets!$E$5,I$4,"m"),0))))/12,0))*INDEX(Countries!$C$2:$C$5,MATCH(Assets!$B$5,Countries!$A$2:$A$5,0)),0) -> 4269328.7 | ... L11: =IF(AND(L$3>=1,L$3<=Inputs!$B$11,OR(Assets!$G$5="",L$4<Assets!$G$5)),Assets!$C$5*(Assets!$D$5*(1+MIN(INDEX(Countries!$F$2:$F$5,MATCH(Assets!$B$5,Countries!$A$2:$A$5,0)),MAX(INDEX(Countries!$E$2:$E$5,MATCH(Assets!$B$5,Countries!$A$2:$A$5,0)),INDEX(Countries!$D$2:$D$5,MATCH(Assets!$B$5,Countries!$A$2:$A$5,0)))))^(L$3-1)*MAX(0,MIN(1,YEARFRAC(L$4,MIN(Assets!$E$5,EDATE(L$4,12)),1)*(Assets!$E$5>L$4)))+Assets!$F$5*(1+MIN(INDEX(Countries!$F$2:$F$5,MATCH(Assets!$B$5,Countries!$A$2:$A$5,0)),MAX(INDEX(Countries!$E$2:$E$5,MATCH(Assets!$B$5,Countries!$A$2:$A$5,0)),INDEX(Countries!$D$2:$D$5,MATCH(Assets!$B$5,Countries!$A$2:$A$5,0)))))^(L$3-1)*IF(Assets!$E$5<EDATE(L$4,12),(Inputs!$B$13*MAX(0,MIN(12,DATEDIF(MAX(Assets!$E$5,L$4),EDATE(L$4,12),"m")))+(1-Inputs!$B$13)*MAX(0,MAX(0,MIN(12,DATEDIF(MAX(Assets!$E$5,L$4),EDATE(L$4,12),"m")))-MAX(0,Inputs!$B$12-IF(Assets!$E$5<L$4,DATEDIF(Assets!$E$5,L$4,"m"),0))))/12,0))*INDEX(Countries!$C$2:$C$5,MATCH(Assets!$B$5,Countries!$A$2:$A$5,0)),0) -> 0
A12: Lodz Hub · disposal (EUR) | B12: =IF(AND(Assets!$G$5<>"",Assets!$G$5>=B$4,Assets!$G$5<EDATE(B$4,12)),Assets!$C$5*Assets!$F$5*(1+MIN(INDEX(Countries!$F$2:$F$5,MATCH(Assets!$B$5,Countries!$A$2:$A$5,0)),MAX(INDEX(Countries!$E$2:$E$5,MATCH(Assets!$B$5,Countries!$A$2:$A$5,0)),INDEX(Countries!$D$2:$D$5,MATCH(Assets!$B$5,Countries!$A$2:$A$5,0)))))^(B$3-1)*INDEX(Countries!$C$2:$C$5,MATCH(Assets!$B$5,Countries!$A$2:$A$5,0))/Assets!$H$5,0) -> 0 | C12: =IF(AND(Assets!$G$5<>"",Assets!$G$5>=C$4,Assets!$G$5<EDATE(C$4,12)),Assets!$C$5*Assets!$F$5*(1+MIN(INDEX(Countries!$F$2:$F$5,MATCH(Assets!$B$5,Countries!$A$2:$A$5,0)),MAX(INDEX(Countries!$E$2:$E$5,MATCH(Assets!$B$5,Countries!$A$2:$A$5,0)),INDEX(Countries!$D$2:$D$5,MATCH(Assets!$B$5,Countries!$A$2:$A$5,0)))))^(C$3-1)*INDEX(Countries!$C$2:$C$5,MATCH(Assets!$B$5,Countries!$A$2:$A$5,0))/Assets!$H$5,0) -> 0 | D12: =IF(AND(Assets!$G$5<>"",Assets!$G$5>=D$4,Assets!$G$5<EDATE(D$4,12)),Assets!$C$5*Assets!$F$5*(1+MIN(INDEX(Countries!$F$2:$F$5,MATCH(Assets!$B$5,Countries!$A$2:$A$5,0)),MAX(INDEX(Countries!$E$2:$E$5,MATCH(Assets!$B$5,Countries!$A$2:$A$5,0)),INDEX(Countries!$D$2:$D$5,MATCH(Assets!$B$5,Countries!$A$2:$A$5,0)))))^(D$3-1)*INDEX(Countries!$C$2:$C$5,MATCH(Assets!$B$5,Countries!$A$2:$A$5,0))/Assets!$H$5,0) -> 0 | E12: =IF(AND(Assets!$G$5<>"",Assets!$G$5>=E$4,Assets!$G$5<EDATE(E$4,12)),Assets!$C$5*Assets!$F$5*(1+MIN(INDEX(Countries!$F$2:$F$5,MATCH(Assets!$B$5,Countries!$A$2:$A$5,0)),MAX(INDEX(Countries!$E$2:$E$5,MATCH(Assets!$B$5,Countries!$A$2:$A$5,0)),INDEX(Countries!$D$2:$D$5,MATCH(Assets!$B$5,Countries!$A$2:$A$5,0)))))^(E$3-1)*INDEX(Countries!$C$2:$C$5,MATCH(Assets!$B$5,Countries!$A$2:$A$5,0))/Assets!$H$5,0) -> 0 | F12: =IF(AND(Assets!$G$5<>"",Assets!$G$5>=F$4,Assets!$G$5<EDATE(F$4,12)),Assets!$C$5*Assets!$F$5*(1+MIN(INDEX(Countries!$F$2:$F$5,MATCH(Assets!$B$5,Countries!$A$2:$A$5,0)),MAX(INDEX(Countries!$E$2:$E$5,MATCH(Assets!$B$5,Countries!$A$2:$A$5,0)),INDEX(Countries!$D$2:$D$5,MATCH(Assets!$B$5,Countries!$A$2:$A$5,0)))))^(F$3-1)*INDEX(Countries!$C$2:$C$5,MATCH(Assets!$B$5,Countries!$A$2:$A$5,0))/Assets!$H$5,0) -> 0 | G12: =IF(AND(Assets!$G$5<>"",Assets!$G$5>=G$4,Assets!$G$5<EDATE(G$4,12)),Assets!$C$5*Assets!$F$5*(1+MIN(INDEX(Countries!$F$2:$F$5,MATCH(Assets!$B$5,Countries!$A$2:$A$5,0)),MAX(INDEX(Countries!$E$2:$E$5,MATCH(Assets!$B$5,Countries!$A$2:$A$5,0)),INDEX(Countries!$D$2:$D$5,MATCH(Assets!$B$5,Countries!$A$2:$A$5,0)))))^(G$3-1)*INDEX(Countries!$C$2:$C$5,MATCH(Assets!$B$5,Countries!$A$2:$A$5,0))/Assets!$H$5,0) -> 0 | H12: =IF(AND(Assets!$G$5<>"",Assets!$G$5>=H$4,Assets!$G$5<EDATE(H$4,12)),Assets!$C$5*Assets!$F$5*(1+MIN(INDEX(Countries!$F$2:$F$5,MATCH(Assets!$B$5,Countries!$A$2:$A$5,0)),MAX(INDEX(Countries!$E$2:$E$5,MATCH(Assets!$B$5,Countries!$A$2:$A$5,0)),INDEX(Countries!$D$2:$D$5,MATCH(Assets!$B$5,Countries!$A$2:$A$5,0)))))^(H$3-1)*INDEX(Countries!$C$2:$C$5,MATCH(Assets!$B$5,Countries!$A$2:$A$5,0))/Assets!$H$5,0) -> 0 | I12: =IF(AND(Assets!$G$5<>"",Assets!$G$5>=I$4,Assets!$G$5<EDATE(I$4,12)),Assets!$C$5*Assets!$F$5*(1+MIN(INDEX(Countries!$F$2:$F$5,MATCH(Assets!$B$5,Countries!$A$2:$A$5,0)),MAX(INDEX(Countries!$E$2:$E$5,MATCH(Assets!$B$5,Countries!$A$2:$A$5,0)),INDEX(Countries!$D$2:$D$5,MATCH(Assets!$B$5,Countries!$A$2:$A$5,0)))))^(I$3-1)*INDEX(Countries!$C$2:$C$5,MATCH(Assets!$B$5,Countries!$A$2:$A$5,0))/Assets!$H$5,0) -> 0 | ... L12: =IF(AND(Assets!$G$5<>"",Assets!$G$5>=L$4,Assets!$G$5<EDATE(L$4,12)),Assets!$C$5*Assets!$F$5*(1+MIN(INDEX(Countries!$F$2:$F$5,MATCH(Assets!$B$5,Countries!$A$2:$A$5,0)),MAX(INDEX(Countries!$E$2:$E$5,MATCH(Assets!$B$5,Countries!$A$2:$A$5,0)),INDEX(Countries!$D$2:$D$5,MATCH(Assets!$B$5,Countries!$A$2:$A$5,0)))))^(L$3-1)*INDEX(Countries!$C$2:$C$5,MATCH(Assets!$B$5,Countries!$A$2:$A$5,0))/Assets!$H$5,0) -> 0
