Workbook

Sheet Fund
A1: HELIX SECONDARIES FUND II – EUR
A3: First close | B3: 46203
A4: Management fee (% of NAV a year) | B4: 0.01
A5: Subscription line bridge (quarters) | B5: 2
A6: Line rate a year | B6: 0.045
A7: Preferred return | B7: 0.08
A8: Carried interest | B8: 0.125
A9: GP catch-up | B9: 1
A10: Reporting date | B10: 48029

Sheet Interests
A1: Interest | B1: Purchase quarter | C1: NAV at purchase (€) | D1: Discount to NAV | E1: Unfunded at purchase (€) | F1: Calls a year (% of unfunded) | G1: Distributions a year (% of NAV) | H1: NAV growth a year | I1: Fund end (quarter)
A2: Buyout 2018 | B2: 1 | C2: 62000000 | D2: 0.12 | E2: 8000000 | F2: 0.3 | G2: 0.18 | H2: 0.06 | I2: 20
A3: Growth 2019 | B3: 2 | C3: 48000000 | D3: 0.18 | E3: 14000000 | F3: 0.35 | G3: 0.12 | H3: 0.08 | I3: 24
A4: Infra 2017 | B4: 2 | C4: 55000000 | D4: 0.07 | E4: 3000000 | F4: 0.4 | G4: 0.1 | H4: 0.04 | I4: 22
A5: Venture 2020 | B5: 4 | C5: 30000000 | D5: 0.3 | E5: 12000000 | F5: 0.3 | G5: 0.06 | H5: 0.1 | I5: 28
A6: RE debt 2019 | B6: 5 | C6: 40000000 | D6: 0.09 | E6: 6000000 | F6: 0.5 | G6: 0.2 | H6: 0.03 | I6: 16
A7: Buyout 2021 | B7: 7 | C7: 70000000 | D7: 0.15 | E7: 25000000 | F7: 0.3 | G7: 0.08 | H7: 0.07 | I7: 30

Sheet Cash Flow
A3: Quarter | B3: 0 | C3: 1 | D3: 2 | E3: 3 | F3: 4 | G3: 5 | H3: 6 | I3: 7 | J3: 8 | K3: 9 | L3: 10 | M3: 11 | N3: 12 | O3: 13 | P3: 14 | Q3: 15 | R3: 16 | S3: 17 | T3: 18 | U3: 19 | V3: 20 | W3: 21 | X3: 22 | Y3: 23 | Z3: 24 | AA3: 25 | AB3: 26 | AC3: 27 | AD3: 28 | AE3: 29 | AF3: 30 | AG3: 31 | AH3: 32
A4: Date | B4: =EOMONTH(Fund!$B$3,3*B$3) -> 46203 | C4: =EOMONTH(Fund!$B$3,3*C$3) -> 46295 | D4: =EOMONTH(Fund!$B$3,3*D$3) -> 46387 | E4: =EOMONTH(Fund!$B$3,3*E$3) -> 46477 | F4: =EOMONTH(Fund!$B$3,3*F$3) -> 46568 | G4: =EOMONTH(Fund!$B$3,3*G$3) -> 46660 | H4: =EOMONTH(Fund!$B$3,3*H$3) -> 46752 | I4: =EOMONTH(Fund!$B$3,3*I$3) -> 46843 | ... AH4: =EOMONTH(Fund!$B$3,3*AH$3) -> 49125
A5: NAV 1 | B5: =IF(B$3=Interests!$B$2,Interests!$C$2,IF(AND(B$3>Interests!$B$2,B$3<Interests!$I$2),0*(1+Interests!$H$2/4)+B7-B8,0)) -> 0 | C5: =IF(C$3=Interests!$B$2,Interests!$C$2,IF(AND(C$3>Interests!$B$2,C$3<Interests!$I$2),B5*(1+Interests!$H$2/4)+C7-C8,0)) -> 62000000 | D5: =IF(D$3=Interests!$B$2,Interests!$C$2,IF(AND(D$3>Interests!$B$2,D$3<Interests!$I$2),C5*(1+Interests!$H$2/4)+D7-D8,0)) -> 60740000 | E5: =IF(E$3=Interests!$B$2,Interests!$C$2,IF(AND(E$3>Interests!$B$2,E$3<Interests!$I$2),D5*(1+Interests!$H$2/4)+E7-E8,0)) -> 59472800 | F5: =IF(F$3=Interests!$B$2,Interests!$C$2,IF(AND(F$3>Interests!$B$2,F$3<Interests!$I$2),E5*(1+Interests!$H$2/4)+F7-F8,0)) -> 58201991 | G5: =IF(G$3=Interests!$B$2,Interests!$C$2,IF(AND(G$3>Interests!$B$2,G$3<Interests!$I$2),F5*(1+Interests!$H$2/4)+G7-G8,0)) -> 56930803 | H5: =IF(H$3=Interests!$B$2,Interests!$C$2,IF(AND(H$3>Interests!$B$2,H$3<Interests!$I$2),G5*(1+Interests!$H$2/4)+H7-H8,0)) -> 55662136 | I5: =IF(I$3=Interests!$B$2,Interests!$C$2,IF(AND(I$3>Interests!$B$2,I$3<Interests!$I$2),H5*(1+Interests!$H$2/4)+I7-I8,0)) -> 54398584 | J5: =IF(J$3=Interests!$B$2,Interests!$C$2,IF(AND(J$3>Interests!$B$2,J$3<Interests!$I$2),I5*(1+Interests!$H$2/4)+J7-J8,0)) -> 53142465 | ... AH5: =IF(AH$3=Interests!$B$2,Interests!$C$2,IF(AND(AH$3>Interests!$B$2,AH$3<Interests!$I$2),AG5*(1+Interests!$H$2/4)+AH7-AH8,0)) -> 0
A6: Unfunded 1 | B6: =IF(B$3=Interests!$B$2,Interests!$E$2,IF(AND(B$3>Interests!$B$2,B$3<Interests!$I$2),0-B7,0)) -> 0 | C6: =IF(C$3=Interests!$B$2,Interests!$E$2,IF(AND(C$3>Interests!$B$2,C$3<Interests!$I$2),B6-C7,0)) -> 8000000 | D6: =IF(D$3=Interests!$B$2,Interests!$E$2,IF(AND(D$3>Interests!$B$2,D$3<Interests!$I$2),C6-D7,0)) -> 7400000 | E6: =IF(E$3=Interests!$B$2,Interests!$E$2,IF(AND(E$3>Interests!$B$2,E$3<Interests!$I$2),D6-E7,0)) -> 6845000 | F6: =IF(F$3=Interests!$B$2,Interests!$E$2,IF(AND(F$3>Interests!$B$2,F$3<Interests!$I$2),E6-F7,0)) -> 6331625 | G6: =IF(G$3=Interests!$B$2,Interests!$E$2,IF(AND(G$3>Interests!$B$2,G$3<Interests!$I$2),F6-G7,0)) -> 5856753.1 | H6: =IF(H$3=Interests!$B$2,Interests!$E$2,IF(AND(H$3>Interests!$B$2,H$3<Interests!$I$2),G6-H7,0)) -> 5417496.6 | I6: =IF(I$3=Interests!$B$2,Interests!$E$2,IF(AND(I$3>Interests!$B$2,I$3<Interests!$I$2),H6-I7,0)) -> 5011184.4 | J6: =IF(J$3=Interests!$B$2,Interests!$E$2,IF(AND(J$3>Interests!$B$2,J$3<Interests!$I$2),I6-J7,0)) -> 4635345.6 | ... AH6: =IF(AH$3=Interests!$B$2,Interests!$E$2,IF(AND(AH$3>Interests!$B$2,AH$3<Interests!$I$2),AG6-AH7,0)) -> 0
A7: Call 1 | B7: =IF(AND(B$3>Interests!$B$2,B$3<Interests!$I$2),0*Interests!$F$2/4,0) -> 0 | C7: =IF(AND(C$3>Interests!$B$2,C$3<Interests!$I$2),B6*Interests!$F$2/4,0) -> 0 | D7: =IF(AND(D$3>Interests!$B$2,D$3<Interests!$I$2),C6*Interests!$F$2/4,0) -> 600000 | E7: =IF(AND(E$3>Interests!$B$2,E$3<Interests!$I$2),D6*Interests!$F$2/4,0) -> 555000 | F7: =IF(AND(F$3>Interests!$B$2,F$3<Interests!$I$2),E6*Interests!$F$2/4,0) -> 513375 | G7: =IF(AND(G$3>Interests!$B$2,G$3<Interests!$I$2),F6*Interests!$F$2/4,0) -> 474871.88 | H7: =IF(AND(H$3>Interests!$B$2,H$3<Interests!$I$2),G6*Interests!$F$2/4,0) -> 439256.48 | I7: =IF(AND(I$3>Interests!$B$2,I$3<Interests!$I$2),H6*Interests!$F$2/4,0) -> 406312.25 | J7: =IF(AND(J$3>Interests!$B$2,J$3<Interests!$I$2),I6*Interests!$F$2/4,0) -> 375838.83 | ... AH7: =IF(AND(AH$3>Interests!$B$2,AH$3<Interests!$I$2),AG6*Interests!$F$2/4,0) -> 0
A8: Distribution 1 | B8: =IF(B$3=Interests!$I$2,0*(1+Interests!$H$2/4)+B7,IF(AND(B$3>Interests!$B$2,B$3<Interests!$I$2),0*Interests!$G$2/4,0)) -> 0 | C8: =IF(C$3=Interests!$I$2,B5*(1+Interests!$H$2/4)+C7,IF(AND(C$3>Interests!$B$2,C$3<Interests!$I$2),B5*Interests!$G$2/4,0)) -> 0 | D8: =IF(D$3=Interests!$I$2,C5*(1+Interests!$H$2/4)+D7,IF(AND(D$3>Interests!$B$2,D$3<Interests!$I$2),C5*Interests!$G$2/4,0)) -> 2790000 | E8: =IF(E$3=Interests!$I$2,D5*(1+Interests!$H$2/4)+E7,IF(AND(E$3>Interests!$B$2,E$3<Interests!$I$2),D5*Interests!$G$2/4,0)) -> 2733300 | F8: =IF(F$3=Interests!$I$2,E5*(1+Interests!$H$2/4)+F7,IF(AND(F$3>Interests!$B$2,F$3<Interests!$I$2),E5*Interests!$G$2/4,0)) -> 2676276 | G8: =IF(G$3=Interests!$I$2,F5*(1+Interests!$H$2/4)+G7,IF(AND(G$3>Interests!$B$2,G$3<Interests!$I$2),F5*Interests!$G$2/4,0)) -> 2619089.6 | H8: =IF(H$3=Interests!$I$2,G5*(1+Interests!$H$2/4)+H7,IF(AND(H$3>Interests!$B$2,H$3<Interests!$I$2),G5*Interests!$G$2/4,0)) -> 2561886.1 | I8: =IF(I$3=Interests!$I$2,H5*(1+Interests!$H$2/4)+I7,IF(AND(I$3>Interests!$B$2,I$3<Interests!$I$2),H5*Interests!$G$2/4,0)) -> 2504796.1 | J8: =IF(J$3=Interests!$I$2,I5*(1+Interests!$H$2/4)+J7,IF(AND(J$3>Interests!$B$2,J$3<Interests!$I$2),I5*Interests!$G$2/4,0)) -> 2447936.3 | ... AH8: =IF(AH$3=Interests!$I$2,AG5*(1+Interests!$H$2/4)+AH7,IF(AND(AH$3>Interests!$B$2,AH$3<Interests!$I$2),AG5*Interests!$G$2/4,0)) -> 0
A9: Purchase 1 | B9: =IF(B$3=Interests!$B$2,Interests!$C$2*(1-Interests!$D$2),0) -> 0 | C9: =IF(C$3=Interests!$B$2,Interests!$C$2*(1-Interests!$D$2),0) -> 54560000 | D9: =IF(D$3=Interests!$B$2,Interests!$C$2*(1-Interests!$D$2),0) -> 0 | E9: =IF(E$3=Interests!$B$2,Interests!$C$2*(1-Interests!$D$2),0) -> 0 | F9: =IF(F$3=Interests!$B$2,Interests!$C$2*(1-Interests!$D$2),0) -> 0 | G9: =IF(G$3=Interests!$B$2,Interests!$C$2*(1-Interests!$D$2),0) -> 0 | H9: =IF(H$3=Interests!$B$2,Interests!$C$2*(1-Interests!$D$2),0) -> 0 | I9: =IF(I$3=Interests!$B$2,Interests!$C$2*(1-Interests!$D$2),0) -> 0 | ... AH9: =IF(AH$3=Interests!$B$2,Interests!$C$2*(1-Interests!$D$2),0) -> 0
A10: NAV 2 | B10: =IF(B$3=Interests!$B$3,Interests!$C$3,IF(AND(B$3>Interests!$B$3,B$3<Interests!$I$3),0*(1+Interests!$H$3/4)+B12-B13,0)) -> 0 | C10: =IF(C$3=Interests!$B$3,Interests!$C$3,IF(AND(C$3>Interests!$B$3,C$3<Interests!$I$3),B10*(1+Interests!$H$3/4)+C12-C13,0)) -> 0 | D10: =IF(D$3=Interests!$B$3,Interests!$C$3,IF(AND(D$3>Interests!$B$3,D$3<Interests!$I$3),C10*(1+Interests!$H$3/4)+D12-D13,0)) -> 48000000 | E10: =IF(E$3=Interests!$B$3,Interests!$C$3,IF(AND(E$3>Interests!$B$3,E$3<Interests!$I$3),D10*(1+Interests!$H$3/4)+E12-E13,0)) -> 48745000 | F10: =IF(F$3=Interests!$B$3,Interests!$C$3,IF(AND(F$3>Interests!$B$3,F$3<Interests!$I$3),E10*(1+Interests!$H$3/4)+F12-F13,0)) -> 49375362 | G10: =IF(G$3=Interests!$B$3,Interests!$C$3,IF(AND(G$3>Interests!$B$3,G$3<Interests!$I$3),F10*(1+Interests!$H$3/4)+G12-G13,0)) -> 49901613 | H10: =IF(H$3=Interests!$B$3,Interests!$C$3,IF(AND(H$3>Interests!$B$3,H$3<Interests!$I$3),G10*(1+Interests!$H$3/4)+H12-H13,0)) -> 50333350 | I10: =IF(I$3=Interests!$B$3,Interests!$C$3,IF(AND(I$3>Interests!$B$3,I$3<Interests!$I$3),H10*(1+Interests!$H$3/4)+I12-I13,0)) -> 50679329 | J10: =IF(J$3=Interests!$B$3,Interests!$C$3,IF(AND(J$3>Interests!$B$3,J$3<Interests!$I$3),I10*(1+Interests!$H$3/4)+J12-J13,0)) -> 50947534 | ... AH10: =IF(AH$3=Interests!$B$3,Interests!$C$3,IF(AND(AH$3>Interests!$B$3,AH$3<Interests!$I$3),AG10*(1+Interests!$H$3/4)+AH12-AH13,0)) -> 0
A11: Unfunded 2 | B11: =IF(B$3=Interests!$B$3,Interests!$E$3,IF(AND(B$3>Interests!$B$3,B$3<Interests!$I$3),0-B12,0)) -> 0 | C11: =IF(C$3=Interests!$B$3,Interests!$E$3,IF(AND(C$3>Interests!$B$3,C$3<Interests!$I$3),B11-C12,0)) -> 0 | D11: =IF(D$3=Interests!$B$3,Interests!$E$3,IF(AND(D$3>Interests!$B$3,D$3<Interests!$I$3),C11-D12,0)) -> 14000000 | E11: =IF(E$3=Interests!$B$3,Interests!$E$3,IF(AND(E$3>Interests!$B$3,E$3<Interests!$I$3),D11-E12,0)) -> 12775000 | F11: =IF(F$3=Interests!$B$3,Interests!$E$3,IF(AND(F$3>Interests!$B$3,F$3<Interests!$I$3),E11-F12,0)) -> 11657188 | G11: =IF(G$3=Interests!$B$3,Interests!$E$3,IF(AND(G$3>Interests!$B$3,G$3<Interests!$I$3),F11-G12,0)) -> 10637184 | H11: =IF(H$3=Interests!$B$3,Interests!$E$3,IF(AND(H$3>Interests!$B$3,H$3<Interests!$I$3),G11-H12,0)) -> 9706430 | I11: =IF(I$3=Interests!$B$3,Interests!$E$3,IF(AND(I$3>Interests!$B$3,I$3<Interests!$I$3),H11-I12,0)) -> 8857117.4 | J11: =IF(J$3=Interests!$B$3,Interests!$E$3,IF(AND(J$3>Interests!$B$3,J$3<Interests!$I$3),I11-J12,0)) -> 8082119.6 | ... AH11: =IF(AH$3=Interests!$B$3,Interests!$E$3,IF(AND(AH$3>Interests!$B$3,AH$3<Interests!$I$3),AG11-AH12,0)) -> 0
A12: Call 2 | B12: =IF(AND(B$3>Interests!$B$3,B$3<Interests!$I$3),0*Interests!$F$3/4,0) -> 0 | C12: =IF(AND(C$3>Interests!$B$3,C$3<Interests!$I$3),B11*Interests!$F$3/4,0) -> 0 | D12: =IF(AND(D$3>Interests!$B$3,D$3<Interests!$I$3),C11*Interests!$F$3/4,0) -> 0 | E12: =IF(AND(E$3>Interests!$B$3,E$3<Interests!$I$3),D11*Interests!$F$3/4,0) -> 1225000 | F12: =IF(AND(F$3>Interests!$B$3,F$3<Interests!$I$3),E11*Interests!$F$3/4,0) -> 1117812.5 | G12: =IF(AND(G$3>Interests!$B$3,G$3<Interests!$I$3),F11*Interests!$F$3/4,0) -> 1020003.9 | H12: =IF(AND(H$3>Interests!$B$3,H$3<Interests!$I$3),G11*Interests!$F$3/4,0) -> 930753.56 | I12: =IF(AND(I$3>Interests!$B$3,I$3<Interests!$I$3),H11*Interests!$F$3/4,0) -> 849312.63 | J12: =IF(AND(J$3>Interests!$B$3,J$3<Interests!$I$3),I11*Interests!$F$3/4,0) -> 774997.77 | ... AH12: =IF(AND(AH$3>Interests!$B$3,AH$3<Interests!$I$3),AG11*Interests!$F$3/4,0) -> 0
A13: Distribution 2 | B13: =IF(B$3=Interests!$I$3,0*(1+Interests!$H$3/4)+B12,IF(AND(B$3>Interests!$B$3,B$3<Interests!$I$3),0*Interests!$G$3/4,0)) -> 0 | C13: =IF(C$3=Interests!$I$3,B10*(1+Interests!$H$3/4)+C12,IF(AND(C$3>Interests!$B$3,C$3<Interests!$I$3),B10*Interests!$G$3/4,0)) -> 0 | D13: =IF(D$3=Interests!$I$3,C10*(1+Interests!$H$3/4)+D12,IF(AND(D$3>Interests!$B$3,D$3<Interests!$I$3),C10*Interests!$G$3/4,0)) -> 0 | E13: =IF(E$3=Interests!$I$3,D10*(1+Interests!$H$3/4)+E12,IF(AND(E$3>Interests!$B$3,E$3<Interests!$I$3),D10*Interests!$G$3/4,0)) -> 1440000 | F13: =IF(F$3=Interests!$I$3,E10*(1+Interests!$H$3/4)+F12,IF(AND(F$3>Interests!$B$3,F$3<Interests!$I$3),E10*Interests!$G$3/4,0)) -> 1462350 | G13: =IF(G$3=Interests!$I$3,F10*(1+Interests!$H$3/4)+G12,IF(AND(G$3>Interests!$B$3,G$3<Interests!$I$3),F10*Interests!$G$3/4,0)) -> 1481260.9 | H13: =IF(H$3=Interests!$I$3,G10*(1+Interests!$H$3/4)+H12,IF(AND(H$3>Interests!$B$3,H$3<Interests!$I$3),G10*Interests!$G$3/4,0)) -> 1497048.4 | I13: =IF(I$3=Interests!$I$3,H10*(1+Interests!$H$3/4)+I12,IF(AND(I$3>Interests!$B$3,I$3<Interests!$I$3),H10*Interests!$G$3/4,0)) -> 1510000.5 | J13: =IF(J$3=Interests!$I$3,I10*(1+Interests!$H$3/4)+J12,IF(AND(J$3>Interests!$B$3,J$3<Interests!$I$3),I10*Interests!$G$3/4,0)) -> 1520379.9 | ... AH13: =IF(AH$3=Interests!$I$3,AG10*(1+Interests!$H$3/4)+AH12,IF(AND(AH$3>Interests!$B$3,AH$3<Interests!$I$3),AG10*Interests!$G$3/4,0)) -> 0
A14: Purchase 2 | B14: =IF(B$3=Interests!$B$3,Interests!$C$3*(1-Interests!$D$3),0) -> 0 | C14: =IF(C$3=Interests!$B$3,Interests!$C$3*(1-Interests!$D$3),0) -> 0 | D14: =IF(D$3=Interests!$B$3,Interests!$C$3*(1-Interests!$D$3),0) -> 39360000 | E14: =IF(E$3=Interests!$B$3,Interests!$C$3*(1-Interests!$D$3),0) -> 0 | F14: =IF(F$3=Interests!$B$3,Interests!$C$3*(1-Interests!$D$3),0) -> 0 | G14: =IF(G$3=Interests!$B$3,Interests!$C$3*(1-Interests!$D$3),0) -> 0 | H14: =IF(H$3=Interests!$B$3,Interests!$C$3*(1-Interests!$D$3),0) -> 0 | I14: =IF(I$3=Interests!$B$3,Interests!$C$3*(1-Interests!$D$3),0) -> 0 | ... AH14: =IF(AH$3=Interests!$B$3,Interests!$C$3*(1-Interests!$D$3),0) -> 0
A15: NAV 3 | B15: =IF(B$3=Interests!$B$4,Interests!$C$4,IF(AND(B$3>Interests!$B$4,B$3<Interests!$I$4),0*(1+Interests!$H$4/4)+B17-B18,0)) -> 0 | C15: =IF(C$3=Interests!$B$4,Interests!$C$4,IF(AND(C$3>Interests!$B$4,C$3<Interests!$I$4),B15*(1+Interests!$H$4/4)+C17-C18,0)) -> 0 | D15: =IF(D$3=Interests!$B$4,Interests!$C$4,IF(AND(D$3>Interests!$B$4,D$3<Interests!$I$4),C15*(1+Interests!$H$4/4)+D17-D18,0)) -> 55000000 | E15: =IF(E$3=Interests!$B$4,Interests!$C$4,IF(AND(E$3>Interests!$B$4,E$3<Interests!$I$4),D15*(1+Interests!$H$4/4)+E17-E18,0)) -> 54475000 | F15: =IF(F$3=Interests!$B$4,Interests!$C$4,IF(AND(F$3>Interests!$B$4,F$3<Interests!$I$4),E15*(1+Interests!$H$4/4)+F17-F18,0)) -> 53927875 | G15: =IF(G$3=Interests!$B$4,Interests!$C$4,IF(AND(G$3>Interests!$B$4,G$3<Interests!$I$4),F15*(1+Interests!$H$4/4)+G17-G18,0)) -> 53361957 | H15: =IF(H$3=Interests!$B$4,Interests!$C$4,IF(AND(H$3>Interests!$B$4,H$3<Interests!$I$4),G15*(1+Interests!$H$4/4)+H17-H18,0)) -> 52780228 | I15: =IF(I$3=Interests!$B$4,Interests!$C$4,IF(AND(I$3>Interests!$B$4,I$3<Interests!$I$4),H15*(1+Interests!$H$4/4)+I17-I18,0)) -> 52185354 | J15: =IF(J$3=Interests!$B$4,Interests!$C$4,IF(AND(J$3>Interests!$B$4,J$3<Interests!$I$4),I15*(1+Interests!$H$4/4)+J17-J18,0)) -> 51579721 | ... AH15: =IF(AH$3=Interests!$B$4,Interests!$C$4,IF(AND(AH$3>Interests!$B$4,AH$3<Interests!$I$4),AG15*(1+Interests!$H$4/4)+AH17-AH18,0)) -> 0
A16: Unfunded 3 | B16: =IF(B$3=Interests!$B$4,Interests!$E$4,IF(AND(B$3>Interests!$B$4,B$3<Interests!$I$4),0-B17,0)) -> 0 | C16: =IF(C$3=Interests!$B$4,Interests!$E$4,IF(AND(C$3>Interests!$B$4,C$3<Interests!$I$4),B16-C17,0)) -> 0 | D16: =IF(D$3=Interests!$B$4,Interests!$E$4,IF(AND(D$3>Interests!$B$4,D$3<Interests!$I$4),C16-D17,0)) -> 3000000 | E16: =IF(E$3=Interests!$B$4,Interests!$E$4,IF(AND(E$3>Interests!$B$4,E$3<Interests!$I$4),D16-E17,0)) -> 2700000 | F16: =IF(F$3=Interests!$B$4,Interests!$E$4,IF(AND(F$3>Interests!$B$4,F$3<Interests!$I$4),E16-F17,0)) -> 2430000 | G16: =IF(G$3=Interests!$B$4,Interests!$E$4,IF(AND(G$3>Interests!$B$4,G$3<Interests!$I$4),F16-G17,0)) -> 2187000 | H16: =IF(H$3=Interests!$B$4,Interests!$E$4,IF(AND(H$3>Interests!$B$4,H$3<Interests!$I$4),G16-H17,0)) -> 1968300 | I16: =IF(I$3=Interests!$B$4,Interests!$E$4,IF(AND(I$3>Interests!$B$4,I$3<Interests!$I$4),H16-I17,0)) -> 1771470 | J16: =IF(J$3=Interests!$B$4,Interests!$E$4,IF(AND(J$3>Interests!$B$4,J$3<Interests!$I$4),I16-J17,0)) -> 1594323 | ... AH16: =IF(AH$3=Interests!$B$4,Interests!$E$4,IF(AND(AH$3>Interests!$B$4,AH$3<Interests!$I$4),AG16-AH17,0)) -> 0
A17: Call 3 | B17: =IF(AND(B$3>Interests!$B$4,B$3<Interests!$I$4),0*Interests!$F$4/4,0) -> 0 | C17: =IF(AND(C$3>Interests!$B$4,C$3<Interests!$I$4),B16*Interests!$F$4/4,0) -> 0 | D17: =IF(AND(D$3>Interests!$B$4,D$3<Interests!$I$4),C16*Interests!$F$4/4,0) -> 0 | E17: =IF(AND(E$3>Interests!$B$4,E$3<Interests!$I$4),D16*Interests!$F$4/4,0) -> 300000 | F17: =IF(AND(F$3>Interests!$B$4,F$3<Interests!$I$4),E16*Interests!$F$4/4,0) -> 270000 | G17: =IF(AND(G$3>Interests!$B$4,G$3<Interests!$I$4),F16*Interests!$F$4/4,0) -> 243000 | H17: =IF(AND(H$3>Interests!$B$4,H$3<Interests!$I$4),G16*Interests!$F$4/4,0) -> 218700 | I17: =IF(AND(I$3>Interests!$B$4,I$3<Interests!$I$4),H16*Interests!$F$4/4,0) -> 196830 | J17: =IF(AND(J$3>Interests!$B$4,J$3<Interests!$I$4),I16*Interests!$F$4/4,0) -> 177147 | ... AH17: =IF(AND(AH$3>Interests!$B$4,AH$3<Interests!$I$4),AG16*Interests!$F$4/4,0) -> 0
A18: Distribution 3 | B18: =IF(B$3=Interests!$I$4,0*(1+Interests!$H$4/4)+B17,IF(AND(B$3>Interests!$B$4,B$3<Interests!$I$4),0*Interests!$G$4/4,0)) -> 0 | C18: =IF(C$3=Interests!$I$4,B15*(1+Interests!$H$4/4)+C17,IF(AND(C$3>Interests!$B$4,C$3<Interests!$I$4),B15*Interests!$G$4/4,0)) -> 0 | D18: =IF(D$3=Interests!$I$4,C15*(1+Interests!$H$4/4)+D17,IF(AND(D$3>Interests!$B$4,D$3<Interests!$I$4),C15*Interests!$G$4/4,0)) -> 0 | E18: =IF(E$3=Interests!$I$4,D15*(1+Interests!$H$4/4)+E17,IF(AND(E$3>Interests!$B$4,E$3<Interests!$I$4),D15*Interests!$G$4/4,0)) -> 1375000 | F18: =IF(F$3=Interests!$I$4,E15*(1+Interests!$H$4/4)+F17,IF(AND(F$3>Interests!$B$4,F$3<Interests!$I$4),E15*Interests!$G$4/4,0)) -> 1361875 | G18: =IF(G$3=Interests!$I$4,F15*(1+Interests!$H$4/4)+G17,IF(AND(G$3>Interests!$B$4,G$3<Interests!$I$4),F15*Interests!$G$4/4,0)) -> 1348196.9 | H18: =IF(H$3=Interests!$I$4,G15*(1+Interests!$H$4/4)+H17,IF(AND(H$3>Interests!$B$4,H$3<Interests!$I$4),G15*Interests!$G$4/4,0)) -> 1334048.9 | I18: =IF(I$3=Interests!$I$4,H15*(1+Interests!$H$4/4)+I17,IF(AND(I$3>Interests!$B$4,I$3<Interests!$I$4),H15*Interests!$G$4/4,0)) -> 1319505.7 | J18: =IF(J$3=Interests!$I$4,I15*(1+Interests!$H$4/4)+J17,IF(AND(J$3>Interests!$B$4,J$3<Interests!$I$4),I15*Interests!$G$4/4,0)) -> 1304633.9 | ... AH18: =IF(AH$3=Interests!$I$4,AG15*(1+Interests!$H$4/4)+AH17,IF(AND(AH$3>Interests!$B$4,AH$3<Interests!$I$4),AG15*Interests!$G$4/4,0)) -> 0
A19: Purchase 3 | B19: =IF(B$3=Interests!$B$4,Interests!$C$4*(1-Interests!$D$4),0) -> 0 | C19: =IF(C$3=Interests!$B$4,Interests!$C$4*(1-Interests!$D$4),0) -> 0 | D19: =IF(D$3=Interests!$B$4,Interests!$C$4*(1-Interests!$D$4),0) -> 51150000 | E19: =IF(E$3=Interests!$B$4,Interests!$C$4*(1-Interests!$D$4),0) -> 0 | F19: =IF(F$3=Interests!$B$4,Interests!$C$4*(1-Interests!$D$4),0) -> 0 | G19: =IF(G$3=Interests!$B$4,Interests!$C$4*(1-Interests!$D$4),0) -> 0 | H19: =IF(H$3=Interests!$B$4,Interests!$C$4*(1-Interests!$D$4),0) -> 0 | I19: =IF(I$3=Interests!$B$4,Interests!$C$4*(1-Interests!$D$4),0) -> 0 | ... AH19: =IF(AH$3=Interests!$B$4,Interests!$C$4*(1-Interests!$D$4),0) -> 0
A20: NAV 4 | B20: =IF(B$3=Interests!$B$5,Interests!$C$5,IF(AND(B$3>Interests!$B$5,B$3<Interests!$I$5),0*(1+Interests!$H$5/4)+B22-B23,0)) -> 0 | C20: =IF(C$3=Interests!$B$5,Interests!$C$5,IF(AND(C$3>Interests!$B$5,C$3<Interests!$I$5),B20*(1+Interests!$H$5/4)+C22-C23,0)) -> 0 | D20: =IF(D$3=Interests!$B$5,Interests!$C$5,IF(AND(D$3>Interests!$B$5,D$3<Interests!$I$5),C20*(1+Interests!$H$5/4)+D22-D23,0)) -> 0 | E20: =IF(E$3=Interests!$B$5,Interests!$C$5,IF(AND(E$3>Interests!$B$5,E$3<Interests!$I$5),D20*(1+Interests!$H$5/4)+E22-E23,0)) -> 0 | F20: =IF(F$3=Interests!$B$5,Interests!$C$5,IF(AND(F$3>Interests!$B$5,F$3<Interests!$I$5),E20*(1+Interests!$H$5/4)+F22-F23,0)) -> 30000000 | G20: =IF(G$3=Interests!$B$5,Interests!$C$5,IF(AND(G$3>Interests!$B$5,G$3<Interests!$I$5),F20*(1+Interests!$H$5/4)+G22-G23,0)) -> 31200000 | H20: =IF(H$3=Interests!$B$5,Interests!$C$5,IF(AND(H$3>Interests!$B$5,H$3<Interests!$I$5),G20*(1+Interests!$H$5/4)+H22-H23,0)) -> 32344500 | I20: =IF(I$3=Interests!$B$5,Interests!$C$5,IF(AND(I$3>Interests!$B$5,I$3<Interests!$I$5),H20*(1+Interests!$H$5/4)+I22-I23,0)) -> 33438008 | J20: =IF(J$3=Interests!$B$5,Interests!$C$5,IF(AND(J$3>Interests!$B$5,J$3<Interests!$I$5),I20*(1+Interests!$H$5/4)+J22-J23,0)) -> 34484695 | ... AH20: =IF(AH$3=Interests!$B$5,Interests!$C$5,IF(AND(AH$3>Interests!$B$5,AH$3<Interests!$I$5),AG20*(1+Interests!$H$5/4)+AH22-AH23,0)) -> 0
A21: Unfunded 4 | B21: =IF(B$3=Interests!$B$5,Interests!$E$5,IF(AND(B$3>Interests!$B$5,B$3<Interests!$I$5),0-B22,0)) -> 0 | C21: =IF(C$3=Interests!$B$5,Interests!$E$5,IF(AND(C$3>Interests!$B$5,C$3<Interests!$I$5),B21-C22,0)) -> 0 | D21: =IF(D$3=Interests!$B$5,Interests!$E$5,IF(AND(D$3>Interests!$B$5,D$3<Interests!$I$5),C21-D22,0)) -> 0 | E21: =IF(E$3=Interests!$B$5,Interests!$E$5,IF(AND(E$3>Interests!$B$5,E$3<Interests!$I$5),D21-E22,0)) -> 0 | F21: =IF(F$3=Interests!$B$5,Interests!$E$5,IF(AND(F$3>Interests!$B$5,F$3<Interests!$I$5),E21-F22,0)) -> 12000000 | G21: =IF(G$3=Interests!$B$5,Interests!$E$5,IF(AND(G$3>Interests!$B$5,G$3<Interests!$I$5),F21-G22,0)) -> 11100000 | H21: =IF(H$3=Interests!$B$5,Interests!$E$5,IF(AND(H$3>Interests!$B$5,H$3<Interests!$I$5),G21-H22,0)) -> 10267500 | I21: =IF(I$3=Interests!$B$5,Interests!$E$5,IF(AND(I$3>Interests!$B$5,I$3<Interests!$I$5),H21-I22,0)) -> 9497437.5 | J21: =IF(J$3=Interests!$B$5,Interests!$E$5,IF(AND(J$3>Interests!$B$5,J$3<Interests!$I$5),I21-J22,0)) -> 8785129.7 | ... AH21: =IF(AH$3=Interests!$B$5,Interests!$E$5,IF(AND(AH$3>Interests!$B$5,AH$3<Interests!$I$5),AG21-AH22,0)) -> 0
A22: Call 4 | B22: =IF(AND(B$3>Interests!$B$5,B$3<Interests!$I$5),0*Interests!$F$5/4,0) -> 0 | C22: =IF(AND(C$3>Interests!$B$5,C$3<Interests!$I$5),B21*Interests!$F$5/4,0) -> 0 | D22: =IF(AND(D$3>Interests!$B$5,D$3<Interests!$I$5),C21*Interests!$F$5/4,0) -> 0 | E22: =IF(AND(E$3>Interests!$B$5,E$3<Interests!$I$5),D21*Interests!$F$5/4,0) -> 0 | F22: =IF(AND(F$3>Interests!$B$5,F$3<Interests!$I$5),E21*Interests!$F$5/4,0) -> 0 | G22: =IF(AND(G$3>Interests!$B$5,G$3<Interests!$I$5),F21*Interests!$F$5/4,0) -> 900000 | H22: =IF(AND(H$3>Interests!$B$5,H$3<Interests!$I$5),G21*Interests!$F$5/4,0) -> 832500 | I22: =IF(AND(I$3>Interests!$B$5,I$3<Interests!$I$5),H21*Interests!$F$5/4,0) -> 770062.5 | J22: =IF(AND(J$3>Interests!$B$5,J$3<Interests!$I$5),I21*Interests!$F$5/4,0) -> 712307.81 | ... AH22: =IF(AND(AH$3>Interests!$B$5,AH$3<Interests!$I$5),AG21*Interests!$F$5/4,0) -> 0
A23: Distribution 4 | B23: =IF(B$3=Interests!$I$5,0*(1+Interests!$H$5/4)+B22,IF(AND(B$3>Interests!$B$5,B$3<Interests!$I$5),0*Interests!$G$5/4,0)) -> 0 | C23: =IF(C$3=Interests!$I$5,B20*(1+Interests!$H$5/4)+C22,IF(AND(C$3>Interests!$B$5,C$3<Interests!$I$5),B20*Interests!$G$5/4,0)) -> 0 | D23: =IF(D$3=Interests!$I$5,C20*(1+Interests!$H$5/4)+D22,IF(AND(D$3>Interests!$B$5,D$3<Interests!$I$5),C20*Interests!$G$5/4,0)) -> 0 | E23: =IF(E$3=Interests!$I$5,D20*(1+Interests!$H$5/4)+E22,IF(AND(E$3>Interests!$B$5,E$3<Interests!$I$5),D20*Interests!$G$5/4,0)) -> 0 | F23: =IF(F$3=Interests!$I$5,E20*(1+Interests!$H$5/4)+F22,IF(AND(F$3>Interests!$B$5,F$3<Interests!$I$5),E20*Interests!$G$5/4,0)) -> 0 | G23: =IF(G$3=Interests!$I$5,F20*(1+Interests!$H$5/4)+G22,IF(AND(G$3>Interests!$B$5,G$3<Interests!$I$5),F20*Interests!$G$5/4,0)) -> 450000 | H23: =IF(H$3=Interests!$I$5,G20*(1+Interests!$H$5/4)+H22,IF(AND(H$3>Interests!$B$5,H$3<Interests!$I$5),G20*Interests!$G$5/4,0)) -> 468000 | I23: =IF(I$3=Interests!$I$5,H20*(1+Interests!$H$5/4)+I22,IF(AND(I$3>Interests!$B$5,I$3<Interests!$I$5),H20*Interests!$G$5/4,0)) -> 485167.5 | J23: =IF(J$3=Interests!$I$5,I20*(1+Interests!$H$5/4)+J22,IF(AND(J$3>Interests!$B$5,J$3<Interests!$I$5),I20*Interests!$G$5/4,0)) -> 501570.11 | ... AH23: =IF(AH$3=Interests!$I$5,AG20*(1+Interests!$H$5/4)+AH22,IF(AND(AH$3>Interests!$B$5,AH$3<Interests!$I$5),AG20*Interests!$G$5/4,0)) -> 0
A24: Purchase 4 | B24: =IF(B$3=Interests!$B$5,Interests!$C$5*(1-Interests!$D$5),0) -> 0 | C24: =IF(C$3=Interests!$B$5,Interests!$C$5*(1-Interests!$D$5),0) -> 0 | D24: =IF(D$3=Interests!$B$5,Interests!$C$5*(1-Interests!$D$5),0) -> 0 | E24: =IF(E$3=Interests!$B$5,Interests!$C$5*(1-Interests!$D$5),0) -> 0 | F24: =IF(F$3=Interests!$B$5,Interests!$C$5*(1-Interests!$D$5),0) -> 21000000 | G24: =IF(G$3=Interests!$B$5,Interests!$C$5*(1-Interests!$D$5),0) -> 0 | H24: =IF(H$3=Interests!$B$5,Interests!$C$5*(1-Interests!$D$5),0) -> 0 | I24: =IF(I$3=Interests!$B$5,Interests!$C$5*(1-Interests!$D$5),0) -> 0 | ... AH24: =IF(AH$3=Interests!$B$5,Interests!$C$5*(1-Interests!$D$5),0) -> 0
A25: NAV 5 | B25: =IF(B$3=Interests!$B$6,Interests!$C$6,IF(AND(B$3>Interests!$B$6,B$3<Interests!$I$6),0*(1+Interests!$H$6/4)+B27-B28,0)) -> 0 | C25: =IF(C$3=Interests!$B$6,Interests!$C$6,IF(AND(C$3>Interests!$B$6,C$3<Interests!$I$6),B25*(1+Interests!$H$6/4)+C27-C28,0)) -> 0 | D25: =IF(D$3=Interests!$B$6,Interests!$C$6,IF(AND(D$3>Interests!$B$6,D$3<Interests!$I$6),C25*(1+Interests!$H$6/4)+D27-D28,0)) -> 0 | E25: =IF(E$3=Interests!$B$6,Interests!$C$6,IF(AND(E$3>Interests!$B$6,E$3<Interests!$I$6),D25*(1+Interests!$H$6/4)+E27-E28,0)) -> 0 | F25: =IF(F$3=Interests!$B$6,Interests!$C$6,IF(AND(F$3>Interests!$B$6,F$3<Interests!$I$6),E25*(1+Interests!$H$6/4)+F27-F28,0)) -> 0 | G25: =IF(G$3=Interests!$B$6,Interests!$C$6,IF(AND(G$3>Interests!$B$6,G$3<Interests!$I$6),F25*(1+Interests!$H$6/4)+G27-G28,0)) -> 40000000 | H25: =IF(H$3=Interests!$B$6,Interests!$C$6,IF(AND(H$3>Interests!$B$6,H$3<Interests!$I$6),G25*(1+Interests!$H$6/4)+H27-H28,0)) -> 39050000 | I25: =IF(I$3=Interests!$B$6,Interests!$C$6,IF(AND(I$3>Interests!$B$6,I$3<Interests!$I$6),H25*(1+Interests!$H$6/4)+I27-I28,0)) -> 38046625 | J25: =IF(J$3=Interests!$B$6,Interests!$C$6,IF(AND(J$3>Interests!$B$6,J$3<Interests!$I$6),I25*(1+Interests!$H$6/4)+J27-J28,0)) -> 37003862 | ... AH25: =IF(AH$3=Interests!$B$6,Interests!$C$6,IF(AND(AH$3>Interests!$B$6,AH$3<Interests!$I$6),AG25*(1+Interests!$H$6/4)+AH27-AH28,0)) -> 0
A26: Unfunded 5 | B26: =IF(B$3=Interests!$B$6,Interests!$E$6,IF(AND(B$3>Interests!$B$6,B$3<Interests!$I$6),0-B27,0)) -> 0 | C26: =IF(C$3=Interests!$B$6,Interests!$E$6,IF(AND(C$3>Interests!$B$6,C$3<Interests!$I$6),B26-C27,0)) -> 0 | D26: =IF(D$3=Interests!$B$6,Interests!$E$6,IF(AND(D$3>Interests!$B$6,D$3<Interests!$I$6),C26-D27,0)) -> 0 | E26: =IF(E$3=Interests!$B$6,Interests!$E$6,IF(AND(E$3>Interests!$B$6,E$3<Interests!$I$6),D26-E27,0)) -> 0 | F26: =IF(F$3=Interests!$B$6,Interests!$E$6,IF(AND(F$3>Interests!$B$6,F$3<Interests!$I$6),E26-F27,0)) -> 0 | G26: =IF(G$3=Interests!$B$6,Interests!$E$6,IF(AND(G$3>Interests!$B$6,G$3<Interests!$I$6),F26-G27,0)) -> 6000000 | H26: =IF(H$3=Interests!$B$6,Interests!$E$6,IF(AND(H$3>Interests!$B$6,H$3<Interests!$I$6),G26-H27,0)) -> 5250000 | I26: =IF(I$3=Interests!$B$6,Interests!$E$6,IF(AND(I$3>Interests!$B$6,I$3<Interests!$I$6),H26-I27,0)) -> 4593750 | J26: =IF(J$3=Interests!$B$6,Interests!$E$6,IF(AND(J$3>Interests!$B$6,J$3<Interests!$I$6),I26-J27,0)) -> 4019531.2 | ... AH26: =IF(AH$3=Interests!$B$6,Interests!$E$6,IF(AND(AH$3>Interests!$B$6,AH$3<Interests!$I$6),AG26-AH27,0)) -> 0
A27: Call 5 | B27: =IF(AND(B$3>Interests!$B$6,B$3<Interests!$I$6),0*Interests!$F$6/4,0) -> 0 | C27: =IF(AND(C$3>Interests!$B$6,C$3<Interests!$I$6),B26*Interests!$F$6/4,0) -> 0 | D27: =IF(AND(D$3>Interests!$B$6,D$3<Interests!$I$6),C26*Interests!$F$6/4,0) -> 0 | E27: =IF(AND(E$3>Interests!$B$6,E$3<Interests!$I$6),D26*Interests!$F$6/4,0) -> 0 | F27: =IF(AND(F$3>Interests!$B$6,F$3<Interests!$I$6),E26*Interests!$F$6/4,0) -> 0 | G27: =IF(AND(G$3>Interests!$B$6,G$3<Interests!$I$6),F26*Interests!$F$6/4,0) -> 0 | H27: =IF(AND(H$3>Interests!$B$6,H$3<Interests!$I$6),G26*Interests!$F$6/4,0) -> 750000 | I27: =IF(AND(I$3>Interests!$B$6,I$3<Interests!$I$6),H26*Interests!$F$6/4,0) -> 656250 | J27: =IF(AND(J$3>Interests!$B$6,J$3<Interests!$I$6),I26*Interests!$F$6/4,0) -> 574218.75 | ... AH27: =IF(AND(AH$3>Interests!$B$6,AH$3<Interests!$I$6),AG26*Interests!$F$6/4,0) -> 0
A28: Distribution 5 | B28: =IF(B$3=Interests!$I$6,0*(1+Interests!$H$6/4)+B27,IF(AND(B$3>Interests!$B$6,B$3<Interests!$I$6),0*Interests!$G$6/4,0)) -> 0 | C28: =IF(C$3=Interests!$I$6,B25*(1+Interests!$H$6/4)+C27,IF(AND(C$3>Interests!$B$6,C$3<Interests!$I$6),B25*Interests!$G$6/4,0)) -> 0 | D28: =IF(D$3=Interests!$I$6,C25*(1+Interests!$H$6/4)+D27,IF(AND(D$3>Interests!$B$6,D$3<Interests!$I$6),C25*Interests!$G$6/4,0)) -> 0 | E28: =IF(E$3=Interests!$I$6,D25*(1+Interests!$H$6/4)+E27,IF(AND(E$3>Interests!$B$6,E$3<Interests!$I$6),D25*Interests!$G$6/4,0)) -> 0 | F28: =IF(F$3=Interests!$I$6,E25*(1+Interests!$H$6/4)+F27,IF(AND(F$3>Interests!$B$6,F$3<Interests!$I$6),E25*Interests!$G$6/4,0)) -> 0 | G28: =IF(G$3=Interests!$I$6,F25*(1+Interests!$H$6/4)+G27,IF(AND(G$3>Interests!$B$6,G$3<Interests!$I$6),F25*Interests!$G$6/4,0)) -> 0 | H28: =IF(H$3=Interests!$I$6,G25*(1+Interests!$H$6/4)+H27,IF(AND(H$3>Interests!$B$6,H$3<Interests!$I$6),G25*Interests!$G$6/4,0)) -> 2000000 | I28: =IF(I$3=Interests!$I$6,H25*(1+Interests!$H$6/4)+I27,IF(AND(I$3>Interests!$B$6,I$3<Interests!$I$6),H25*Interests!$G$6/4,0)) -> 1952500 | J28: =IF(J$3=Interests!$I$6,I25*(1+Interests!$H$6/4)+J27,IF(AND(J$3>Interests!$B$6,J$3<Interests!$I$6),I25*Interests!$G$6/4,0)) -> 1902331.2 | ... AH28: =IF(AH$3=Interests!$I$6,AG25*(1+Interests!$H$6/4)+AH27,IF(AND(AH$3>Interests!$B$6,AH$3<Interests!$I$6),AG25*Interests!$G$6/4,0)) -> 0
A29: Purchase 5 | B29: =IF(B$3=Interests!$B$6,Interests!$C$6*(1-Interests!$D$6),0) -> 0 | C29: =IF(C$3=Interests!$B$6,Interests!$C$6*(1-Interests!$D$6),0) -> 0 | D29: =IF(D$3=Interests!$B$6,Interests!$C$6*(1-Interests!$D$6),0) -> 0 | E29: =IF(E$3=Interests!$B$6,Interests!$C$6*(1-Interests!$D$6),0) -> 0 | F29: =IF(F$3=Interests!$B$6,Interests!$C$6*(1-Interests!$D$6),0) -> 0 | G29: =IF(G$3=Interests!$B$6,Interests!$C$6*(1-Interests!$D$6),0) -> 36400000 | H29: =IF(H$3=Interests!$B$6,Interests!$C$6*(1-Interests!$D$6),0) -> 0 | I29: =IF(I$3=Interests!$B$6,Interests!$C$6*(1-Interests!$D$6),0) -> 0 | ... AH29: =IF(AH$3=Interests!$B$6,Interests!$C$6*(1-Interests!$D$6),0) -> 0
A30: NAV 6 | B30: =IF(B$3=Interests!$B$7,Interests!$C$7,IF(AND(B$3>Interests!$B$7,B$3<Interests!$I$7),0*(1+Interests!$H$7/4)+B32-B33,0)) -> 0 | C30: =IF(C$3=Interests!$B$7,Interests!$C$7,IF(AND(C$3>Interests!$B$7,C$3<Interests!$I$7),B30*(1+Interests!$H$7/4)+C32-C33,0)) -> 0 | D30: =IF(D$3=Interests!$B$7,Interests!$C$7,IF(AND(D$3>Interests!$B$7,D$3<Interests!$I$7),C30*(1+Interests!$H$7/4)+D32-D33,0)) -> 0 | E30: =IF(E$3=Interests!$B$7,Interests!$C$7,IF(AND(E$3>Interests!$B$7,E$3<Interests!$I$7),D30*(1+Interests!$H$7/4)+E32-E33,0)) -> 0 | F30: =IF(F$3=Interests!$B$7,Interests!$C$7,IF(AND(F$3>Interests!$B$7,F$3<Interests!$I$7),E30*(1+Interests!$H$7/4)+F32-F33,0)) -> 0 | G30: =IF(G$3=Interests!$B$7,Interests!$C$7,IF(AND(G$3>Interests!$B$7,G$3<Interests!$I$7),F30*(1+Interests!$H$7/4)+G32-G33,0)) -> 0 | H30: =IF(H$3=Interests!$B$7,Interests!$C$7,IF(AND(H$3>Interests!$B$7,H$3<Interests!$I$7),G30*(1+Interests!$H$7/4)+H32-H33,0)) -> 0 | I30: =IF(I$3=Interests!$B$7,Interests!$C$7,IF(AND(I$3>Interests!$B$7,I$3<Interests!$I$7),H30*(1+Interests!$H$7/4)+I32-I33,0)) -> 70000000 | J30: =IF(J$3=Interests!$B$7,Interests!$C$7,IF(AND(J$3>Interests!$B$7,J$3<Interests!$I$7),I30*(1+Interests!$H$7/4)+J32-J33,0)) -> 71700000 | ... AH30: =IF(AH$3=Interests!$B$7,Interests!$C$7,IF(AND(AH$3>Interests!$B$7,AH$3<Interests!$I$7),AG30*(1+Interests!$H$7/4)+AH32-AH33,0)) -> 0
A31: Unfunded 6 | B31: =IF(B$3=Interests!$B$7,Interests!$E$7,IF(AND(B$3>Interests!$B$7,B$3<Interests!$I$7),0-B32,0)) -> 0 | C31: =IF(C$3=Interests!$B$7,Interests!$E$7,IF(AND(C$3>Interests!$B$7,C$3<Interests!$I$7),B31-C32,0)) -> 0 | D31: =IF(D$3=Interests!$B$7,Interests!$E$7,IF(AND(D$3>Interests!$B$7,D$3<Interests!$I$7),C31-D32,0)) -> 0 | E31: =IF(E$3=Interests!$B$7,Interests!$E$7,IF(AND(E$3>Interests!$B$7,E$3<Interests!$I$7),D31-E32,0)) -> 0 | F31: =IF(F$3=Interests!$B$7,Interests!$E$7,IF(AND(F$3>Interests!$B$7,F$3<Interests!$I$7),E31-F32,0)) -> 0 | G31: =IF(G$3=Interests!$B$7,Interests!$E$7,IF(AND(G$3>Interests!$B$7,G$3<Interests!$I$7),F31-G32,0)) -> 0 | H31: =IF(H$3=Interests!$B$7,Interests!$E$7,IF(AND(H$3>Interests!$B$7,H$3<Interests!$I$7),G31-H32,0)) -> 0 | I31: =IF(I$3=Interests!$B$7,Interests!$E$7,IF(AND(I$3>Interests!$B$7,I$3<Interests!$I$7),H31-I32,0)) -> 25000000 | J31: =IF(J$3=Interests!$B$7,Interests!$E$7,IF(AND(J$3>Interests!$B$7,J$3<Interests!$I$7),I31-J32,0)) -> 23125000 | ... AH31: =IF(AH$3=Interests!$B$7,Interests!$E$7,IF(AND(AH$3>Interests!$B$7,AH$3<Interests!$I$7),AG31-AH32,0)) -> 0
A32: Call 6 | B32: =IF(AND(B$3>Interests!$B$7,B$3<Interests!$I$7),0*Interests!$F$7/4,0) -> 0 | C32: =IF(AND(C$3>Interests!$B$7,C$3<Interests!$I$7),B31*Interests!$F$7/4,0) -> 0 | D32: =IF(AND(D$3>Interests!$B$7,D$3<Interests!$I$7),C31*Interests!$F$7/4,0) -> 0 | E32: =IF(AND(E$3>Interests!$B$7,E$3<Interests!$I$7),D31*Interests!$F$7/4,0) -> 0 | F32: =IF(AND(F$3>Interests!$B$7,F$3<Interests!$I$7),E31*Interests!$F$7/4,0) -> 0 | G32: =IF(AND(G$3>Interests!$B$7,G$3<Interests!$I$7),F31*Interests!$F$7/4,0) -> 0 | H32: =IF(AND(H$3>Interests!$B$7,H$3<Interests!$I$7),G31*Interests!$F$7/4,0) -> 0 | I32: =IF(AND(I$3>Interests!$B$7,I$3<Interests!$I$7),H31*Interests!$F$7/4,0) -> 0 | J32: =IF(AND(J$3>Interests!$B$7,J$3<Interests!$I$7),I31*Interests!$F$7/4,0) -> 1875000 | ... AH32: =IF(AND(AH$3>Interests!$B$7,AH$3<Interests!$I$7),AG31*Interests!$F$7/4,0) -> 0
A33: Distribution 6 | B33: =IF(B$3=Interests!$I$7,0*(1+Interests!$H$7/4)+B32,IF(AND(B$3>Interests!$B$7,B$3<Interests!$I$7),0*Interests!$G$7/4,0)) -> 0 | C33: =IF(C$3=Interests!$I$7,B30*(1+Interests!$H$7/4)+C32,IF(AND(C$3>Interests!$B$7,C$3<Interests!$I$7),B30*Interests!$G$7/4,0)) -> 0 | D33: =IF(D$3=Interests!$I$7,C30*(1+Interests!$H$7/4)+D32,IF(AND(D$3>Interests!$B$7,D$3<Interests!$I$7),C30*Interests!$G$7/4,0)) -> 0 | E33: =IF(E$3=Interests!$I$7,D30*(1+Interests!$H$7/4)+E32,IF(AND(E$3>Interests!$B$7,E$3<Interests!$I$7),D30*Interests!$G$7/4,0)) -> 0 | F33: =IF(F$3=Interests!$I$7,E30*(1+Interests!$H$7/4)+F32,IF(AND(F$3>Interests!$B$7,F$3<Interests!$I$7),E30*Interests!$G$7/4,0)) -> 0 | G33: =IF(G$3=Interests!$I$7,F30*(1+Interests!$H$7/4)+G32,IF(AND(G$3>Interests!$B$7,G$3<Interests!$I$7),F30*Interests!$G$7/4,0)) -> 0 | H33: =IF(H$3=Interests!$I$7,G30*(1+Interests!$H$7/4)+H32,IF(AND(H$3>Interests!$B$7,H$3<Interests!$I$7),G30*Interests!$G$7/4,0)) -> 0 | I33: =IF(I$3=Interests!$I$7,H30*(1+Interests!$H$7/4)+I32,IF(AND(I$3>Interests!$B$7,I$3<Interests!$I$7),H30*Interests!$G$7/4,0)) -> 0 | J33: =IF(J$3=Interests!$I$7,I30*(1+Interests!$H$7/4)+J32,IF(AND(J$3>Interests!$B$7,J$3<Interests!$I$7),I30*Interests!$G$7/4,0)) -> 1400000 | ... AH33: =IF(AH$3=Interests!$I$7,AG30*(1+Interests!$H$7/4)+AH32,IF(AND(AH$3>Interests!$B$7,AH$3<Interests!$I$7),AG30*Interests!$G$7/4,0)) -> 0
A34: Purchase 6 | B34: =IF(B$3=Interests!$B$7,Interests!$C$7*(1-Interests!$D$7),0) -> 0 | C34: =IF(C$3=Interests!$B$7,Interests!$C$7*(1-Interests!$D$7),0) -> 0 | D34: =IF(D$3=Interests!$B$7,Interests!$C$7*(1-Interests!$D$7),0) -> 0 | E34: =IF(E$3=Interests!$B$7,Interests!$C$7*(1-Interests!$D$7),0) -> 0 | F34: =IF(F$3=Interests!$B$7,Interests!$C$7*(1-Interests!$D$7),0) -> 0 | G34: =IF(G$3=Interests!$B$7,Interests!$C$7*(1-Interests!$D$7),0) -> 0 | H34: =IF(H$3=Interests!$B$7,Interests!$C$7*(1-Interests!$D$7),0) -> 0 | I34: =IF(I$3=Interests!$B$7,Interests!$C$7*(1-Interests!$D$7),0) -> 59500000 | ... AH34: =IF(AH$3=Interests!$B$7,Interests!$C$7*(1-Interests!$D$7),0) -> 0
A35: Purchases | B35: =B9+B14+B19+B24+B29+B34 -> 0 | C35: =C9+C14+C19+C24+C29+C34 -> 54560000 | D35: =D9+D14+D19+D24+D29+D34 -> 90510000 | E35: =E9+E14+E19+E24+E29+E34 -> 0 | F35: =F9+F14+F19+F24+F29+F34 -> 21000000 | G35: =G9+G14+G19+G24+G29+G34 -> 36400000 | H35: =H9+H14+H19+H24+H29+H34 -> 0 | I35: =I9+I14+I19+I24+I29+I34 -> 59500000 | ... AH35: =AH9+AH14+AH19+AH24+AH29+AH34 -> 0
A36: Calls | B36: =B7+B12+B17+B22+B27+B32 -> 0 | C36: =C7+C12+C17+C22+C27+C32 -> 0 | D36: =D7+D12+D17+D22+D27+D32 -> 600000 | E36: =E7+E12+E17+E22+E27+E32 -> 2080000 | F36: =F7+F12+F17+F22+F27+F32 -> 1901187.5 | G36: =G7+G12+G17+G22+G27+G32 -> 2637875.8 | H36: =H7+H12+H17+H22+H27+H32 -> 3171210 | I36: =I7+I12+I17+I22+I27+I32 -> 2878767.4 | ... AH36: =AH7+AH12+AH17+AH22+AH27+AH32 -> 0
A37: Distributions | B37: =B8+B13+B18+B23+B28+B33 -> 0 | C37: =C8+C13+C18+C23+C28+C33 -> 0 | D37: =D8+D13+D18+D23+D28+D33 -> 2790000 | E37: =E8+E13+E18+E23+E28+E33 -> 5548300 | F37: =F8+F13+F18+F23+F28+F33 -> 5500501 | G37: =G8+G13+G18+G23+G28+G33 -> 5898547.3 | H37: =H8+H13+H18+H23+H28+H33 -> 7860983.4 | I37: =I8+I13+I18+I23+I28+I33 -> 7771969.8 | ... AH37: =AH8+AH13+AH18+AH23+AH28+AH33 -> 0
A38: NAV | B38: =B5+B10+B15+B20+B25+B30 -> 0 | C38: =C5+C10+C15+C20+C25+C30 -> 62000000 | D38: =D5+D10+D15+D20+D25+D30 -> 163740000 | E38: =E5+E10+E15+E20+E25+E30 -> 162692800 | F38: =F5+F10+F15+F20+F25+F30 -> 1.9150523e+08 | G38: =G5+G10+G15+G20+G25+G30 -> 2.3139437e+08 | H38: =H5+H10+H15+H20+H25+H30 -> 2.3017021e+08 | I38: =I5+I10+I15+I20+I25+I30 -> 2.987479e+08 | ... AH38: =AH5+AH10+AH15+AH20+AH25+AH30 -> 0
A39: Fees | B39: =0 -> 0 | C39: =B38*Fund!$B$4/4 -> 0 | D39: =C38*Fund!$B$4/4 -> 155000 | E39: =D38*Fund!$B$4/4 -> 409350 | F39: =E38*Fund!$B$4/4 -> 406732 | G39: =F38*Fund!$B$4/4 -> 478763.07 | H39: =G38*Fund!$B$4/4 -> 578485.93 | I39: =H38*Fund!$B$4/4 -> 575425.53 | J39: =I38*Fund!$B$4/4 -> 746869.75 | ... AH39: =AG38*Fund!$B$4/4 -> 0
A40: Investments | B40: =B35+B36+B39 -> 0 | C40: =C35+C36+C39 -> 54560000 | D40: =D35+D36+D39 -> 91265000 | E40: =E35+E36+E39 -> 2489350 | F40: =F35+F36+F39 -> 23307920 | G40: =G35+G36+G39 -> 39516639 | H40: =H35+H36+H39 -> 3749696 | I40: =I35+I36+I39 -> 62954193 | ... AH40: =AH35+AH36+AH39 -> 0
A41: Line drawn | B41: =B40 -> 0 | C41: =C40 -> 54560000 | D41: =D40 -> 91265000 | E41: =E40 -> 2489350 | F41: =F40 -> 23307920 | G41: =G40 -> 39516639 | H41: =H40 -> 3749696 | I41: =I40 -> 62954193 | ... AH41: =AH40 -> 0
A42: Line repaid | B42: =0 -> 0 | C42: =IF(C$3>Fund!$B$5,OFFSET(C41,0,-Fund!$B$5),0) -> 0 | D42: =IF(D$3>Fund!$B$5,OFFSET(D41,0,-Fund!$B$5),0) -> 0 | E42: =IF(E$3>Fund!$B$5,OFFSET(E41,0,-Fund!$B$5),0) -> 54560000 | F42: =IF(F$3>Fund!$B$5,OFFSET(F41,0,-Fund!$B$5),0) -> 91265000 | G42: =IF(G$3>Fund!$B$5,OFFSET(G41,0,-Fund!$B$5),0) -> 2489350 | H42: =IF(H$3>Fund!$B$5,OFFSET(H41,0,-Fund!$B$5),0) -> 23307920 | I42: =IF(I$3>Fund!$B$5,OFFSET(I41,0,-Fund!$B$5),0) -> 39516639 | J42: =IF(J$3>Fund!$B$5,OFFSET(J41,0,-Fund!$B$5),0) -> 3749696 | ... AH42: =IF(AH$3>Fund!$B$5,OFFSET(AH41,0,-Fund!$B$5),0) -> 215180.65
...

Sheet Returns
A3: Net IRR to LPs (XIRR) | B3: =XIRR('Cash Flow'!$B$53:$AH$53,'Cash Flow'!$B$4:$AH$4) -> 0.093151479
A4: Gross IRR (XIRR) | B4: =XIRR('Cash Flow'!$B$54:$AH$54,'Cash Flow'!$B$4:$AH$4) -> 0.10665444
A5: TVPI (net) | B5: =SUMIF('Cash Flow'!$B$53:$AH$53,">0")/SUM('Cash Flow'!$B$45:$AH$45) -> 1.0322369
A6: DPI at the reporting date | B6: =SUM(OFFSET('Cash Flow'!$B$47,0,0,1,MATCH(Fund!$B$10,'Cash Flow'!$B$4:$AH$4,0)))/SUM(OFFSET('Cash Flow'!$B$45,0,0,1,MATCH(Fund!$B$10,'Cash Flow'!$B$4:$AH$4,0)))+SUM(OFFSET('Cash Flow'!$B$49,0,0,1,MATCH(Fund!$B$10,'Cash Flow'!$B$4:$AH$4,0)))/SUM(OFFSET('Cash Flow'!$B$45,0,0,1,MATCH(Fund!$B$10,'Cash Flow'!$B$4:$AH$4,0)))+SUM(OFFSET('Cash Flow'!$B$51,0,0,1,MATCH(Fund!$B$10,'Cash Flow'!$B$4:$AH$4,0)))/SUM(OFFSET('Cash Flow'!$B$45,0,0,1,MATCH(Fund!$B$10,'Cash Flow'!$B$4:$AH$4,0))) -> 0.6402456
A7: RVPI at the reporting date | B7: =INDEX('Cash Flow'!$B$38:$AH$38,MATCH(Fund!$B$10,'Cash Flow'!$B$4:$AH$4,0))/SUM(OFFSET('Cash Flow'!$B$45,0,0,1,MATCH(Fund!$B$10,'Cash Flow'!$B$4:$AH$4,0))) -> 0.68243024
A8: Discount captured (€) | B8: =SUMPRODUCT(Interests!$C$2:$C$7,Interests!$D$2:$D$7) -> 43030000
A9: Peak unfunded exposure (€) | B9: =MAX('Cash Flow'!$B$56:$AH$56) -> 54730959
A10: GP carry (€) | B10: =SUM('Cash Flow'!$B$50:$AH$50)+SUM('Cash Flow'!$B$52:$AH$52) -> 15869144
A11: Line interest (€) | B11: =SUM('Cash Flow'!$B$44:$AH$44) -> 7496384.6
A12: LP net profit (€) | B12: =SUM('Cash Flow'!$B$53:$AH$53) -> 1.1027793e+08
