Workbook

Sheet Inputs & Monthly CF
B2: INPUTS AND MONTHLY CASH FLOW
C10: Inputs | H10: Monthly DCF
C12: Property Inputs | H12: Annual Growth Rate | I12: Unlevered DCF
I13: Date | J13: =$D$19 -> 46023 | K13: =EDATE(J13,1) -> 46054 | L13: =EDATE(K13,1) -> 46082 | M13: =EDATE(L13,1) -> 46113 | N13: =EDATE(M13,1) -> 46143 | O13: =EDATE(N13,1) -> 46174 | P13: =EDATE(O13,1) -> 46204 | Q13: =EDATE(P13,1) -> 46235 | R13: =EDATE(Q13,1) -> 46266 | ... EL13: =EDATE(EK13,1) -> 50041
I14: Calendar Year | J14: =$D$21 -> 2026 | K14: =YEAR(K13) -> 2026 | L14: =YEAR(L13) -> 2026 | M14: =YEAR(M13) -> 2026 | N14: =YEAR(N13) -> 2026 | O14: =YEAR(O13) -> 2026 | P14: =YEAR(P13) -> 2026 | Q14: =YEAR(Q13) -> 2026 | R14: =YEAR(R13) -> 2026 | ... EL14: =YEAR(EL13) -> 2037
I15: Fiscal Year | J15: 0 | K15: =ROUNDUP(K18/12,0) -> 1 | L15: =ROUNDUP(L18/12,0) -> 1 | M15: =ROUNDUP(M18/12,0) -> 1 | N15: =ROUNDUP(N18/12,0) -> 1 | O15: =ROUNDUP(O18/12,0) -> 1 | P15: =ROUNDUP(P18/12,0) -> 1 | Q15: =ROUNDUP(Q18/12,0) -> 1 | R15: =ROUNDUP(R18/12,0) -> 1 | ... EL15: =ROUNDUP(EL18/12,0) -> 11
I16: Month | J16: =$D$20 -> January | K16: =INDEX($D$87:$D$98,MONTH(K13)) -> February | L16: =INDEX($D$87:$D$98,MONTH(L13)) -> March | M16: =INDEX($D$87:$D$98,MONTH(M13)) -> April | N16: =INDEX($D$87:$D$98,MONTH(N13)) -> May | O16: =INDEX($D$87:$D$98,MONTH(O13)) -> June | P16: =INDEX($D$87:$D$98,MONTH(P13)) -> July | Q16: =INDEX($D$87:$D$98,MONTH(Q13)) -> August | R16: =INDEX($D$87:$D$98,MONTH(R13)) -> September | ... EL16: =INDEX($D$87:$D$98,MONTH(EL13)) -> January
I18: Fiscal Month | J18: 0 | K18: =J18+1 -> 1 | L18: =K18+1 -> 2 | M18: =L18+1 -> 3 | N18: =M18+1 -> 4 | O18: =N18+1 -> 5 | P18: =O18+1 -> 6 | Q18: =P18+1 -> 7 | R18: =Q18+1 -> 8 | ... EL18: =EK18+1 -> 132
C19: Analysis Start | D19: =DATE(D21,MATCH(D20,$D$87:$D$98,0),1) -> 46023 | I19: Purchase Price | J19: =-$D$30 -> -18870000
C20: Start Month | D20: January | H20: 0.025 | I20: Gross Potential Income | K20: =$D$37/12*(1+$H$20)^(K15-1) -> 158083.33 | L20: =$D$37/12*(1+$H$20)^(L15-1) -> 158083.33 | M20: =$D$37/12*(1+$H$20)^(M15-1) -> 158083.33 | N20: =$D$37/12*(1+$H$20)^(N15-1) -> 158083.33 | O20: =$D$37/12*(1+$H$20)^(O15-1) -> 158083.33 | P20: =$D$37/12*(1+$H$20)^(P15-1) -> 158083.33 | Q20: =$D$37/12*(1+$H$20)^(Q15-1) -> 158083.33 | R20: =$D$37/12*(1+$H$20)^(R15-1) -> 158083.33 | ... EL20: =$D$37/12*(1+$H$20)^(EL15-1) -> 202360.03
C21: Start Year | D21: 2026 | I21: Expected Vacancy | K21: =-K20*$D$38 -> -7904.1667 | L21: =-L20*$D$38 -> -7904.1667 | M21: =-M20*$D$38 -> -7904.1667 | N21: =-N20*$D$38 -> -7904.1667 | O21: =-O20*$D$38 -> -7904.1667 | P21: =-P20*$D$38 -> -7904.1667 | Q21: =-Q20*$D$38 -> -7904.1667 | R21: =-R20*$D$38 -> -7904.1667 | ... EL21: =-EL20*$D$38 -> -10118.002
C22: Property Name | D22: Lakeside Logistics Park | I22: Additional Vacancy - (Input as Negative) | K22: -8000 | L22: -8000 | M22: -8000 | N22: -8000 | O22: -8000 | P22: -8000 | Q22: 0 | R22: 0 | S22: 0 | T22: 0 | U22: 0 | V22: 0 | W22: 0 | X22: 0 | Y22: 0 | Z22: 0 | AA22: 0 | AB22: 0 | AC22: 0 | AD22: 0 | AE22: 0 | AF22: 0 | AG22: 0 | AH22: 0 | AI22: 0 | AJ22: 0 | AK22: 0 | AL22: 0 | AM22: 0 | AN22: 0 | AO22: 0 | AP22: 0 | AQ22: 0 | AR22: 0 | AS22: 0 | AT22: 0 | AU22: 0 | AV22: 0 | AW22: 0 | AX22: 0 | AY22: 0 | AZ22: 0 | BA22: 0 | BB22: 0 | BC22: 0 | BD22: 0 | BE22: 0 | BF22: 0 | BG22: 0 | BH22: 0 | BI22: 0 | BJ22: 0 | BK22: 0 | BL22: 0 | BM22: 0 | BN22: 0 | BO22: 0 | BP22: 0 | BQ22: 0 | BR22: 0 | BS22: 0 | BT22: 0 | BU22: 0 | BV22: 0 | BW22: 0 | BX22: 0 | BY22: 0 | BZ22: 0 | CA22: 0 | CB22: 0 | CC22: 0 | CD22: 0 | CE22: 0 | CF22: 0 | CG22: 0 | CH22: 0 | CI22: 0 | CJ22: 0 | CK22: 0 | CL22: 0 | CM22: 0 | CN22: 0 | CO22: 0 | CP22: 0 | CQ22: 0 | CR22: 0 | CS22: 0 | CT22: 0 | CU22: 0 | CV22: 0 | CW22: 0 | CX22: 0 | CY22: 0 | CZ22: 0 | DA22: 0 | DB22: 0 | DC22: 0 | DD22: 0 | DE22: 0 | DF22: 0 | DG22: 0 | DH22: 0 | DI22: 0 | DJ22: 0 | DK22: 0 | DL22: 0 | DM22: 0 | DN22: 0 | DO22: 0 | DP22: 0 | DQ22: 0 | DR22: 0 | DS22: 0 | DT22: 0 | DU22: 0 | DV22: 0 | DW22: 0 | DX22: 0 | DY22: 0 | DZ22: 0 | EA22: 0 | EB22: 0 | EC22: 0 | ED22: 0 | EE22: 0 | EF22: 0 | EG22: 0 | EH22: 0 | EI22: 0 | EJ22: 0 | EK22: 0 | EL22: 0
C23: City, State | D23: Columbus, OH | I23: Effective Gross Income | K23: =SUM(K20:K22) -> 142179.17 | L23: =SUM(L20:L22) -> 142179.17 | M23: =SUM(M20:M22) -> 142179.17 | N23: =SUM(N20:N22) -> 142179.17 | O23: =SUM(O20:O22) -> 142179.17 | P23: =SUM(P20:P22) -> 142179.17 | Q23: =SUM(Q20:Q22) -> 150179.17 | R23: =SUM(R20:R22) -> 150179.17 | ... EL23: =SUM(EL20:EL22) -> 192242.03
H24: 0.03 | I24: Tax | K24: =($D$40=K16)*-$D$39*(1+$H$24)^(K15-1) -> 0 | L24: =($D$40=L16)*-$D$39*(1+$H$24)^(L15-1) -> 0 | M24: =($D$40=M16)*-$D$39*(1+$H$24)^(M15-1) -> 0 | N24: =($D$40=N16)*-$D$39*(1+$H$24)^(N15-1) -> 0 | O24: =($D$40=O16)*-$D$39*(1+$H$24)^(O15-1) -> 0 | P24: =($D$40=P16)*-$D$39*(1+$H$24)^(P15-1) -> 0 | Q24: =($D$40=Q16)*-$D$39*(1+$H$24)^(Q15-1) -> 0 | R24: =($D$40=R16)*-$D$39*(1+$H$24)^(R15-1) -> 0 | ... EL24: =($D$40=EL16)*-$D$39*(1+$H$24)^(EL15-1) -> 0
C25: Property SF | D25: 145000 | H25: 0.03 | I25: Insurance | K25: =($D$42=K16)*-$D$41*(1+$H$25)^(K15-1) -> 0 | L25: =($D$42=L16)*-$D$41*(1+$H$25)^(L15-1) -> -51000 | M25: =($D$42=M16)*-$D$41*(1+$H$25)^(M15-1) -> 0 | N25: =($D$42=N16)*-$D$41*(1+$H$25)^(N15-1) -> 0 | O25: =($D$42=O16)*-$D$41*(1+$H$25)^(O15-1) -> 0 | P25: =($D$42=P16)*-$D$41*(1+$H$25)^(P15-1) -> 0 | Q25: =($D$42=Q16)*-$D$41*(1+$H$25)^(Q15-1) -> 0 | R25: =($D$42=R16)*-$D$41*(1+$H$25)^(R15-1) -> 0 | ... EL25: =($D$42=EL16)*-$D$41*(1+$H$25)^(EL15-1) -> 0
C26: Purchase Price | D26: 18500000 | H26: 0.03 | I26: CAM | K26: =-$D$43/12*(1+$H$26)^(K15-1) -> -14000 | L26: =-$D$43/12*(1+$H$26)^(L15-1) -> -14000 | M26: =-$D$43/12*(1+$H$26)^(M15-1) -> -14000 | N26: =-$D$43/12*(1+$H$26)^(N15-1) -> -14000 | O26: =-$D$43/12*(1+$H$26)^(O15-1) -> -14000 | P26: =-$D$43/12*(1+$H$26)^(P15-1) -> -14000 | Q26: =-$D$43/12*(1+$H$26)^(Q15-1) -> -14000 | R26: =-$D$43/12*(1+$H$26)^(R15-1) -> -14000 | ... EL26: =-$D$43/12*(1+$H$26)^(EL15-1) -> -18814.829
C27: Going in Cap Rate | D27: =SUM($K$28:$V$28)/D26 -> 0.068568946 | I27: Mgmt Fee | K27: =-K23*$D$44 -> -4265.375 | L27: =-L23*$D$44 -> -4265.375 | M27: =-M23*$D$44 -> -4265.375 | N27: =-N23*$D$44 -> -4265.375 | O27: =-O23*$D$44 -> -4265.375 | P27: =-P23*$D$44 -> -4265.375 | Q27: =-Q23*$D$44 -> -4505.375 | R27: =-R23*$D$44 -> -4505.375 | ... EL27: =-EL23*$D$44 -> -5767.2609
C28: $/PSF | D28: =D26/D25 -> 127.58621 | I28: NOI | K28: =SUM(K23:K27) -> 123913.79 | L28: =SUM(L23:L27) -> 72913.792 | M28: =SUM(M23:M27) -> 123913.79 | N28: =SUM(N23:N27) -> 123913.79 | O28: =SUM(O23:O27) -> 123913.79 | P28: =SUM(P23:P27) -> 123913.79 | Q28: =SUM(Q23:Q27) -> 131673.79 | R28: =SUM(R23:R27) -> 131673.79 | ... EL28: =SUM(EL23:EL27) -> 167659.94
C29: Closing costs | D29: 0.02 | I29: Leasing Commissions - (Input as Negative) | AN29: -64000
C30: All-in Purchase Cost | D30: =D26*(1+$D$29) -> 18870000 | I30: Tenant Improvements - (Input as Negative) | AN30: -120000
C31: Hold Period | D31: 5 | H31: 0.02 | I31: Cap Ex & Misc | K31: =-$D$45/12*(1+$H$31)^(K15-1) -> -2416.6667 | L31: =-$D$45/12*(1+$H$31)^(L15-1) -> -2416.6667 | M31: =-$D$45/12*(1+$H$31)^(M15-1) -> -2416.6667 | N31: =-$D$45/12*(1+$H$31)^(N15-1) -> -2416.6667 | O31: =-$D$45/12*(1+$H$31)^(O15-1) -> -2416.6667 | P31: =-$D$45/12*(1+$H$31)^(P15-1) -> -2416.6667 | Q31: =-$D$45/12*(1+$H$31)^(Q15-1) -> -2416.6667 | R31: =-$D$45/12*(1+$H$31)^(R15-1) -> -2416.6667 | ... EL31: =-$D$45/12*(1+$H$31)^(EL15-1) -> -2945.9032
C32: Exit Month | D32: =D20 -> January
C33: Exit Year | D33: =YEAR(D19)+ROUND(D31,0) -> 2031 | I33: CFO | K33: =(K15<=ROUND($D$31,0))*SUM(K28:K31) -> 121497.12 | L33: =(L15<=ROUND($D$31,0))*SUM(L28:L31) -> 70497.125 | M33: =(M15<=ROUND($D$31,0))*SUM(M28:M31) -> 121497.12 | N33: =(N15<=ROUND($D$31,0))*SUM(N28:N31) -> 121497.12 | O33: =(O15<=ROUND($D$31,0))*SUM(O28:O31) -> 121497.12 | P33: =(P15<=ROUND($D$31,0))*SUM(P28:P31) -> 121497.12 | Q33: =(Q15<=ROUND($D$31,0))*SUM(Q28:Q31) -> 129257.12 | R33: =(R15<=ROUND($D$31,0))*SUM(R28:R31) -> 129257.12 | ... EL33: =(EL15<=ROUND($D$31,0))*SUM(EL28:EL31) -> 0
C34: Gross Potential Rent - Year 1 | D34: 1480000
C35: Reimbursable Expenses Year 1 | D35: 395000 | I35: Sale | K35: =AND($D$32=K16,$D$33=K14)*SUM(L$28:W$28)/$D$51 -> 0 | L35: =AND($D$32=L16,$D$33=L14)*SUM(M$28:X$28)/$D$51 -> 0 | M35: =AND($D$32=M16,$D$33=M14)*SUM(N$28:Y$28)/$D$51 -> 0 | N35: =AND($D$32=N16,$D$33=N14)*SUM(O$28:Z$28)/$D$51 -> 0 | O35: =AND($D$32=O16,$D$33=O14)*SUM(P$28:AA$28)/$D$51 -> 0 | P35: =AND($D$32=P16,$D$33=P14)*SUM(Q$28:AB$28)/$D$51 -> 0 | Q35: =AND($D$32=Q16,$D$33=Q14)*SUM(R$28:AC$28)/$D$51 -> 0 | R35: =AND($D$32=R16,$D$33=R14)*SUM(S$28:AD$28)/$D$51 -> 0 | ... EL35: =AND($D$32=EL16,$D$33=EL14)*SUM(EM$28:EX$28)/$D$51 -> 0
C36: Misc. Income | D36: 22000 | I36: Selling Expenses | K36: =K35*$D$52 -> 0 | L36: =L35*$D$52 -> 0 | M36: =M35*$D$52 -> 0 | N36: =N35*$D$52 -> 0 | O36: =O35*$D$52 -> 0 | P36: =P35*$D$52 -> 0 | Q36: =Q35*$D$52 -> 0 | R36: =R35*$D$52 -> 0 | ... EL36: =EL35*$D$52 -> 0
C37: Gross Potential Income Year 1 | D37: =SUM(D34:D36) -> 1897000 | I37: Proceeds | K37: =K35-K36 -> 0 | L37: =L35-L36 -> 0 | M37: =M35-M36 -> 0 | N37: =N35-N36 -> 0 | O37: =O35-O36 -> 0 | P37: =P35-P36 -> 0 | Q37: =Q35-Q36 -> 0 | R37: =R35-R36 -> 0 | ... EL37: =EL35-EL36 -> 0
C38: Expected Vacancy Loss (% of GPI) | D38: 0.05
C39: Tax in Year 1 | D39: 214000 | I39: Unlvered Cash Flow | J39: =J19 -> -18870000 | K39: =(K15<=ROUND($D$31,0))*SUM(K33,K37) -> 121497.12 | L39: =(L15<=ROUND($D$31,0))*SUM(L33,L37) -> 70497.125 | M39: =(M15<=ROUND($D$31,0))*SUM(M33,M37) -> 121497.12 | N39: =(N15<=ROUND($D$31,0))*SUM(N33,N37) -> 121497.12 | O39: =(O15<=ROUND($D$31,0))*SUM(O33,O37) -> 121497.12 | P39: =(P15<=ROUND($D$31,0))*SUM(P33,P37) -> 121497.12 | Q39: =(Q15<=ROUND($D$31,0))*SUM(Q33,Q37) -> 129257.12 | R39: =(R15<=ROUND($D$31,0))*SUM(R33,R37) -> 129257.12 | ... EL39: =(EL15<=ROUND($D$31,0))*SUM(EL33,EL37) -> 0
C40: Tax Payable in Month | D40: October | I40: IRR | J40: =XIRR($J$39:$EL$39,$J$13:$EL$13) -> 0.081882813
C41: Annual Insurance premium | D41: 51000 | I41: Equity Multiple | J41: =SUMIF($J$39:$EL$39,">0")/-SUMIF($J$39:$EL$39,"<0") -> 1.3968455
C42: Insurance Payable in Month | D42: March | I42: Net Gain (loss) | J42: =SUM(J39:EL39) -> 7689146
C43: CAM (Annual Expense) | D43: 168000
C44: Property Mgmt Fee | D44: 0.03
C45: Ave Annual Cap ex & Misc | D45: 29000
I46: Levered DCF
I49: Purchase Price | J49: =J19 -> -18870000
I50: Loan Proceeds | J50: =$D$61 -> 11904750
C51: Going Out Cap Rate | D51: 0.0725
C52: Selling Expenses | D52: 0.015
...

Sheet AmortSched
B2: AMORTIZATION SCHEDULE
C12: Loan Amortization Schedule
D13: Period | E13: Balance | F13: Pmt | G13: Int | H13: Princ | I13: End
D14: 1 | E14: ='Inputs & Monthly CF'!$D$26*'Inputs & Monthly CF'!$D$56 -> 12025000 | F14: =-PMT('Inputs & Monthly CF'!$D$57/12,'Inputs & Monthly CF'!$D$58*12,$E$14) -> 74039.993 | G14: =E14*'Inputs & Monthly CF'!$D$57/12 -> 62630.208 | H14: =F14-G14 -> 11409.785 | I14: =E14-H14 -> 12013590
D15: 2 | E15: =I14 -> 12013590 | F15: =-PMT('Inputs & Monthly CF'!$D$57/12,'Inputs & Monthly CF'!$D$58*12,$E$14) -> 74039.993 | G15: =E15*'Inputs & Monthly CF'!$D$57/12 -> 62570.782 | H15: =F15-G15 -> 11469.211 | I15: =E15-H15 -> 12002121
D16: 3 | E16: =I15 -> 12002121 | F16: =-PMT('Inputs & Monthly CF'!$D$57/12,'Inputs & Monthly CF'!$D$58*12,$E$14) -> 74039.993 | G16: =E16*'Inputs & Monthly CF'!$D$57/12 -> 62511.047 | H16: =F16-G16 -> 11528.946 | I16: =E16-H16 -> 11990592
D17: 4 | E17: =I16 -> 11990592 | F17: =-PMT('Inputs & Monthly CF'!$D$57/12,'Inputs & Monthly CF'!$D$58*12,$E$14) -> 74039.993 | G17: =E17*'Inputs & Monthly CF'!$D$57/12 -> 62451 | H17: =F17-G17 -> 11588.993 | I17: =E17-H17 -> 11979003
D18: 5 | E18: =I17 -> 11979003 | F18: =-PMT('Inputs & Monthly CF'!$D$57/12,'Inputs & Monthly CF'!$D$58*12,$E$14) -> 74039.993 | G18: =E18*'Inputs & Monthly CF'!$D$57/12 -> 62390.641 | H18: =F18-G18 -> 11649.352 | I18: =E18-H18 -> 11967354
D19: 6 | E19: =I18 -> 11967354 | F19: =-PMT('Inputs & Monthly CF'!$D$57/12,'Inputs & Monthly CF'!$D$58*12,$E$14) -> 74039.993 | G19: =E19*'Inputs & Monthly CF'!$D$57/12 -> 62329.967 | H19: =F19-G19 -> 11710.026 | I19: =E19-H19 -> 11955644
D20: 7 | E20: =I19 -> 11955644 | F20: =-PMT('Inputs & Monthly CF'!$D$57/12,'Inputs & Monthly CF'!$D$58*12,$E$14) -> 74039.993 | G20: =E20*'Inputs & Monthly CF'!$D$57/12 -> 62268.978 | H20: =F20-G20 -> 11771.016 | I20: =E20-H20 -> 11943873
D21: 8 | E21: =I20 -> 11943873 | F21: =-PMT('Inputs & Monthly CF'!$D$57/12,'Inputs & Monthly CF'!$D$58*12,$E$14) -> 74039.993 | G21: =E21*'Inputs & Monthly CF'!$D$57/12 -> 62207.67 | H21: =F21-G21 -> 11832.323 | I21: =E21-H21 -> 11932040
D22: 9 | E22: =I21 -> 11932040 | F22: =-PMT('Inputs & Monthly CF'!$D$57/12,'Inputs & Monthly CF'!$D$58*12,$E$14) -> 74039.993 | G22: =E22*'Inputs & Monthly CF'!$D$57/12 -> 62146.043 | H22: =F22-G22 -> 11893.95 | I22: =E22-H22 -> 11920146
D23: 10 | E23: =I22 -> 11920146 | F23: =-PMT('Inputs & Monthly CF'!$D$57/12,'Inputs & Monthly CF'!$D$58*12,$E$14) -> 74039.993 | G23: =E23*'Inputs & Monthly CF'!$D$57/12 -> 62084.096 | H23: =F23-G23 -> 11955.898 | I23: =E23-H23 -> 11908190
D24: 11 | E24: =I23 -> 11908190 | F24: =-PMT('Inputs & Monthly CF'!$D$57/12,'Inputs & Monthly CF'!$D$58*12,$E$14) -> 74039.993 | G24: =E24*'Inputs & Monthly CF'!$D$57/12 -> 62021.826 | H24: =F24-G24 -> 12018.168 | I24: =E24-H24 -> 11896172
D25: 12 | E25: =I24 -> 11896172 | F25: =-PMT('Inputs & Monthly CF'!$D$57/12,'Inputs & Monthly CF'!$D$58*12,$E$14) -> 74039.993 | G25: =E25*'Inputs & Monthly CF'!$D$57/12 -> 61959.231 | H25: =F25-G25 -> 12080.762 | I25: =E25-H25 -> 11884092
D26: 13 | E26: =I25 -> 11884092 | F26: =-PMT('Inputs & Monthly CF'!$D$57/12,'Inputs & Monthly CF'!$D$58*12,$E$14) -> 74039.993 | G26: =E26*'Inputs & Monthly CF'!$D$57/12 -> 61896.31 | H26: =F26-G26 -> 12143.683 | I26: =E26-H26 -> 11871948
... D373: 360 | E373: =I372 -> 73656.366 | F373: =-PMT('Inputs & Monthly CF'!$D$57/12,'Inputs & Monthly CF'!$D$58*12,$E$14) -> 74039.993 | G373: =E373*'Inputs & Monthly CF'!$D$57/12 -> 383.62691 | H373: =F373-G373 -> 73656.366 | I373: =E373-H373 -> -1.8524588e-08

Sheet AnnualCF & Returns
B2: RETURNS AND ANNUAL CASH FLOW
C10: Return Metrics & Sensitivity | H10: Annual Cash Flow
C12: Return Summary | H12: Unlevered DCF
H14: Calendar Year | I14: ='Inputs & Monthly CF'!$D$21+I15 -> 2026 | J14: ='Inputs & Monthly CF'!$D$21+J15 -> 2027 | K14: ='Inputs & Monthly CF'!$D$21+K15 -> 2028 | L14: ='Inputs & Monthly CF'!$D$21+L15 -> 2029 | M14: ='Inputs & Monthly CF'!$D$21+M15 -> 2030 | N14: ='Inputs & Monthly CF'!$D$21+N15 -> 2031 | O14: ='Inputs & Monthly CF'!$D$21+O15 -> 2032 | P14: ='Inputs & Monthly CF'!$D$21+P15 -> 2033 | ... S14: ='Inputs & Monthly CF'!$D$21+S15 -> 2036
H15: Fiscal Year | I15: 0 | J15: 1 | K15: 2 | L15: 3 | M15: 4 | N15: 5 | O15: 6 | P15: 7 | Q15: 8 | R15: 9 | S15: 10
C16: Hold Period | D16: ='Inputs & Monthly CF'!D31 -> 5 | H16: Purchase Price | I16: ='Inputs & Monthly CF'!J19 -> -18870000
C17: Purchase Price | D17: ='Inputs & Monthly CF'!D26 -> 18500000
C18: Purchase Price PSF | D18: ='Inputs & Monthly CF'!D28 -> 127.58621
C19: Going-In Cap Rate | D19: =J25/-I16 -> 0.067224457
C20: Going-Out Cap Rate | D20: ='Inputs & Monthly CF'!D51 -> 0.0725
C21: Exit Price | D21: =SUM('Inputs & Monthly CF'!K35:EL35) -> 20356312
C22: Unlevered Return Summary
C23: IRR | D23: ='Inputs & Monthly CF'!J40 -> 0.081882813
C24: Equity Multiple | D24: ='Inputs & Monthly CF'!J41 -> 1.3968455
C25: Net Gain (loss) | D25: ='Inputs & Monthly CF'!J42 -> 7689146 | H25: NOI | J25: =SUMIF('Inputs & Monthly CF'!$K$15:$EL$15,J$15,'Inputs & Monthly CF'!$K28:$EL28) -> 1268525.5 | K25: =SUMIF('Inputs & Monthly CF'!$K$15:$EL$15,K$15,'Inputs & Monthly CF'!$K28:$EL28) -> 1345797.6 | L25: =SUMIF('Inputs & Monthly CF'!$K$15:$EL$15,L$15,'Inputs & Monthly CF'!$K28:$EL28) -> 1377212.6 | M25: =SUMIF('Inputs & Monthly CF'!$K$15:$EL$15,M$15,'Inputs & Monthly CF'!$K28:$EL28) -> 1409346.1 | N25: =SUMIF('Inputs & Monthly CF'!$K$15:$EL$15,N$15,'Inputs & Monthly CF'!$K28:$EL28) -> 1442214 | O25: =SUMIF('Inputs & Monthly CF'!$K$15:$EL$15,O$15,'Inputs & Monthly CF'!$K28:$EL28) -> 1475832.6 | P25: =SUMIF('Inputs & Monthly CF'!$K$15:$EL$15,P$15,'Inputs & Monthly CF'!$K28:$EL28) -> 1510218.6 | Q25: =SUMIF('Inputs & Monthly CF'!$K$15:$EL$15,Q$15,'Inputs & Monthly CF'!$K28:$EL28) -> 1545388.9 | ... S25: =SUMIF('Inputs & Monthly CF'!$K$15:$EL$15,S$15,'Inputs & Monthly CF'!$K28:$EL28) -> 1618152.5
C27: NPV Discount Rate | D27: 0.08
C28: NPV | D28: =NPV($D$27,$J$36:$S$36)+$I$36 -> -50762.215
C29: Levered Return Summary
C30: IRR | D30: ='Inputs & Monthly CF'!J74 -> 0.10461835
C31: Equity Multiple | D31: ='Inputs & Monthly CF'!J75 -> 1.4960022
C32: Equity Needed at Acquisition | D32: =-(I46+I47) -> 6965250
C33: Net Gain (loss) | D33: ='Inputs & Monthly CF'!J76 -> 3927693.1
C35: Min DSCR | D35: =MIN('Inputs & Monthly CF'!J79:S79) -> 1.4277481
H36: Unlvered Cash Flow | I36: ='Inputs & Monthly CF'!J39 -> -18870000 | J36: =SUMIF('Inputs & Monthly CF'!$K$15:$EL$15,J$15,'Inputs & Monthly CF'!$K39:$EL39) -> 1239525.5 | K36: =SUMIF('Inputs & Monthly CF'!$K$15:$EL$15,K$15,'Inputs & Monthly CF'!$K39:$EL39) -> 1316217.6 | L36: =SUMIF('Inputs & Monthly CF'!$K$15:$EL$15,L$15,'Inputs & Monthly CF'!$K39:$EL39) -> 1163041 | M36: =SUMIF('Inputs & Monthly CF'!$K$15:$EL$15,M$15,'Inputs & Monthly CF'!$K39:$EL39) -> 1378571.1 | N36: =SUMIF('Inputs & Monthly CF'!$K$15:$EL$15,N$15,'Inputs & Monthly CF'!$K39:$EL39) -> 21461791 | O36: =SUMIF('Inputs & Monthly CF'!$K$15:$EL$15,O$15,'Inputs & Monthly CF'!$K39:$EL39) -> 0 | P36: =SUMIF('Inputs & Monthly CF'!$K$15:$EL$15,P$15,'Inputs & Monthly CF'!$K39:$EL39) -> 0 | Q36: =SUMIF('Inputs & Monthly CF'!$K$15:$EL$15,Q$15,'Inputs & Monthly CF'!$K39:$EL39) -> 0 | ... S36: =SUMIF('Inputs & Monthly CF'!$K$15:$EL$15,S$15,'Inputs & Monthly CF'!$K39:$EL39) -> 0
H43: Levered DCF
H46: Purchase Price | I46: ='Inputs & Monthly CF'!J49 -> -18870000
H47: Loan Proceeds | I47: ='Inputs & Monthly CF'!J50 -> 11904750
H70: Levered Cash Flow | I70: ='Inputs & Monthly CF'!J73 -> -6965250 | J70: =SUMIF('Inputs & Monthly CF'!$K$15:$EL$15,J$15,'Inputs & Monthly CF'!$K73:$EL73) -> 351045.58 | K70: =SUMIF('Inputs & Monthly CF'!$K$15:$EL$15,K$15,'Inputs & Monthly CF'!$K73:$EL73) -> 427737.72 | L70: =SUMIF('Inputs & Monthly CF'!$K$15:$EL$15,L$15,'Inputs & Monthly CF'!$K73:$EL73) -> 274561.11 | M70: =SUMIF('Inputs & Monthly CF'!$K$15:$EL$15,M$15,'Inputs & Monthly CF'!$K73:$EL73) -> 490091.14 | N70: =SUMIF('Inputs & Monthly CF'!$K$15:$EL$15,N$15,'Inputs & Monthly CF'!$K73:$EL73) -> 9349507.5 | O70: =SUMIF('Inputs & Monthly CF'!$K$15:$EL$15,O$15,'Inputs & Monthly CF'!$K73:$EL73) -> 0 | P70: =SUMIF('Inputs & Monthly CF'!$K$15:$EL$15,P$15,'Inputs & Monthly CF'!$K73:$EL73) -> 0 | Q70: =SUMIF('Inputs & Monthly CF'!$K$15:$EL$15,Q$15,'Inputs & Monthly CF'!$K73:$EL73) -> 0 | ... S70: =SUMIF('Inputs & Monthly CF'!$K$15:$EL$15,S$15,'Inputs & Monthly CF'!$K73:$EL73) -> 0
