Workbook

Sheet Summary
B2: STNL VALUATION MODEL | INVESTMENT SUMMARY
B6: PROPERTY DESCRIPTION | I6: LEASE SUMMARY
B7: Name | G7: Harbor Pharmacy
B11: Net Rentable Area (SF) | G11: 14500 | I11: Remaining Term (months) | L11: =Inputs!M27 -> 96
I12: Lease Type | L12: NNN
I14: PRICING/VALUATION | L14: Cap Rate | N14: Price
I15: Asking Price | L15: ='Investment Returns'!$D$23/N15 -> 0.084810606 | N15: 6600000
B16: RETURN SUMMARY | F16: Analysis Period: | G16: =Residual_Month -> 156 | I16: Acquisition Price | L16: ='Investment Returns'!$D$23/N16 -> 0.075 | N16: =Inputs!M7 -> 7463333.3
E17: Profit | F17: IRR | G17: EMx
B18: Unlevered | E18: =SUM('Investment Returns'!C33:W33) -> 9259108.4 | F18: ='Investment Returns'!E7 -> 0.089657108 | G18: ='Investment Returns'!E8 -> 2.2222788 | I18: DCF Value | L18: ='Investment Returns'!$D$23/N18 -> 0.069881395 | N18: =Valuation!C42 -> 8010000.4
B19: Levered | E19: =SUM('Investment Returns'!C34:W34) -> 5765510.5 | F19: ='Investment Returns'!E12 -> 0.12374239 | G19: ='Investment Returns'!E13 -> 3.1164697

Sheet Inputs
B2: STNL VALUATION MODEL | INPUTS
B6: ANALYSIS DETAILS | I6: PROJECT INVESTMENT | K6: % | M6: Amount
B7: Analysis Start | G7: 46023 | I7: Purchase Price | M7: ='Investment Returns'!D23/0.075 -> 7463333.3
B8: Analysis Period | G8: =F9 -> 156 | I8: Acquisition Fees | K8: 0.01 | M8: =M7*K8 -> 74633.333
B9: Analysis End | E9: Residual Month | F9: =MIN(IF($M$33="Yes",$L$35,$L$28),240) -> 156 | G9: =EOMONTH(G7,G8-1) -> 50770 | I9: Due Diligence Costs | K9: 0.005 | M9: =M7*K9 -> 37316.667
B10: General Vacancy | G10: 0 | I10: Construction Costs | M10: 0
I11: Total Project Costs | M11: =SUM(M7:M10) -> 7575283.3
B12: OTHER INCOME ASSUMPTIONS
B13: Other Income - Billboard Rent | G13: 1500 | I13: DEBT | K13: % of Price
I14: Loan Amount | K14: 0.65 | M14: =M7*K14 -> 4851166.7
B15: Income Growth (% /Yr.) | G15: 0.02 | I15: Fixed Interest Rate | M15: 0.0615
I16: Amortization | M16: 360
B17: EXPENSE ASSUMPTIONS
B18: Tenant Expense Recovery % | G18: 1 | I18: TENANT DETAILS
I19: Tenant Name | M19: Harbor Pharmacy, Inc
B20: Year 1 Operating Expenses | G20: =SF_NRA*7.25 -> 105125
B21: Year 1 Capital Expenditures | G21: =SF_NRA*0.4 -> 5800 | I21: Credit Rating | M21: BBB+
B22: Expense Growth (% /Yr.) | G22: 0.025 | I22: Credit Income Discount Rate | M22: 0.0675
I23: Spec Income Discount Rate | M23: =G26 -> 0.0925
B24: Year 1 Net Operating Income | G24: ='Investment Returns'!D23 -> 559750
B25: RESIDUAL ASSUMPTIONS | I25: LEASE RENT DETAILS
B26: Residual Discount Rate | G26: =E39+0.02 -> 0.0925
I27: Remaining Lease Term (months) | M27: 96
B28: Gross Rent | F28: =$M$43*SF_NRA*(1+$G$15)^(F9/12) -> 675262.66 | I28: Lease End | K28: End Month | L28: =ROUND(M27,0) -> 96
B29: Expense Recovery Income | F29: =$G$20*$G$18*(1+$G$22)^(F9/12) -> 144915.97
B30: Other Income | F30: =$G$13*(1+$G$15)^(F9/12) -> 1940.4099 | I30: Rent Increase Type | M30: Annual
I31: Base Rent /SF/Yr (as of Month 1) | L31: =M31*SF_NRA -> 558250 | M31: 38.5
I32: Rent Increase | M32: 0.02
I33: OPTION #1 - RENEWAL INCOME | M33: Yes
B34: - Operating Expenses | F34: =$G$20*(1+$G$22)^(F9/12) -> 144915.97 | I34: Exercise Probability | K34: Start Month | L34: =L28+1 -> 97 | M34: 0.7
B35: Net Operating Income | F35: =F28+F29+F30-F34 -> 677203.07 | I35: Length | K35: End Month | L35: =L34+ROUND(M35,0)-1 -> 156 | M35: 60
I36: Option Rent /SF/Yr | M36: =M31*(1+M32)^(ROUND(M27,0)/12)*(1+M37) -> 45.108886
I37: Option Rent Increase (% /Yr.) | M37: 0
B38: Net Residual Value | E38: Input | G38: Amount
B39: Gross Residual Value | D39: Cap Rate | E39: 0.0725 | G39: =F35/E39 -> 9340732
B42: - Selling Costs | D42: % | E42: 0.02 | G42: =E42*G39 -> 186814.64
B43: Net Residual Value | G43: =G39-G42 -> 9153917.4 | I43: Market Rent /SF/Yr (if not renewed) | M43: 36
I44: Downtime (months) | M44: 9
P78: Year | Q78: =ROUNDUP(Q79/12,0) -> 0 | R78: =ROUNDUP(R79/12,0) -> 1 | S78: =ROUNDUP(S79/12,0) -> 1 | T78: =ROUNDUP(T79/12,0) -> 1 | U78: =ROUNDUP(U79/12,0) -> 1 | V78: =ROUNDUP(V79/12,0) -> 1 | W78: =ROUNDUP(W79/12,0) -> 1 | X78: =ROUNDUP(X79/12,0) -> 1 | ... IW78: =ROUNDUP(IW79/12,0) -> 20
P79: Month | Q79: 0 | R79: 1 | S79: 2 | T79: 3 | U79: 4 | V79: 5 | W79: 6 | X79: 7 | Y79: 8 | Z79: 9 | AA79: 10 | AB79: 11 | AC79: 12 | AD79: 13 | AE79: 14 | AF79: 15 | AG79: 16 | AH79: 17 | AI79: 18 | AJ79: 19 | AK79: 20 | AL79: 21 | AM79: 22 | AN79: 23 | AO79: 24 | AP79: 25 | AQ79: 26 | AR79: 27 | AS79: 28 | AT79: 29 | AU79: 30 | AV79: 31 | AW79: 32 | AX79: 33 | AY79: 34 | AZ79: 35 | BA79: 36 | BB79: 37 | BC79: 38 | BD79: 39 | BE79: 40 | BF79: 41 | BG79: 42 | BH79: 43 | BI79: 44 | BJ79: 45 | BK79: 46 | BL79: 47 | BM79: 48 | BN79: 49 | BO79: 50 | BP79: 51 | BQ79: 52 | BR79: 53 | BS79: 54 | BT79: 55 | BU79: 56 | BV79: 57 | BW79: 58 | BX79: 59 | BY79: 60 | BZ79: 61 | CA79: 62 | CB79: 63 | CC79: 64 | CD79: 65 | CE79: 66 | CF79: 67 | CG79: 68 | CH79: 69 | CI79: 70 | CJ79: 71 | CK79: 72 | CL79: 73 | CM79: 74 | CN79: 75 | CO79: 76 | CP79: 77 | CQ79: 78 | CR79: 79 | CS79: 80 | CT79: 81 | CU79: 82 | CV79: 83 | CW79: 84 | CX79: 85 | CY79: 86 | CZ79: 87 | DA79: 88 | DB79: 89 | DC79: 90 | DD79: 91 | DE79: 92 | DF79: 93 | DG79: 94 | DH79: 95 | DI79: 96 | DJ79: 97 | DK79: 98 | DL79: 99 | DM79: 100 | DN79: 101 | DO79: 102 | DP79: 103 | DQ79: 104 | DR79: 105 | DS79: 106 | DT79: 107 | DU79: 108 | DV79: 109 | DW79: 110 | DX79: 111 | DY79: 112 | DZ79: 113 | EA79: 114 | EB79: 115 | EC79: 116 | ED79: 117 | EE79: 118 | EF79: 119 | EG79: 120 | EH79: 121 | EI79: 122 | EJ79: 123 | EK79: 124 | EL79: 125 | EM79: 126 | EN79: 127 | EO79: 128 | EP79: 129 | EQ79: 130 | ER79: 131 | ES79: 132 | ET79: 133 | EU79: 134 | EV79: 135 | EW79: 136 | EX79: 137 | EY79: 138 | EZ79: 139 | FA79: 140 | FB79: 141 | FC79: 142 | FD79: 143 | FE79: 144 | FF79: 145 | FG79: 146 | FH79: 147 | FI79: 148 | FJ79: 149 | FK79: 150 | FL79: 151 | FM79: 152 | FN79: 153 | FO79: 154 | FP79: 155 | FQ79: 156 | FR79: 157 | FS79: 158 | FT79: 159 | FU79: 160 | FV79: 161 | FW79: 162 | FX79: 163 | FY79: 164 | FZ79: 165 | GA79: 166 | GB79: 167 | GC79: 168 | GD79: 169 | GE79: 170 | GF79: 171 | GG79: 172 | GH79: 173 | GI79: 174 | GJ79: 175 | GK79: 176 | GL79: 177 | GM79: 178 | GN79: 179 | GO79: 180 | GP79: 181 | GQ79: 182 | GR79: 183 | GS79: 184 | GT79: 185 | GU79: 186 | GV79: 187 | GW79: 188 | GX79: 189 | GY79: 190 | GZ79: 191 | HA79: 192 | HB79: 193 | HC79: 194 | HD79: 195 | HE79: 196 | HF79: 197 | HG79: 198 | HH79: 199 | HI79: 200 | HJ79: 201 | HK79: 202 | HL79: 203 | HM79: 204 | HN79: 205 | HO79: 206 | HP79: 207 | HQ79: 208 | HR79: 209 | HS79: 210 | HT79: 211 | HU79: 212 | HV79: 213 | HW79: 214 | HX79: 215 | HY79: 216 | HZ79: 217 | IA79: 218 | IB79: 219 | IC79: 220 | ID79: 221 | IE79: 222 | IF79: 223 | IG79: 224 | IH79: 225 | II79: 226 | IJ79: 227 | IK79: 228 | IL79: 229 | IM79: 230 | IN79: 231 | IO79: 232 | IP79: 233 | IQ79: 234 | IR79: 235 | IS79: 236 | IT79: 237 | IU79: 238 | IV79: 239 | IW79: 240
...

Sheet Investment Returns
B2: STNL VALUATION MODEL | INVESTMENT RETURNS
B6: Unlevered Returns | K6: Debt
B7: IRR | E7: =C61 -> 0.089657108 | K7: Payment (Monthly) | N7: =PMT(Inputs!M15/12,Inputs!M16,-Inputs!M14) -> 29554.673
B8: EMx | E8: =C62 -> 2.2222788 | K8: Balloon Balance | N8: =PV(Inputs!M15/12,Inputs!M16-'Investment Returns'!N9,-Debt_Payment) -> 3734235.5
K9: Term | N9: =Residual_Month -> 156
B11: Levered Returns
B12: IRR | E12: =C66 -> 0.12374239
B13: EMx | E13: =C67 -> 3.1164697
B16: ANNUAL CASH FLOW | C16: 0 | D16: 1 | E16: 2 | F16: 3 | G16: 4 | H16: 5 | I16: 6 | J16: 7 | K16: 8 | L16: 9 | M16: 10 | N16: 11 | O16: 12 | P16: 13 | Q16: 14 | R16: 15 | S16: 16 | T16: 17 | U16: 18 | V16: 19 | W16: 20
B17: Gross Rents | C17: =SUMIF($C$37:$II$37,C$16,$C40:$II40) -> 0 | D17: =SUMIF($C$37:$II$37,D$16,$C40:$II40) -> 558250 | E17: =SUMIF($C$37:$II$37,E$16,$C40:$II40) -> 569415 | F17: =SUMIF($C$37:$II$37,F$16,$C40:$II40) -> 580803.3 | G17: =SUMIF($C$37:$II$37,G$16,$C40:$II40) -> 592419.37 | H17: =SUMIF($C$37:$II$37,H$16,$C40:$II40) -> 604267.75 | I17: =SUMIF($C$37:$II$37,I$16,$C40:$II40) -> 616353.11 | J17: =SUMIF($C$37:$II$37,J$16,$C40:$II40) -> 628680.17 | ... W17: =SUMIF($C$37:$II$37,W$16,$C40:$II40) -> 0
B23: Net Operating Income | C23: =SUMIF($C$37:$II$37,C$16,$C46:$II46) -> 0 | D23: =SUMIF($C$37:$II$37,D$16,$C46:$II46) -> 559750 | E23: =SUMIF($C$37:$II$37,E$16,$C46:$II46) -> 570945 | F23: =SUMIF($C$37:$II$37,F$16,$C46:$II46) -> 582363.9 | G23: =SUMIF($C$37:$II$37,G$16,$C46:$II46) -> 594011.18 | H23: =SUMIF($C$37:$II$37,H$16,$C46:$II46) -> 605891.4 | I23: =SUMIF($C$37:$II$37,I$16,$C46:$II46) -> 618009.23 | J23: =SUMIF($C$37:$II$37,J$16,$C46:$II46) -> 630369.41 | ... W23: =SUMIF($C$37:$II$37,W$16,$C46:$II46) -> 0
B25: Cash Flow from Operations | C25: =SUMIF($C$37:$II$37,C$16,$C48:$II48) -> 0 | D25: =SUMIF($C$37:$II$37,D$16,$C48:$II48) -> 553950 | E25: =SUMIF($C$37:$II$37,E$16,$C48:$II48) -> 565000 | F25: =SUMIF($C$37:$II$37,F$16,$C48:$II48) -> 576270.28 | G25: =SUMIF($C$37:$II$37,G$16,$C48:$II48) -> 587765.21 | H25: =SUMIF($C$37:$II$37,H$16,$C48:$II48) -> 599489.29 | I25: =SUMIF($C$37:$II$37,I$16,$C48:$II48) -> 611447.06 | J25: =SUMIF($C$37:$II$37,J$16,$C48:$II48) -> 623643.19 | ... W25: =SUMIF($C$37:$II$37,W$16,$C48:$II48) -> 0
B26: Debt Service | C26: =SUMIF($C$37:$II$37,C$16,$C49:$II49) -> 0 | D26: =SUMIF($C$37:$II$37,D$16,$C49:$II49) -> 354656.08 | E26: =SUMIF($C$37:$II$37,E$16,$C49:$II49) -> 354656.08 | F26: =SUMIF($C$37:$II$37,F$16,$C49:$II49) -> 354656.08 | G26: =SUMIF($C$37:$II$37,G$16,$C49:$II49) -> 354656.08 | H26: =SUMIF($C$37:$II$37,H$16,$C49:$II49) -> 354656.08 | I26: =SUMIF($C$37:$II$37,I$16,$C49:$II49) -> 354656.08 | J26: =SUMIF($C$37:$II$37,J$16,$C49:$II49) -> 354656.08 | ... W26: =SUMIF($C$37:$II$37,W$16,$C49:$II49) -> 0
B33: Unlevered Cash Flow | C33: =SUMIF($C$37:$II$37,C$16,$C56:$II56) -> -7575283.3 | D33: =SUMIF($C$37:$II$37,D$16,$C56:$II56) -> 553950 | E33: =SUMIF($C$37:$II$37,E$16,$C56:$II56) -> 565000 | F33: =SUMIF($C$37:$II$37,F$16,$C56:$II56) -> 576270.28 | G33: =SUMIF($C$37:$II$37,G$16,$C56:$II56) -> 587765.21 | H33: =SUMIF($C$37:$II$37,H$16,$C56:$II56) -> 599489.29 | I33: =SUMIF($C$37:$II$37,I$16,$C56:$II56) -> 611447.06 | J33: =SUMIF($C$37:$II$37,J$16,$C56:$II56) -> 623643.19 | ... W33: =SUMIF($C$37:$II$37,W$16,$C56:$II56) -> 0
B34: Levered Cash Flow | C34: =SUMIF($C$37:$II$37,C$16,$C57:$II57) -> -2724116.7 | D34: =SUMIF($C$37:$II$37,D$16,$C57:$II57) -> 199293.92 | E34: =SUMIF($C$37:$II$37,E$16,$C57:$II57) -> 210343.92 | F34: =SUMIF($C$37:$II$37,F$16,$C57:$II57) -> 221614.19 | G34: =SUMIF($C$37:$II$37,G$16,$C57:$II57) -> 233109.13 | H34: =SUMIF($C$37:$II$37,H$16,$C57:$II57) -> 244833.21 | I34: =SUMIF($C$37:$II$37,I$16,$C57:$II57) -> 256790.98 | J34: =SUMIF($C$37:$II$37,J$16,$C57:$II57) -> 268987.11 | ... W34: =SUMIF($C$37:$II$37,W$16,$C57:$II57) -> 0
B36: MONTHLY CASH FLOW
B37: Year | C37: 0 | D37: =IF(D38="","",ROUNDUP(D38/12,0)) -> 1 | E37: =IF(E38="","",ROUNDUP(E38/12,0)) -> 1 | F37: =IF(F38="","",ROUNDUP(F38/12,0)) -> 1 | G37: =IF(G38="","",ROUNDUP(G38/12,0)) -> 1 | H37: =IF(H38="","",ROUNDUP(H38/12,0)) -> 1 | I37: =IF(I38="","",ROUNDUP(I38/12,0)) -> 1 | J37: =IF(J38="","",ROUNDUP(J38/12,0)) -> 1 | K37: =IF(K38="","",ROUNDUP(K38/12,0)) -> 1 | ... II37: =IF(II38="","",ROUNDUP(II38/12,0)) -> #VALUE!
B38: Month | C38: 0 | D38: =IF(C38+1>Residual_Month,"",C38+1) -> 1 | E38: =IF(D38+1>Residual_Month,"",D38+1) -> 2 | F38: =IF(E38+1>Residual_Month,"",E38+1) -> 3 | G38: =IF(F38+1>Residual_Month,"",F38+1) -> 4 | H38: =IF(G38+1>Residual_Month,"",G38+1) -> 5 | I38: =IF(H38+1>Residual_Month,"",H38+1) -> 6 | J38: =IF(I38+1>Residual_Month,"",I38+1) -> 7 | K38: =IF(J38+1>Residual_Month,"",J38+1) -> 8 | ... II38: =IF(IH38+1>Residual_Month,"",IH38+1) -> #VALUE!
B39: Month Ending | C39: =EOMONTH(D39,-1) -> 46022 | D39: =IF(D38="","",EOMONTH(Inputs!$G$7,D38-1)) -> 46053 | E39: =IF(E38="","",EOMONTH(Inputs!$G$7,E38-1)) -> 46081 | F39: =IF(F38="","",EOMONTH(Inputs!$G$7,F38-1)) -> 46112 | G39: =IF(G38="","",EOMONTH(Inputs!$G$7,G38-1)) -> 46142 | H39: =IF(H38="","",EOMONTH(Inputs!$G$7,H38-1)) -> 46173 | I39: =IF(I38="","",EOMONTH(Inputs!$G$7,I38-1)) -> 46203 | J39: =IF(J38="","",EOMONTH(Inputs!$G$7,J38-1)) -> 46234 | K39: =IF(K38="","",EOMONTH(Inputs!$G$7,K38-1)) -> 46265 | ... II39: =IF(II38="","",EOMONTH(Inputs!$G$7,II38-1)) -> #VALUE!
B40: Gross Rents | C40: =IF(C38="","",SUM(Inputs!Q81:Q83)) -> 0 | D40: =IF(D38="","",SUM(Inputs!R81:R83)) -> 46520.833 | E40: =IF(E38="","",SUM(Inputs!S81:S83)) -> 46520.833 | F40: =IF(F38="","",SUM(Inputs!T81:T83)) -> 46520.833 | G40: =IF(G38="","",SUM(Inputs!U81:U83)) -> 46520.833 | H40: =IF(H38="","",SUM(Inputs!V81:V83)) -> 46520.833 | I40: =IF(I38="","",SUM(Inputs!W81:W83)) -> 46520.833 | J40: =IF(J38="","",SUM(Inputs!X81:X83)) -> 46520.833 | ... II40: =IF(II38="","",SUM(Inputs!IW81:IW83)) -> #VALUE!
B41: Expense Recovery | C41: =IF(C38="","",Inputs!Q91) -> 0 | D41: =IF(D38="","",Inputs!R91) -> 8760.4167 | E41: =IF(E38="","",Inputs!S91) -> 8760.4167 | F41: =IF(F38="","",Inputs!T91) -> 8760.4167 | G41: =IF(G38="","",Inputs!U91) -> 8760.4167 | H41: =IF(H38="","",Inputs!V91) -> 8760.4167 | I41: =IF(I38="","",Inputs!W91) -> 8760.4167 | J41: =IF(J38="","",Inputs!X91) -> 8760.4167 | ... II41: =IF(II38="","",Inputs!IW91) -> #VALUE!
B42: Other Income | C42: =IF(C38="","",Inputs!Q96) -> 0 | D42: =IF(D38="","",Inputs!R96) -> 125 | E42: =IF(E38="","",Inputs!S96) -> 125 | F42: =IF(F38="","",Inputs!T96) -> 125 | G42: =IF(G38="","",Inputs!U96) -> 125 | H42: =IF(H38="","",Inputs!V96) -> 125 | I42: =IF(I38="","",Inputs!W96) -> 125 | J42: =IF(J38="","",Inputs!X96) -> 125 | ... II42: =IF(II38="","",Inputs!IW96) -> #VALUE!
B43: General Vacancy | C43: =IF(C38="","",SUM(C40:C42)*-Vacancy) -> 0 | D43: =IF(D38="","",SUM(D40:D42)*-Vacancy) -> 0 | E43: =IF(E38="","",SUM(E40:E42)*-Vacancy) -> 0 | F43: =IF(F38="","",SUM(F40:F42)*-Vacancy) -> 0 | G43: =IF(G38="","",SUM(G40:G42)*-Vacancy) -> 0 | H43: =IF(H38="","",SUM(H40:H42)*-Vacancy) -> 0 | I43: =IF(I38="","",SUM(I40:I42)*-Vacancy) -> 0 | J43: =IF(J38="","",SUM(J40:J42)*-Vacancy) -> 0 | ... II43: =IF(II38="","",SUM(II40:II42)*-Vacancy) -> #VALUE!
B44: Effective Gross Revenue | C44: =IF(C38="","",SUM(C40:C43)) -> 0 | D44: =IF(D38="","",SUM(D40:D43)) -> 55406.25 | E44: =IF(E38="","",SUM(E40:E43)) -> 55406.25 | F44: =IF(F38="","",SUM(F40:F43)) -> 55406.25 | G44: =IF(G38="","",SUM(G40:G43)) -> 55406.25 | H44: =IF(H38="","",SUM(H40:H43)) -> 55406.25 | I44: =IF(I38="","",SUM(I40:I43)) -> 55406.25 | J44: =IF(J38="","",SUM(J40:J43)) -> 55406.25 | ... II44: =IF(II38="","",SUM(II40:II43)) -> #VALUE!
B45: Operating Expenses | C45: =IF(C38="","",Inputs!Q102) -> 0 | D45: =IF(D38="","",Inputs!R102) -> 8760.4167 | E45: =IF(E38="","",Inputs!S102) -> 8760.4167 | F45: =IF(F38="","",Inputs!T102) -> 8760.4167 | G45: =IF(G38="","",Inputs!U102) -> 8760.4167 | H45: =IF(H38="","",Inputs!V102) -> 8760.4167 | I45: =IF(I38="","",Inputs!W102) -> 8760.4167 | J45: =IF(J38="","",Inputs!X102) -> 8760.4167 | ... II45: =IF(II38="","",Inputs!IW102) -> #VALUE!
B46: Net Operating Income | C46: =IF(C38="","",C44-C45) -> 0 | D46: =IF(D38="","",D44-D45) -> 46645.833 | E46: =IF(E38="","",E44-E45) -> 46645.833 | F46: =IF(F38="","",F44-F45) -> 46645.833 | G46: =IF(G38="","",G44-G45) -> 46645.833 | H46: =IF(H38="","",H44-H45) -> 46645.833 | I46: =IF(I38="","",I44-I45) -> 46645.833 | J46: =IF(J38="","",J44-J45) -> 46645.833 | ... II46: =IF(II38="","",II44-II45) -> #VALUE!
B47: Capital Expenditures | C47: =IF(C38="","",Inputs!Q107) -> 0 | D47: =IF(D38="","",Inputs!R107) -> 483.33333 | E47: =IF(E38="","",Inputs!S107) -> 483.33333 | F47: =IF(F38="","",Inputs!T107) -> 483.33333 | G47: =IF(G38="","",Inputs!U107) -> 483.33333 | H47: =IF(H38="","",Inputs!V107) -> 483.33333 | I47: =IF(I38="","",Inputs!W107) -> 483.33333 | J47: =IF(J38="","",Inputs!X107) -> 483.33333 | ... II47: =IF(II38="","",Inputs!IW107) -> #VALUE!
B48: Cash Flow from Operations | C48: =IF(C38="","",C46-C47) -> 0 | D48: =IF(D38="","",D46-D47) -> 46162.5 | E48: =IF(E38="","",E46-E47) -> 46162.5 | F48: =IF(F38="","",F46-F47) -> 46162.5 | G48: =IF(G38="","",G46-G47) -> 46162.5 | H48: =IF(H38="","",H46-H47) -> 46162.5 | I48: =IF(I38="","",I46-I47) -> 46162.5 | J48: =IF(J38="","",J46-J47) -> 46162.5 | ... II48: =IF(II38="","",II46-II47) -> #VALUE!
B49: Debt Service | C49: 0 | D49: =IF(D38="","",Debt_Payment) -> 29554.673 | E49: =IF(E38="","",Debt_Payment) -> 29554.673 | F49: =IF(F38="","",Debt_Payment) -> 29554.673 | G49: =IF(G38="","",Debt_Payment) -> 29554.673 | H49: =IF(H38="","",Debt_Payment) -> 29554.673 | I49: =IF(I38="","",Debt_Payment) -> 29554.673 | J49: =IF(J38="","",Debt_Payment) -> 29554.673 | K49: =IF(K38="","",Debt_Payment) -> 29554.673 | ... II49: =IF(II38="","",Debt_Payment) -> #VALUE!
B50: Cash Flow after Financing | C50: =IF(C38="","",C48-C49) -> 0 | D50: =IF(D38="","",D48-D49) -> 16607.827 | E50: =IF(E38="","",E48-E49) -> 16607.827 | F50: =IF(F38="","",F48-F49) -> 16607.827 | G50: =IF(G38="","",G48-G49) -> 16607.827 | H50: =IF(H38="","",H48-H49) -> 16607.827 | I50: =IF(I38="","",I48-I49) -> 16607.827 | J50: =IF(J38="","",J48-J49) -> 16607.827 | ... II50: =IF(II38="","",II48-II49) -> #VALUE!
B51: Initial Investment | C51: =IF(C38="","",IF(C38>0,0,Project_TotalCost)) -> 7575283.3 | D51: =IF(D38="","",IF(D38>0,0,Project_TotalCost)) -> 0 | E51: =IF(E38="","",IF(E38>0,0,Project_TotalCost)) -> 0 | F51: =IF(F38="","",IF(F38>0,0,Project_TotalCost)) -> 0 | G51: =IF(G38="","",IF(G38>0,0,Project_TotalCost)) -> 0 | H51: =IF(H38="","",IF(H38>0,0,Project_TotalCost)) -> 0 | I51: =IF(I38="","",IF(I38>0,0,Project_TotalCost)) -> 0 | J51: =IF(J38="","",IF(J38>0,0,Project_TotalCost)) -> 0 | ... II51: =IF(II38="","",IF(II38>0,0,Project_TotalCost)) -> #VALUE!
B52: Initial Loan Draw | C52: =IF(C38="","",IF(C38=0,Debt_Amount,0)) -> 4851166.7 | D52: =IF(D38="","",IF(D38=0,Debt_Amount,0)) -> 0 | E52: =IF(E38="","",IF(E38=0,Debt_Amount,0)) -> 0 | F52: =IF(F38="","",IF(F38=0,Debt_Amount,0)) -> 0 | G52: =IF(G38="","",IF(G38=0,Debt_Amount,0)) -> 0 | H52: =IF(H38="","",IF(H38=0,Debt_Amount,0)) -> 0 | I52: =IF(I38="","",IF(I38=0,Debt_Amount,0)) -> 0 | J52: =IF(J38="","",IF(J38=0,Debt_Amount,0)) -> 0 | ... II52: =IF(II38="","",IF(II38=0,Debt_Amount,0)) -> #VALUE!
B53: Net Residual Value | C53: =IF(C38="","",IF(C38<Residual_Month,0,Residual_NetValue)) -> 0 | D53: =IF(D38="","",IF(D38<Residual_Month,0,Residual_NetValue)) -> 0 | E53: =IF(E38="","",IF(E38<Residual_Month,0,Residual_NetValue)) -> 0 | F53: =IF(F38="","",IF(F38<Residual_Month,0,Residual_NetValue)) -> 0 | G53: =IF(G38="","",IF(G38<Residual_Month,0,Residual_NetValue)) -> 0 | H53: =IF(H38="","",IF(H38<Residual_Month,0,Residual_NetValue)) -> 0 | I53: =IF(I38="","",IF(I38<Residual_Month,0,Residual_NetValue)) -> 0 | J53: =IF(J38="","",IF(J38<Residual_Month,0,Residual_NetValue)) -> 0 | ... II53: =IF(II38="","",IF(II38<Residual_Month,0,Residual_NetValue)) -> #VALUE!
B54: Loan Payoff | C54: =IF(C38="","",IF(C38=Residual_Month,Debt_Balloon,0)) -> 0 | D54: =IF(D38="","",IF(D38=Residual_Month,Debt_Balloon,0)) -> 0 | E54: =IF(E38="","",IF(E38=Residual_Month,Debt_Balloon,0)) -> 0 | F54: =IF(F38="","",IF(F38=Residual_Month,Debt_Balloon,0)) -> 0 | G54: =IF(G38="","",IF(G38=Residual_Month,Debt_Balloon,0)) -> 0 | H54: =IF(H38="","",IF(H38=Residual_Month,Debt_Balloon,0)) -> 0 | I54: =IF(I38="","",IF(I38=Residual_Month,Debt_Balloon,0)) -> 0 | J54: =IF(J38="","",IF(J38=Residual_Month,Debt_Balloon,0)) -> 0 | ... II54: =IF(II38="","",IF(II38=Residual_Month,Debt_Balloon,0)) -> #VALUE!
B56: Unlevered Cash Flow | C56: =IF(C38="","",C48-C51+C53) -> -7575283.3 | D56: =IF(D38="","",D48-D51+D53) -> 46162.5 | E56: =IF(E38="","",E48-E51+E53) -> 46162.5 | F56: =IF(F38="","",F48-F51+F53) -> 46162.5 | G56: =IF(G38="","",G48-G51+G53) -> 46162.5 | H56: =IF(H38="","",H48-H51+H53) -> 46162.5 | I56: =IF(I38="","",I48-I51+I53) -> 46162.5 | J56: =IF(J38="","",J48-J51+J53) -> 46162.5 | ... II56: =IF(II38="","",II48-II51+II53) -> #VALUE!
B57: Levered Cash Flow | C57: =IF(C38="","",C50-C51+C52+C53-C54) -> -2724116.7 | D57: =IF(D38="","",D50-D51+D52+D53-D54) -> 16607.827 | E57: =IF(E38="","",E50-E51+E52+E53-E54) -> 16607.827 | F57: =IF(F38="","",F50-F51+F52+F53-F54) -> 16607.827 | G57: =IF(G38="","",G50-G51+G52+G53-G54) -> 16607.827 | H57: =IF(H38="","",H50-H51+H52+H53-H54) -> 16607.827 | I57: =IF(I38="","",I50-I51+I52+I53-I54) -> 16607.827 | J57: =IF(J38="","",J50-J51+J52+J53-J54) -> 16607.827 | ... II57: =IF(II38="","",II50-II51+II52+II53-II54) -> #VALUE!
B59: Unlevered Returns
B61: IRR | C61: =XIRR(OFFSET($C$56,0,0,1,Residual_Month+1),OFFSET($C$39,0,0,1,Residual_Month+1)) -> 0.089657108
B62: EMx | C62: =SUMIF($C$56:$II$56,">0")/-SUMIF($C$56:$II$56,"<0") -> 2.2222788
B64: Levered Returns
...

Sheet Valuation
B2: STNL VALUATION MODEL | VALUATION
B6: VALUATION SUMMARY
B7: Year 1 NOI | C7: ='Investment Returns'!D23 -> 559750
B8: PV of Project Cash Flows | C8: =C42 -> 8010000.4
B9: Yield-on PV | C9: =C7/C8 -> 0.069881395
B14: Month | D14: 1 | E14: 2 | F14: 3 | G14: 4 | H14: 5 | I14: 6 | J14: 7 | K14: 8 | L14: 9 | M14: 10 | N14: 11 | O14: 12 | P14: 13 | Q14: 14 | R14: 15 | S14: 16 | T14: 17 | U14: 18 | V14: 19 | W14: 20 | X14: 21 | Y14: 22 | Z14: 23 | AA14: 24 | AB14: 25 | AC14: 26 | AD14: 27 | AE14: 28 | AF14: 29 | AG14: 30 | AH14: 31 | AI14: 32 | AJ14: 33 | AK14: 34 | AL14: 35 | AM14: 36 | AN14: 37 | AO14: 38 | AP14: 39 | AQ14: 40 | AR14: 41 | AS14: 42 | AT14: 43 | AU14: 44 | AV14: 45 | AW14: 46 | AX14: 47 | AY14: 48 | AZ14: 49 | BA14: 50 | BB14: 51 | BC14: 52 | BD14: 53 | BE14: 54 | BF14: 55 | BG14: 56 | BH14: 57 | BI14: 58 | BJ14: 59 | BK14: 60 | BL14: 61 | BM14: 62 | BN14: 63 | BO14: 64 | BP14: 65 | BQ14: 66 | BR14: 67 | BS14: 68 | BT14: 69 | BU14: 70 | BV14: 71 | BW14: 72 | BX14: 73 | BY14: 74 | BZ14: 75 | CA14: 76 | CB14: 77 | CC14: 78 | CD14: 79 | CE14: 80 | CF14: 81 | CG14: 82 | CH14: 83 | CI14: 84 | CJ14: 85 | CK14: 86 | CL14: 87 | CM14: 88 | CN14: 89 | CO14: 90 | CP14: 91 | CQ14: 92 | CR14: 93 | CS14: 94 | CT14: 95 | CU14: 96 | CV14: 97 | CW14: 98 | CX14: 99 | CY14: 100 | CZ14: 101 | DA14: 102 | DB14: 103 | DC14: 104 | DD14: 105 | DE14: 106 | DF14: 107 | DG14: 108 | DH14: 109 | DI14: 110 | DJ14: 111 | DK14: 112 | DL14: 113 | DM14: 114 | DN14: 115 | DO14: 116 | DP14: 117 | DQ14: 118 | DR14: 119 | DS14: 120 | DT14: 121 | DU14: 122 | DV14: 123 | DW14: 124 | DX14: 125 | DY14: 126 | DZ14: 127 | EA14: 128 | EB14: 129 | EC14: 130 | ED14: 131 | EE14: 132 | EF14: 133 | EG14: 134 | EH14: 135 | EI14: 136 | EJ14: 137 | EK14: 138 | EL14: 139 | EM14: 140 | EN14: 141 | EO14: 142 | EP14: 143 | EQ14: 144 | ER14: 145 | ES14: 146 | ET14: 147 | EU14: 148 | EV14: 149 | EW14: 150 | EX14: 151 | EY14: 152 | EZ14: 153 | FA14: 154 | FB14: 155 | FC14: 156 | FD14: 157 | FE14: 158 | FF14: 159 | FG14: 160 | FH14: 161 | FI14: 162 | FJ14: 163 | FK14: 164 | FL14: 165 | FM14: 166 | FN14: 167 | FO14: 168 | FP14: 169 | FQ14: 170 | FR14: 171 | FS14: 172 | FT14: 173 | FU14: 174 | FV14: 175 | FW14: 176 | FX14: 177 | FY14: 178 | FZ14: 179 | GA14: 180 | GB14: 181 | GC14: 182 | GD14: 183 | GE14: 184 | GF14: 185 | GG14: 186 | GH14: 187 | GI14: 188 | GJ14: 189 | GK14: 190 | GL14: 191 | GM14: 192 | GN14: 193 | GO14: 194 | GP14: 195 | GQ14: 196 | GR14: 197 | GS14: 198 | GT14: 199 | GU14: 200 | GV14: 201 | GW14: 202 | GX14: 203 | GY14: 204 | GZ14: 205 | HA14: 206 | HB14: 207 | HC14: 208 | HD14: 209 | HE14: 210 | HF14: 211 | HG14: 212 | HH14: 213 | HI14: 214 | HJ14: 215 | HK14: 216 | HL14: 217 | HM14: 218 | HN14: 219 | HO14: 220 | HP14: 221 | HQ14: 222 | HR14: 223 | HS14: 224 | HT14: 225 | HU14: 226 | HV14: 227 | HW14: 228 | HX14: 229 | HY14: 230 | HZ14: 231 | IA14: 232 | IB14: 233 | IC14: 234 | ID14: 235 | IE14: 236 | IF14: 237 | IG14: 238 | IH14: 239 | II14: 240
B15: Month Ending | D15: ='Investment Returns'!D39 -> 46053 | E15: ='Investment Returns'!E39 -> 46081 | F15: ='Investment Returns'!F39 -> 46112 | G15: ='Investment Returns'!G39 -> 46142 | H15: ='Investment Returns'!H39 -> 46173 | I15: ='Investment Returns'!I39 -> 46203 | J15: ='Investment Returns'!J39 -> 46234 | K15: ='Investment Returns'!K39 -> 46265 | ... II15: ='Investment Returns'!II39 -> #VALUE!
C33: Discount Rate
B34: Credit Cash Flow | C34: =Discount_Rate_Credit -> 0.0675 | D34: =IF(D14>Residual_Month,0,Inputs!R81+Inputs!R82+IF(SUM(Inputs!R81:R83)=0,0,(Inputs!R81+Inputs!R82)/SUM(Inputs!R81:R83))*(Inputs!R91+Inputs!R96-Inputs!R102-Inputs!R107)) -> 46162.5 | E34: =IF(E14>Residual_Month,0,Inputs!S81+Inputs!S82+IF(SUM(Inputs!S81:S83)=0,0,(Inputs!S81+Inputs!S82)/SUM(Inputs!S81:S83))*(Inputs!S91+Inputs!S96-Inputs!S102-Inputs!S107)) -> 46162.5 | F34: =IF(F14>Residual_Month,0,Inputs!T81+Inputs!T82+IF(SUM(Inputs!T81:T83)=0,0,(Inputs!T81+Inputs!T82)/SUM(Inputs!T81:T83))*(Inputs!T91+Inputs!T96-Inputs!T102-Inputs!T107)) -> 46162.5 | G34: =IF(G14>Residual_Month,0,Inputs!U81+Inputs!U82+IF(SUM(Inputs!U81:U83)=0,0,(Inputs!U81+Inputs!U82)/SUM(Inputs!U81:U83))*(Inputs!U91+Inputs!U96-Inputs!U102-Inputs!U107)) -> 46162.5 | H34: =IF(H14>Residual_Month,0,Inputs!V81+Inputs!V82+IF(SUM(Inputs!V81:V83)=0,0,(Inputs!V81+Inputs!V82)/SUM(Inputs!V81:V83))*(Inputs!V91+Inputs!V96-Inputs!V102-Inputs!V107)) -> 46162.5 | I34: =IF(I14>Residual_Month,0,Inputs!W81+Inputs!W82+IF(SUM(Inputs!W81:W83)=0,0,(Inputs!W81+Inputs!W82)/SUM(Inputs!W81:W83))*(Inputs!W91+Inputs!W96-Inputs!W102-Inputs!W107)) -> 46162.5 | J34: =IF(J14>Residual_Month,0,Inputs!X81+Inputs!X82+IF(SUM(Inputs!X81:X83)=0,0,(Inputs!X81+Inputs!X82)/SUM(Inputs!X81:X83))*(Inputs!X91+Inputs!X96-Inputs!X102-Inputs!X107)) -> 46162.5 | K34: =IF(K14>Residual_Month,0,Inputs!Y81+Inputs!Y82+IF(SUM(Inputs!Y81:Y83)=0,0,(Inputs!Y81+Inputs!Y82)/SUM(Inputs!Y81:Y83))*(Inputs!Y91+Inputs!Y96-Inputs!Y102-Inputs!Y107)) -> 46162.5 | ... II34: =IF(II14>Residual_Month,0,Inputs!IW81+Inputs!IW82+IF(SUM(Inputs!IW81:IW83)=0,0,(Inputs!IW81+Inputs!IW82)/SUM(Inputs!IW81:IW83))*(Inputs!IW91+Inputs!IW96-Inputs!IW102-Inputs!IW107)) -> 0
B35: Spec Cash Flow | C35: =Discount_Rate_Spec -> 0.0925 | D35: =IF(D14>Residual_Month,0,Inputs!R83+IF(SUM(Inputs!R81:R83)=0,0,Inputs!R83/SUM(Inputs!R81:R83))*(Inputs!R91+Inputs!R96-Inputs!R102-Inputs!R107)) -> 0 | E35: =IF(E14>Residual_Month,0,Inputs!S83+IF(SUM(Inputs!S81:S83)=0,0,Inputs!S83/SUM(Inputs!S81:S83))*(Inputs!S91+Inputs!S96-Inputs!S102-Inputs!S107)) -> 0 | F35: =IF(F14>Residual_Month,0,Inputs!T83+IF(SUM(Inputs!T81:T83)=0,0,Inputs!T83/SUM(Inputs!T81:T83))*(Inputs!T91+Inputs!T96-Inputs!T102-Inputs!T107)) -> 0 | G35: =IF(G14>Residual_Month,0,Inputs!U83+IF(SUM(Inputs!U81:U83)=0,0,Inputs!U83/SUM(Inputs!U81:U83))*(Inputs!U91+Inputs!U96-Inputs!U102-Inputs!U107)) -> 0 | H35: =IF(H14>Residual_Month,0,Inputs!V83+IF(SUM(Inputs!V81:V83)=0,0,Inputs!V83/SUM(Inputs!V81:V83))*(Inputs!V91+Inputs!V96-Inputs!V102-Inputs!V107)) -> 0 | I35: =IF(I14>Residual_Month,0,Inputs!W83+IF(SUM(Inputs!W81:W83)=0,0,Inputs!W83/SUM(Inputs!W81:W83))*(Inputs!W91+Inputs!W96-Inputs!W102-Inputs!W107)) -> 0 | J35: =IF(J14>Residual_Month,0,Inputs!X83+IF(SUM(Inputs!X81:X83)=0,0,Inputs!X83/SUM(Inputs!X81:X83))*(Inputs!X91+Inputs!X96-Inputs!X102-Inputs!X107)) -> 0 | K35: =IF(K14>Residual_Month,0,Inputs!Y83+IF(SUM(Inputs!Y81:Y83)=0,0,Inputs!Y83/SUM(Inputs!Y81:Y83))*(Inputs!Y91+Inputs!Y96-Inputs!Y102-Inputs!Y107)) -> 0 | ... II35: =IF(II14>Residual_Month,0,Inputs!IW83+IF(SUM(Inputs!IW81:IW83)=0,0,Inputs!IW83/SUM(Inputs!IW81:IW83))*(Inputs!IW91+Inputs!IW96-Inputs!IW102-Inputs!IW107)) -> 0
B36: Residual Cash Flow | C36: =Discount_Rate_Residual -> 0.0925 | D36: =(D14=Residual_Month)*Residual_NetValue -> 0 | E36: =(E14=Residual_Month)*Residual_NetValue -> 0 | F36: =(F14=Residual_Month)*Residual_NetValue -> 0 | G36: =(G14=Residual_Month)*Residual_NetValue -> 0 | H36: =(H14=Residual_Month)*Residual_NetValue -> 0 | I36: =(I14=Residual_Month)*Residual_NetValue -> 0 | J36: =(J14=Residual_Month)*Residual_NetValue -> 0 | K36: =(K14=Residual_Month)*Residual_NetValue -> 0 | ... II36: =(II14=Residual_Month)*Residual_NetValue -> 0
C38: PV of CF
B39: Credit Cash Flow | C39: =XNPV(C34,OFFSET(D34,0,0,1,Residual_Month),OFFSET($D$15,0,0,1,Residual_Month)) -> 4837753.7
B40: Spec Cash Flow | C40: =XNPV(C35,OFFSET(D35,0,0,1,Residual_Month),OFFSET($D$15,0,0,1,Residual_Month)) -> 254311.85
B41: Residual Cash Flow | C41: =XNPV(C36,OFFSET(D36,0,0,1,Residual_Month),OFFSET($D$15,0,0,1,Residual_Month)) -> 2917934.9
B42: Present Value | C42: =SUM(C39:C41) -> 8010000.4
