Workbook

Sheet Underwriting
B2: DATA CENTER DEVELOPMENT | UNDERWRITING
B3: All amounts in USD | H3: KEY METRICS
I4: EQUITY MULTIPLE | J4: IRR | K4: NET PROFIT
H5: Unlevered | I5: =SUMIF($S$104:$CY$104,">0")/-SUMIF($S$104:$CY$104,"<0") -> 1.960866 | J5: =XIRR(OFFSET($S$104,0,0,1,Sale_Month+1),OFFSET($S$51,0,0,1,Sale_Month+1)) -> 0.1541769 | K5: =SUM($S$104:$CY$104) -> 4.1251575e+08
B6: TIMING | H6: Levered | I6: =SUMIF($S$112:$CY$112,">0")/-SUMIF($S$112:$CY$112,"<0") -> 2.6037985 | J6: =XIRR(OFFSET($S$112,0,0,1,Sale_Month+1),OFFSET($S$51,0,0,1,Sale_Month+1)) -> 0.2507876 | K6: =SUM($S$112:$CY$112) -> 3.125069e+08
B7: Analysis Start | E7: 46388
B8: Sale Month | E8: 72 | H8: YIELD ON COST
B9: Stabilization (1st month) | E9: =MAX(F29+G29,F30+G30,F31+G31,F32+G32) -> 40 | H9: Untrended | J9: =Stabilized_NOI_Untrended/Project_Cost_Total -> 0.092109212
B10: Total IT Load (kW) | E10: =SUM(C29:C32) -> 24000 | H10: Trended | J10: =Stabilized_NOI/Project_Cost_Total -> 0.094514003
B11: Land Area (SF) | E11: 420000 | H11: At Sale | J11: =Exit_NOI/Project_Cost_Total -> 0.10264949
B12: Gross Building Area (SF) | E12: 185000 | H12: Development Spread (bps) | J12: =(J10-Exit_Cap)*10000 -> 320.14003
B14: USES | C14: Per kW | D14: Per GSF | E14: Total | F14: Start Month | G14: End Month | H14: Method
B15: Land Acquisition | E15: =E11*42 -> 17640000 | F15: 0 | G15: 0 | H15: Straight-Line
B16: Shell & Core | D16: 410 | E16: =D16*E12 -> 75850000 | F16: 1 | G16: 16 | H16: S-Curve
B17: Power & Cooling (MEP) | C17: 9800 | E17: =C17*IT_Load -> 235200000 | F17: 4 | G17: 20 | H17: S-Curve
B18: Fit-Out & IT Infrastructure | C18: 1400 | E18: =C18*IT_Load -> 33600000 | F18: 12 | G18: 22 | H18: Straight-Line
B19: Soft Costs | E19: =0.11*SUM(E16:E18) -> 37911500 | F19: 1 | G19: 22 | H19: Straight-Line
B20: Developer Fee | E20: =0.03*SUM(E16:E18) -> 10339500 | F20: 1 | G20: 22 | H20: Straight-Line
B21: Contingency | E21: =0.05*SUM(E16:E18) -> 17232500 | F21: 4 | G21: 22 | H21: S-Curve
B22: Total Project Cost | E22: =SUM(E15:E21) -> 427773500
B24: FINANCING
B25: Construction Loan to Cost | E25: 0.6 | F25: Rate | G25: 0.075
B26: Permanent Loan LTV | E26: 0.5 | F26: Rate | G26: 0.0625
B28: TENANT | C28: IT Load (kW) | D28: Rent / kW / Month | E28: Growth (% /Yr.) | F28: Lease Start Month | G28: Ramp-Up (months)
B29: Hyperscaler A | C29: 12000 | D29: 128 | E29: 0.025 | F29: 20 | G29: 12
B30: Hyperscaler B | C30: 8000 | D30: 134 | E30: 0.025 | F30: 24 | G30: 9
B31: Enterprise Colocation | C31: 2500 | D31: 195 | E31: 0.03 | F31: 22 | G31: 18
B32: Cloud On-Ramp | C32: 1500 | D32: 170 | E32: 0.03 | F32: 26 | G32: 6
B33: Total | C33: =SUM(C29:C32) -> 24000
B35: OPERATING EXPENSES | C35: Year 1 | D35: Basis
B36: Utilities | C36: 1150 | D36: per leased kW / yr
B37: Maintenance | C37: 2600000 | D37: fixed / yr
B38: Staffing | C38: 3300000 | D38: fixed / yr
B39: Insurance | C39: 950000 | D39: fixed / yr
B40: G&A | C40: 650000 | D40: fixed / yr
B41: Property Taxes | C41: 1900000 | D41: fixed / yr
B42: Management Fee | C42: 0.02 | D42: % of rent
B43: Expense Growth (% /Yr.) | C43: 0.03
B44: Expense Recovery % | C44: 1
B45: Opex Start Month | C45: =MIN(F29:F32) -> 20
...

Sheet Annual CF
B2: DATA CENTER DEVELOPMENT | ANNUAL CASH FLOW
B4: Year | C4: 0 | D4: 1 | E4: 2 | F4: 3 | G4: 4 | H4: 5 | I4: 6 | J4: 7
B5: Total Development Cost | C5: =SUMIF(Underwriting!$S$52:$CY$52,C$4,Underwriting!$S$61:$CY$61) -> 17640000 | D5: =SUMIF(Underwriting!$S$52:$CY$52,D$4,Underwriting!$S$61:$CY$61) -> 2.3047078e+08 | E5: =SUMIF(Underwriting!$S$52:$CY$52,E$4,Underwriting!$S$61:$CY$61) -> 1.7966272e+08 | F5: =SUMIF(Underwriting!$S$52:$CY$52,F$4,Underwriting!$S$61:$CY$61) -> 0 | G5: =SUMIF(Underwriting!$S$52:$CY$52,G$4,Underwriting!$S$61:$CY$61) -> 0 | H5: =SUMIF(Underwriting!$S$52:$CY$52,H$4,Underwriting!$S$61:$CY$61) -> 0 | I5: =SUMIF(Underwriting!$S$52:$CY$52,I$4,Underwriting!$S$61:$CY$61) -> 0 | J5: =SUMIF(Underwriting!$S$52:$CY$52,J$4,Underwriting!$S$61:$CY$61) -> 0
B6: Total Rental Revenue | C6: =SUMIF(Underwriting!$S$52:$CY$52,C$4,Underwriting!$S$68:$CY$68) -> 0 | D6: =SUMIF(Underwriting!$S$52:$CY$52,D$4,Underwriting!$S$68:$CY$68) -> 0 | E6: =SUMIF(Underwriting!$S$52:$CY$52,E$4,Underwriting!$S$68:$CY$68) -> 2201611.1 | F6: =SUMIF(Underwriting!$S$52:$CY$52,F$4,Underwriting!$S$68:$CY$68) -> 30780814 | G6: =SUMIF(Underwriting!$S$52:$CY$52,G$4,Underwriting!$S$68:$CY$68) -> 41433824 | H6: =SUMIF(Underwriting!$S$52:$CY$52,H$4,Underwriting!$S$68:$CY$68) -> 42601523 | I6: =SUMIF(Underwriting!$S$52:$CY$52,I$4,Underwriting!$S$68:$CY$68) -> 43714018 | J6: =SUMIF(Underwriting!$S$52:$CY$52,J$4,Underwriting!$S$68:$CY$68) -> 0
B7: Total Recovery Income | C7: =SUMIF(Underwriting!$S$52:$CY$52,C$4,Underwriting!$S$74:$CY$74) -> 0 | D7: =SUMIF(Underwriting!$S$52:$CY$52,D$4,Underwriting!$S$74:$CY$74) -> 0 | E7: =SUMIF(Underwriting!$S$52:$CY$52,E$4,Underwriting!$S$74:$CY$74) -> 2212791.3 | F7: =SUMIF(Underwriting!$S$52:$CY$52,F$4,Underwriting!$S$74:$CY$74) -> 30352402 | G7: =SUMIF(Underwriting!$S$52:$CY$52,G$4,Underwriting!$S$74:$CY$74) -> 40372405 | H7: =SUMIF(Underwriting!$S$52:$CY$52,H$4,Underwriting!$S$74:$CY$74) -> 41643826 | I7: =SUMIF(Underwriting!$S$52:$CY$52,I$4,Underwriting!$S$74:$CY$74) -> 42893141 | J7: =SUMIF(Underwriting!$S$52:$CY$52,J$4,Underwriting!$S$74:$CY$74) -> 0
B8: Total Operating Expenses | C8: =SUMIF(Underwriting!$S$52:$CY$52,C$4,Underwriting!$S$84:$CY$84) -> 0 | D8: =SUMIF(Underwriting!$S$52:$CY$52,D$4,Underwriting!$S$84:$CY$84) -> 0 | E8: =SUMIF(Underwriting!$S$52:$CY$52,E$4,Underwriting!$S$84:$CY$84) -> 5728821.6 | F8: =SUMIF(Underwriting!$S$52:$CY$52,F$4,Underwriting!$S$84:$CY$84) -> 33229328 | G8: =SUMIF(Underwriting!$S$52:$CY$52,G$4,Underwriting!$S$84:$CY$84) -> 41215942 | H8: =SUMIF(Underwriting!$S$52:$CY$52,H$4,Underwriting!$S$84:$CY$84) -> 42495856 | I8: =SUMIF(Underwriting!$S$52:$CY$52,I$4,Underwriting!$S$84:$CY$84) -> 43767421 | J8: =SUMIF(Underwriting!$S$52:$CY$52,J$4,Underwriting!$S$84:$CY$84) -> 0
B9: Net Operating Income | C9: =SUMIF(Underwriting!$S$52:$CY$52,C$4,Underwriting!$S$83:$CY$83) -> 0 | D9: =SUMIF(Underwriting!$S$52:$CY$52,D$4,Underwriting!$S$83:$CY$83) -> 0 | E9: =SUMIF(Underwriting!$S$52:$CY$52,E$4,Underwriting!$S$83:$CY$83) -> -1314419.2 | F9: =SUMIF(Underwriting!$S$52:$CY$52,F$4,Underwriting!$S$83:$CY$83) -> 27903888 | G9: =SUMIF(Underwriting!$S$52:$CY$52,G$4,Underwriting!$S$83:$CY$83) -> 40590287 | H9: =SUMIF(Underwriting!$S$52:$CY$52,H$4,Underwriting!$S$83:$CY$83) -> 41749493 | I9: =SUMIF(Underwriting!$S$52:$CY$52,I$4,Underwriting!$S$83:$CY$83) -> 42839737 | J9: =SUMIF(Underwriting!$S$52:$CY$52,J$4,Underwriting!$S$83:$CY$83) -> 0
B10: Net Sale Proceeds | C10: =SUMIF(Underwriting!$S$52:$CY$52,C$4,Underwriting!$S$88:$CY$88) -> 0 | D10: =SUMIF(Underwriting!$S$52:$CY$52,D$4,Underwriting!$S$88:$CY$88) -> 0 | E10: =SUMIF(Underwriting!$S$52:$CY$52,E$4,Underwriting!$S$88:$CY$88) -> 0 | F10: =SUMIF(Underwriting!$S$52:$CY$52,F$4,Underwriting!$S$88:$CY$88) -> 0 | G10: =SUMIF(Underwriting!$S$52:$CY$52,G$4,Underwriting!$S$88:$CY$88) -> 0 | H10: =SUMIF(Underwriting!$S$52:$CY$52,H$4,Underwriting!$S$88:$CY$88) -> 0 | I10: =SUMIF(Underwriting!$S$52:$CY$52,I$4,Underwriting!$S$88:$CY$88) -> 6.8852026e+08 | J10: =SUMIF(Underwriting!$S$52:$CY$52,J$4,Underwriting!$S$88:$CY$88) -> 0
B11: Unlevered Cash Flow | C11: =SUMIF(Underwriting!$S$52:$CY$52,C$4,Underwriting!$S$104:$CY$104) -> -17640000 | D11: =SUMIF(Underwriting!$S$52:$CY$52,D$4,Underwriting!$S$104:$CY$104) -> -2.3047078e+08 | E11: =SUMIF(Underwriting!$S$52:$CY$52,E$4,Underwriting!$S$104:$CY$104) -> -1.8097714e+08 | F11: =SUMIF(Underwriting!$S$52:$CY$52,F$4,Underwriting!$S$104:$CY$104) -> 27903888 | G11: =SUMIF(Underwriting!$S$52:$CY$52,G$4,Underwriting!$S$104:$CY$104) -> 40590287 | H11: =SUMIF(Underwriting!$S$52:$CY$52,H$4,Underwriting!$S$104:$CY$104) -> 41749493 | I11: =SUMIF(Underwriting!$S$52:$CY$52,I$4,Underwriting!$S$104:$CY$104) -> 7.3136e+08 | J11: =SUMIF(Underwriting!$S$52:$CY$52,J$4,Underwriting!$S$104:$CY$104) -> 0
B12: Levered Cash Flow | C12: =SUMIF(Underwriting!$S$52:$CY$52,C$4,Underwriting!$S$112:$CY$112) -> -7056000 | D12: =SUMIF(Underwriting!$S$52:$CY$52,D$4,Underwriting!$S$112:$CY$112) -> -96040057 | E12: =SUMIF(Underwriting!$S$52:$CY$52,E$4,Underwriting!$S$112:$CY$112) -> -89762750 | F12: =SUMIF(Underwriting!$S$52:$CY$52,F$4,Underwriting!$S$112:$CY$112) -> 8654080.9 | G12: =SUMIF(Underwriting!$S$52:$CY$52,G$4,Underwriting!$S$112:$CY$112) -> 87477410 | H12: =SUMIF(Underwriting!$S$52:$CY$52,H$4,Underwriting!$S$112:$CY$112) -> 21534200 | I12: =SUMIF(Underwriting!$S$52:$CY$52,I$4,Underwriting!$S$112:$CY$112) -> 3.8770002e+08 | J12: =SUMIF(Underwriting!$S$52:$CY$52,J$4,Underwriting!$S$112:$CY$112) -> 0
