Workbook

Sheet Summary
B2: =Underwriting!B2 -> RETAIL DEVELOPMENT MODEL
B4: INVESTMENT DESCRIPTION
B6: Net Rentable Area (SF) | F6: =Underwriting!E18 -> 83000
B11: Sale Month | F11: =Underwriting!I15 -> 96
N20: PARTNERSHIP RETURNS | Q20: ROI | R20: EMx | S20: IRR
N21: LP | Q21: =Underwriting!I229/-SUMIF(Underwriting!L229:DP229,"<0") -> 1.483388 | R21: =Underwriting!G229 -> 2.483388 | S21: =Underwriting!H229 -> 0.15801218
N22: GP | Q22: =Underwriting!I228/-SUMIF(Underwriting!L228:DP228,"<0") -> 3.893068 | R22: =Underwriting!G228 -> 4.893068 | S22: =Underwriting!H228 -> 0.27062634
N24: PROPERTY RETURNS | Q24: ROI | R24: EMx | S24: IRR
N25: Unlevered | Q25: =Underwriting!I211/Underwriting!I36 -> 1.1046745 | R25: =Underwriting!G211 -> 2.1017549 | S25: =Underwriting!H211 -> 0.11915338
N26: Levered | Q26: =Underwriting!I212/Underwriting!I232 -> 1.724356 | R26: =Underwriting!G212 -> 2.724356 | S26: =Underwriting!H212 -> 0.17326763
N27: DEVELOPMENT RETURNS
N28: Yield-on-Cost | S28: =Underwriting!H215 -> 0.076203211
N29: Market Cap Rate | S29: =Underwriting!H216 -> 0.0675
N30: Development Spread | S30: =Underwriting!H217 -> 87.032115
H31: USES | M31: Amount
H32: Total Project Cost | M32: =Underwriting!I36 -> 27387471

Sheet Underwriting
B2: RETAIL DEVELOPMENT MODEL
B3: Analysis Month | L3: 0 | M3: 1 | N3: 2 | O3: 3 | P3: 4 | Q3: 5 | R3: 6 | S3: 7 | T3: 8 | U3: 9 | V3: 10 | W3: 11 | X3: 12 | Y3: 13 | Z3: 14 | AA3: 15 | AB3: 16 | AC3: 17 | AD3: 18 | AE3: 19 | AF3: 20 | AG3: 21 | AH3: 22 | AI3: 23 | AJ3: 24 | AK3: 25 | AL3: 26 | AM3: 27 | AN3: 28 | AO3: 29 | AP3: 30 | AQ3: 31 | AR3: 32 | AS3: 33 | AT3: 34 | AU3: 35 | AV3: 36 | AW3: 37 | AX3: 38 | AY3: 39 | AZ3: 40 | BA3: 41 | BB3: 42 | BC3: 43 | BD3: 44 | BE3: 45 | BF3: 46 | BG3: 47 | BH3: 48 | BI3: 49 | BJ3: 50 | BK3: 51 | BL3: 52 | BM3: 53 | BN3: 54 | BO3: 55 | BP3: 56 | BQ3: 57 | BR3: 58 | BS3: 59 | BT3: 60 | BU3: 61 | BV3: 62 | BW3: 63 | BX3: 64 | BY3: 65 | BZ3: 66 | CA3: 67 | CB3: 68 | CC3: 69 | CD3: 70 | CE3: 71 | CF3: 72 | CG3: 73 | CH3: 74 | CI3: 75 | CJ3: 76 | CK3: 77 | CL3: 78 | CM3: 79 | CN3: 80 | CO3: 81 | CP3: 82 | CQ3: 83 | CR3: 84 | CS3: 85 | CT3: 86 | CU3: 87 | CV3: 88 | CW3: 89 | CX3: 90 | CY3: 91 | CZ3: 92 | DA3: 93 | DB3: 94 | DC3: 95 | DD3: 96 | DE3: 97 | DF3: 98 | DG3: 99 | DH3: 100 | DI3: 101 | DJ3: 102 | DK3: 103 | DL3: 104 | DM3: 105 | DN3: 106 | DO3: 107 | DP3: 108
B5: Levered IRR | C5: =H212 -> 0.17326763 | D5: Levered EMx: | E5: =G212 -> 2.724356 | H5: Development Spread (Untrended) | I5: =H217 -> 87.032115
B13: Analysis Begin Date | E13: 46447
F15: Sale Month | I15: 96
B17: Land Area (SF) | E17: 520000
B18: Net Rentable Area (SF) | E18: =E105 -> 83000
B24: Analysis Date | L24: =EOMONTH($E$13,L3-1) -> 46446 | M24: =EOMONTH($E$13,M3-1) -> 46477 | N24: =EOMONTH($E$13,N3-1) -> 46507 | O24: =EOMONTH($E$13,O3-1) -> 46538 | P24: =EOMONTH($E$13,P3-1) -> 46568 | Q24: =EOMONTH($E$13,Q3-1) -> 46599 | R24: =EOMONTH($E$13,R3-1) -> 46630 | S24: =EOMONTH($E$13,S3-1) -> 46660 | ... DP24: =EOMONTH($E$13,DP3-1) -> 49734
B25: USES | D25: START | E25: END | F25: METHOD | H25: /RENTABLE SF | I25: AMOUNT
B27: Land Purchase Price | D27: 0 | E27: 0 | F27: Straight-Line | H27: =I27/$E$18 -> 118.07229 | I27: 9800000
B28: Closing / Legal Costs | D28: 0 | E28: 0 | F28: Straight-Line | H28: =I28/$E$18 -> 1.1807229 | I28: =I27*0.01 -> 98000
B30: Site Work | D30: 2 | E30: 8 | F30: Straight-Line | H30: 14 | I30: =H30*E18 -> 1162000
B31: Building Shell | D31: 4 | E31: 16 | F31: S-Curve | H31: 118 | I31: =H31*E18 -> 9794000
B32: Tenant Improvements | D32: 12 | E32: 20 | F32: S-Curve | H32: 42 | I32: =H32*E18 -> 3486000
B33: Soft Costs | D33: 1 | E33: 20 | F33: Straight-Line | H33: =I33/$E$18 -> 15.66 | I33: =0.09*SUM(I30:I32) -> 1299780
B34: Developer Fee | D34: 1 | E34: 20 | F34: Straight-Line | H34: =I34/$E$18 -> 12.35652 | I34: =0.04*SUM(I27:I33) -> 1025591.2
B35: Contingency | D35: 4 | E35: 20 | F35: S-Curve | H35: =I35/$E$18 -> 8.7 | I35: =0.05*SUM(I30:I32) -> 722100
B36: Total Project Cost | I36: =SUM(I27:I35) -> 27387471
B40: Construction Loan to Cost | E40: 0.6
B41: Construction Loan Rate | E41: 0.0775
B42: Permanent Loan LTV | E42: 0.6
B43: Permanent Loan Rate | E43: 0.0625
B44: Permanent Loan Month | E44: 30
B91: RETAIL BASE RENTAL INCOME
B92: SUITE | C92: TENANT | D92: LEASE START | E92: SF | F92: RENT START | G92: RENT GROWTH % | H92: RENT/SF/YR | I92: ANNUAL RENT | K92: STEP
B93: Anchor-1 | C93: Greenfield Grocers | D93: 18 | E93: 52000 | F93: =D93+3 -> 21 | G93: 0.1 | H93: 21 | I93: =H93*E93 -> 1092000 | K93: Every 5 Years
B94: 101 | C94: Spec | D94: 20 | E94: 4200 | F94: =D94+3 -> 23 | G94: 0.03 | H94: 35 | I94: =H94*E94 -> 147000 | K94: Annual
B95: 102 | C95: Spec | D95: 22 | E95: 3600 | F95: =D95+3 -> 25 | G95: 0.03 | H95: 35 | I95: =H95*E95 -> 126000 | K95: Annual
B96: 103 | C96: Spec | D96: 24 | E96: 3600 | F96: =D96+3 -> 27 | G96: 0.03 | H96: 34 | I96: =H96*E96 -> 122400 | K96: Annual
B97: 104 | C97: Spec | D97: 26 | E97: 2800 | F97: =D97+3 -> 29 | G97: 0.03 | H97: 37 | I97: =H97*E97 -> 103600 | K97: Annual
B98: 201 | C98: Spec | D98: 22 | E98: 6000 | F98: =D98+3 -> 25 | G98: 0.03 | H98: 32 | I98: =H98*E98 -> 192000 | K98: Annual
B99: 202 | C99: Spec | D99: 28 | E99: 5200 | F99: =D99+3 -> 31 | G99: 0.03 | H99: 32 | I99: =H99*E99 -> 166400 | K99: Annual
B100: Outparcel-1 | C100: Burger Drive-Thru | D100: 16 | E100: 3200 | F100: =D100+3 -> 19 | G100: 0.1 | H100: 58 | I100: =H100*E100 -> 185600 | K100: Every 5 Years
B101: Outparcel-2 | C101: Corner Coffee | D101: 18 | E101: 2400 | F101: =D101+3 -> 21 | G101: 0.1 | H101: 64 | I101: =H101*E101 -> 153600 | K101: Every 5 Years
B105: TOTAL RENTAL INCOME | E105: =SUM(E93:E101) -> 83000 | H105: =I105/E105 -> 27.573494 | I105: =SUM(I93:I101) -> 2288600
B120: Operating Expenses / SF / Yr | E120: 7.4
B121: Expense Growth | E121: 0.03
B122: Recovery % | E122: 0.9
B123: General Vacancy | E123: 0.05
B124: Exit Cap Rate | E124: 0.07
...
